Workbook
Name aud_per_usd: [1]Sheet1!$C$6
Name aud_per_usd: [1]Sheet1!$C$6
Name aud_per_usd: [1]Sheet1!$C$6
Name aud_per_usd: [1]Sheet1!$C$6
Name aud_per_usd: [1]Sheet1!$C$6
Name aud_per_usd: [1]Sheet1!$C$6
Name aud_per_usd: [1]Sheet1!$C$6
Name aud_per_usd: [1]Sheet1!$C$6
Name aud_per_usd: [1]Sheet1!$C$6
Name aud_per_usd: [1]Sheet1!$C$6
Name aud_per_usd: [1]Sheet1!$C$6
Name aud_per_usd: [1]Sheet1!$C$6
Name aud_per_usd: [1]Sheet1!$C$6
Name aud_per_usd: [1]Sheet1!$C$6
Name aud_per_usd: [1]Sheet1!$C$6
Name aud_per_usd: [1]Sheet1!$C$6
Name aud_per_usd: [1]Sheet1!$C$6
Name aud_per_usd: [1]Sheet1!$C$6
Name aud_per_usd: [1]Sheet1!$C$6
Name aud_per_usd: [1]Sheet1!$C$6
Name aud_per_usd: [1]Sheet1!$C$6
Name aud_per_usd: [1]Sheet1!$C$6
Name aud_per_usd: [1]Sheet1!$C$6
Name aud_per_usd: [1]Sheet1!$C$6
Name aud_per_usd: [1]Sheet1!$C$6
Name aud_per_usd: [1]Sheet1!$C$6
Name aud_per_usd: [1]Sheet1!$C$6
Name aud_per_usd: [1]Sheet1!$C$6
Name aud_per_usd: [1]Sheet1!$C$6
Name aud_per_usd: [1]Sheet1!$C$6
Name aud_per_usd: [1]Sheet1!$C$6
Name aud_per_usd: [1]Sheet1!$C$6
Name aud_per_usd: [1]Sheet1!$C$6
Name aud_per_usd: [1]Sheet1!$C$6
Name aud_per_usd: [1]Sheet1!$C$6
Name aud_per_usd: [1]Sheet1!$C$6
Name aud_per_usd: [1]Sheet1!$C$6
Name aud_per_usd: [1]Sheet1!$C$6
Name aud_per_usd: [1]Sheet1!$C$6
Name aud_per_usd: [1]Sheet1!$C$6
Name aud_per_usd: [1]Sheet1!$C$6
Name aud_per_usd: [1]Sheet1!$C$6
Name aud_per_usd: [1]Sheet1!$C$6
Name aud_per_usd: [1]Sheet1!$C$6
Name aud_per_usd: [1]Sheet1!$C$6
Name aud_per_usd: [1]Sheet1!$C$6
Name aud_per_usd: [1]Sheet1!$C$6
Name aud_per_usd: [1]Sheet1!$C$6
Name aud_per_usd: [1]Sheet1!$C$6
Name aud_per_usd: [1]Sheet1!$C$6
Name aud_per_usd: [1]Sheet1!$C$6
Name aud_per_usd: [1]Sheet1!$C$6
Name aud_per_usd: [1]Sheet1!$C$6
Name aud_per_usd: [1]Sheet1!$C$6
Name aud_per_usd: [1]Sheet1!$C$6
Name aud_per_usd: [1]Sheet1!$C$6
Name aud_per_usd: [1]Sheet1!$C$6
Name aud_per_usd: [1]Sheet1!$C$6
Name aud_per_usd: [1]Sheet1!$C$6
Name aud_per_usd: [1]Sheet1!$C$6

Sheet SpotOnly
A1: SUMMARY
A2: Hong Kong Stock Exchange
A3: =INDIRECT("SUMMARY!A3") -> As of November 6, 2020
A5: Great Wall Motor (2333)
A6: Buy and Sell Spot
A7: Account | B7: BUY Spot Shares | C7: AVERAGE Spot | D7: BUY Spot HKD | F7: SELL Spot Shares | G7: AVERAGE Spot | H7: SELL Spot HKD | J7: Net Buy (Sell)Shares | K7: Net HKD | L7: Gain / Loss
A8: Citibank
A9: Account 1 | B9: =IFERROR(SUMIF(INDIRECT("'"&M9&"'!D:D"),"Buy (Spot)",INDIRECT("'"&M9&"'!E:E")),0) -> 0 | C9: =IFERROR(D9/B9,"") | D9: =IFERROR(SUMIF(INDIRECT("'"&M9&"'!D:D"),"Buy (Spot)",INDIRECT("'"&M9&"'!g:g")),0) -> 0 | F9: =IFERROR(SUMIF(INDIRECT("'"&M9&"'!D:D"),"Sell (Spot)",INDIRECT("'"&M9&"'!E:E")),0) -> 0 | G9: =IFERROR(H9/F9,"") | H9: =IFERROR(SUMIF(INDIRECT("'"&M9&"'!D:D"),"Sell (Spot)",INDIRECT("'"&M9&"'!g:g")),0) -> 0 | J9: =B9+F9 -> 0 | K9: =D9+H9 -> 0 | L9: =IFERROR(SUMIF(INDIRECT("'"&M9&"'!D:D"),"TOTAL",INDIRECT("'"&M9&"'!L:L")),0) -> 0 | M9: CB1-HKD
A10: Account 2 | B10: =IFERROR(SUMIF(INDIRECT("'"&M10&"'!D:D"),"Buy (Spot)",INDIRECT("'"&M10&"'!E:E")),0) -> 0 | C10: =IFERROR(D10/B10,"") | D10: =IFERROR(SUMIF(INDIRECT("'"&M10&"'!D:D"),"Buy (Spot)",INDIRECT("'"&M10&"'!g:g")),0) -> 0 | F10: =IFERROR(SUMIF(INDIRECT("'"&M10&"'!D:D"),"Sell (Spot)",INDIRECT("'"&M10&"'!E:E")),0) -> 0 | G10: =IFERROR(H10/F10,"") | H10: =IFERROR(SUMIF(INDIRECT("'"&M10&"'!D:D"),"Sell (Spot)",INDIRECT("'"&M10&"'!g:g")),0) -> 0 | J10: =B10+F10 -> 0 | K10: =D10+H10 -> 0 | L10: =IFERROR(SUMIF(INDIRECT("'"&M10&"'!D:D"),"TOTAL",INDIRECT("'"&M10&"'!L:L")),0) -> 0 | M10: CB2-HKD
A11: BH | B11: =IFERROR(SUMIF(INDIRECT("'"&M11&"'!D:D"),"Buy (Spot)",INDIRECT("'"&M11&"'!E:E")),0) -> 0 | C11: =IFERROR(D11/B11,"") | D11: =IFERROR(SUMIF(INDIRECT("'"&M11&"'!D:D"),"Buy (Spot)",INDIRECT("'"&M11&"'!g:g")),0) -> 0 | F11: =IFERROR(SUMIF(INDIRECT("'"&M11&"'!D:D"),"Sell (Spot)",INDIRECT("'"&M11&"'!E:E")),0) -> 0 | G11: =IFERROR(H11/F11,"") | H11: =IFERROR(SUMIF(INDIRECT("'"&M11&"'!D:D"),"Sell (Spot)",INDIRECT("'"&M11&"'!g:g")),0) -> 0 | J11: =B11+F11 -> 0 | K11: =D11+H11 -> 0 | L11: =IFERROR(SUMIF(INDIRECT("'"&M11&"'!D:D"),"TOTAL",INDIRECT("'"&M11&"'!L:L")),0) -> 0 | M11: CBBH-HKD
A12: SUB-Total | B12: =SUM(B9:B11) -> 0 | C12: =IFERROR(D12/B12,"") | D12: =SUM(D9:D11) -> 0 | F12: =SUM(F9:F11) -> 0 | G12: =IFERROR(H12/F12,"") | H12: =SUM(H9:H11) -> 0 | J12: =SUM(J9:J11) -> 0 | K12: =SUM(K9:K11) -> 0 | L12: =SUM(L9:L11) -> 0
A14: Bank of Singapore
A15: BOS | B15: =IFERROR(SUMIF(INDIRECT("'"&M15&"'!D:D"),"Buy (Spot)",INDIRECT("'"&M15&"'!E:E")),0) -> 0 | C15: =IFERROR(D15/B15,"") | D15: =IFERROR(SUMIF(INDIRECT("'"&M15&"'!D:D"),"Buy (Spot)",INDIRECT("'"&M15&"'!g:g")),0) -> 0 | F15: =IFERROR(SUMIF(INDIRECT("'"&M15&"'!D:D"),"Sell (Spot)",INDIRECT("'"&M15&"'!E:E")),0) -> 0 | G15: =IFERROR(H15/F15,"") | H15: =IFERROR(SUMIF(INDIRECT("'"&M15&"'!D:D"),"Sell (Spot)",INDIRECT("'"&M15&"'!g:g")),0) -> 0 | J15: =B15+F15 -> 0 | K15: =D15+H15 -> 0 | L15: =IFERROR(SUMIF(INDIRECT("'"&M15&"'!D:D"),"TOTAL",INDIRECT("'"&M15&"'!L:L")),0) -> 0 | M15: BOS-HKD
A16: SUB-Total | B16: =SUM(B15:B15) -> 0 | C16: =IFERROR(D16/B16,"") | D16: =SUM(D15:D15) -> 0 | F16: =SUM(F15:F15) -> 0 | G16: =IFERROR(H16/F16,"") | H16: =SUM(H15:H15) -> 0 | J16: =SUM(J15:J15) -> 0 | K16: =SUM(K15:K15) -> 0 | L16: =SUM(L15:L15) -> 0
A18: Deutsche Bank
A19: Personal | B19: =IFERROR(SUMIF(INDIRECT("'"&M19&"'!D:D"),"Buy (Spot)",INDIRECT("'"&M19&"'!E:E")),0) -> 0 | C19: =IFERROR(D19/B19,"") | D19: =IFERROR(SUMIF(INDIRECT("'"&M19&"'!D:D"),"Buy (Spot)",INDIRECT("'"&M19&"'!g:g")),0) -> 0 | F19: =IFERROR(SUMIF(INDIRECT("'"&M19&"'!D:D"),"Sell (Spot)",INDIRECT("'"&M19&"'!E:E")),0) -> 0 | G19: =IFERROR(H19/F19,"") | H19: =IFERROR(SUMIF(INDIRECT("'"&M19&"'!D:D"),"Sell (Spot)",INDIRECT("'"&M19&"'!g:g")),0) -> 0 | J19: =B19+F19 -> 0 | K19: =D19+H19 -> 0 | L19: =IFERROR(SUMIF(INDIRECT("'"&M19&"'!D:D"),"TOTAL",INDIRECT("'"&M19&"'!L:L")),0) -> 0 | M19: DBPe-HKD
A20: PL | B20: =IFERROR(SUMIF(INDIRECT("'"&M20&"'!D:D"),"Buy (Spot)",INDIRECT("'"&M20&"'!E:E")),0) -> 0 | C20: =IFERROR(D20/B20,"") | D20: =IFERROR(SUMIF(INDIRECT("'"&M20&"'!D:D"),"Buy (Spot)",INDIRECT("'"&M20&"'!g:g")),0) -> 0 | F20: =IFERROR(SUMIF(INDIRECT("'"&M20&"'!D:D"),"Sell (Spot)",INDIRECT("'"&M20&"'!E:E")),0) -> 0 | G20: =IFERROR(H20/F20,"") | H20: =IFERROR(SUMIF(INDIRECT("'"&M20&"'!D:D"),"Sell (Spot)",INDIRECT("'"&M20&"'!g:g")),0) -> 0 | J20: =B20+F20 -> 0 | K20: =D20+H20 -> 0 | L20: =IFERROR(SUMIF(INDIRECT("'"&M20&"'!D:D"),"TOTAL",INDIRECT("'"&M20&"'!L:L")),0) -> 0 | M20: DBPL-HKD
A21: SUB-Total | B21: =SUM(B19:B20) -> 0 | C21: =IFERROR(D21/B21,"") | D21: =SUM(D19:D20) -> 0 | F21: =SUM(F19:F20) -> 0 | G21: =IFERROR(H21/F21,"") | H21: =SUM(H19:H20) -> 0 | J21: =SUM(J19:J20) -> 0 | K21: =SUM(K19:K20) -> 0 | L21: =SUM(L19:L20) -> 0
A23: Standard Chartered
A24: Stocks | B24: =IFERROR(SUMIF(INDIRECT("'"&M24&"'!D:D"),"Buy (Spot)",INDIRECT("'"&M24&"'!E:E")),0) -> 0 | C24: =IFERROR(D24/B24,"") | D24: =IFERROR(SUMIF(INDIRECT("'"&M24&"'!D:D"),"Buy (Spot)",INDIRECT("'"&M24&"'!g:g")),0) -> 0 | F24: =IFERROR(SUMIF(INDIRECT("'"&M24&"'!D:D"),"Sell (Spot)",INDIRECT("'"&M24&"'!E:E")),0) -> 0 | G24: =IFERROR(H24/F24,"") | H24: =IFERROR(SUMIF(INDIRECT("'"&M24&"'!D:D"),"Sell (Spot)",INDIRECT("'"&M24&"'!g:g")),0) -> 0 | J24: =B24+F24 -> 0 | K24: =D24+H24 -> 0 | L24: =IFERROR(SUMIF(INDIRECT("'"&M24&"'!D:D"),"TOTAL",INDIRECT("'"&M24&"'!L:L")),0) -> 0 | M24: SC-HKD
A25: SUB-Total | B25: =SUM(B24:B24) -> 0 | C25: =IFERROR(D25/B25,"") | D25: =SUM(D24:D24) -> 0 | F25: =SUM(F24:F24) -> 0 | G25: =IFERROR(H25/F25,"") | H25: =SUM(H24:H24) -> 0 | J25: =SUM(J24:J24) -> 0 | K25: =SUM(K24:K24) -> 0 | L25: =L24 -> 0
A27: SHK Private
A28: SHKIS | B28: =IFERROR(SUMIF(INDIRECT("'"&M28&"'!D:D"),"Buy (Spot)",INDIRECT("'"&M28&"'!E:E")),0) -> 0 | C28: =IFERROR(D28/B28,"") | D28: =IFERROR(SUMIF(INDIRECT("'"&M28&"'!D:D"),"Buy (Spot)",INDIRECT("'"&M28&"'!g:g")),0) -> 0 | F28: =IFERROR(SUMIF(INDIRECT("'"&M28&"'!D:D"),"Sell (Spot)",INDIRECT("'"&M28&"'!E:E")),0) -> 0 | G28: =IFERROR(H28/F28,"") | H28: =IFERROR(SUMIF(INDIRECT("'"&M28&"'!D:D"),"Sell (Spot)",INDIRECT("'"&M28&"'!g:g")),0) -> 0 | J28: =B28+F28 -> 0 | K28: =D28+H28 -> 0 | L28: =IFERROR(SUMIF(INDIRECT("'"&M28&"'!D:D"),"TOTAL",INDIRECT("'"&M28&"'!L:L")),0) -> 0 | M28: SHK-HKD
A29: SUB-Total | B29: =SUM(B28:B28) -> 0 | C29: =IFERROR(D29/B29,"") | D29: =SUM(D28:D28) -> 0 | F29: =SUM(F28:F28) -> 0 | G29: =IFERROR(H29/F29,"") | H29: =SUM(H28:H28) -> 0 | J29: =SUM(J28:J28) -> 0 | K29: =SUM(K28:K28) -> 0 | L29: =L28 -> 0
A31: Morgan Stanley
A32: T1 | B32: =IFERROR(SUMIF(INDIRECT("'"&M32&"'!D:D"),"Buy (Spot)",INDIRECT("'"&M32&"'!E:E")),0) -> 0 | C32: =IFERROR(D32/B32,"") | D32: =IFERROR(SUMIF(INDIRECT("'"&M32&"'!D:D"),"Buy (Spot)",INDIRECT("'"&M32&"'!g:g")),0) -> 0 | F32: =IFERROR(SUMIF(INDIRECT("'"&M32&"'!D:D"),"Sell (Spot)",INDIRECT("'"&M32&"'!E:E")),0) -> 0 | G32: =IFERROR(H32/F32,"") | H32: =IFERROR(SUMIF(INDIRECT("'"&M32&"'!D:D"),"Sell (Spot)",INDIRECT("'"&M32&"'!g:g")),0) -> 0 | J32: =B32+F32 -> 0 | K32: =D32+H32 -> 0 | L32: =IFERROR(SUMIF(INDIRECT("'"&M32&"'!D:D"),"TOTAL",INDIRECT("'"&M32&"'!L:L")),0) -> 0 | M32: MST1-HKD
A33: T2 | B33: =IFERROR(SUMIF(INDIRECT("'"&M33&"'!D:D"),"Buy (Spot)",INDIRECT("'"&M33&"'!E:E")),0) -> 0 | C33: =IFERROR(D33/B33,"") | D33: =IFERROR(SUMIF(INDIRECT("'"&M33&"'!D:D"),"Buy (Spot)",INDIRECT("'"&M33&"'!g:g")),0) -> 0 | F33: =IFERROR(SUMIF(INDIRECT("'"&M33&"'!D:D"),"Sell (Spot)",INDIRECT("'"&M33&"'!E:E")),0) -> 0 | G33: =IFERROR(H33/F33,"") | H33: =IFERROR(SUMIF(INDIRECT("'"&M33&"'!D:D"),"Sell (Spot)",INDIRECT("'"&M33&"'!g:g")),0) -> 0 | J33: =B33+F33 -> 0 | K33: =D33+H33 -> 0 | L33: =IFERROR(SUMIF(INDIRECT("'"&M33&"'!D:D"),"TOTAL",INDIRECT("'"&M33&"'!L:L")),0) -> 0 | M33: MST2-HKD
A34: PL | B34: =IFERROR(SUMIF(INDIRECT("'"&M34&"'!D:D"),"Buy (Spot)",INDIRECT("'"&M34&"'!E:E")),0) -> 0 | C34: =IFERROR(D34/B34,"") | D34: =IFERROR(SUMIF(INDIRECT("'"&M34&"'!D:D"),"Buy (Spot)",INDIRECT("'"&M34&"'!g:g")),0) -> 0 | F34: =IFERROR(SUMIF(INDIRECT("'"&M34&"'!D:D"),"Sell (Spot)",INDIRECT("'"&M34&"'!E:E")),0) -> 0 | G34: =IFERROR(H34/F34,"") | H34: =IFERROR(SUMIF(INDIRECT("'"&M34&"'!D:D"),"Sell (Spot)",INDIRECT("'"&M34&"'!g:g")),0) -> 0 | J34: =B34+F34 -> 0 | K34: =D34+H34 -> 0 | L34: =IFERROR(SUMIF(INDIRECT("'"&M34&"'!D:D"),"TOTAL",INDIRECT("'"&M34&"'!L:L")),0) -> 0 | M34: MSPL-HKD
A35: SUB-Total | B35: =SUM(B32:B34) -> 0 | C35: =IFERROR(D35/B35,"") | D35: =SUM(D32:D34) -> 0 | F35: =SUM(F32:F34) -> 0 | G35: =IFERROR(H35/F35,"") | H35: =SUM(H32:H34) -> 0 | J35: =SUM(J32:J34) -> 0 | K35: =SUM(K32:K34) -> 0 | L35: =SUM(L32:L34) -> 0
A37: Total | B37: =SUM(B12, B16, B21, B25, B35, B29) -> 0 | C37: =IFERROR(D37/B37,"") | D37: =SUM(D12, D16, D21, D25, D35, D29) -> 0 | F37: =SUM(F12, F16, F21, F25, F35, F29) -> 0 | G37: =H37/F37 -> #DIV/0! | H37: =SUM(H12, H16, H21, H25, H35, H29) -> 0 | J37: =SUM(J12, J16, J21, J25, J35, J29) -> 0 | K37: =SUM(K12, K16, K21, K25, K35, K29) -> 0 | L37: =SUM(L12, L16, L21, L25, L35, L29) -> 0
B38: Shares | D38: HKD | F38: Shares | H38: HKD | J38: Shares | K38: HKD | L38: HKD
B39: SPOT | F39: SPOT

Sheet AQDQSpot
A1: SUMMARY
A2: Hong Kong Stock Exchange
A3: =INDIRECT("SUMMARY!A3") -> As of November 6, 2020
A5: Great Wall Motor (2333)
A6: Accu, Decu and Spot
A7: Account | B7: BUY Accu Shares | C7: AVERAGE Accu | D7: BUY Accu HKD | E7: BUY Spot Shares | F7: AVERAGE Spot | G7: BUY Spot HKD | H7: Total BUY Shares | I7: Total AVERAGE Buy | J7: SUB-Total | L7: SELL Decu Shares | M7: AVERAGE Decu | N7: SELL Decu HKD | O7: SELL Spot Shares | P7: AVERAGE Spot | Q7: SELL Spot HKD | R7: Total Sell Shares | S7: Total AVERAGE Sell | T7: SUB-Total | V7: Net Buy (Sell)Shares | W7: Net HKD | X7: Gain / Loss
A8: Citibank
A9: Account 1 | B9: =IFERROR(SUMIF(INDIRECT("'"&Y9&"'!D:D"),"Buy (Accu)",INDIRECT("'"&Y9&"'!E:E"))+SUMIF(INDIRECT("'"&Y9&"'!D:D"),"Buy (Accu-KO)",INDIRECT("'"&Y9&"'!E:E")),0) -> 0 | C9: =IFERROR(D9/B9,"") | D9: =IFERROR(SUMIF(INDIRECT("'"&Y9&"'!D:D"),"Buy (Accu)",INDIRECT("'"&Y9&"'!g:g"))+SUMIF(INDIRECT("'"&Y9&"'!D:D"),"Buy (Accu-KO)",INDIRECT("'"&Y9&"'!g:g")),0) -> 0 | E9: =IFERROR(SUMIF(INDIRECT("'"&Y9&"'!D:D"),"Buy (Spot)",INDIRECT("'"&Y9&"'!E:E")),0) -> 0 | F9: =IFERROR(G9/E9,"") | G9: =IFERROR(SUMIF(INDIRECT("'"&Y9&"'!D:D"),"Buy (Spot)",INDIRECT("'"&Y9&"'!g:g")),0) -> 0 | H9: =B9+E9 -> 0 | I9: =IFERROR(J9/H9,"") | J9: =D9+G9 -> 0 | L9: =IFERROR(SUMIF(INDIRECT("'"&Y9&"'!D:D"),"Sell (Decu)",INDIRECT("'"&Y9&"'!E:E"))+SUMIF(INDIRECT("'"&Y9&"'!D:D"),"Sell (Decu-KO)",INDIRECT("'"&Y9&"'!E:E")),0) -> 0 | M9: =IFERROR(N9/L9,"") | N9: =IFERROR(SUMIF(INDIRECT("'"&Y9&"'!D:D"),"Sell (Decu)",INDIRECT("'"&Y9&"'!g:g"))+SUMIF(INDIRECT("'"&Y9&"'!D:D"),"Sell (Decu-KO)",INDIRECT("'"&Y9&"'!g:g")),0) -> 0 | O9: =IFERROR(SUMIF(INDIRECT("'"&Y9&"'!D:D"),"Sell (Spot)",INDIRECT("'"&Y9&"'!E:E")),0) -> 0 | P9: =IFERROR(Q9/O9,"") | Q9: =IFERROR(SUMIF(INDIRECT("'"&Y9&"'!D:D"),"Sell (Spot)",INDIRECT("'"&Y9&"'!g:g")),0) -> 0 | R9: =L9+O9 -> 0 | S9: =IFERROR(T9/R9,"") | T9: =N9+Q9 -> 0 | V9: =B9+E9+L9+O9 -> 0 | W9: =SUM(J9,T9) -> 0 | X9: =IFERROR(SUMIF(INDIRECT("'"&Y9&"'!D:D"),"TOTAL",INDIRECT("'"&Y9&"'!L:L")),0) -> 0 | Y9: CB1-HKD
A10: Account 2 | B10: =IFERROR(SUMIF(INDIRECT("'"&Y10&"'!D:D"),"Buy (Accu)",INDIRECT("'"&Y10&"'!E:E"))+SUMIF(INDIRECT("'"&Y10&"'!D:D"),"Buy (Accu-KO)",INDIRECT("'"&Y10&"'!E:E")),0) -> 0 | C10: =IFERROR(D10/B10,"") | D10: =IFERROR(SUMIF(INDIRECT("'"&Y10&"'!D:D"),"Buy (Accu)",INDIRECT("'"&Y10&"'!g:g"))+SUMIF(INDIRECT("'"&Y10&"'!D:D"),"Buy (Accu-KO)",INDIRECT("'"&Y10&"'!g:g")),0) -> 0 | E10: =IFERROR(SUMIF(INDIRECT("'"&Y10&"'!D:D"),"Buy (Spot)",INDIRECT("'"&Y10&"'!E:E")),0) -> 0 | F10: =IFERROR(G10/E10,"") | G10: =IFERROR(SUMIF(INDIRECT("'"&Y10&"'!D:D"),"Buy (Spot)",INDIRECT("'"&Y10&"'!g:g")),0) -> 0 | H10: =B10+E10 -> 0 | I10: =IFERROR(J10/H10,"") | J10: =D10+G10 -> 0 | L10: =IFERROR(SUMIF(INDIRECT("'"&Y10&"'!D:D"),"Sell (Decu)",INDIRECT("'"&Y10&"'!E:E"))+SUMIF(INDIRECT("'"&Y10&"'!D:D"),"Sell (Decu-KO)",INDIRECT("'"&Y10&"'!E:E")),0) -> 0 | M10: =IFERROR(N10/L10,"") | N10: =IFERROR(SUMIF(INDIRECT("'"&Y10&"'!D:D"),"Sell (Decu)",INDIRECT("'"&Y10&"'!g:g"))+SUMIF(INDIRECT("'"&Y10&"'!D:D"),"Sell (Decu-KO)",INDIRECT("'"&Y10&"'!g:g")),0) -> 0 | O10: =IFERROR(SUMIF(INDIRECT("'"&Y10&"'!D:D"),"Sell (Spot)",INDIRECT("'"&Y10&"'!E:E")),0) -> 0 | P10: =IFERROR(Q10/O10,"") | Q10: =IFERROR(SUMIF(INDIRECT("'"&Y10&"'!D:D"),"Sell (Spot)",INDIRECT("'"&Y10&"'!g:g")),0) -> 0 | R10: =L10+O10 -> 0 | S10: =IFERROR(T10/R10,"") | T10: =N10+Q10 -> 0 | V10: =B10+E10+L10+O10 -> 0 | W10: =SUM(J10,T10) -> 0 | X10: =IFERROR(SUMIF(INDIRECT("'"&Y10&"'!D:D"),"TOTAL",INDIRECT("'"&Y10&"'!L:L")),0) -> 0 | Y10: CB2-HKD
A11: BH | B11: =IFERROR(SUMIF(INDIRECT("'"&Y11&"'!D:D"),"Buy (Accu)",INDIRECT("'"&Y11&"'!E:E"))+SUMIF(INDIRECT("'"&Y11&"'!D:D"),"Buy (Accu-KO)",INDIRECT("'"&Y11&"'!E:E")),0) -> 0 | C11: =IFERROR(D11/B11,"") | D11: =IFERROR(SUMIF(INDIRECT("'"&Y11&"'!D:D"),"Buy (Accu)",INDIRECT("'"&Y11&"'!g:g"))+SUMIF(INDIRECT("'"&Y11&"'!D:D"),"Buy (Accu-KO)",INDIRECT("'"&Y11&"'!g:g")),0) -> 0 | E11: =IFERROR(SUMIF(INDIRECT("'"&Y11&"'!D:D"),"Buy (Spot)",INDIRECT("'"&Y11&"'!E:E")),0) -> 0 | F11: =IFERROR(G11/E11,"") | G11: =IFERROR(SUMIF(INDIRECT("'"&Y11&"'!D:D"),"Buy (Spot)",INDIRECT("'"&Y11&"'!g:g")),0) -> 0 | H11: =B11+E11 -> 0 | I11: =IFERROR(J11/H11,"") | J11: =D11+G11 -> 0 | L11: =IFERROR(SUMIF(INDIRECT("'"&Y11&"'!D:D"),"Sell (Decu)",INDIRECT("'"&Y11&"'!E:E"))+SUMIF(INDIRECT("'"&Y11&"'!D:D"),"Sell (Decu-KO)",INDIRECT("'"&Y11&"'!E:E")),0) -> 0 | M11: =IFERROR(N11/L11,"") | N11: =IFERROR(SUMIF(INDIRECT("'"&Y11&"'!D:D"),"Sell (Decu)",INDIRECT("'"&Y11&"'!g:g"))+SUMIF(INDIRECT("'"&Y11&"'!D:D"),"Sell (Decu-KO)",INDIRECT("'"&Y11&"'!g:g")),0) -> 0 | O11: =IFERROR(SUMIF(INDIRECT("'"&Y11&"'!D:D"),"Sell (Spot)",INDIRECT("'"&Y11&"'!E:E")),0) -> 0 | P11: =IFERROR(Q11/O11,"") | Q11: =IFERROR(SUMIF(INDIRECT("'"&Y11&"'!D:D"),"Sell (Spot)",INDIRECT("'"&Y11&"'!g:g")),0) -> 0 | R11: =L11+O11 -> 0 | S11: =IFERROR(T11/R11,"") | T11: =N11+Q11 -> 0 | V11: =B11+E11+L11+O11 -> 0 | W11: =SUM(J11,T11) -> 0 | X11: =IFERROR(SUMIF(INDIRECT("'"&Y11&"'!D:D"),"TOTAL",INDIRECT("'"&Y11&"'!L:L")),0) -> 0 | Y11: CBBH-HKD
A12: SUB-Total | B12: =SUM(B9:B11) -> 0 | C12: =IFERROR(D12/B12,"") | D12: =SUM(D9:D11) -> 0 | E12: =SUM(E9:E11) -> 0 | F12: =IFERROR(G12/E12,"") | G12: =SUM(G9:G11) -> 0 | H12: =SUM(H9:H11) -> 0 | I12: =IFERROR(J12/H12,"") | J12: =SUM(J9:J11) -> 0 | L12: =SUM(L9:L11) -> 0 | M12: =IFERROR(N12/L12,"") | N12: =SUM(N9:N11) -> 0 | O12: =SUM(O9:O11) -> 0 | P12: =IFERROR(Q12/O12,"") | Q12: =SUM(Q9:Q11) -> 0 | R12: =SUM(R9:R11) -> 0 | S12: =IFERROR(T12/R12,"") | T12: =SUM(T9:T11) -> 0 | V12: =SUM(V9:V11) -> 0 | W12: =SUM(W9:W11) -> 0 | X12: =SUM(X9:X11) -> 0
A14: Bank of Singapore
A15: BOS | B15: =IFERROR(SUMIF(INDIRECT("'"&Y15&"'!D:D"),"Buy (Accu)",INDIRECT("'"&Y15&"'!E:E"))+SUMIF(INDIRECT("'"&Y15&"'!D:D"),"Buy (Accu-KO)",INDIRECT("'"&Y15&"'!E:E")),0) -> 0 | C15: =IFERROR(D15/B15,"") | D15: =IFERROR(SUMIF(INDIRECT("'"&Y15&"'!D:D"),"Buy (Accu)",INDIRECT("'"&Y15&"'!g:g"))+SUMIF(INDIRECT("'"&Y15&"'!D:D"),"Buy (Accu-KO)",INDIRECT("'"&Y15&"'!g:g")),0) -> 0 | E15: =IFERROR(SUMIF(INDIRECT("'"&Y15&"'!D:D"),"Buy (Spot)",INDIRECT("'"&Y15&"'!E:E")),0) -> 0 | F15: =IFERROR(G15/E15,"") | G15: =IFERROR(SUMIF(INDIRECT("'"&Y15&"'!D:D"),"Buy (Spot)",INDIRECT("'"&Y15&"'!g:g")),0) -> 0 | H15: =B15+E15 -> 0 | I15: =IFERROR(J15/H15,"") | J15: =D15+G15 -> 0 | L15: =IFERROR(SUMIF(INDIRECT("'"&Y15&"'!D:D"),"Sell (Decu)",INDIRECT("'"&Y15&"'!E:E"))+SUMIF(INDIRECT("'"&Y15&"'!D:D"),"Sell (Decu-KO)",INDIRECT("'"&Y15&"'!E:E")),0) -> 0 | M15: =IFERROR(N15/L15,"") | N15: =IFERROR(SUMIF(INDIRECT("'"&Y15&"'!D:D"),"Sell (Decu)",INDIRECT("'"&Y15&"'!g:g"))+SUMIF(INDIRECT("'"&Y15&"'!D:D"),"Sell (Decu-KO)",INDIRECT("'"&Y15&"'!g:g")),0) -> 0 | O15: =IFERROR(SUMIF(INDIRECT("'"&Y15&"'!D:D"),"Sell (Spot)",INDIRECT("'"&Y15&"'!E:E")),0) -> 0 | P15: =IFERROR(Q15/O15,"") | Q15: =IFERROR(SUMIF(INDIRECT("'"&Y15&"'!D:D"),"Sell (Spot)",INDIRECT("'"&Y15&"'!g:g")),0) -> 0 | R15: =L15+O15 -> 0 | S15: =IFERROR(T15/R15,"") | T15: =N15+Q15 -> 0 | V15: =B15+E15+L15+O15 -> 0 | W15: =SUM(J15,T15) -> 0 | X15: =IFERROR(SUMIF(INDIRECT("'"&Y15&"'!D:D"),"TOTAL",INDIRECT("'"&Y15&"'!L:L")),0) -> 0 | Y15: BOS-HKD
A16: SUB-Total | B16: =SUM(B15:B15) -> 0 | C16: =IFERROR(D16/B16,"") | D16: =SUM(D15:D15) -> 0 | E16: =SUM(E15:E15) -> 0 | F16: =IFERROR(G16/E16,"") | G16: =SUM(G15:G15) -> 0 | H16: =SUM(H15:H15) -> 0 | I16: =IFERROR(J16/H16,"") | J16: =SUM(J15:J15) -> 0 | L16: =SUM(L15:L15) -> 0 | M16: =IFERROR(N16/L16,"") | N16: =SUM(N15:N15) -> 0 | O16: =SUM(O15:O15) -> 0 | P16: =IFERROR(Q16/O16,"") | Q16: =SUM(Q15:Q15) -> 0 | R16: =SUM(R15:R15) -> 0 | S16: =IFERROR(T16/R16,"") | T16: =SUM(T15:T15) -> 0 | V16: =SUM(V15:V15) -> 0 | W16: =SUM(W15:W15) -> 0 | X16: =X15 -> 0
A18: Deutsche Bank
A19: Personal | B19: =IFERROR(SUMIF(INDIRECT("'"&Y19&"'!D:D"),"Buy (Accu)",INDIRECT("'"&Y19&"'!E:E"))+SUMIF(INDIRECT("'"&Y19&"'!D:D"),"Buy (Accu-KO)",INDIRECT("'"&Y19&"'!E:E")),0) -> 0 | C19: =IFERROR(D19/B19,"") | D19: =IFERROR(SUMIF(INDIRECT("'"&Y19&"'!D:D"),"Buy (Accu)",INDIRECT("'"&Y19&"'!g:g"))+SUMIF(INDIRECT("'"&Y19&"'!D:D"),"Buy (Accu-KO)",INDIRECT("'"&Y19&"'!g:g")),0) -> 0 | E19: =IFERROR(SUMIF(INDIRECT("'"&Y19&"'!D:D"),"Buy (Spot)",INDIRECT("'"&Y19&"'!E:E")),0) -> 0 | F19: =IFERROR(G19/E19,"") | G19: =IFERROR(SUMIF(INDIRECT("'"&Y19&"'!D:D"),"Buy (Spot)",INDIRECT("'"&Y19&"'!g:g")),0) -> 0 | H19: =B19+E19 -> 0 | I19: =IFERROR(J19/H19,"") | J19: =D19+G19 -> 0 | L19: =IFERROR(SUMIF(INDIRECT("'"&Y19&"'!D:D"),"Sell (Decu)",INDIRECT("'"&Y19&"'!E:E"))+SUMIF(INDIRECT("'"&Y19&"'!D:D"),"Sell (Decu-KO)",INDIRECT("'"&Y19&"'!E:E")),0) -> 0 | M19: =IFERROR(N19/L19,"") | N19: =IFERROR(SUMIF(INDIRECT("'"&Y19&"'!D:D"),"Sell (Decu)",INDIRECT("'"&Y19&"'!g:g"))+SUMIF(INDIRECT("'"&Y19&"'!D:D"),"Sell (Decu-KO)",INDIRECT("'"&Y19&"'!g:g")),0) -> 0 | O19: =IFERROR(SUMIF(INDIRECT("'"&Y19&"'!D:D"),"Sell (Spot)",INDIRECT("'"&Y19&"'!E:E")),0) -> 0 | P19: =IFERROR(Q19/O19,"") | Q19: =IFERROR(SUMIF(INDIRECT("'"&Y19&"'!D:D"),"Sell (Spot)",INDIRECT("'"&Y19&"'!g:g")),0) -> 0 | R19: =L19+O19 -> 0 | S19: =IFERROR(T19/R19,"") | T19: =N19+Q19 -> 0 | V19: =B19+E19+L19+O19 -> 0 | W19: =SUM(J19,T19) -> 0 | X19: =IFERROR(SUMIF(INDIRECT("'"&Y19&"'!D:D"),"TOTAL",INDIRECT("'"&Y19&"'!L:L")),0) -> 0 | Y19: DBPe-HKD
A20: PL | B20: =IFERROR(SUMIF(INDIRECT("'"&Y20&"'!D:D"),"Buy (Accu)",INDIRECT("'"&Y20&"'!E:E"))+SUMIF(INDIRECT("'"&Y20&"'!D:D"),"Buy (Accu-KO)",INDIRECT("'"&Y20&"'!E:E")),0) -> 0 | C20: =IFERROR(D20/B20,"") | D20: =IFERROR(SUMIF(INDIRECT("'"&Y20&"'!D:D"),"Buy (Accu)",INDIRECT("'"&Y20&"'!g:g"))+SUMIF(INDIRECT("'"&Y20&"'!D:D"),"Buy (Accu-KO)",INDIRECT("'"&Y20&"'!g:g")),0) -> 0 | E20: =IFERROR(SUMIF(INDIRECT("'"&Y20&"'!D:D"),"Buy (Spot)",INDIRECT("'"&Y20&"'!E:E")),0) -> 0 | F20: =IFERROR(G20/E20,"") | G20: =IFERROR(SUMIF(INDIRECT("'"&Y20&"'!D:D"),"Buy (Spot)",INDIRECT("'"&Y20&"'!g:g")),0) -> 0 | H20: =B20+E20 -> 0 | I20: =IFERROR(J20/H20,"") | J20: =D20+G20 -> 0 | L20: =IFERROR(SUMIF(INDIRECT("'"&Y20&"'!D:D"),"Sell (Decu)",INDIRECT("'"&Y20&"'!E:E"))+SUMIF(INDIRECT("'"&Y20&"'!D:D"),"Sell (Decu-KO)",INDIRECT("'"&Y20&"'!E:E")),0) -> 0 | M20: =IFERROR(N20/L20,"") | N20: =IFERROR(SUMIF(INDIRECT("'"&Y20&"'!D:D"),"Sell (Decu)",INDIRECT("'"&Y20&"'!g:g"))+SUMIF(INDIRECT("'"&Y20&"'!D:D"),"Sell (Decu-KO)",INDIRECT("'"&Y20&"'!g:g")),0) -> 0 | O20: =IFERROR(SUMIF(INDIRECT("'"&Y20&"'!D:D"),"Sell (Spot)",INDIRECT("'"&Y20&"'!E:E")),0) -> 0 | P20: =IFERROR(Q20/O20,"") | Q20: =IFERROR(SUMIF(INDIRECT("'"&Y20&"'!D:D"),"Sell (Spot)",INDIRECT("'"&Y20&"'!g:g")),0) -> 0 | R20: =L20+O20 -> 0 | S20: =IFERROR(T20/R20,"") | T20: =N20+Q20 -> 0 | V20: =B20+E20+L20+O20 -> 0 | W20: =SUM(J20,T20) -> 0 | X20: =IFERROR(SUMIF(INDIRECT("'"&Y20&"'!D:D"),"TOTAL",INDIRECT("'"&Y20&"'!L:L")),0) -> 0 | Y20: DBPL-HKD
A21: SUB-Total | B21: =SUM(B19:B20) -> 0 | C21: =IFERROR(D21/B21,"") | D21: =SUM(D19:D20) -> 0 | E21: =SUM(E19:E20) -> 0 | F21: =IFERROR(G21/E21,"") | G21: =SUM(G19:G20) -> 0 | H21: =SUM(H19:H20) -> 0 | I21: =IFERROR(J21/H21,"") | J21: =SUM(J19:J20) -> 0 | L21: =SUM(L19:L20) -> 0 | M21: =IFERROR(N21/L21,"") | N21: =SUM(N19:N20) -> 0 | O21: =SUM(O19:O20) -> 0 | P21: =IFERROR(Q21/O21,"") | Q21: =SUM(Q19:Q20) -> 0 | R21: =SUM(R19:R20) -> 0 | S21: =IFERROR(T21/R21,"") | T21: =SUM(T19:T20) -> 0 | V21: =SUM(V19:V20) -> 0 | W21: =SUM(W19:W20) -> 0 | X21: =SUM(X19:X20) -> 0
A23: Standard Chartered
A24: Stocks | B24: =IFERROR(SUMIF(INDIRECT("'"&Y24&"'!D:D"),"Buy (Accu)",INDIRECT("'"&Y24&"'!E:E"))+SUMIF(INDIRECT("'"&Y24&"'!D:D"),"Buy (Accu-KO)",INDIRECT("'"&Y24&"'!E:E")),0) -> 0 | C24: =IFERROR(D24/B24,"") | D24: =IFERROR(SUMIF(INDIRECT("'"&Y24&"'!D:D"),"Buy (Accu)",INDIRECT("'"&Y24&"'!g:g"))+SUMIF(INDIRECT("'"&Y24&"'!D:D"),"Buy (Accu-KO)",INDIRECT("'"&Y24&"'!g:g")),0) -> 0 | E24: =IFERROR(SUMIF(INDIRECT("'"&Y24&"'!D:D"),"Buy (Spot)",INDIRECT("'"&Y24&"'!E:E")),0) -> 0 | F24: =IFERROR(G24/E24,"") | G24: =IFERROR(SUMIF(INDIRECT("'"&Y24&"'!D:D"),"Buy (Spot)",INDIRECT("'"&Y24&"'!g:g")),0) -> 0 | H24: =B24+E24 -> 0 | I24: =IFERROR(J24/H24,"") | J24: =D24+G24 -> 0 | L24: =IFERROR(SUMIF(INDIRECT("'"&Y24&"'!D:D"),"Sell (Decu)",INDIRECT("'"&Y24&"'!E:E"))+SUMIF(INDIRECT("'"&Y24&"'!D:D"),"Sell (Decu-KO)",INDIRECT("'"&Y24&"'!E:E")),0) -> 0 | M24: =IFERROR(N24/L24,"") | N24: =IFERROR(SUMIF(INDIRECT("'"&Y24&"'!D:D"),"Sell (Decu)",INDIRECT("'"&Y24&"'!g:g"))+SUMIF(INDIRECT("'"&Y24&"'!D:D"),"Sell (Decu-KO)",INDIRECT("'"&Y24&"'!g:g")),0) -> 0 | O24: =IFERROR(SUMIF(INDIRECT("'"&Y24&"'!D:D"),"Sell (Spot)",INDIRECT("'"&Y24&"'!E:E")),0) -> 0 | P24: =IFERROR(Q24/O24,"") | Q24: =IFERROR(SUMIF(INDIRECT("'"&Y24&"'!D:D"),"Sell (Spot)",INDIRECT("'"&Y24&"'!g:g")),0) -> 0 | R24: =L24+O24 -> 0 | S24: =IFERROR(T24/R24,"") | T24: =N24+Q24 -> 0 | V24: =B24+E24+L24+O24 -> 0 | W24: =SUM(J24,T24) -> 0 | X24: =IFERROR(SUMIF(INDIRECT("'"&Y24&"'!D:D"),"TOTAL",INDIRECT("'"&Y24&"'!L:L")),0) -> 0 | Y24: SC-HKD
A25: SUB-Total | B25: =SUM(B24:B24) -> 0 | C25: =IFERROR(D25/B25,"") | D25: =SUM(D24:D24) -> 0 | E25: =SUM(E24:E24) -> 0 | F25: =IFERROR(G25/E25,"") | G25: =SUM(G24:G24) -> 0 | H25: =SUM(H24:H24) -> 0 | I25: =IFERROR(J25/H25,"") | J25: =SUM(J24:J24) -> 0 | L25: =SUM(L24:L24) -> 0 | M25: =IFERROR(N25/L25,"") | N25: =SUM(N24:N24) -> 0 | O25: =SUM(O24:O24) -> 0 | P25: =IFERROR(Q25/O25,"") | Q25: =SUM(Q24:Q24) -> 0 | R25: =SUM(R24:R24) -> 0 | S25: =IFERROR(T25/R25,"") | T25: =SUM(T24:T24) -> 0 | V25: =SUM(V24:V24) -> 0 | W25: =SUM(W24:W24) -> 0 | X25: =X24 -> 0
A27: SHK Private
A28: SHKIS | B28: =IFERROR(SUMIF(INDIRECT("'"&Y28&"'!D:D"),"Buy (Accu)",INDIRECT("'"&Y28&"'!E:E"))+SUMIF(INDIRECT("'"&Y28&"'!D:D"),"Buy (Accu-KO)",INDIRECT("'"&Y28&"'!E:E")),0) -> 0 | C28: =IFERROR(D28/B28,"") | D28: =IFERROR(SUMIF(INDIRECT("'"&Y28&"'!D:D"),"Buy (Accu)",INDIRECT("'"&Y28&"'!g:g"))+SUMIF(INDIRECT("'"&Y28&"'!D:D"),"Buy (Accu-KO)",INDIRECT("'"&Y28&"'!g:g")),0) -> 0 | E28: =IFERROR(SUMIF(INDIRECT("'"&Y28&"'!D:D"),"Buy (Spot)",INDIRECT("'"&Y28&"'!E:E")),0) -> 0 | F28: =IFERROR(G28/E28,"") | G28: =IFERROR(SUMIF(INDIRECT("'"&Y28&"'!D:D"),"Buy (Spot)",INDIRECT("'"&Y28&"'!g:g")),0) -> 0 | H28: =B28+E28 -> 0 | I28: =IFERROR(J28/H28,"") | J28: =D28+G28 -> 0 | L28: =IFERROR(SUMIF(INDIRECT("'"&Y28&"'!D:D"),"Sell (Decu)",INDIRECT("'"&Y28&"'!E:E"))+SUMIF(INDIRECT("'"&Y28&"'!D:D"),"Sell (Decu-KO)",INDIRECT("'"&Y28&"'!E:E")),0) -> 0 | M28: =IFERROR(N28/L28,"") | N28: =IFERROR(SUMIF(INDIRECT("'"&Y28&"'!D:D"),"Sell (Decu)",INDIRECT("'"&Y28&"'!g:g"))+SUMIF(INDIRECT("'"&Y28&"'!D:D"),"Sell (Decu-KO)",INDIRECT("'"&Y28&"'!g:g")),0) -> 0 | O28: =IFERROR(SUMIF(INDIRECT("'"&Y28&"'!D:D"),"Sell (Spot)",INDIRECT("'"&Y28&"'!E:E")),0) -> 0 | P28: =IFERROR(Q28/O28,"") | Q28: =IFERROR(SUMIF(INDIRECT("'"&Y28&"'!D:D"),"Sell (Spot)",INDIRECT("'"&Y28&"'!g:g")),0) -> 0 | R28: =L28+O28 -> 0 | S28: =IFERROR(T28/R28,"") | T28: =N28+Q28 -> 0 | V28: =B28+E28+L28+O28 -> 0 | W28: =SUM(J28,T28) -> 0 | X28: =IFERROR(SUMIF(INDIRECT("'"&Y28&"'!D:D"),"TOTAL",INDIRECT("'"&Y28&"'!L:L")),0) -> 0 | Y28: SHK-HKD
A29: SUB-Total | B29: =SUM(B28:B28) -> 0 | C29: =IFERROR(D29/B29,"") | D29: =SUM(D28:D28) -> 0 | E29: =SUM(E28:E28) -> 0 | F29: =IFERROR(G29/E29,"") | G29: =SUM(G28:G28) -> 0 | H29: =SUM(H28:H28) -> 0 | I29: =IFERROR(J29/H29,"") | J29: =SUM(J28:J28) -> 0 | L29: =SUM(L28:L28) -> 0 | M29: =IFERROR(N29/L29,"") | N29: =SUM(N28:N28) -> 0 | O29: =SUM(O28:O28) -> 0 | P29: =IFERROR(Q29/O29,"") | Q29: =SUM(Q28:Q28) -> 0 | R29: =SUM(R28:R28) -> 0 | S29: =IFERROR(T29/R29,"") | T29: =SUM(T28:T28) -> 0 | V29: =SUM(V28:V28) -> 0 | W29: =SUM(W28:W28) -> 0 | X29: =X28 -> 0
A31: Morgan Stanley
A32: T1 | B32: =IFERROR(SUMIF(INDIRECT("'"&Y32&"'!D:D"),"Buy (Accu)",INDIRECT("'"&Y32&"'!E:E"))+SUMIF(INDIRECT("'"&Y32&"'!D:D"),"Buy (Accu-KO)",INDIRECT("'"&Y32&"'!E:E")),0) -> 0 | C32: =IFERROR(D32/B32,"") | D32: =IFERROR(SUMIF(INDIRECT("'"&Y32&"'!D:D"),"Buy (Accu)",INDIRECT("'"&Y32&"'!g:g"))+SUMIF(INDIRECT("'"&Y32&"'!D:D"),"Buy (Accu-KO)",INDIRECT("'"&Y32&"'!g:g")),0) -> 0 | E32: =IFERROR(SUMIF(INDIRECT("'"&Y32&"'!D:D"),"Buy (Spot)",INDIRECT("'"&Y32&"'!E:E")),0) -> 0 | F32: =IFERROR(G32/E32,"") | G32: =IFERROR(SUMIF(INDIRECT("'"&Y32&"'!D:D"),"Buy (Spot)",INDIRECT("'"&Y32&"'!g:g")),0) -> 0 | H32: =B32+E32 -> 0 | I32: =IFERROR(J32/H32,"") | J32: =D32+G32 -> 0 | L32: =IFERROR(SUMIF(INDIRECT("'"&Y32&"'!D:D"),"Sell (Decu)",INDIRECT("'"&Y32&"'!E:E"))+SUMIF(INDIRECT("'"&Y32&"'!D:D"),"Sell (Decu-KO)",INDIRECT("'"&Y32&"'!E:E")),0) -> 0 | M32: =IFERROR(N32/L32,"") | N32: =IFERROR(SUMIF(INDIRECT("'"&Y32&"'!D:D"),"Sell (Decu)",INDIRECT("'"&Y32&"'!g:g"))+SUMIF(INDIRECT("'"&Y32&"'!D:D"),"Sell (Decu-KO)",INDIRECT("'"&Y32&"'!g:g")),0) -> 0 | O32: =IFERROR(SUMIF(INDIRECT("'"&Y32&"'!D:D"),"Sell (Spot)",INDIRECT("'"&Y32&"'!E:E")),0) -> 0 | P32: =IFERROR(Q32/O32,"") | Q32: =IFERROR(SUMIF(INDIRECT("'"&Y32&"'!D:D"),"Sell (Spot)",INDIRECT("'"&Y32&"'!g:g")),0) -> 0 | R32: =L32+O32 -> 0 | S32: =IFERROR(T32/R32,"") | T32: =N32+Q32 -> 0 | V32: =B32+E32+L32+O32 -> 0 | W32: =SUM(J32,T32) -> 0 | X32: =IFERROR(SUMIF(INDIRECT("'"&Y32&"'!D:D"),"TOTAL",INDIRECT("'"&Y32&"'!L:L")),0) -> 0 | Y32: MST1-HKD
A33: T2 | B33: =IFERROR(SUMIF(INDIRECT("'"&Y33&"'!D:D"),"Buy (Accu)",INDIRECT("'"&Y33&"'!E:E"))+SUMIF(INDIRECT("'"&Y33&"'!D:D"),"Buy (Accu-KO)",INDIRECT("'"&Y33&"'!E:E")),0) -> 0 | C33: =IFERROR(D33/B33,"") | D33: =IFERROR(SUMIF(INDIRECT("'"&Y33&"'!D:D"),"Buy (Accu)",INDIRECT("'"&Y33&"'!g:g"))+SUMIF(INDIRECT("'"&Y33&"'!D:D"),"Buy (Accu-KO)",INDIRECT("'"&Y33&"'!g:g")),0) -> 0 | E33: =IFERROR(SUMIF(INDIRECT("'"&Y33&"'!D:D"),"Buy (Spot)",INDIRECT("'"&Y33&"'!E:E")),0) -> 0 | F33: =IFERROR(G33/E33,"") | G33: =IFERROR(SUMIF(INDIRECT("'"&Y33&"'!D:D"),"Buy (Spot)",INDIRECT("'"&Y33&"'!g:g")),0) -> 0 | H33: =B33+E33 -> 0 | I33: =IFERROR(J33/H33,"") | J33: =D33+G33 -> 0 | L33: =IFERROR(SUMIF(INDIRECT("'"&Y33&"'!D:D"),"Sell (Decu)",INDIRECT("'"&Y33&"'!E:E"))+SUMIF(INDIRECT("'"&Y33&"'!D:D"),"Sell (Decu-KO)",INDIRECT("'"&Y33&"'!E:E")),0) -> 0 | M33: =IFERROR(N33/L33,"") | N33: =IFERROR(SUMIF(INDIRECT("'"&Y33&"'!D:D"),"Sell (Decu)",INDIRECT("'"&Y33&"'!g:g"))+SUMIF(INDIRECT("'"&Y33&"'!D:D"),"Sell (Decu-KO)",INDIRECT("'"&Y33&"'!g:g")),0) -> 0 | O33: =IFERROR(SUMIF(INDIRECT("'"&Y33&"'!D:D"),"Sell (Spot)",INDIRECT("'"&Y33&"'!E:E")),0) -> 0 | P33: =IFERROR(Q33/O33,"") | Q33: =IFERROR(SUMIF(INDIRECT("'"&Y33&"'!D:D"),"Sell (Spot)",INDIRECT("'"&Y33&"'!g:g")),0) -> 0 | R33: =L33+O33 -> 0 | S33: =IFERROR(T33/R33,"") | T33: =N33+Q33 -> 0 | V33: =B33+E33+L33+O33 -> 0 | W33: =SUM(J33,T33) -> 0 | X33: =IFERROR(SUMIF(INDIRECT("'"&Y33&"'!D:D"),"TOTAL",INDIRECT("'"&Y33&"'!L:L")),0) -> 0 | Y33: MST2-HKD
A34: PL | B34: =IFERROR(SUMIF(INDIRECT("'"&Y34&"'!D:D"),"Buy (Accu)",INDIRECT("'"&Y34&"'!E:E"))+SUMIF(INDIRECT("'"&Y34&"'!D:D"),"Buy (Accu-KO)",INDIRECT("'"&Y34&"'!E:E")),0) -> 0 | C34: =IFERROR(D34/B34,"") | D34: =IFERROR(SUMIF(INDIRECT("'"&Y34&"'!D:D"),"Buy (Accu)",INDIRECT("'"&Y34&"'!g:g"))+SUMIF(INDIRECT("'"&Y34&"'!D:D"),"Buy (Accu-KO)",INDIRECT("'"&Y34&"'!g:g")),0) -> 0 | E34: =IFERROR(SUMIF(INDIRECT("'"&Y34&"'!D:D"),"Buy (Spot)",INDIRECT("'"&Y34&"'!E:E")),0) -> 0 | F34: =IFERROR(G34/E34,"") | G34: =IFERROR(SUMIF(INDIRECT("'"&Y34&"'!D:D"),"Buy (Spot)",INDIRECT("'"&Y34&"'!g:g")),0) -> 0 | H34: =B34+E34 -> 0 | I34: =IFERROR(J34/H34,"") | J34: =D34+G34 -> 0 | L34: =IFERROR(SUMIF(INDIRECT("'"&Y34&"'!D:D"),"Sell (Decu)",INDIRECT("'"&Y34&"'!E:E"))+SUMIF(INDIRECT("'"&Y34&"'!D:D"),"Sell (Decu-KO)",INDIRECT("'"&Y34&"'!E:E")),0) -> 0 | M34: =IFERROR(N34/L34,"") | N34: =IFERROR(SUMIF(INDIRECT("'"&Y34&"'!D:D"),"Sell (Decu)",INDIRECT("'"&Y34&"'!g:g"))+SUMIF(INDIRECT("'"&Y34&"'!D:D"),"Sell (Decu-KO)",INDIRECT("'"&Y34&"'!g:g")),0) -> 0 | O34: =IFERROR(SUMIF(INDIRECT("'"&Y34&"'!D:D"),"Sell (Spot)",INDIRECT("'"&Y34&"'!E:E")),0) -> 0 | P34: =IFERROR(Q34/O34,"") | Q34: =IFERROR(SUMIF(INDIRECT("'"&Y34&"'!D:D"),"Sell (Spot)",INDIRECT("'"&Y34&"'!g:g")),0) -> 0 | R34: =L34+O34 -> 0 | S34: =IFERROR(T34/R34,"") | T34: =N34+Q34 -> 0 | V34: =B34+E34+L34+O34 -> 0 | W34: =SUM(J34,T34) -> 0 | X34: =IFERROR(SUMIF(INDIRECT("'"&Y34&"'!D:D"),"TOTAL",INDIRECT("'"&Y34&"'!L:L")),0) -> 0 | Y34: MSPL-HKD
A35: SUB-Total | B35: =SUM(B32:B34) -> 0 | C35: =IFERROR(D35/B35,"") | D35: =SUM(D32:D34) -> 0 | E35: =SUM(E32:E34) -> 0 | F35: =IFERROR(G35/E35,"") | G35: =SUM(G32:G34) -> 0 | H35: =SUM(H32:H34) -> 0 | I35: =IFERROR(J35/H35,"") | J35: =SUM(J32:J34) -> 0 | L35: =SUM(L32:L34) -> 0 | M35: =IFERROR(N35/L35,"") | N35: =SUM(N32:N34) -> 0 | O35: =SUM(O32:O34) -> 0 | P35: =IFERROR(Q35/O35,"") | Q35: =SUM(Q32:Q34) -> 0 | R35: =SUM(R32:R34) -> 0 | S35: =IFERROR(T35/R35,"") | T35: =SUM(T32:T34) -> 0 | V35: =SUM(V32:V34) -> 0 | W35: =SUM(W32:W34) -> 0 | X35: =SUM(X32:X34) -> 0
A37: Total | B37: =SUM(B12, B16, B21, B25, B35, B29) -> 0 | C37: =IFERROR(D37/B37,"") | D37: =SUM(D12, D16, D21, D25, D35, E41,D29) -> 0 | E37: =SUM(E12, E16, E21, E25, E35, E29) -> 0 | F37: =IFERROR(G37/E37,"") | G37: =SUM(G12, G16, G21, G25, G35, G29) -> 0 | H37: =SUM(H12, H16, H21, H25, H35, H29) -> 0 | I37: =IFERROR(J37/H37,"") | J37: =SUM(J12, J16, J21, J25, J35, J29) -> 0 | L37: =SUM(L12, L16, L21, L25, L35, L29) -> 0 | M37: =IFERROR(N37/L37,"") | N37: =SUM(N12, N16, N21, N25, N35, N29) -> 0 | O37: =SUM(O12, O16, O21, O25, O35, O29) -> 0 | P37: =IFERROR(Q37/O37,"") | Q37: =SUM(Q12, Q16, Q21, Q25, Q35, Q29) -> 0 | R37: =SUM(R12, R16, R21, R25, R35, R29) -> 0 | S37: =IFERROR(T37/R37,"") | T37: =SUM(T12, T16, T21, T25, T35, T29) -> 0 | V37: =SUM(V12, V16, V21, V25, V35, V29) -> 0 | W37: =SUM(W12, W16, W21, W25, W35, W29) -> 0 | X37: =SUM(X12, X16, X21, X25, X35, X29) -> 0
B38: Shares | D38: HKD | E38: Shares | G38: HKD | H38: Shares | J38: HKD | L38: Shares | N38: HKD | O38: Shares | Q38: HKD | R38: Shares | T38: HKD | V38: Shares | W38: HKD | X38: HKD
B39: ACCU | E39: SPOT | H39: TOTAL BUY | L39: DECU | O39: SPOT | R39: TOTAL SELL

Sheet Sheet1
B2: hkd_per_usd | C2: 7.85
B4: jpy_per_usd | C4: 111.37
B6: aud_per_usd | C6: 1.4
B8: sgd_per_usd | C8: 1.36

Sheet Top Sheet
A1: Avg. Price vs Selling Price
A2: Summary of Gain Loss
A3: =INDIRECT("SUMMARY!A3") -> As of November 6, 2020
A6: Bank / Account | B6: January | C6: February | D6: March | E6: April | F6: May | G6: June | H6: July | I6: August | J6: September | K6: October | L6: November | M6: December | O6: Total
A8: Citibank
A9: Account 1 | B9: -555795.82 | C9: 512.74064 | D9: -103248.99 | E9: 444542.96 | F9: 15314.19 | G9: 32716.547 | H9: 24570.315 | I9: 53765.865 | J9: -611712.67 | K9: -4552776.8 | L9: -385341.3 | M9: =SUMIF(SUMMARY!$N:$N,$P9,SUMMARY!$M:$M) -> 0 | O9: =SUM(B9:N9) -> -5637453 | P9: CB1
A10: Account 2 | B10: 27482.086 | C10: -24786.392 | D10: -116587.01 | E10: 422380.43 | F10: 0 | G10: -25169.854 | H10: 122074.1 | I10: 45863.789 | J10: -222165.21 | K10: -5786950.6 | L10: -559698.47 | M10: =SUMIF(SUMMARY!$N:$N,$P10,SUMMARY!$M:$M) -> 0 | O10: =SUM(B10:N10) -> -6117557.1 | P10: CB2
A11: Account 3 | B11: -232060.99 | C11: -45507.227 | D11: 87662.412 | E11: -53933.01 | F11: -63605.607 | G11: -63665.607 | H11: -37384.642 | I11: 294877.86 | J11: 81215.828 | K11: -1179602.6 | L11: 0 | M11: =SUMIF(SUMMARY!$N:$N,$P11,SUMMARY!$M:$M) -> 0 | O11: =SUM(B11:N11) -> -1212003.5 | P11: CB3
A12: Berry Hill No. 1 | B12: -339399.95 | C12: -77670.524 | D12: -3974341.6 | E12: -324098.67 | F12: 0 | G12: 0 | H12: 0 | I12: 0 | J12: 0 | K12: 0 | L12: 0 | M12: =SUMIF(SUMMARY!$N:$N,$P12,SUMMARY!$M:$M) -> 0 | O12: =SUM(B12:N12) -> -4715510.8 | P12: CBBH
A13: Berry Hill No. 2 | B13: 0 | C13: 0 | D13: 0 | E13: 0 | F13: 0 | G13: 0 | H13: 0 | I13: 0 | J13: 0 | K13: 0 | L13: 0 | M13: =SUMIF(SUMMARY!$N:$N,$P13,SUMMARY!$M:$M) -> 0 | O13: =SUM(B13:N13) -> 0 | P13: CBBH2
A14: SUB-Total | B14: -1099774.7 | C14: -147451.4 | D14: -4106515.2 | E14: 488891.71 | F14: -48291.417 | G14: -56118.914 | H14: 109259.77 | I14: 394507.51 | J14: -752662.05 | K14: -11519330 | L14: -945039.76 | M14: =SUM(M9:M13) -> 0 | O14: =SUM(O9:O13) -> -17682524
A16: Bank of Singapore
A17: BOS | B17: -300181.5 | C17: -80518.737 | D17: -5056275.2 | E17: 378321.36 | F17: -661886.76 | G17: 100052.61 | H17: 199616.2 | I17: 180603.11 | J17: -1976633.1 | K17: -14220340 | L17: -13827139 | M17: =SUMIF(SUMMARY!$N:$N,$P17,SUMMARY!$M:$M) -> 0 | O17: =SUM(B17:N17) -> -35264381 | P17: BOS
A18: SUB-Total | B18: -300181.5 | C18: -80518.737 | D18: -5056275.2 | E18: 378321.36 | F18: -661886.76 | G18: 100052.61 | H18: 199616.2 | I18: 180603.11 | J18: -1976633.1 | K18: -14220340 | L18: -13827139 | M18: =SUM(M17:M17) -> 0 | O18: =SUM(O17:O17) -> -35264381
A20: Deutsche Bank
A21: Personal | B21: 58415.376 | C21: 27836.715 | D21: 53599.322 | E21: 149731.89 | F21: 93020.919 | G21: 188355.26 | H21: 114649.7 | I21: 144423.97 | J21: -587863.07 | K21: -18887299 | L21: -10377399 | M21: =SUMIF(SUMMARY!$N:$N,$P21,SUMMARY!$M:$M) -> 0 | O21: =SUM(B21:N21) -> -29022528 | P21: DBPe
A22: PL | B22: 45778.85 | C22: 89902.33 | D22: 47126.75 | E22: 55701.594 | F22: 0 | G22: 245404.45 | H22: 84541.173 | I22: 13725.713 | J22: -609500.09 | K22: -7075512.1 | L22: -4680125 | M22: =SUMIF(SUMMARY!$N:$N,$P22,SUMMARY!$M:$M) -> 0 | O22: =SUM(B22:N22) -> -11782956 | P22: DBPL
A23: SUB-Total | B23: 104194.23 | C23: 117739.04 | D23: 100726.07 | E23: 205433.48 | F23: 93020.919 | G23: 433759.71 | H23: 199190.87 | I23: 158149.68 | J23: -1197363.2 | K23: -25962811 | L23: -15057524 | M23: =SUM(M21:M22) -> 0 | O23: =SUM(O21:O22) -> -40805485
A25: Standard Chartered
A26: Stocks | B26: -36962.621 | C26: 36642.985 | D26: -63541.16 | E26: 293318.79 | F26: 0 | G26: 0 | H26: 0 | I26: 0 | J26: 0 | K26: 0 | L26: 0 | M26: =SUMIF(SUMMARY!$N:$N,$P26,SUMMARY!$M:$M) -> 0 | O26: =SUM(B26:N26) -> 229457.99 | P26: SC
A27: SUB-Total | B27: -36962.621 | C27: 36642.985 | D27: -63541.16 | E27: 293318.79 | F27: 0 | G27: 0 | H27: 0 | I27: 0 | J27: 0 | K27: 0 | L27: 0 | M27: =SUM(M26:M26) -> 0 | O27: =SUM(O26:O26) -> 229457.99
A29: Sun Hung Kai
A30: SHKIS | B30: -953882.78 | C30: -1168705.3 | D30: -3540591.6 | E30: -986732.07 | F30: -557935.32 | G30: -55771.517 | H30: 95412.761 | I30: -40014.067 | J30: -481695.67 | K30: -8978510 | L30: -28610401 | M30: =SUMIF(SUMMARY!$N:$N,$P30,SUMMARY!$M:$M) -> 0 | O30: =SUM(B30:N30) -> -45278827 | P30: SHK
A31: SUB-Total | B31: -953882.78 | C31: -1168705.3 | D31: -3540591.6 | E31: -986732.07 | F31: -557935.32 | G31: -55771.517 | H31: 95412.761 | I31: -40014.067 | J31: -481695.67 | K31: -8978510 | L31: -28610401 | M31: =SUM(M30:M30) -> 0 | O31: =SUM(O30:O30) -> -45278827
A33: Morgan Stanley
A34: T1 | B34: -1579397.3 | C34: -635615.65 | D34: -4187073.3 | E34: -53253.946 | F34: -132490.72 | G34: -98894.177 | H34: 164547.17 | I34: 136007.99 | J34: -1904625.5 | K34: -2241599 | L34: -507355.07 | M34: =SUMIF(SUMMARY!$N:$N,$P34,SUMMARY!$M:$M) -> 0 | O34: =SUM(B34:N34) -> -11039749 | P34: MST1
A35: T2 | B35: -46552.73 | C35: 53966.946 | D35: -423363.48 | E35: 119239.42 | F35: 11388.731 | G35: 42130.237 | H35: 236528.45 | I35: 253114.07 | J35: -2272012.9 | K35: -4022659.2 | L35: -1040983 | M35: =SUMIF(SUMMARY!$N:$N,$P35,SUMMARY!$M:$M) -> 0 | O35: =SUM(B35:N35) -> -7089203.4 | P35: MST2
A36: PL | B36: -1722426.7 | C36: -1008972.9 | D36: 980763.93 | E36: -434138.64 | F36: -627205.19 | G36: 740164.97 | H36: 202185.77 | I36: 368307.89 | J36: -1403999.8 | K36: -6828818.3 | L36: -1699818.2 | M36: =SUMIF(SUMMARY!$N:$N,$P36,SUMMARY!$M:$M) -> 0 | O36: =SUM(B36:N36) -> -11433957 | P36: MSPL
A37: SUB-Total | B37: -3348376.7 | C37: -1590621.6 | D37: -3629672.8 | E37: -368153.17 | F37: -748307.18 | G37: 683401.03 | H37: 603261.38 | I37: 757429.96 | J37: -5580638.2 | K37: -13093076 | L37: -3248156.2 | M37: =SUM(M34:M36) -> 0 | O37: =SUM(O34:O36) -> -29562910
A39: Total | B39: -5634984 | C39: -2832915 | D39: -16295870 | E39: 11080.102 | F39: -1923399.8 | G39: 1105322.9 | H39: 1206741 | I39: 1450676.2 | J39: -9988992.2 | K39: -73774068 | L39: -61688260 | M39: =SUM(M14, M18, M23, M27, M37, M31) -> 0 | O39: =SUM(O14, O18, O23, O27, O37, O31) -> -1.6836467e+08

Sheet Marissa Page
A1: AVERAGE PRICE VS SELLING PRICE
A2: SUMMARY OF GAIN / LOSS
A3: =INDIRECT("SUMMARY!A3") -> As of November 6, 2020
A5: BANK / ACCOUNT | B5: JANUARY | G5: FEBRUARY | L5: MARCH | Q5: TOTAL - HKD
A7: CITIBANK | C7: EX RATE | E7: HKD | H7: EX RATE | J7: HKD | M7: EX RATE | O7: HKD
A8: SINGAPORE A/C No. 1 | B8: 6165.492 | E8: 6165.492 | G8: 0 | J8: 0 | L8: =SUMMARY!C10 -> 0 | O8: =+L8 -> 0 | Q8: =SUMIF(A$7:P$7,"HKD",A8:P8) -> 6165.492
A9: SUB TOTAL | E9: 6165.492 | J9: 0 | O9: =SUM(O8:O8) -> 0 | Q9: =SUM(Q8:Q8) -> 6165.492
A11: BANK OF SINGAPORE | B11: 202292.98 | C11: 1 | D11: 202292.98 | E11: 202292.98 | G11: 350508.62 | H11: 1 | I11: 350508.62 | J11: 350508.62 | L11: =SUMMARY!C14 -> 0 | M11: 1 | N11: =+L11*M11 -> 0 | O11: =SUM(N11:N14) -> 0 | Q11: =SUMIF(A$7:P$7,"HKD",A11:P11) -> 552801.6
B12: 0 | C12: 0.07 | D12: 0 | G12: 0 | H12: 0.07 | I12: 0 | L12: =SUMMARY!D14 -> 0 | M12: 0.07 | N12: =+L12*M12 -> 0 | Q12: =SUMIF(A$7:P$7,"HKD",A12:P12) -> 0
B13: 0 | C13: 0.18 | D13: 0 | G13: 0 | H13: 0.18 | I13: 0 | L13: =SUMMARY!F14 -> 0 | M13: 0.18 | N13: =+L13*M13 -> 0 | Q13: =SUMIF(A$7:P$7,"HKD",A13:P13) -> 0
C14: 7.85 | D14: 0 | H14: 7.85 | I14: 0 | M14: 7.85 | N14: =+L14*M14 -> 0 | Q14: =SUMIF(A$7:P$7,"HKD",A14:P14) -> 0
A15: SUB TOTAL | E15: 202292.98 | J15: 350508.62 | O15: =SUM(O11) -> 0 | Q15: =SUM(Q11) -> 552801.6
A17: DUETSCHE BANK
A18: PERSONAL | B18: 194600.53 | C18: 1 | D18: 194600.53 | E18: 194600.53 | G18: 469547.8 | H18: 1 | I18: 469547.8 | J18: 469547.8 | L18: =SUMMARY!C18 -> 0 | M18: 1 | N18: =+L18*M18 -> 0 | O18: =SUM(N18:N20) -> 0 | Q18: =SUMIF(A$7:P$7,"HKD",A18:P18) -> 664148.33
B19: 0 | C19: 7.85 | D19: 0 | G19: 0 | H19: 7.85 | I19: 0 | L19: =SUMMARY!E18 -> 0 | M19: 7.85 | N19: =+L19*M19 -> 0 | Q19: =SUMIF(A$7:P$7,"HKD",A19:P19) -> 0
B20: 0 | C20: 0.18 | D20: 0 | G20: 0 | H20: 0.18 | I20: 0 | L20: =SUMMARY!F18 -> 0 | M20: 0.18 | N20: =+L20*M20 -> 0 | Q20: =SUMIF(A$7:P$7,"HKD",A20:P20) -> 0
A21: PERFECT LEGEND | B21: 23442.251 | C21: 1 | D21: 23442.251 | E21: 23442.251 | G21: 25402.93 | H21: 1 | I21: 25402.93 | J21: 25402.93 | L21: =SUMMARY!C19 -> 0 | M21: 1 | N21: =+L21*M21 -> 0 | O21: =SUM(N21:N22) -> 0 | Q21: =SUMIF(A$7:P$7,"HKD",A21:P21) -> 48845.18
C22: 7.85 | D22: 0 | H22: 7.85 | I22: 0 | M22: 7.85 | N22: =+L22*M22 -> 0 | Q22: =SUMIF(A$7:P$7,"HKD",A22:P22) -> 0
A23: SUB TOTAL | E23: 218042.78 | J23: 494950.73 | O23: =SUM(O18:O22) -> 0 | Q23: =SUM(Q18:Q22) -> 712993.51
A25: STANDARD CHARTERED
A26: STOCKS | E26: 0 | J26: 0 | O26: =+L26 -> 0 | Q26: =SUMIF(A$7:P$7,"HKD",A26:P26) -> 0
A27: SUB TOTAL | E27: 0 | J27: 0 | O27: =SUM(O26) -> 0 | Q27: =SUM(Q26) -> 0
A29: Sun Hung Kai
A30: SHKIS | B30: -1663537.3 | E30: -1663537.3 | G30: 1225125.7 | J30: 1225125.7 | L30: =SUMMARY!C27 -> 0 | O30: =+L30 -> 0 | Q30: =SUMIF(A$7:P$7,"HKD",A30:P30) -> -438411.63
A31: SUB TOTAL | E31: -1663537.3 | J31: 1225125.7 | O31: =SUM(O30) -> 0 | Q31: =SUM(Q30) -> -438411.63
A33: MORGAN STANLEY
A34: TITAN 1 | B34: 105942.33 | E34: 105942.33 | G34: 9673.5411 | J34: 9673.5411 | L34: =SUMMARY!C31 -> 0 | O34: =+L34 -> 0 | Q34: =SUMIF(A$7:P$7,"HKD",A34:P34) -> 115615.87
A35: TITAN 2 | B35: 149254.87 | E35: 149254.87 | G35: 190708.32 | J35: 190708.32 | L35: =SUMMARY!C32 -> 0 | O35: =+L35 -> 0 | Q35: =SUMIF(A$7:P$7,"HKD",A35:P35) -> 339963.19
A36: PERFECT LEGEND | B36: 54095.646 | C36: 1 | D36: 54095.646 | E36: 54095.646 | G36: 180763.66 | H36: 1 | I36: 180763.66 | J36: 180763.66 | L36: =SUMMARY!C33 -> 0 | M36: 1 | N36: =+L36*M36 -> 0 | O36: =SUM(N36:N37) -> 0 | Q36: =SUMIF(A$7:P$7,"HKD",A36:P36) -> 234859.3
D37: 0 | I37: 0 | N37: =+L37*M37 -> 0 | Q37: =SUMIF(A$7:P$7,"HKD",A37:P37) -> 0
A38: SUB TOTAL | E38: 309292.84 | J38: 381145.52 | O38: =SUM(O34:O36) -> 0 | Q38: =SUM(Q34:Q37) -> 690438.36
A40: GRAND TOTAL | E40: -927743.24 | J40: 2451730.6 | O40: =+O9+O15+O23+O27+O31+O38 -> 0 | Q40: =+Q9+Q15+Q23+Q27+Q31+Q38 -> 1523987.3

Sheet SUMMARY
A1: Avg. Price vs Selling Price
A2: Summary of Gain Loss
A3: As of November 6, 2020
A6: Bank / Account | B6: Gain Loss | H6: HKD | I6: HKD | J6: HKD | K6: HKD | L6: HKD
B7: Australian Securities Exchange | C7: Hong Kong Stock Exchange | D7: Tokyo Stock Exchange | E7: New York Stock Exchange | F7: Singapore Exchange | H7: =D40 -> 5.5 | I7: 1 | J7: =D39 -> 0.07 | K7: =D41 -> 7.85 | L7: =D42 -> 0.18
B8: Net | C8: Net | D8: Net | E8: Net | F8: Net | H8: AUD | I8: HKD | J8: JPY | K8: USD | L8: SGD | M8: TOTAL
A9: Citibank
A10: Singapore Account 1 | B10: =IFERROR(SUMIF(INDIRECT("'"&$N10&"-"&B$46&"'!L:L"),"TOTAL",INDIRECT("'"&$N10&"-"&B$46&"'!K:K")),0) -> 0 | C10: =IFERROR(SUMIF(INDIRECT("'"&$N10&"-"&C$46&"'!L:L"),"TOTAL",INDIRECT("'"&$N10&"-"&C$46&"'!K:K")),0) -> 0 | D10: =IFERROR(SUMIF(INDIRECT("'"&$N10&"-"&D$46&"'!L:L"),"TOTAL",INDIRECT("'"&$N10&"-"&D$46&"'!K:K")),0) -> 0 | E10: =IFERROR(SUMIF(INDIRECT("'"&$N10&"-"&E$46&"'!L:L"),"TOTAL",INDIRECT("'"&$N10&"-"&E$46&"'!K:K")),0) -> 0 | F10: =IFERROR(SUMIF(INDIRECT("'"&$N10&"-"&F$46&"'!L:L"),"TOTAL",INDIRECT("'"&$N10&"-"&F$46&"'!K:K")),0) -> 0 | H10: =B10*H$7 -> 0 | I10: =C10*I$7 -> 0 | J10: =D10*J$7 -> 0 | K10: =E10*K$7 -> 0 | L10: =F10*L$7 -> 0 | M10: =SUM(H10:L10) -> 0 | N10: CBSG | Q10: =C10-P10 -> 0
A11: SUB-Total | B11: =SUM(B10:B10) -> 0 | C11: =SUM(C10:C10) -> 0 | D11: =SUM(D10:D10) -> 0 | E11: =SUM(E10:E10) -> 0 | F11: =SUM(F10:F10) -> 0
A13: Bank of Singapore
A14: BOS | B14: =IFERROR(SUMIF(INDIRECT("'"&$N14&"-"&B$46&"'!L:L"),"TOTAL",INDIRECT("'"&$N14&"-"&B$46&"'!K:K")),0) -> 0 | C14: =IFERROR(SUMIF(INDIRECT("'"&$N14&"-"&C$46&"'!L:L"),"TOTAL",INDIRECT("'"&$N14&"-"&C$46&"'!K:K")),0) -> 0 | D14: =IFERROR(SUMIF(INDIRECT("'"&$N14&"-"&D$46&"'!L:L"),"TOTAL",INDIRECT("'"&$N14&"-"&D$46&"'!K:K")),0) -> 0 | E14: =IFERROR(SUMIF(INDIRECT("'"&$N14&"-"&E$46&"'!L:L"),"TOTAL",INDIRECT("'"&$N14&"-"&E$46&"'!K:K")),0) -> 0 | F14: =IFERROR(SUMIF(INDIRECT("'"&$N14&"-"&F$46&"'!L:L"),"TOTAL",INDIRECT("'"&$N14&"-"&F$46&"'!K:K")),0) -> 0 | H14: =B14*H$7 -> 0 | I14: =C14*I$7 -> 0 | J14: =D14*J$7 -> 0 | K14: =E14*K$7 -> 0 | L14: =F14*L$7 -> 0 | M14: =SUM(H14:L14) -> 0 | N14: BOS | Q14: =C14-P14 -> 0
A15: SUB-Total | B15: =SUM(B14:B14) -> 0 | C15: =SUM(C14:C14) -> 0 | D15: =SUM(D14:D14) -> 0 | E15: =SUM(E14:E14) -> 0 | F15: =SUM(F14:F14) -> 0
A17: Deutsche Bank
A18: Personal | B18: =IFERROR(SUMIF(INDIRECT("'"&$N18&"-"&B$46&"'!L:L"),"TOTAL",INDIRECT("'"&$N18&"-"&B$46&"'!K:K")),0) -> 0 | C18: =IFERROR(SUMIF(INDIRECT("'"&$N18&"-"&C$46&"'!L:L"),"TOTAL",INDIRECT("'"&$N18&"-"&C$46&"'!K:K")),0) -> 0 | D18: =IFERROR(SUMIF(INDIRECT("'"&$N18&"-"&D$46&"'!L:L"),"TOTAL",INDIRECT("'"&$N18&"-"&D$46&"'!K:K")),0) -> 0 | E18: =IFERROR(SUMIF(INDIRECT("'"&$N18&"-"&E$46&"'!L:L"),"TOTAL",INDIRECT("'"&$N18&"-"&E$46&"'!K:K")),0) -> 0 | F18: =IFERROR(SUMIF(INDIRECT("'"&$N18&"-"&F$46&"'!L:L"),"TOTAL",INDIRECT("'"&$N18&"-"&F$46&"'!K:K")),0) -> 0 | H18: =B18*H$7 -> 0 | I18: =C18*I$7 -> 0 | J18: =D18*J$7 -> 0 | K18: =E18*K$7 -> 0 | L18: =F18*L$7 -> 0 | M18: =SUM(H18:L18) -> 0 | N18: DBPe | Q18: =C18-P18 -> 0
A19: PL | B19: =IFERROR(SUMIF(INDIRECT("'"&$N19&"-"&B$46&"'!L:L"),"TOTAL",INDIRECT("'"&$N19&"-"&B$46&"'!K:K")),0) -> 0 | C19: =IFERROR(SUMIF(INDIRECT("'"&$N19&"-"&C$46&"'!L:L"),"TOTAL",INDIRECT("'"&$N19&"-"&C$46&"'!K:K")),0) -> 0 | D19: =IFERROR(SUMIF(INDIRECT("'"&$N19&"-"&D$46&"'!L:L"),"TOTAL",INDIRECT("'"&$N19&"-"&D$46&"'!K:K")),0) -> 0 | E19: =IFERROR(SUMIF(INDIRECT("'"&$N19&"-"&E$46&"'!L:L"),"TOTAL",INDIRECT("'"&$N19&"-"&E$46&"'!K:K")),0) -> 0 | F19: =IFERROR(SUMIF(INDIRECT("'"&$N19&"-"&F$46&"'!L:L"),"TOTAL",INDIRECT("'"&$N19&"-"&F$46&"'!K:K")),0) -> 0 | H19: =B19*H$7 -> 0 | I19: =C19*I$7 -> 0 | J19: =D19*J$7 -> 0 | K19: =E19*K$7 -> 0 | L19: =F19*L$7 -> 0 | M19: =SUM(H19:L19) -> 0 | N19: DBPL | Q19: =C19-P19 -> 0
A20: SUB-Total | B20: =SUM(B18:B19) -> 0 | C20: =SUM(C18:C19) -> 0 | D20: =SUM(D18:D19) -> 0 | E20: =SUM(E18:E19) -> 0 | F20: =SUM(F18:F19) -> 0
A22: Standard Chartered
A23: Stocks | B23: =IFERROR(SUMIF(INDIRECT("'"&$N23&"-"&B$46&"'!L:L"),"TOTAL",INDIRECT("'"&$N23&"-"&B$46&"'!K:K")),0) -> 0 | C23: =IFERROR(SUMIF(INDIRECT("'"&$N23&"-"&C$46&"'!L:L"),"TOTAL",INDIRECT("'"&$N23&"-"&C$46&"'!K:K")),0) -> 0 | D23: =IFERROR(SUMIF(INDIRECT("'"&$N23&"-"&D$46&"'!L:L"),"TOTAL",INDIRECT("'"&$N23&"-"&D$46&"'!K:K")),0) -> 0 | E23: =IFERROR(SUMIF(INDIRECT("'"&$N23&"-"&E$46&"'!L:L"),"TOTAL",INDIRECT("'"&$N23&"-"&E$46&"'!K:K")),0) -> 0 | F23: =IFERROR(SUMIF(INDIRECT("'"&$N23&"-"&F$46&"'!L:L"),"TOTAL",INDIRECT("'"&$N23&"-"&F$46&"'!K:K")),0) -> 0 | H23: =B23*H$7 -> 0 | I23: =C23*I$7 -> 0 | J23: =D23*J$7 -> 0 | K23: =E23*K$7 -> 0 | L23: =F23*L$7 -> 0 | M23: =SUM(H23:L23) -> 0 | N23: SC | Q23: =C23-P23 -> 0
A24: SUB-Total | B24: =SUM(B23:B23) -> 0 | C24: =SUM(C23:C23) -> 0 | D24: =SUM(D23:D23) -> 0 | E24: =SUM(E23:E23) -> 0 | F24: =SUM(F23:F23) -> 0
A26: Sun Hung Kai
A27: SHKIS | B27: =IFERROR(SUMIF(INDIRECT("'"&$N27&"-"&B$46&"'!L:L"),"TOTAL",INDIRECT("'"&$N27&"-"&B$46&"'!K:K")),0) -> 0 | C27: =IFERROR(SUMIF(INDIRECT("'"&$N27&"-"&C$46&"'!L:L"),"TOTAL",INDIRECT("'"&$N27&"-"&C$46&"'!K:K")),0) -> 0 | D27: =IFERROR(SUMIF(INDIRECT("'"&$N27&"-"&D$46&"'!L:L"),"TOTAL",INDIRECT("'"&$N27&"-"&D$46&"'!K:K")),0) -> 0 | E27: =IFERROR(SUMIF(INDIRECT("'"&$N27&"-"&E$46&"'!L:L"),"TOTAL",INDIRECT("'"&$N27&"-"&E$46&"'!K:K")),0) -> 0 | F27: =IFERROR(SUMIF(INDIRECT("'"&$N27&"-"&F$46&"'!L:L"),"TOTAL",INDIRECT("'"&$N27&"-"&F$46&"'!K:K")),0) -> 0 | H27: =B27*H$7 -> 0 | I27: =C27*I$7 -> 0 | J27: =D27*J$7 -> 0 | K27: =E27*K$7 -> 0 | L27: =F27*L$7 -> 0 | M27: =SUM(H27:L27) -> 0 | N27: SHK | Q27: =C27-P27 -> 0
A28: SUB-Total | B28: =SUM(B27:B27) -> 0 | C28: =SUM(C27:C27) -> 0 | D28: =SUM(D27:D27) -> 0 | E28: =SUM(E27:E27) -> 0 | F28: =SUM(F27:F27) -> 0
A30: Morgan Stanley
A31: T1 | B31: =IFERROR(SUMIF(INDIRECT("'"&$N31&"-"&B$46&"'!L:L"),"TOTAL",INDIRECT("'"&$N31&"-"&B$46&"'!K:K")),0) -> 0 | C31: =IFERROR(SUMIF(INDIRECT("'"&$N31&"-"&C$46&"'!L:L"),"TOTAL",INDIRECT("'"&$N31&"-"&C$46&"'!K:K")),0) -> 0 | D31: =IFERROR(SUMIF(INDIRECT("'"&$N31&"-"&D$46&"'!L:L"),"TOTAL",INDIRECT("'"&$N31&"-"&D$46&"'!K:K")),0) -> 0 | E31: =IFERROR(SUMIF(INDIRECT("'"&$N31&"-"&E$46&"'!L:L"),"TOTAL",INDIRECT("'"&$N31&"-"&E$46&"'!K:K")),0) -> 0 | F31: =IFERROR(SUMIF(INDIRECT("'"&$N31&"-"&F$46&"'!L:L"),"TOTAL",INDIRECT("'"&$N31&"-"&F$46&"'!K:K")),0) -> 0 | H31: =B31*H$7 -> 0 | I31: =C31*I$7 -> 0 | J31: =D31*J$7 -> 0 | K31: =E31*K$7 -> 0 | L31: =F31*L$7 -> 0 | M31: =SUM(H31:L31) -> 0 | N31: MST1 | Q31: =C31-P31 -> 0
A32: T2 | B32: =IFERROR(SUMIF(INDIRECT("'"&$N32&"-"&B$46&"'!L:L"),"TOTAL",INDIRECT("'"&$N32&"-"&B$46&"'!K:K")),0) -> 0 | C32: =IFERROR(SUMIF(INDIRECT("'"&$N32&"-"&C$46&"'!L:L"),"TOTAL",INDIRECT("'"&$N32&"-"&C$46&"'!K:K")),0) -> 0 | D32: =IFERROR(SUMIF(INDIRECT("'"&$N32&"-"&D$46&"'!L:L"),"TOTAL",INDIRECT("'"&$N32&"-"&D$46&"'!K:K")),0) -> 0 | E32: =IFERROR(SUMIF(INDIRECT("'"&$N32&"-"&E$46&"'!L:L"),"TOTAL",INDIRECT("'"&$N32&"-"&E$46&"'!K:K")),0) -> 0 | F32: =IFERROR(SUMIF(INDIRECT("'"&$N32&"-"&F$46&"'!L:L"),"TOTAL",INDIRECT("'"&$N32&"-"&F$46&"'!K:K")),0) -> 0 | H32: =B32*H$7 -> 0 | I32: =C32*I$7 -> 0 | J32: =D32*J$7 -> 0 | K32: =E32*K$7 -> 0 | L32: =F32*L$7 -> 0 | M32: =SUM(H32:L32) -> 0 | N32: MST2 | Q32: =C32-P32 -> 0
A33: PL | B33: =IFERROR(SUMIF(INDIRECT("'"&$N33&"-"&B$46&"'!L:L"),"TOTAL",INDIRECT("'"&$N33&"-"&B$46&"'!K:K")),0) -> 0 | C33: =IFERROR(SUMIF(INDIRECT("'"&$N33&"-"&C$46&"'!L:L"),"TOTAL",INDIRECT("'"&$N33&"-"&C$46&"'!K:K")),0) -> 0 | D33: =IFERROR(SUMIF(INDIRECT("'"&$N33&"-"&D$46&"'!L:L"),"TOTAL",INDIRECT("'"&$N33&"-"&D$46&"'!K:K")),0) -> 0 | E33: =IFERROR(SUMIF(INDIRECT("'"&$N33&"-"&E$46&"'!L:L"),"TOTAL",INDIRECT("'"&$N33&"-"&E$46&"'!K:K")),0) -> 0 | F33: =IFERROR(SUMIF(INDIRECT("'"&$N33&"-"&F$46&"'!L:L"),"TOTAL",INDIRECT("'"&$N33&"-"&F$46&"'!K:K")),0) -> 0 | H33: =B33*H$7 -> 0 | I33: =C33*I$7 -> 0 | J33: =D33*J$7 -> 0 | K33: =E33*K$7 -> 0 | L33: =F33*L$7 -> 0 | M33: =SUM(H33:L33) -> 0 | N33: MSPL | Q33: =C33-P33 -> 0
A34: SUB-Total | B34: =SUM(B31:B33) -> 0 | C34: =SUM(C31:C33) -> 0 | D34: =SUM(D31:D33) -> 0 | E34: =SUM(E31:E33) -> 0 | F34: =SUM(F31:F33) -> 0
A36: Total | B36: =SUM(B11, B15, B20, B24, B34, B28) -> 0 | C36: =SUM(C11, C15, C20, C24, C34, C28) -> 0 | D36: =SUM(D11, D15, D20, D24, D34, D28) -> 0 | E36: =SUM(E11, E15, E20, E24, E34, E28) -> 0 | F36: =SUM(F11, F15, F20, F24, F34, F28) -> 0 | M36: =SUM(M8:M35) -> 0
B38: HKD | C38: =C36 -> 0 | E38: =C38 -> 0
B39: JPY | C39: =D36 -> 0 | D39: 0.07 | E39: =C39*D39 -> 0
B40: AUD | C40: =B36 -> 0 | D40: 5.5 | E40: =C40*D40 -> 0
B41: USD | C41: =E36 -> 0 | D41: 7.85 | E41: =C41*D41 -> 0
B42: SGD | C42: =F36 -> 0 | D42: 0.18 | E42: =C42*D42 -> 0
B43: TOTAL | E43: =SUM(E38:E42) -> 0
B46: AUD | C46: HKD | D46: JPY | E46: USD | F46: SGD

Sheet SUM-HK
A1: SUMMARY
A2: Hong Kong Stock Exchange
A3: =INDIRECT("SUMMARY!A3") -> As of November 6, 2020
A6: Account | B6: BUY Accu | C6: BUY Spot | D6: SUB-Total | F6: SELL Decu | G6: SELL Spot | H6: SUB-Total | J6: Total
A7: Citibank
A8: Singapore Account No. 1 | B8: =IFERROR(SUMIF(INDIRECT("'"&L8&"'!D:D"),"Buy (Accu)",INDIRECT("'"&L8&"'!G:G"))+SUMIF(INDIRECT("'"&L8&"'!D:D"),"Buy (Accu-KO)",INDIRECT("'"&L8&"'!G:G")),0) -> 0 | C8: =IFERROR(SUMIF(INDIRECT("'"&L8&"'!D:D"),"Buy (Spot)",INDIRECT("'"&L8&"'!G:G")),0) -> 0 | D8: =SUM(B8:C8) -> 0 | F8: =IFERROR(SUMIF(INDIRECT("'"&L8&"'!D:D"),"Sell (Decu)",INDIRECT("'"&L8&"'!G:G"))+SUMIF(INDIRECT("'"&L8&"'!D:D"),"Sell (Decu-KO)",INDIRECT("'"&L8&"'!G:G")),0) -> 0 | G8: =IFERROR(SUMIF(INDIRECT("'"&L8&"'!D:D"),"Sell (Spot)",INDIRECT("'"&L8&"'!G:G")),0) -> 0 | H8: =SUM(F8:G8) -> 0 | J8: =SUM(D8,H8) -> 0 | L8: CBSG-HKD
A9: SUB-Total | B9: =SUM(B8:B8) -> 0 | C9: =SUM(C8:C8) -> 0 | D9: =SUM(D8:D8) -> 0 | F9: =SUM(F8:F8) -> 0 | G9: =SUM(G8:G8) -> 0 | H9: =SUM(H8:H8) -> 0 | J9: =SUM(J8:J8) -> 0
A11: Bank of Singapore
A12: BOS | B12: =IFERROR(SUMIF(INDIRECT("'"&L12&"'!D:D"),"Buy (Accu)",INDIRECT("'"&L12&"'!G:G"))+SUMIF(INDIRECT("'"&L12&"'!D:D"),"Buy (Accu-KO)",INDIRECT("'"&L12&"'!G:G")),0) -> 0 | C12: =IFERROR(SUMIF(INDIRECT("'"&L12&"'!D:D"),"Buy (Spot)",INDIRECT("'"&L12&"'!G:G")),0) -> 0 | D12: =SUM(B12:C12) -> 0 | F12: =IFERROR(SUMIF(INDIRECT("'"&L12&"'!D:D"),"Sell (Decu)",INDIRECT("'"&L12&"'!G:G"))+SUMIF(INDIRECT("'"&L12&"'!D:D"),"Sell (Decu-KO)",INDIRECT("'"&L12&"'!G:G")),0) -> 0 | G12: =IFERROR(SUMIF(INDIRECT("'"&L12&"'!D:D"),"Sell (Spot)",INDIRECT("'"&L12&"'!G:G")),0) -> 0 | H12: =SUM(F12:G12) -> 0 | J12: =SUM(D12,H12) -> 0 | L12: BOS-HKD
A13: SUB-Total | B13: =SUM(B12:B12) -> 0 | C13: =SUM(C12:C12) -> 0 | D13: =SUM(D12:D12) -> 0 | F13: =SUM(F12:F12) -> 0 | G13: =SUM(G12:G12) -> 0 | H13: =SUM(H12:H12) -> 0 | J13: =SUM(J12:J12) -> 0
A15: Deutsche Bank
A16: Personal | B16: =IFERROR(SUMIF(INDIRECT("'"&L16&"'!D:D"),"Buy (Accu)",INDIRECT("'"&L16&"'!G:G"))+SUMIF(INDIRECT("'"&L16&"'!D:D"),"Buy (Accu-KO)",INDIRECT("'"&L16&"'!G:G")),0) -> 0 | C16: =IFERROR(SUMIF(INDIRECT("'"&L16&"'!D:D"),"Buy (Spot)",INDIRECT("'"&L16&"'!G:G")),0) -> 0 | D16: =SUM(B16:C16) -> 0 | F16: =IFERROR(SUMIF(INDIRECT("'"&L16&"'!D:D"),"Sell (Decu)",INDIRECT("'"&L16&"'!G:G"))+SUMIF(INDIRECT("'"&L16&"'!D:D"),"Sell (Decu-KO)",INDIRECT("'"&L16&"'!G:G")),0) -> 0 | G16: =IFERROR(SUMIF(INDIRECT("'"&L16&"'!D:D"),"Sell (Spot)",INDIRECT("'"&L16&"'!G:G")),0) -> 0 | H16: =SUM(F16:G16) -> 0 | J16: =SUM(D16,H16) -> 0 | L16: DBPe-HKD
A17: PL | B17: =IFERROR(SUMIF(INDIRECT("'"&L17&"'!D:D"),"Buy (Accu)",INDIRECT("'"&L17&"'!G:G"))+SUMIF(INDIRECT("'"&L17&"'!D:D"),"Buy (Accu-KO)",INDIRECT("'"&L17&"'!G:G")),0) -> 0 | C17: =IFERROR(SUMIF(INDIRECT("'"&L17&"'!D:D"),"Buy (Spot)",INDIRECT("'"&L17&"'!G:G")),0) -> 0 | D17: =SUM(B17:C17) -> 0 | F17: =IFERROR(SUMIF(INDIRECT("'"&L17&"'!D:D"),"Sell (Decu)",INDIRECT("'"&L17&"'!G:G"))+SUMIF(INDIRECT("'"&L17&"'!D:D"),"Sell (Decu-KO)",INDIRECT("'"&L17&"'!G:G")),0) -> 0 | G17: =IFERROR(SUMIF(INDIRECT("'"&L17&"'!D:D"),"Sell (Spot)",INDIRECT("'"&L17&"'!G:G")),0) -> 0 | H17: =SUM(F17:G17) -> 0 | J17: =SUM(D17,H17) -> 0 | L17: DBPL-HKD
A18: SUB-Total | B18: =SUM(B16:B17) -> 0 | C18: =SUM(C16:C17) -> 0 | D18: =SUM(D16:D17) -> 0 | F18: =SUM(F16:F17) -> 0 | G18: =SUM(G16:G17) -> 0 | H18: =SUM(H16:H17) -> 0 | J18: =SUM(J16:J17) -> 0
A20: Standard Chartered
A21: Stocks | B21: =IFERROR(SUMIF(INDIRECT("'"&L21&"'!D:D"),"Buy (Accu)",INDIRECT("'"&L21&"'!G:G"))+SUMIF(INDIRECT("'"&L21&"'!D:D"),"Buy (Accu-KO)",INDIRECT("'"&L21&"'!G:G")),0) -> 0 | C21: =IFERROR(SUMIF(INDIRECT("'"&L21&"'!D:D"),"Buy (Spot)",INDIRECT("'"&L21&"'!G:G")),0) -> 0 | D21: =SUM(B21:C21) -> 0 | F21: =IFERROR(SUMIF(INDIRECT("'"&L21&"'!D:D"),"Sell (Decu)",INDIRECT("'"&L21&"'!G:G"))+SUMIF(INDIRECT("'"&L21&"'!D:D"),"Sell (Decu-KO)",INDIRECT("'"&L21&"'!G:G")),0) -> 0 | G21: =IFERROR(SUMIF(INDIRECT("'"&L21&"'!D:D"),"Sell (Spot)",INDIRECT("'"&L21&"'!G:G")),0) -> 0 | H21: =SUM(F21:G21) -> 0 | J21: =SUM(D21,H21) -> 0 | L21: SC-HKD
A22: SUB-Total | B22: =SUM(B21:B21) -> 0 | C22: =SUM(C21:C21) -> 0 | D22: =SUM(D21:D21) -> 0 | F22: =SUM(F21:F21) -> 0 | G22: =SUM(G21:G21) -> 0 | H22: =SUM(H21:H21) -> 0 | J22: =SUM(J21:J21) -> 0
A24: Sun Hung Kai
A25: SHKIS | B25: =IFERROR(SUMIF(INDIRECT("'"&L25&"'!D:D"),"Buy (Accu)",INDIRECT("'"&L25&"'!G:G"))+SUMIF(INDIRECT("'"&L25&"'!D:D"),"Buy (Accu-KO)",INDIRECT("'"&L25&"'!G:G")),0) -> 0 | C25: =IFERROR(SUMIF(INDIRECT("'"&L25&"'!D:D"),"Buy (Spot)",INDIRECT("'"&L25&"'!G:G")),0) -> 0 | D25: =SUM(B25:C25) -> 0 | F25: =IFERROR(SUMIF(INDIRECT("'"&L25&"'!D:D"),"Sell (Decu)",INDIRECT("'"&L25&"'!G:G"))+SUMIF(INDIRECT("'"&L25&"'!D:D"),"Sell (Decu-KO)",INDIRECT("'"&L25&"'!G:G")),0) -> 0 | G25: =IFERROR(SUMIF(INDIRECT("'"&L25&"'!D:D"),"Sell (Spot)",INDIRECT("'"&L25&"'!G:G")),0) -> 0 | H25: =SUM(F25:G25) -> 0 | J25: =SUM(D25,H25) -> 0 | L25: SHK-HKD
A26: SUB-Total | B26: =SUM(B25:B25) -> 0 | C26: =SUM(C25:C25) -> 0 | D26: =SUM(D25:D25) -> 0 | F26: =SUM(F25:F25) -> 0 | G26: =SUM(G25:G25) -> 0 | H26: =SUM(H25:H25) -> 0 | J26: =SUM(J25:J25) -> 0
A28: Morgan Stanley
A29: T1 | B29: =IFERROR(SUMIF(INDIRECT("'"&L29&"'!D:D"),"Buy (Accu)",INDIRECT("'"&L29&"'!G:G"))+SUMIF(INDIRECT("'"&L29&"'!D:D"),"Buy (Accu-KO)",INDIRECT("'"&L29&"'!G:G")),0) -> 0 | C29: =IFERROR(SUMIF(INDIRECT("'"&L29&"'!D:D"),"Buy (Spot)",INDIRECT("'"&L29&"'!G:G")),0) -> 0 | D29: =SUM(B29:C29) -> 0 | F29: =IFERROR(SUMIF(INDIRECT("'"&L29&"'!D:D"),"Sell (Decu)",INDIRECT("'"&L29&"'!G:G"))+SUMIF(INDIRECT("'"&L29&"'!D:D"),"Sell (Decu-KO)",INDIRECT("'"&L29&"'!G:G")),0) -> 0 | G29: =IFERROR(SUMIF(INDIRECT("'"&L29&"'!D:D"),"Sell (Spot)",INDIRECT("'"&L29&"'!G:G")),0) -> 0 | H29: =SUM(F29:G29) -> 0 | J29: =SUM(D29,H29) -> 0 | L29: MST1-HKD
A30: T2 | B30: =IFERROR(SUMIF(INDIRECT("'"&L30&"'!D:D"),"Buy (Accu)",INDIRECT("'"&L30&"'!G:G"))+SUMIF(INDIRECT("'"&L30&"'!D:D"),"Buy (Accu-KO)",INDIRECT("'"&L30&"'!G:G")),0) -> 0 | C30: =IFERROR(SUMIF(INDIRECT("'"&L30&"'!D:D"),"Buy (Spot)",INDIRECT("'"&L30&"'!G:G")),0) -> 0 | D30: =SUM(B30:C30) -> 0 | F30: =IFERROR(SUMIF(INDIRECT("'"&L30&"'!D:D"),"Sell (Decu)",INDIRECT("'"&L30&"'!G:G"))+SUMIF(INDIRECT("'"&L30&"'!D:D"),"Sell (Decu-KO)",INDIRECT("'"&L30&"'!G:G")),0) -> 0 | G30: =IFERROR(SUMIF(INDIRECT("'"&L30&"'!D:D"),"Sell (Spot)",INDIRECT("'"&L30&"'!G:G")),0) -> 0 | H30: =SUM(F30:G30) -> 0 | J30: =SUM(D30,H30) -> 0 | L30: MST2-HKD
A31: PL | B31: =IFERROR(SUMIF(INDIRECT("'"&L31&"'!D:D"),"Buy (Accu)",INDIRECT("'"&L31&"'!G:G"))+SUMIF(INDIRECT("'"&L31&"'!D:D"),"Buy (Accu-KO)",INDIRECT("'"&L31&"'!G:G")),0) -> 0 | C31: =IFERROR(SUMIF(INDIRECT("'"&L31&"'!D:D"),"Buy (Spot)",INDIRECT("'"&L31&"'!G:G")),0) -> 0 | D31: =SUM(B31:C31) -> 0 | F31: =IFERROR(SUMIF(INDIRECT("'"&L31&"'!D:D"),"Sell (Decu)",INDIRECT("'"&L31&"'!G:G"))+SUMIF(INDIRECT("'"&L31&"'!D:D"),"Sell (Decu-KO)",INDIRECT("'"&L31&"'!G:G")),0) -> 0 | G31: =IFERROR(SUMIF(INDIRECT("'"&L31&"'!D:D"),"Sell (Spot)",INDIRECT("'"&L31&"'!G:G")),0) -> 0 | H31: =SUM(F31:G31) -> 0 | J31: =SUM(D31,H31) -> 0 | L31: MSPL-HKD
A32: SUB-Total | B32: =SUM(B29:B31) -> 0 | C32: =SUM(C29:C31) -> 0 | D32: =SUM(D29:D31) -> 0 | F32: =SUM(F29:F31) -> 0 | G32: =SUM(G29:G31) -> 0 | H32: =SUM(H29:H31) -> 0 | J32: =SUM(J29:J31) -> 0
A34: Total | B34: =SUM(B9, B13, B18, B22, B32, B26) -> 0 | C34: =SUM(C9, C13, C18, C22, C32, C26) -> 0 | D34: =SUM(D9, D13, D18, D22, D32, D26) -> 0 | F34: =SUM(F9, F13, F18, F22, F32, F26) -> 0 | G34: =SUM(G9, G13, G18, G22, G32, G26) -> 0 | H34: =SUM(H9, H13, H18, H22, H32, H26) -> 0 | J34: =SUM(J9, J13, J18, J22, J32, J26) -> 0
D35: Buy Total | H35: Sell Total

Sheet SUM-JP
A1: SUMMARY
A2: Tokyo Stock Exchange
A3: =INDIRECT("SUMMARY!A3") -> As of November 6, 2020
A6: Account | B6: BUY Accu | C6: BUY Spot | D6: SUB-Total | F6: SELL Decu | G6: SELL Spot | H6: SUB-Total | J6: Total
A7: Bank of Singapore
A8: BOS | B8: =IFERROR(SUMIF(INDIRECT("'"&L8&"'!D:D"),"Buy (Accu)",INDIRECT("'"&L8&"'!G:G"))+SUMIF(INDIRECT("'"&L8&"'!D:D"),"Buy (Accu-KO)",INDIRECT("'"&L8&"'!G:G")),0) -> 0 | C8: =IFERROR(SUMIF(INDIRECT("'"&L8&"'!D:D"),"Buy (Spot)",INDIRECT("'"&L8&"'!G:G")),0) -> 0 | D8: =SUM(B8:C8) -> 0 | F8: =IFERROR(SUMIF(INDIRECT("'"&L8&"'!D:D"),"Sell (Decu)",INDIRECT("'"&L8&"'!G:G"))+SUMIF(INDIRECT("'"&L8&"'!D:D"),"Sell (Decu-KO)",INDIRECT("'"&L8&"'!G:G")),0) -> 0 | G8: =IFERROR(SUMIF(INDIRECT("'"&L8&"'!D:D"),"Sell (Spot)",INDIRECT("'"&L8&"'!G:G")),0) -> 0 | H8: =SUM(F8:G8) -> 0 | J8: =SUM(D8,H8) -> 0 | L8: BOS-JPY
