Workbook
Name _10th: System!$B$16
Name _11th: System!$B$17
Name _2nd: System!$B$8
Name _3rd: System!$B$9
Name _4th: System!$B$10
Name _5th: System!$B$11
Name _6th: System!$B$12
Name _7th: System!$B$13
Name _8th: System!$B$14
Name _9th: System!$B$15
Name beginning: System!$B$6
Name Closing: 'Last Month'!$AN$1
Name heroku_trans: 'Last Month'!#REF!
Name last_month: System!$B$7
Name stock_name: System!$B$1
Name transaction_type: 'Last Month'!#REF!

Sheet System
A1: Stock Name | B1: Great Wall Motor
A3: Accu / Decu | B3: Transactions September 1-6, 2021
A4: Spot / Transfer / Payshort | B4: Transactions September 1-3, 2021
A6: Beginning | B6: 44804
A7: Last Month | B7: =EOMONTH(B6,1) -> 44834
A8: 2nd | B8: =EOMONTH(B7,1) -> 44865
A9: 3rd | B9: =EOMONTH(B8,1) -> 44895
A10: 4th | B10: =EOMONTH(B9,1) -> 44926
A11: 5th | B11: =EOMONTH(B10,1) -> 44957
A12: 6th | B12: =EOMONTH(B11,1) -> 44985
A13: 7th | B13: =EOMONTH(B12,1) -> 45016
A14: 8th | B14: =EOMONTH(B13,1) -> 45046
A15: 9th | B15: =EOMONTH(B14,1) -> 45077
A16: 10th | B16: =EOMONTH(B15,1) -> 45107
A17: 11th | B17: =EOMONTH(B16,1) -> 45138

Sheet Last Month
A1: ="Estimate "&stock_name&" Shares till Month of "&TEXT(W6,"mmmm yyyy")&" End" -> Estimate Great Wall Motor Shares till Month of September 2022 End | K1: as of | P1: =TEXT(NOW(),"mmm d, yyyy hh:mm AM/PM") -> Sep 1, 2022 01:50 pm | AK1: =MONTH(W6) -> 9 | AM1: Closing | AN1: 5.85
E3: Transactions September 1 - , 2022 | I3: Transactions September 1 - , 2022
A4: # | B4: Account | C4: Shares on hand | D4: + | E4: Buy (Accu) | F4: - | G4: Sell (Decu) | H4: + | I4: Buy (Spot) | J4: - | K4: Sell (Spot) | L4: + | M4: Transfer | N4: + | O4: Pay Short | P4: = | Q4: Balance | R4: + | S4: Accumulator | T4: - | U4: Decumulator | V4: = | W4: Estimate End Shares Balance
E5: Done | G5: Done | O5: From Acct. | S5: Future | U5: Future
A6: A. Citibank | C6: =beginning -> 44804 | W6: =last_month -> 44834 | AE6: Total short till January
A7: 1 | B7: Citibank Account No. 1 | C7: =INDIRECT("'"&AJ7&"'!T11") -> 0 | D7: + | E7: =SUMIF(INDIRECT($AJ7&"!AC:AC"),$AK7&"Buy (Accu)",INDIRECT($AJ7&"!AD:AD"))+SUMIF(INDIRECT($AJ7&"!AC:AC"),$AK7&"Buy (Accu-KO)",INDIRECT($AJ7&"!AD:AD")) -> 0 | F7: - | G7: =SUMIF(INDIRECT($AJ7&"!AC:AC"),$AK7&"Sell (Decu)",INDIRECT($AJ7&"!AD:AD"))+SUMIF(INDIRECT($AJ7&"!AC:AC"),$AK7&"Sell (Decu-KO)",INDIRECT($AJ7&"!AD:AD")) -> 0 | H7: + | I7: =SUMIF(INDIRECT($AJ7&"!AC:AC"),$AK7&"Buy (Spot)",INDIRECT($AJ7&"!AD:AD")) -> 0 | J7: - | K7: =SUMIF(INDIRECT($AJ7&"!AC:AC"),$AK7&"Sell (Spot)",INDIRECT($AJ7&"!AD:AD")) -> 0 | L7: + | M7: =SUMIF(INDIRECT($AJ7&"!AC:AC"),$AK7&"Transfer-In",INDIRECT($AJ7&"!AD:AD"))+SUMIF(INDIRECT($AJ7&"!AC:AC"),$AK7&"Transfer-Out",INDIRECT($AJ7&"!AD:AD")) -> 0 | N7: + | O7: =SUMIF(INDIRECT($AJ7&"!AC:AC"),$AK7&"Pay Short",INDIRECT($AJ7&"!AD:AD")) -> 0 | P7: = | Q7: =SUM(C7:P7) -> 0 | R7: + | S7: =SUMIF(INDIRECT($AJ7&"!AC:AC"),$AK7&"ACCU",INDIRECT($AJ7&"!AD:AD")) -> 0 | T7: - | U7: =SUMIF(INDIRECT($AJ7&"!AC:AC"),$AK7&"DECU",INDIRECT($AJ7&"!AD:AD")) -> 0 | V7: = | W7: =Q7+S7+U7 -> 0 | Y7: 43082 | Z7: -193700 | AB7: 43115 | AC7: -223800 | AE7: Total | AF7: =SUM(Z7,AC7) -> -417500 | AJ7: CB1 | AK7: =AK$1 -> 9 | AL7: =B7 -> Citibank Account No. 1
A8: 2 | B8: Citibank Account No. 2 | C8: =INDIRECT("'"&AJ8&"'!T11") -> 0 | D8: + | E8: =SUMIF(INDIRECT($AJ8&"!AC:AC"),$AK8&"Buy (Accu)",INDIRECT($AJ8&"!AD:AD"))+SUMIF(INDIRECT($AJ8&"!AC:AC"),$AK8&"Buy (Accu-KO)",INDIRECT($AJ8&"!AD:AD")) -> 0 | F8: - | G8: =SUMIF(INDIRECT($AJ8&"!AC:AC"),$AK8&"Sell (Decu)",INDIRECT($AJ8&"!AD:AD"))+SUMIF(INDIRECT($AJ8&"!AC:AC"),$AK8&"Sell (Decu-KO)",INDIRECT($AJ8&"!AD:AD")) -> 0 | H8: + | I8: =SUMIF(INDIRECT($AJ8&"!AC:AC"),$AK8&"Buy (Spot)",INDIRECT($AJ8&"!AD:AD")) -> 0 | J8: - | K8: =SUMIF(INDIRECT($AJ8&"!AC:AC"),$AK8&"Sell (Spot)",INDIRECT($AJ8&"!AD:AD")) -> 0 | L8: + | M8: =SUMIF(INDIRECT($AJ8&"!AC:AC"),$AK8&"Transfer-In",INDIRECT($AJ8&"!AD:AD"))+SUMIF(INDIRECT($AJ8&"!AC:AC"),$AK8&"Transfer-Out",INDIRECT($AJ8&"!AD:AD")) -> 0 | N8: + | O8: =SUMIF(INDIRECT($AJ8&"!AC:AC"),$AK8&"Pay Short",INDIRECT($AJ8&"!AD:AD")) -> 0 | P8: = | Q8: =SUM(C8:P8) -> 0 | R8: + | S8: =SUMIF(INDIRECT($AJ8&"!AC:AC"),$AK8&"ACCU",INDIRECT($AJ8&"!AD:AD")) -> 0 | T8: - | U8: =SUMIF(INDIRECT($AJ8&"!AC:AC"),$AK8&"DECU",INDIRECT($AJ8&"!AD:AD")) -> 0 | V8: = | W8: =Q8+S8+U8 -> 0 | AJ8: CB2 | AK8: =AK$1 -> 9 | AL8: =B8 -> Citibank Account No. 2
A9: 3 | B9: Citibank Account No. 3 | C9: =INDIRECT("'"&AJ9&"'!T11") -> 0 | D9: + | E9: =SUMIF(INDIRECT($AJ9&"!AC:AC"),$AK9&"Buy (Accu)",INDIRECT($AJ9&"!AD:AD"))+SUMIF(INDIRECT($AJ9&"!AC:AC"),$AK9&"Buy (Accu-KO)",INDIRECT($AJ9&"!AD:AD")) -> 0 | F9: - | G9: =SUMIF(INDIRECT($AJ9&"!AC:AC"),$AK9&"Sell (Decu)",INDIRECT($AJ9&"!AD:AD"))+SUMIF(INDIRECT($AJ9&"!AC:AC"),$AK9&"Sell (Decu-KO)",INDIRECT($AJ9&"!AD:AD")) -> 0 | H9: + | I9: =SUMIF(INDIRECT($AJ9&"!AC:AC"),$AK9&"Buy (Spot)",INDIRECT($AJ9&"!AD:AD")) -> 0 | J9: - | K9: =SUMIF(INDIRECT($AJ9&"!AC:AC"),$AK9&"Sell (Spot)",INDIRECT($AJ9&"!AD:AD")) -> 0 | L9: + | M9: =SUMIF(INDIRECT($AJ9&"!AC:AC"),$AK9&"Transfer-In",INDIRECT($AJ9&"!AD:AD"))+SUMIF(INDIRECT($AJ9&"!AC:AC"),$AK9&"Transfer-Out",INDIRECT($AJ9&"!AD:AD")) -> 0 | N9: + | O9: =SUMIF(INDIRECT($AJ9&"!AC:AC"),$AK9&"Pay Short",INDIRECT($AJ9&"!AD:AD")) -> 0 | P9: = | Q9: =SUM(C9:P9) -> 0 | R9: + | S9: =SUMIF(INDIRECT($AJ9&"!AC:AC"),$AK9&"ACCU",INDIRECT($AJ9&"!AD:AD")) -> 0 | T9: - | U9: =SUMIF(INDIRECT($AJ9&"!AC:AC"),$AK9&"DECU",INDIRECT($AJ9&"!AD:AD")) -> 0 | V9: = | W9: =Q9+S9+U9 -> 0 | AJ9: CB3 | AK9: =AK$1 -> 9 | AL9: =B9 -> Citibank Account No. 3
A10: 4 | B10: Citibank Berry Hill | C10: =INDIRECT("'"&AJ10&"'!T11") -> 0 | D10: + | E10: =SUMIF(INDIRECT($AJ10&"!AC:AC"),$AK10&"Buy (Accu)",INDIRECT($AJ10&"!AD:AD"))+SUMIF(INDIRECT($AJ10&"!AC:AC"),$AK10&"Buy (Accu-KO)",INDIRECT($AJ10&"!AD:AD")) -> 0 | F10: - | G10: =SUMIF(INDIRECT($AJ10&"!AC:AC"),$AK10&"Sell (Decu)",INDIRECT($AJ10&"!AD:AD"))+SUMIF(INDIRECT($AJ10&"!AC:AC"),$AK10&"Sell (Decu-KO)",INDIRECT($AJ10&"!AD:AD")) -> 0 | H10: + | I10: =SUMIF(INDIRECT($AJ10&"!AC:AC"),$AK10&"Buy (Spot)",INDIRECT($AJ10&"!AD:AD")) -> 0 | J10: - | K10: =SUMIF(INDIRECT($AJ10&"!AC:AC"),$AK10&"Sell (Spot)",INDIRECT($AJ10&"!AD:AD")) -> 0 | L10: + | M10: =SUMIF(INDIRECT($AJ10&"!AC:AC"),$AK10&"Transfer-In",INDIRECT($AJ10&"!AD:AD"))+SUMIF(INDIRECT($AJ10&"!AC:AC"),$AK10&"Transfer-Out",INDIRECT($AJ10&"!AD:AD")) -> 0 | N10: + | O10: =SUMIF(INDIRECT($AJ10&"!AC:AC"),$AK10&"Pay Short",INDIRECT($AJ10&"!AD:AD")) -> 0 | P10: = | Q10: =SUM(C10:P10) -> 0 | R10: + | S10: =SUMIF(INDIRECT($AJ10&"!AC:AC"),$AK10&"ACCU",INDIRECT($AJ10&"!AD:AD")) -> 0 | T10: - | U10: =SUMIF(INDIRECT($AJ10&"!AC:AC"),$AK10&"DECU",INDIRECT($AJ10&"!AD:AD")) -> 0 | V10: = | W10: =Q10+S10+U10 -> 0 | Y10: 43081 | Z10: -99590 | AB10: 42746 | AC10: -410000 | AE10: Total | AF10: =SUM(Z12,AC10) -> -442800 | AJ10: CBBH | AK10: =AK$1 -> 9 | AL10: =B10 -> Citibank Berry Hill
A11: 5 | B11: Citibank Berry Hill No. 2 | C11: =INDIRECT("'"&AJ11&"'!T11") -> 0 | D11: + | E11: =SUMIF(INDIRECT($AJ11&"!AC:AC"),$AK11&"Buy (Accu)",INDIRECT($AJ11&"!AD:AD"))+SUMIF(INDIRECT($AJ11&"!AC:AC"),$AK11&"Buy (Accu-KO)",INDIRECT($AJ11&"!AD:AD")) -> 0 | F11: - | G11: =SUMIF(INDIRECT($AJ11&"!AC:AC"),$AK11&"Sell (Decu)",INDIRECT($AJ11&"!AD:AD"))+SUMIF(INDIRECT($AJ11&"!AC:AC"),$AK11&"Sell (Decu-KO)",INDIRECT($AJ11&"!AD:AD")) -> 0 | H11: + | I11: =SUMIF(INDIRECT($AJ11&"!AC:AC"),$AK11&"Buy (Spot)",INDIRECT($AJ11&"!AD:AD")) -> 0 | J11: - | K11: =SUMIF(INDIRECT($AJ11&"!AC:AC"),$AK11&"Sell (Spot)",INDIRECT($AJ11&"!AD:AD")) -> 0 | L11: + | M11: =SUMIF(INDIRECT($AJ11&"!AC:AC"),$AK11&"Transfer-In",INDIRECT($AJ11&"!AD:AD"))+SUMIF(INDIRECT($AJ11&"!AC:AC"),$AK11&"Transfer-Out",INDIRECT($AJ11&"!AD:AD")) -> 0 | N11: + | O11: =SUMIF(INDIRECT($AJ11&"!AC:AC"),$AK11&"Pay Short",INDIRECT($AJ11&"!AD:AD")) -> 0 | P11: = | Q11: =SUM(C11:P11) -> 0 | R11: + | S11: =SUMIF(INDIRECT($AJ11&"!AC:AC"),$AK11&"ACCU",INDIRECT($AJ11&"!AD:AD")) -> 0 | T11: - | U11: =SUMIF(INDIRECT($AJ11&"!AC:AC"),$AK11&"DECU",INDIRECT($AJ11&"!AD:AD")) -> 0 | V11: = | W11: =Q11+S11+U11 -> 0 | Y11: 43081 | Z11: -99590 | AB11: 42746 | AC11: -410000 | AE11: Total | AF11: =SUM(Z13,AC11) -> -542390 | AJ11: CBBH2 | AK11: =AK$1 -> 9 | AL11: =B11 -> Citibank Berry Hill No. 2
B12: Sub-Total | C12: =SUM(C7:C11) -> 0 | E12: =SUM(E7:E11) -> 0 | G12: =SUM(G7:G11) -> 0 | I12: =SUM(I7:I11) -> 0 | K12: =SUM(K7:K11) -> 0 | M12: =SUM(M7:M11) -> 0 | O12: =SUM(O7:O11) -> 0 | Q12: =SUM(Q7:Q11) -> 0 | S12: =SUM(S7:S11) -> 0 | U12: =SUM(U7:U11) -> 0 | W12: =SUM(W7:W11) -> 0 | Y12: 43097 | Z12: -32800
Z13: =SUM(Z11:Z12) -> -132390
A15: B. Bank of Singapore | C15: =INDIRECT("'"&AJ15&"'!T11") -> 0 | D15: + | E15: =SUMIF(INDIRECT($AJ15&"!AC:AC"),$AK15&"Buy (Accu)",INDIRECT($AJ15&"!AD:AD"))+SUMIF(INDIRECT($AJ15&"!AC:AC"),$AK15&"Buy (Accu-KO)",INDIRECT($AJ15&"!AD:AD")) -> 0 | F15: - | G15: =SUMIF(INDIRECT($AJ15&"!AC:AC"),$AK15&"Sell (Decu)",INDIRECT($AJ15&"!AD:AD"))+SUMIF(INDIRECT($AJ15&"!AC:AC"),$AK15&"Sell (Decu-KO)",INDIRECT($AJ15&"!AD:AD")) -> 0 | H15: + | I15: =SUMIF(INDIRECT($AJ15&"!AC:AC"),$AK15&"Buy (Spot)",INDIRECT($AJ15&"!AD:AD")) -> 0 | J15: - | K15: =SUMIF(INDIRECT($AJ15&"!AC:AC"),$AK15&"Sell (Spot)",INDIRECT($AJ15&"!AD:AD")) -> 0 | L15: + | M15: =SUMIF(INDIRECT($AJ15&"!AC:AC"),$AK15&"Transfer-In",INDIRECT($AJ15&"!AD:AD"))+SUMIF(INDIRECT($AJ15&"!AC:AC"),$AK15&"Transfer-Out",INDIRECT($AJ15&"!AD:AD")) -> 0 | N15: + | O15: =SUMIF(INDIRECT($AJ15&"!AC:AC"),$AK15&"Pay Short",INDIRECT($AJ15&"!AD:AD")) -> 0 | P15: = | Q15: =SUM(C15:P15) -> 0 | R15: + | S15: =SUMIF(INDIRECT($AJ15&"!AC:AC"),$AK15&"ACCU",INDIRECT($AJ15&"!AD:AD")) -> 0 | T15: - | U15: =SUMIF(INDIRECT($AJ15&"!AC:AC"),$AK15&"DECU",INDIRECT($AJ15&"!AD:AD")) -> 0 | V15: = | W15: =Q15+S15+U15 -> 0 | AJ15: BOS | AK15: =AK$1 -> 9 | AL15: Bank of Singapore
A18: C. Deutsche Bank
A19: 1 | B19: Deutsche - Personal | C19: =INDIRECT("'"&AJ19&"'!T11") -> 0 | D19: + | E19: =SUMIF(INDIRECT($AJ19&"!AC:AC"),$AK19&"Buy (Accu)",INDIRECT($AJ19&"!AD:AD"))+SUMIF(INDIRECT($AJ19&"!AC:AC"),$AK19&"Buy (Accu-KO)",INDIRECT($AJ19&"!AD:AD")) -> 0 | F19: - | G19: =SUMIF(INDIRECT($AJ19&"!AC:AC"),$AK19&"Sell (Decu)",INDIRECT($AJ19&"!AD:AD"))+SUMIF(INDIRECT($AJ19&"!AC:AC"),$AK19&"Sell (Decu-KO)",INDIRECT($AJ19&"!AD:AD")) -> 0 | H19: + | I19: =SUMIF(INDIRECT($AJ19&"!AC:AC"),$AK19&"Buy (Spot)",INDIRECT($AJ19&"!AD:AD")) -> 0 | J19: - | K19: =SUMIF(INDIRECT($AJ19&"!AC:AC"),$AK19&"Sell (Spot)",INDIRECT($AJ19&"!AD:AD")) -> 0 | L19: + | M19: =SUMIF(INDIRECT($AJ19&"!AC:AC"),$AK19&"Transfer-In",INDIRECT($AJ19&"!AD:AD"))+SUMIF(INDIRECT($AJ19&"!AC:AC"),$AK19&"Transfer-Out",INDIRECT($AJ19&"!AD:AD")) -> 0 | N19: + | O19: =SUMIF(INDIRECT($AJ19&"!AC:AC"),$AK19&"Pay Short",INDIRECT($AJ19&"!AD:AD")) -> 0 | P19: = | Q19: =SUM(C19:P19) -> 0 | R19: + | S19: =SUMIF(INDIRECT($AJ19&"!AC:AC"),$AK19&"ACCU",INDIRECT($AJ19&"!AD:AD")) -> 0 | T19: - | U19: =SUMIF(INDIRECT($AJ19&"!AC:AC"),$AK19&"DECU",INDIRECT($AJ19&"!AD:AD")) -> 0 | V19: = | W19: =Q19+S19+U19 -> 0 | AJ19: DBPe | AK19: =AK$1 -> 9 | AL19: =B19 -> Deutsche - Personal
A20: 2 | B20: Deutsche - Perfect Legend | C20: =INDIRECT("'"&AJ20&"'!T11") -> 0 | D20: + | E20: =SUMIF(INDIRECT($AJ20&"!AC:AC"),$AK20&"Buy (Accu)",INDIRECT($AJ20&"!AD:AD"))+SUMIF(INDIRECT($AJ20&"!AC:AC"),$AK20&"Buy (Accu-KO)",INDIRECT($AJ20&"!AD:AD")) -> 0 | F20: - | G20: =SUMIF(INDIRECT($AJ20&"!AC:AC"),$AK20&"Sell (Decu)",INDIRECT($AJ20&"!AD:AD"))+SUMIF(INDIRECT($AJ20&"!AC:AC"),$AK20&"Sell (Decu-KO)",INDIRECT($AJ20&"!AD:AD")) -> 0 | H20: + | I20: =SUMIF(INDIRECT($AJ20&"!AC:AC"),$AK20&"Buy (Spot)",INDIRECT($AJ20&"!AD:AD")) -> 0 | J20: - | K20: =SUMIF(INDIRECT($AJ20&"!AC:AC"),$AK20&"Sell (Spot)",INDIRECT($AJ20&"!AD:AD")) -> 0 | L20: + | M20: =SUMIF(INDIRECT($AJ20&"!AC:AC"),$AK20&"Transfer-In",INDIRECT($AJ20&"!AD:AD"))+SUMIF(INDIRECT($AJ20&"!AC:AC"),$AK20&"Transfer-Out",INDIRECT($AJ20&"!AD:AD")) -> 0 | N20: + | O20: =SUMIF(INDIRECT($AJ20&"!AC:AC"),$AK20&"Pay Short",INDIRECT($AJ20&"!AD:AD")) -> 0 | P20: = | Q20: =SUM(C20:P20) -> 0 | R20: + | S20: =SUMIF(INDIRECT($AJ20&"!AC:AC"),$AK20&"ACCU",INDIRECT($AJ20&"!AD:AD")) -> 0 | T20: - | U20: =SUMIF(INDIRECT($AJ20&"!AC:AC"),$AK20&"DECU",INDIRECT($AJ20&"!AD:AD")) -> 0 | V20: = | W20: =Q20+S20+U20 -> 0 | AJ20: DBPL | AK20: =AK$1 -> 9 | AL20: =B20 -> Deutsche - Perfect Legend
B21: Sub-Total | C21: =SUM(C19:C20) -> 0 | E21: =SUM(E19:E20) -> 0 | G21: =SUM(G19:G20) -> 0 | I21: =SUM(I19:I20) -> 0 | K21: =SUM(K19:K20) -> 0 | M21: =SUM(M19:M20) -> 0 | O21: =SUM(O19:O20) -> 0 | Q21: =SUM(Q19:Q20) -> 0 | S21: =SUM(S19:S20) -> 0 | U21: =SUM(U19:U20) -> 0 | W21: =SUM(W19:W20) -> 0
A24: D. Standard Chartered | C24: =INDIRECT("'"&AJ24&"'!T11") -> 0 | D24: + | E24: =SUMIF(INDIRECT($AJ24&"!AC:AC"),$AK24&"Buy (Accu)",INDIRECT($AJ24&"!AD:AD"))+SUMIF(INDIRECT($AJ24&"!AC:AC"),$AK24&"Buy (Accu-KO)",INDIRECT($AJ24&"!AD:AD")) -> 0 | F24: - | G24: =SUMIF(INDIRECT($AJ24&"!AC:AC"),$AK24&"Sell (Decu)",INDIRECT($AJ24&"!AD:AD"))+SUMIF(INDIRECT($AJ24&"!AC:AC"),$AK24&"Sell (Decu-KO)",INDIRECT($AJ24&"!AD:AD")) -> 0 | H24: + | I24: =SUMIF(INDIRECT($AJ24&"!AC:AC"),$AK24&"Buy (Spot)",INDIRECT($AJ24&"!AD:AD")) -> 0 | J24: - | K24: =SUMIF(INDIRECT($AJ24&"!AC:AC"),$AK24&"Sell (Spot)",INDIRECT($AJ24&"!AD:AD")) -> 0 | L24: + | M24: =SUMIF(INDIRECT($AJ24&"!AC:AC"),$AK24&"Transfer-In",INDIRECT($AJ24&"!AD:AD"))+SUMIF(INDIRECT($AJ24&"!AC:AC"),$AK24&"Transfer-Out",INDIRECT($AJ24&"!AD:AD")) -> 0 | N24: + | O24: =SUMIF(INDIRECT($AJ24&"!AC:AC"),$AK24&"Pay Short",INDIRECT($AJ24&"!AD:AD")) -> 0 | P24: = | Q24: =SUM(C24:P24) -> 0 | R24: + | S24: =SUMIF(INDIRECT($AJ24&"!AC:AC"),$AK24&"ACCU",INDIRECT($AJ24&"!AD:AD")) -> 0 | T24: - | U24: =SUMIF(INDIRECT($AJ24&"!AC:AC"),$AK24&"DECU",INDIRECT($AJ24&"!AD:AD")) -> 0 | V24: = | W24: =Q24+S24+U24 -> 0 | AJ24: SC | AK24: =AK$1 -> 9 | AL24: Standard Chartered Bank
A27: D. Sun Hung Kai | C27: =INDIRECT("'"&AJ27&"'!T11") -> 0 | D27: + | E27: =SUMIF(INDIRECT($AJ27&"!AC:AC"),$AK27&"Buy (Accu)",INDIRECT($AJ27&"!AD:AD"))+SUMIF(INDIRECT($AJ27&"!AC:AC"),$AK27&"Buy (Accu-KO)",INDIRECT($AJ27&"!AD:AD")) -> 0 | F27: - | G27: =SUMIF(INDIRECT($AJ27&"!AC:AC"),$AK27&"Sell (Decu)",INDIRECT($AJ27&"!AD:AD"))+SUMIF(INDIRECT($AJ27&"!AC:AC"),$AK27&"Sell (Decu-KO)",INDIRECT($AJ27&"!AD:AD")) -> 0 | H27: + | I27: =SUMIF(INDIRECT($AJ27&"!AC:AC"),$AK27&"Buy (Spot)",INDIRECT($AJ27&"!AD:AD")) -> 0 | J27: - | K27: =SUMIF(INDIRECT($AJ27&"!AC:AC"),$AK27&"Sell (Spot)",INDIRECT($AJ27&"!AD:AD")) -> 0 | L27: + | M27: =SUMIF(INDIRECT($AJ27&"!AC:AC"),$AK27&"Transfer-In",INDIRECT($AJ27&"!AD:AD"))+SUMIF(INDIRECT($AJ27&"!AC:AC"),$AK27&"Transfer-Out",INDIRECT($AJ27&"!AD:AD")) -> 0 | N27: + | O27: =SUMIF(INDIRECT($AJ27&"!AC:AC"),$AK27&"Pay Short",INDIRECT($AJ27&"!AD:AD")) -> 0 | P27: = | Q27: =SUM(C27:P27) -> 0 | R27: + | S27: =SUMIF(INDIRECT($AJ27&"!AC:AC"),$AK27&"ACCU",INDIRECT($AJ27&"!AD:AD")) -> 0 | T27: - | U27: =SUMIF(INDIRECT($AJ27&"!AC:AC"),$AK27&"DECU",INDIRECT($AJ27&"!AD:AD")) -> 0 | V27: = | W27: =Q27+S27+U27 -> 0 | AJ27: SHK | AK27: =AK$1 -> 9 | AL27: Sun Hung Kai
A30: E. Morgan Stanley
A31: 1 | B31: Morgan - Titan No. 1 | C31: =INDIRECT("'"&AJ31&"'!T11") -> 0 | D31: + | E31: =SUMIF(INDIRECT($AJ31&"!AC:AC"),$AK31&"Buy (Accu)",INDIRECT($AJ31&"!AD:AD"))+SUMIF(INDIRECT($AJ31&"!AC:AC"),$AK31&"Buy (Accu-KO)",INDIRECT($AJ31&"!AD:AD")) -> 0 | F31: - | G31: =SUMIF(INDIRECT($AJ31&"!AC:AC"),$AK31&"Sell (Decu)",INDIRECT($AJ31&"!AD:AD"))+SUMIF(INDIRECT($AJ31&"!AC:AC"),$AK31&"Sell (Decu-KO)",INDIRECT($AJ31&"!AD:AD")) -> 0 | H31: + | I31: =SUMIF(INDIRECT($AJ31&"!AC:AC"),$AK31&"Buy (Spot)",INDIRECT($AJ31&"!AD:AD")) -> 0 | J31: - | K31: =SUMIF(INDIRECT($AJ31&"!AC:AC"),$AK31&"Sell (Spot)",INDIRECT($AJ31&"!AD:AD")) -> 0 | L31: + | M31: =SUMIF(INDIRECT($AJ31&"!AC:AC"),$AK31&"Transfer-In",INDIRECT($AJ31&"!AD:AD"))+SUMIF(INDIRECT($AJ31&"!AC:AC"),$AK31&"Transfer-Out",INDIRECT($AJ31&"!AD:AD")) -> 0 | N31: + | O31: =SUMIF(INDIRECT($AJ31&"!AC:AC"),$AK31&"Pay Short",INDIRECT($AJ31&"!AD:AD")) -> 0 | P31: = | Q31: =SUM(C31:P31) -> 0 | R31: + | S31: =SUMIF(INDIRECT($AJ31&"!AC:AC"),$AK31&"ACCU",INDIRECT($AJ31&"!AD:AD")) -> 0 | T31: - | U31: =SUMIF(INDIRECT($AJ31&"!AC:AC"),$AK31&"DECU",INDIRECT($AJ31&"!AD:AD")) -> 0 | V31: = | W31: =Q31+S31+U31 -> 0 | AJ31: MST1 | AK31: =AK$1 -> 9 | AL31: =B31 -> Morgan - Titan No. 1
A32: 2 | B32: Morgan - Titan No. 2 | C32: =INDIRECT("'"&AJ32&"'!T11") -> 0 | D32: + | E32: =SUMIF(INDIRECT($AJ32&"!AC:AC"),$AK32&"Buy (Accu)",INDIRECT($AJ32&"!AD:AD"))+SUMIF(INDIRECT($AJ32&"!AC:AC"),$AK32&"Buy (Accu-KO)",INDIRECT($AJ32&"!AD:AD")) -> 0 | F32: - | G32: =SUMIF(INDIRECT($AJ32&"!AC:AC"),$AK32&"Sell (Decu)",INDIRECT($AJ32&"!AD:AD"))+SUMIF(INDIRECT($AJ32&"!AC:AC"),$AK32&"Sell (Decu-KO)",INDIRECT($AJ32&"!AD:AD")) -> 0 | H32: + | I32: =SUMIF(INDIRECT($AJ32&"!AC:AC"),$AK32&"Buy (Spot)",INDIRECT($AJ32&"!AD:AD")) -> 0 | J32: - | K32: =SUMIF(INDIRECT($AJ32&"!AC:AC"),$AK32&"Sell (Spot)",INDIRECT($AJ32&"!AD:AD")) -> 0 | L32: + | M32: =SUMIF(INDIRECT($AJ32&"!AC:AC"),$AK32&"Transfer-In",INDIRECT($AJ32&"!AD:AD"))+SUMIF(INDIRECT($AJ32&"!AC:AC"),$AK32&"Transfer-Out",INDIRECT($AJ32&"!AD:AD")) -> 0 | N32: + | O32: =SUMIF(INDIRECT($AJ32&"!AC:AC"),$AK32&"Pay Short",INDIRECT($AJ32&"!AD:AD")) -> 0 | P32: = | Q32: =SUM(C32:P32) -> 0 | R32: + | S32: =SUMIF(INDIRECT($AJ32&"!AC:AC"),$AK32&"ACCU",INDIRECT($AJ32&"!AD:AD")) -> 0 | T32: - | U32: =SUMIF(INDIRECT($AJ32&"!AC:AC"),$AK32&"DECU",INDIRECT($AJ32&"!AD:AD")) -> 0 | V32: = | W32: =Q32+S32+U32 -> 0 | AJ32: MST2 | AK32: =AK$1 -> 9 | AL32: =B32 -> Morgan - Titan No. 2
A33: 3 | B33: Morgan - Perfect Legend | C33: =INDIRECT("'"&AJ33&"'!T11") -> 0 | D33: + | E33: =SUMIF(INDIRECT($AJ33&"!AC:AC"),$AK33&"Buy (Accu)",INDIRECT($AJ33&"!AD:AD"))+SUMIF(INDIRECT($AJ33&"!AC:AC"),$AK33&"Buy (Accu-KO)",INDIRECT($AJ33&"!AD:AD")) -> 0 | F33: - | G33: =SUMIF(INDIRECT($AJ33&"!AC:AC"),$AK33&"Sell (Decu)",INDIRECT($AJ33&"!AD:AD"))+SUMIF(INDIRECT($AJ33&"!AC:AC"),$AK33&"Sell (Decu-KO)",INDIRECT($AJ33&"!AD:AD")) -> 0 | H33: + | I33: =SUMIF(INDIRECT($AJ33&"!AC:AC"),$AK33&"Buy (Spot)",INDIRECT($AJ33&"!AD:AD")) -> 0 | J33: - | K33: =SUMIF(INDIRECT($AJ33&"!AC:AC"),$AK33&"Sell (Spot)",INDIRECT($AJ33&"!AD:AD")) -> 0 | L33: + | M33: =SUMIF(INDIRECT($AJ33&"!AC:AC"),$AK33&"Transfer-In",INDIRECT($AJ33&"!AD:AD"))+SUMIF(INDIRECT($AJ33&"!AC:AC"),$AK33&"Transfer-Out",INDIRECT($AJ33&"!AD:AD")) -> 0 | N33: + | O33: =SUMIF(INDIRECT($AJ33&"!AC:AC"),$AK33&"Pay Short",INDIRECT($AJ33&"!AD:AD")) -> 0 | P33: = | Q33: =SUM(C33:P33) -> 0 | R33: + | S33: =SUMIF(INDIRECT($AJ33&"!AC:AC"),$AK33&"ACCU",INDIRECT($AJ33&"!AD:AD")) -> 0 | T33: - | U33: =SUMIF(INDIRECT($AJ33&"!AC:AC"),$AK33&"DECU",INDIRECT($AJ33&"!AD:AD")) -> 0 | V33: = | W33: =Q33+S33+U33 -> 0 | AJ33: MSPL | AK33: =AK$1 -> 9 | AL33: =B33 -> Morgan - Perfect Legend
B34: Sub-Total | C34: =SUM(C31:C33) -> 0 | E34: =SUM(E31:E33) -> 0 | G34: =SUM(G31:G33) -> 0 | I34: =SUM(I31:I33) -> 0 | K34: =SUM(K31:K33) -> 0 | M34: =SUM(M31:M33) -> 0 | O34: =SUM(O31:O33) -> 0 | Q34: =SUM(Q31:Q33) -> 0 | S34: =SUM(S31:S33) -> 0 | U34: =SUM(U31:U33) -> 0 | W34: =SUM(W31:W33) -> 0
B37: Grand Total | C37: =SUM(C12,C15,C21,C27,C34,C24) -> 0 | D37: + | E37: =SUM(E12,E15,E21,E27,E34,E24) -> 0 | F37: - | G37: =SUM(G12,G15,G21,G27,G34,G24) -> 0 | H37: + | I37: =SUM(I12,I15,I21,I27,I34,I24) -> 0 | J37: - | K37: =SUM(K12,K15,K21,K27,K34,K24) -> 0 | L37: + | M37: =SUM(M12,M15,M21,M27,M34,M24) -> 0 | N37: + | O37: =SUM(O12,O15,O21,O27,O34,O24) -> 0 | P37: = | Q37: =SUM(Q12,Q15,Q21,Q27,Q34,Q24) -> 0 | R37: + | S37: =SUM(S12,S15,S21,S27,S34,S24) -> 0 | T37: - | U37: =SUM(U12,U15,U21,U27,U34,U24) -> 0 | V37: = | W37: =SUM(W12,W15,W21,W27,W34,W24) -> 0

Sheet 2nd
A1: ="Estimate "&stock_name&" Shares till Month of "&TEXT(I6,"mmmm yyyy")&" End" -> Estimate Great Wall Motor Shares till Month of October 2022 End | T1: =MONTH(I6) -> 10
A2: as of | B2: =NOW() -> 44805.577
A4: # | B4: Account | C4: Shares on hand | D4: + | E4: Accumulator | F4: - | G4: Decumulator | H4: = | I4: Estimate End Shares Balance
A6: A. Citibank | I6: =_2nd -> 44865 | Q6: Total short till January
A7: 1 | B7: Citibank Account No. 1 | C7: ='Last Month'!W7 -> 0 | D7: + | E7: =SUMIF(INDIRECT($S7&"!AC:AC"),$T7&"ACCU",INDIRECT($S7&"!AD:AD")) -> 0 | F7: - | G7: =SUMIF(INDIRECT($S7&"!AC:AC"),$T7&"DECU",INDIRECT($S7&"!AD:AD")) -> 0 | H7: = | I7: =C7+E7+G7 -> 0 | K7: 43082 | L7: -193700 | N7: 43115 | O7: -223800 | Q7: Total | R7: =SUM(L7,O7) -> -417500 | S7: CB1 | T7: =T$1 -> 10
A8: 2 | B8: Citibank Account No. 2 | C8: ='Last Month'!W8 -> 0 | D8: + | E8: =SUMIF(INDIRECT($S8&"!AC:AC"),$T8&"ACCU",INDIRECT($S8&"!AD:AD")) -> 0 | F8: - | G8: =SUMIF(INDIRECT($S8&"!AC:AC"),$T8&"DECU",INDIRECT($S8&"!AD:AD")) -> 0 | H8: = | I8: =C8+E8+G8 -> 0 | S8: CB2 | T8: =T$1 -> 10
A9: 3 | B9: Citibank Account No. 3 | C9: ='Last Month'!W9 -> 0 | D9: + | E9: =SUMIF(INDIRECT($S9&"!AC:AC"),$T9&"ACCU",INDIRECT($S9&"!AD:AD")) -> 0 | F9: - | G9: =SUMIF(INDIRECT($S9&"!AC:AC"),$T9&"DECU",INDIRECT($S9&"!AD:AD")) -> 0 | H9: = | I9: =C9+E9+G9 -> 0 | S9: CB3 | T9: =T$1 -> 10
A10: 4 | B10: Citibank Berry Hill | C10: ='Last Month'!W10 -> 0 | D10: + | E10: =SUMIF(INDIRECT($S10&"!AC:AC"),$T10&"ACCU",INDIRECT($S10&"!AD:AD")) -> 0 | F10: - | G10: =SUMIF(INDIRECT($S10&"!AC:AC"),$T10&"DECU",INDIRECT($S10&"!AD:AD")) -> 0 | H10: = | I10: =C10+E10+G10 -> 0 | K10: 43081 | L10: -99590 | N10: 42746 | O10: -410000 | Q10: Total | R10: =SUM(L12,O10) -> -442800 | S10: CBBH | T10: =T$1 -> 10
A11: 5 | B11: Citibank Berry Hill No. 2 | C11: ='Last Month'!W11 -> 0 | D11: + | E11: =SUMIF(INDIRECT($S11&"!AC:AC"),$T11&"ACCU",INDIRECT($S11&"!AD:AD")) -> 0 | F11: - | G11: =SUMIF(INDIRECT($S11&"!AC:AC"),$T11&"DECU",INDIRECT($S11&"!AD:AD")) -> 0 | H11: = | I11: =C11+E11+G11 -> 0 | K11: 43081 | L11: -99590 | N11: 42746 | O11: -410000 | Q11: Total | R11: =SUM(L13,O11) -> -542390 | S11: CBBH2 | T11: =T$1 -> 10
B12: Sub-Total | C12: =SUM(C7:C11) -> 0 | E12: =SUM(E7:E11) -> 0 | G12: =SUM(G7:G11) -> 0 | I12: =SUM(I7:I11) -> 0 | K12: 43097 | L12: -32800
L13: =SUM(L11:L12) -> -132390
A15: B. Bank of Singapore | C15: ='Last Month'!W15 -> 0 | D15: + | E15: =SUMIF(INDIRECT($S15&"!AC:AC"),$T15&"ACCU",INDIRECT($S15&"!AD:AD")) -> 0 | F15: - | G15: =SUMIF(INDIRECT($S15&"!AC:AC"),$T15&"DECU",INDIRECT($S15&"!AD:AD")) -> 0 | H15: = | I15: =C15+E15+G15 -> 0 | S15: BOS | T15: =T$1 -> 10
A18: C. Deutsche Bank
A19: 1 | B19: Deutsche - Personal | C19: ='Last Month'!W19 -> 0 | D19: + | E19: =SUMIF(INDIRECT($S19&"!AC:AC"),$T19&"ACCU",INDIRECT($S19&"!AD:AD")) -> 0 | F19: - | G19: =SUMIF(INDIRECT($S19&"!AC:AC"),$T19&"DECU",INDIRECT($S19&"!AD:AD")) -> 0 | H19: = | I19: =C19+E19+G19 -> 0 | S19: DBPe | T19: =T$1 -> 10
A20: 2 | B20: Deutsche - Perfect Legend | C20: ='Last Month'!W20 -> 0 | D20: + | E20: =SUMIF(INDIRECT($S20&"!AC:AC"),$T20&"ACCU",INDIRECT($S20&"!AD:AD")) -> 0 | F20: - | G20: =SUMIF(INDIRECT($S20&"!AC:AC"),$T20&"DECU",INDIRECT($S20&"!AD:AD")) -> 0 | H20: = | I20: =C20+E20+G20 -> 0 | S20: DBPL | T20: =T$1 -> 10
B21: Sub-Total | C21: =SUM(C19:C20) -> 0 | E21: =SUM(E19:E20) -> 0 | G21: =SUM(G19:G20) -> 0 | I21: =SUM(I19:I20) -> 0
A24: D. Standard Chartered | C24: ='Last Month'!W24 -> 0 | D24: + | E24: =SUMIF(INDIRECT($S24&"!AC:AC"),$T24&"ACCU",INDIRECT($S24&"!AD:AD")) -> 0 | F24: - | G24: =SUMIF(INDIRECT($S24&"!AC:AC"),$T24&"DECU",INDIRECT($S24&"!AD:AD")) -> 0 | H24: = | I24: =SUM(C24,E24,G24) -> 0 | S24: SC | T24: =T$1 -> 10
A27: D. Sun Hung Kai | C27: ='Last Month'!W27 -> 0 | D27: + | E27: =SUMIF(INDIRECT($S27&"!AC:AC"),$T27&"ACCU",INDIRECT($S27&"!AD:AD")) -> 0 | F27: - | G27: =SUMIF(INDIRECT($S27&"!AC:AC"),$T27&"DECU",INDIRECT($S27&"!AD:AD")) -> 0 | H27: = | I27: =SUM(C27,E27,G27) -> 0 | S27: SHK | T27: =T$1 -> 10
A30: E. Morgan Stanley
A31: 1 | B31: Morgan - Titan No. 1 | C31: ='Last Month'!W31 -> 0 | D31: + | E31: =SUMIF(INDIRECT($S31&"!AC:AC"),$T31&"ACCU",INDIRECT($S31&"!AD:AD")) -> 0 | F31: - | G31: =SUMIF(INDIRECT($S31&"!AC:AC"),$T31&"DECU",INDIRECT($S31&"!AD:AD")) -> 0 | H31: = | I31: =C31+E31+G31 -> 0 | S31: MST1 | T31: =T$1 -> 10
A32: 2 | B32: Morgan - Titan No. 2 | C32: ='Last Month'!W32 -> 0 | D32: + | E32: =SUMIF(INDIRECT($S32&"!AC:AC"),$T32&"ACCU",INDIRECT($S32&"!AD:AD")) -> 0 | F32: - | G32: =SUMIF(INDIRECT($S32&"!AC:AC"),$T32&"DECU",INDIRECT($S32&"!AD:AD")) -> 0 | H32: = | I32: =C32+E32+G32 -> 0 | S32: MST2 | T32: =T$1 -> 10
A33: 3 | B33: Morgan - Perfect Legend | C33: ='Last Month'!W33 -> 0 | D33: + | E33: =SUMIF(INDIRECT($S33&"!AC:AC"),$T33&"ACCU",INDIRECT($S33&"!AD:AD")) -> 0 | F33: - | G33: =SUMIF(INDIRECT($S33&"!AC:AC"),$T33&"DECU",INDIRECT($S33&"!AD:AD")) -> 0 | H33: = | I33: =C33+E33+G33 -> 0 | K33: 43076 | L33: -156700 | N33: 42744 | O33: -146700 | Q33: Total | R33: =SUM(L33,O33) -> -303400 | S33: MSPL | T33: =T$1 -> 10
B34: Sub-Total | C34: =SUM(C31:C33) -> 0 | E34: =SUM(E31:E33) -> 0 | G34: =SUM(G31:G33) -> 0 | I34: =SUM(I31:I33) -> 0
B37: Grand Total | C37: =SUM(C12,C15,C21,C27,C34,C24) -> 0 | D37: + | E37: =SUM(E12,E15,E21,E27,E34,E24) -> 0 | F37: - | G37: =SUM(G12,G15,G21,G27,G34,G24) -> 0 | H37: = | I37: =SUM(I12,I15,I21,I27,I34,I24) -> 0 | K37: SHORT | L37: =SUM(L7,L13,L18:L28,L33:L34,) -> -482790 | N37: SHORT | O37: =SUM(O7:O33) -> -1190500 | Q37: SHORT | R37: =SUM(R7:R36) -> -1706090
K38: December | N38: January
B39: Grand Total | C39: 5045300 | D39: + | E39: 574000 | F39: - | G39: -2208500 | H39: = | I39: 3410800 | K39: SHORT | L39: -482790 | N39: SHORT | O39: -1190500 | Q39: SHORT | R39: -1706090
G40: =G39-G37 -> -2208500

Sheet 3rd
A1: ="Estimate "&stock_name&" Shares till Month of "&TEXT(I6,"mmmm yyyy")&" End" -> Estimate Great Wall Motor Shares till Month of November 2022 End | L1: =MONTH(I6) -> 11
A2: as of | B2: ='2nd'!B2:C2 -> 44805.577
A4: # | B4: Account | C4: Shares on hand | D4: + | E4: Accumulator | F4: - | G4: Decumulator | H4: = | I4: Estimate End Shares Balance
A6: A. Citibank | I6: =_3rd -> 44895
A7: 1 | B7: Citibank Account No. 1 | C7: ='2nd'!I7 -> 0 | D7: + | E7: =SUMIF(INDIRECT($K7&"!AC:AC"),$L7&"ACCU",INDIRECT($K7&"!AD:AD")) -> 0 | F7: - | G7: =SUMIF(INDIRECT($K7&"!AC:AC"),$L7&"DECU",INDIRECT($K7&"!AD:AD")) -> 0 | H7: = | I7: =C7+E7+G7 -> 0 | K7: CB1 | L7: =L$1 -> 11
A8: 2 | B8: Citibank Account No. 2 | C8: ='2nd'!I8 -> 0 | D8: + | E8: =SUMIF(INDIRECT($K8&"!AC:AC"),$L8&"ACCU",INDIRECT($K8&"!AD:AD")) -> 0 | F8: - | G8: =SUMIF(INDIRECT($K8&"!AC:AC"),$L8&"DECU",INDIRECT($K8&"!AD:AD")) -> 0 | H8: = | I8: =C8+E8+G8 -> 0 | K8: CB2 | L8: =L$1 -> 11
A9: 3 | B9: Citibank Account No. 3 | C9: ='2nd'!I9 -> 0 | D9: + | E9: =SUMIF(INDIRECT($K9&"!AC:AC"),$L9&"ACCU",INDIRECT($K9&"!AD:AD")) -> 0 | F9: - | G9: =SUMIF(INDIRECT($K9&"!AC:AC"),$L9&"DECU",INDIRECT($K9&"!AD:AD")) -> 0 | H9: = | I9: =C9+E9+G9 -> 0 | K9: CB3 | L9: =L$1 -> 11 | S9: CB3
A10: 4 | B10: Citibank Berry Hill | C10: ='2nd'!I10 -> 0 | D10: + | E10: =SUMIF(INDIRECT($K10&"!AC:AC"),$L10&"ACCU",INDIRECT($K10&"!AD:AD")) -> 0 | F10: - | G10: =SUMIF(INDIRECT($K10&"!AC:AC"),$L10&"DECU",INDIRECT($K10&"!AD:AD")) -> 0 | H10: = | I10: =C10+E10+G10 -> 0 | K10: CBBH | L10: =L$1 -> 11
A11: 5 | B11: Citibank Berry Hill No. 2 | C11: ='2nd'!I11 -> 0 | D11: + | E11: =SUMIF(INDIRECT($K11&"!AC:AC"),$L11&"ACCU",INDIRECT($K11&"!AD:AD")) -> 0 | F11: - | G11: =SUMIF(INDIRECT($K11&"!AC:AC"),$L11&"DECU",INDIRECT($K11&"!AD:AD")) -> 0 | H11: = | I11: =C11+E11+G11 -> 0 | K11: CBBH2 | L11: =L$1 -> 11 | S11: CBBH2
B12: Sub-Total | C12: =SUM(C7:C11) -> 0 | E12: =SUM(E7:E11) -> 0 | G12: =SUM(G7:G11) -> 0 | I12: =SUM(I7:I11) -> 0
A15: B. Bank of Singapore | C15: ='2nd'!I15 -> 0 | D15: + | E15: =SUMIF(INDIRECT($K15&"!AC:AC"),$L15&"ACCU",INDIRECT($K15&"!AD:AD")) -> 0 | F15: - | G15: =SUMIF(INDIRECT($K15&"!AC:AC"),$L15&"DECU",INDIRECT($K15&"!AD:AD")) -> 0 | H15: = | I15: =C15+E15+G15 -> 0 | K15: BOS | L15: =L$1 -> 11
A18: C. Deutsche Bank
A19: 1 | B19: Deutsche - Personal | C19: ='2nd'!I19 -> 0 | D19: + | E19: =SUMIF(INDIRECT($K19&"!AC:AC"),$L19&"ACCU",INDIRECT($K19&"!AD:AD")) -> 0 | F19: - | G19: =SUMIF(INDIRECT($K19&"!AC:AC"),$L19&"DECU",INDIRECT($K19&"!AD:AD")) -> 0 | H19: = | I19: =C19+E19+G19 -> 0 | K19: DBPe | L19: =L$1 -> 11
A20: 2 | B20: Deutsche - Perfect Legend | C20: ='2nd'!I20 -> 0 | D20: + | E20: =SUMIF(INDIRECT($K20&"!AC:AC"),$L20&"ACCU",INDIRECT($K20&"!AD:AD")) -> 0 | F20: - | G20: =SUMIF(INDIRECT($K20&"!AC:AC"),$L20&"DECU",INDIRECT($K20&"!AD:AD")) -> 0 | H20: = | I20: =C20+E20+G20 -> 0 | K20: DBPL | L20: =L$1 -> 11
B21: Sub-Total | C21: =SUM(C19:C20) -> 0 | E21: =SUM(E19:E20) -> 0 | G21: =SUM(G19:G20) -> 0 | I21: =SUM(I19:I20) -> 0
A24: D. Standard Chartered | C24: ='2nd'!I24 -> 0 | D24: + | E24: =SUMIF(INDIRECT($K24&"!AC:AC"),$L24&"ACCU",INDIRECT($K24&"!AD:AD")) -> 0 | F24: - | G24: =SUMIF(INDIRECT($K24&"!AC:AC"),$L24&"DECU",INDIRECT($K24&"!AD:AD")) -> 0 | H24: = | I24: =C24+E24+G24 -> 0 | K24: SC | L24: =L$1 -> 11
A27: D. Sun Hung Kai | C27: ='2nd'!I27 -> 0 | D27: + | E27: =SUMIF(INDIRECT($K27&"!AC:AC"),$L27&"ACCU",INDIRECT($K27&"!AD:AD")) -> 0 | F27: - | G27: =SUMIF(INDIRECT($K27&"!AC:AC"),$L27&"DECU",INDIRECT($K27&"!AD:AD")) -> 0 | H27: = | I27: =C27+E27+G27 -> 0 | K27: SHK | L27: =L$1 -> 11
A30: E. Morgan Stanley
A31: 1 | B31: Morgan - Titan No. 1 | C31: ='2nd'!I31 -> 0 | D31: + | E31: =SUMIF(INDIRECT($K31&"!AC:AC"),$L31&"ACCU",INDIRECT($K31&"!AD:AD")) -> 0 | F31: - | G31: =SUMIF(INDIRECT($K31&"!AC:AC"),$L31&"DECU",INDIRECT($K31&"!AD:AD")) -> 0 | H31: = | I31: =C31+E31+G31 -> 0 | K31: MST1 | L31: =L$1 -> 11
A32: 2 | B32: Morgan - Titan No. 2 | C32: ='2nd'!I32 -> 0 | D32: + | E32: =SUMIF(INDIRECT($K32&"!AC:AC"),$L32&"ACCU",INDIRECT($K32&"!AD:AD")) -> 0 | F32: - | G32: =SUMIF(INDIRECT($K32&"!AC:AC"),$L32&"DECU",INDIRECT($K32&"!AD:AD")) -> 0 | H32: = | I32: =C32+E32+G32 -> 0 | K32: MST2 | L32: =L$1 -> 11
A33: 3 | B33: Morgan - Perfect Legend | C33: ='2nd'!I33 -> 0 | D33: + | E33: =SUMIF(INDIRECT($K33&"!AC:AC"),$L33&"ACCU",INDIRECT($K33&"!AD:AD")) -> 0 | F33: - | G33: =SUMIF(INDIRECT($K33&"!AC:AC"),$L33&"DECU",INDIRECT($K33&"!AD:AD")) -> 0 | H33: = | I33: =C33+E33+G33 -> 0 | K33: MSPL | L33: =L$1 -> 11
B34: Sub-Total | C34: =SUM(C31:C33) -> 0 | E34: =SUM(E31:E33) -> 0 | G34: =SUM(G31:G33) -> 0 | I34: =SUM(I31:I33) -> 0
B37: Grand Total | C37: =SUM(C12,C15,C21,C27,C34,C24) -> 0 | D37: + | E37: =SUM(E12,E15,E21,E27,E34,E24) -> 0 | F37: - | G37: =SUM(G12,G15,G21,G27,G34,G24) -> 0 | H37: = | I37: =SUM(I12,I15,I21,I27,I34,I24) -> 0
B39: Grand Total | C39: 3410800 | D39: + | E39: 560000 | F39: - | G39: -1807300 | H39: = | I39: 2163500
E41: =E37-E39 -> -560000 | G41: =G37-G39 -> 1807300

Sheet 4th
A1: ="Estimate "&stock_name&" Shares till Month of "&TEXT(I6,"mmmm yyyy")&" End" -> Estimate Great Wall Motor Shares till Month of December 2022 End | L1: =MONTH(I6) -> 12
A2: as of | B2: ='2nd'!B2:C2 -> 44805.577
A4: # | B4: Account | C4: Shares on hand | D4: + | E4: Accumulator | F4: - | G4: Decumulator | H4: = | I4: Estimate End Shares Balance
A6: A. Citibank | I6: =_4th -> 44926
A7: 1 | B7: Citibank Account No. 1 | C7: ='3rd'!I7 -> 0 | D7: + | E7: =SUMIF(INDIRECT($K7&"!AC:AC"),$L7&"ACCU",INDIRECT($K7&"!AD:AD")) -> 0 | F7: - | G7: =SUMIF(INDIRECT($K7&"!AC:AC"),$L7&"DECU",INDIRECT($K7&"!AD:AD")) -> 0 | H7: = | I7: =C7+E7+G7 -> 0 | K7: CB1 | L7: =L$1 -> 12
A8: 2 | B8: Citibank Account No. 2 | C8: ='3rd'!I8 -> 0 | D8: + | E8: =SUMIF(INDIRECT($K8&"!AC:AC"),$L8&"ACCU",INDIRECT($K8&"!AD:AD")) -> 0 | F8: - | G8: =SUMIF(INDIRECT($K8&"!AC:AC"),$L8&"DECU",INDIRECT($K8&"!AD:AD")) -> 0 | H8: = | I8: =C8+E8+G8 -> 0 | K8: CB2 | L8: =L$1 -> 12
A9: 3 | B9: Citibank Account No. 3 | C9: ='3rd'!I9 -> 0 | D9: + | E9: =SUMIF(INDIRECT($K9&"!AC:AC"),$L9&"ACCU",INDIRECT($K9&"!AD:AD")) -> 0 | F9: - | G9: =SUMIF(INDIRECT($K9&"!AC:AC"),$L9&"DECU",INDIRECT($K9&"!AD:AD")) -> 0 | H9: = | I9: =C9+E9+G9 -> 0 | K9: CB3 | L9: =L$1 -> 12 | S9: CB3
A10: 4 | B10: Citibank Berry Hill | C10: ='3rd'!I10 -> 0 | D10: + | E10: =SUMIF(INDIRECT($K10&"!AC:AC"),$L10&"ACCU",INDIRECT($K10&"!AD:AD")) -> 0 | F10: - | G10: =SUMIF(INDIRECT($K10&"!AC:AC"),$L10&"DECU",INDIRECT($K10&"!AD:AD")) -> 0 | H10: = | I10: =C10+E10+G10 -> 0 | K10: CBBH | L10: =L$1 -> 12
A11: 5 | B11: Citibank Berry Hill No. 2 | C11: ='3rd'!I11 -> 0 | D11: + | E11: =SUMIF(INDIRECT($K11&"!AC:AC"),$L11&"ACCU",INDIRECT($K11&"!AD:AD")) -> 0 | F11: - | G11: =SUMIF(INDIRECT($K11&"!AC:AC"),$L11&"DECU",INDIRECT($K11&"!AD:AD")) -> 0 | H11: = | I11: =C11+E11+G11 -> 0 | K11: CBBH2 | L11: =L$1 -> 12 | S11: CBBH2
B12: Sub-Total | C12: =SUM(C7:C11) -> 0 | E12: =SUM(E7:E11) -> 0 | G12: =SUM(G7:G11) -> 0 | I12: =SUM(I7:I11) -> 0
A15: B. Bank of Singapore | C15: ='3rd'!I15 -> 0 | D15: + | E15: =SUMIF(INDIRECT($K15&"!AC:AC"),$L15&"ACCU",INDIRECT($K15&"!AD:AD")) -> 0 | F15: - | G15: =SUMIF(INDIRECT($K15&"!AC:AC"),$L15&"DECU",INDIRECT($K15&"!AD:AD")) -> 0 | H15: = | I15: =C15+E15+G15 -> 0 | K15: BOS | L15: =L$1 -> 12
A18: C. Deutsche Bank
A19: 1 | B19: Deutsche - Personal | C19: ='3rd'!I19 -> 0 | D19: + | E19: =SUMIF(INDIRECT($K19&"!AC:AC"),$L19&"ACCU",INDIRECT($K19&"!AD:AD")) -> 0 | F19: - | G19: =SUMIF(INDIRECT($K19&"!AC:AC"),$L19&"DECU",INDIRECT($K19&"!AD:AD")) -> 0 | H19: = | I19: =C19+E19+G19 -> 0 | K19: DBPe | L19: =L$1 -> 12
A20: 2 | B20: Deutsche - Perfect Legend | C20: ='3rd'!I20 -> 0 | D20: + | E20: =SUMIF(INDIRECT($K20&"!AC:AC"),$L20&"ACCU",INDIRECT($K20&"!AD:AD")) -> 0 | F20: - | G20: =SUMIF(INDIRECT($K20&"!AC:AC"),$L20&"DECU",INDIRECT($K20&"!AD:AD")) -> 0 | H20: = | I20: =C20+E20+G20 -> 0 | K20: DBPL | L20: =L$1 -> 12
B21: Sub-Total | C21: =SUM(C19:C20) -> 0 | E21: =SUM(E19:E20) -> 0 | G21: =SUM(G19:G20) -> 0 | I21: =SUM(I19:I20) -> 0
A24: D. Standard Chartered | C24: ='3rd'!I24 -> 0 | D24: + | E24: =SUMIF(INDIRECT($K24&"!AC:AC"),$L24&"ACCU",INDIRECT($K24&"!AD:AD")) -> 0 | F24: - | G24: =SUMIF(INDIRECT($K24&"!AC:AC"),$L24&"DECU",INDIRECT($K24&"!AD:AD")) -> 0 | H24: = | I24: =C24+E24+G24 -> 0 | K24: SC | L24: =L$1 -> 12
A27: D. Sun Hung Kai | C27: ='3rd'!I27 -> 0 | D27: + | E27: =SUMIF(INDIRECT($K27&"!AC:AC"),$L27&"ACCU",INDIRECT($K27&"!AD:AD")) -> 0 | F27: - | G27: =SUMIF(INDIRECT($K27&"!AC:AC"),$L27&"DECU",INDIRECT($K27&"!AD:AD")) -> 0 | H27: = | I27: =C27+E27+G27 -> 0 | K27: SHK | L27: =L$1 -> 12
A30: E. Morgan Stanley
A31: 1 | B31: Morgan - Titan No. 1 | C31: ='3rd'!I31 -> 0 | D31: + | E31: =SUMIF(INDIRECT($K31&"!AC:AC"),$L31&"ACCU",INDIRECT($K31&"!AD:AD")) -> 0 | F31: - | G31: =SUMIF(INDIRECT($K31&"!AC:AC"),$L31&"DECU",INDIRECT($K31&"!AD:AD")) -> 0 | H31: = | I31: =C31+E31+G31 -> 0 | K31: MST1 | L31: =L$1 -> 12
A32: 2 | B32: Morgan - Titan No. 2 | C32: ='3rd'!I32 -> 0 | D32: + | E32: =SUMIF(INDIRECT($K32&"!AC:AC"),$L32&"ACCU",INDIRECT($K32&"!AD:AD")) -> 0 | F32: - | G32: =SUMIF(INDIRECT($K32&"!AC:AC"),$L32&"DECU",INDIRECT($K32&"!AD:AD")) -> 0 | H32: = | I32: =C32+E32+G32 -> 0 | K32: MST2 | L32: =L$1 -> 12
A33: 3 | B33: Morgan - Perfect Legend | C33: ='3rd'!I33 -> 0 | D33: + | E33: =SUMIF(INDIRECT($K33&"!AC:AC"),$L33&"ACCU",INDIRECT($K33&"!AD:AD")) -> 0 | F33: - | G33: =SUMIF(INDIRECT($K33&"!AC:AC"),$L33&"DECU",INDIRECT($K33&"!AD:AD")) -> 0 | H33: = | I33: =C33+E33+G33 -> 0 | K33: MSPL | L33: =L$1 -> 12
B34: Sub-Total | C34: =SUM(C31:C33) -> 0 | E34: =SUM(E31:E33) -> 0 | G34: =SUM(G31:G33) -> 0 | I34: =SUM(I31:I33) -> 0
B37: Grand Total | C37: =SUM(C12,C15,C21,C27,C34,C24) -> 0 | D37: + | E37: =SUM(E12,E15,E21,E27,E34,E24) -> 0 | F37: - | G37: =SUM(G12,G15,G21,G27,G34,G24) -> 0 | H37: = | I37: =SUM(I12,I15,I21,I27,I34,I24) -> 0
B39: Grand Total | C39: 2163500 | D39: + | E39: 322000 | F39: - | G39: -882600 | H39: = | I39: 1602900
E41: =E37-E39 -> -322000 | G41: =G37-G39 -> 882600

Sheet 5th
A1: ="Estimate "&stock_name&" Shares till Month of "&TEXT(I6,"mmmm yyyy")&" End" -> Estimate Great Wall Motor Shares till Month of January 2023 End | L1: =MONTH(I6) -> 1
A2: as of | B2: ='2nd'!B2:C2 -> 44805.577
A4: # | B4: Account | C4: Shares on hand | D4: + | E4: Accumulator | F4: - | G4: Decumulator | H4: = | I4: Estimate End Shares Balance
A6: A. Citibank | I6: =_5th -> 44957
A7: 1 | B7: Citibank Account No. 1 | C7: ='4th'!I7 -> 0 | D7: + | E7: =SUMIF(INDIRECT($K7&"!AC:AC"),$L7&"ACCU",INDIRECT($K7&"!AD:AD")) -> 0 | F7: - | G7: =SUMIF(INDIRECT($K7&"!AC:AC"),$L7&"DECU",INDIRECT($K7&"!AD:AD")) -> 0 | H7: = | I7: =C7+E7+G7 -> 0 | K7: CB1 | L7: =L$1 -> 1
A8: 2 | B8: Citibank Account No. 2 | C8: ='4th'!I8 -> 0 | D8: + | E8: =SUMIF(INDIRECT($K8&"!AC:AC"),$L8&"ACCU",INDIRECT($K8&"!AD:AD")) -> 0 | F8: - | G8: =SUMIF(INDIRECT($K8&"!AC:AC"),$L8&"DECU",INDIRECT($K8&"!AD:AD")) -> 0 | H8: = | I8: =C8+E8+G8 -> 0 | K8: CB2 | L8: =L$1 -> 1
A9: 3 | B9: Citibank Account No. 3 | C9: ='4th'!I9 -> 0 | D9: + | E9: =SUMIF(INDIRECT($K9&"!AC:AC"),$L9&"ACCU",INDIRECT($K9&"!AD:AD")) -> 0 | F9: - | G9: =SUMIF(INDIRECT($K9&"!AC:AC"),$L9&"DECU",INDIRECT($K9&"!AD:AD")) -> 0 | H9: = | I9: =C9+E9+G9 -> 0 | K9: CB3 | L9: =L$1 -> 1 | S9: CB3
A10: 4 | B10: Citibank Berry Hill | C10: ='4th'!I10 -> 0 | D10: + | E10: =SUMIF(INDIRECT($K10&"!AC:AC"),$L10&"ACCU",INDIRECT($K10&"!AD:AD")) -> 0 | F10: - | G10: =SUMIF(INDIRECT($K10&"!AC:AC"),$L10&"DECU",INDIRECT($K10&"!AD:AD")) -> 0 | H10: = | I10: =C10+E10+G10 -> 0 | K10: CBBH | L10: =L$1 -> 1
A11: 5 | B11: Citibank Berry Hill No. 2 | C11: ='4th'!I11 -> 0 | D11: + | E11: =SUMIF(INDIRECT($K11&"!AC:AC"),$L11&"ACCU",INDIRECT($K11&"!AD:AD")) -> 0 | F11: - | G11: =SUMIF(INDIRECT($K11&"!AC:AC"),$L11&"DECU",INDIRECT($K11&"!AD:AD")) -> 0 | H11: = | I11: =C11+E11+G11 -> 0 | K11: CBBH2 | L11: =L$1 -> 1 | S11: CBBH2
B12: Sub-Total | C12: =SUM(C7:C11) -> 0 | E12: =SUM(E7:E11) -> 0 | G12: =SUM(G7:G11) -> 0 | I12: =SUM(I7:I11) -> 0
A15: B. Bank of Singapore | C15: ='4th'!I15 -> 0 | D15: + | E15: =SUMIF(INDIRECT($K15&"!AC:AC"),$L15&"ACCU",INDIRECT($K15&"!AD:AD")) -> 0 | F15: - | G15: =SUMIF(INDIRECT($K15&"!AC:AC"),$L15&"DECU",INDIRECT($K15&"!AD:AD")) -> 0 | H15: = | I15: =C15+E15+G15 -> 0 | K15: BOS | L15: =L$1 -> 1
A18: C. Deutsche Bank
A19: 1 | B19: Deutsche - Personal | C19: ='4th'!I19 -> 0 | D19: + | E19: =SUMIF(INDIRECT($K19&"!AC:AC"),$L19&"ACCU",INDIRECT($K19&"!AD:AD")) -> 0 | F19: - | G19: =SUMIF(INDIRECT($K19&"!AC:AC"),$L19&"DECU",INDIRECT($K19&"!AD:AD")) -> 0 | H19: = | I19: =C19+E19+G19 -> 0 | K19: DBPe | L19: =L$1 -> 1
A20: 2 | B20: Deutsche - Perfect Legend | C20: ='4th'!I20 -> 0 | D20: + | E20: =SUMIF(INDIRECT($K20&"!AC:AC"),$L20&"ACCU",INDIRECT($K20&"!AD:AD")) -> 0 | F20: - | G20: =SUMIF(INDIRECT($K20&"!AC:AC"),$L20&"DECU",INDIRECT($K20&"!AD:AD")) -> 0 | H20: = | I20: =C20+E20+G20 -> 0 | K20: DBPL | L20: =L$1 -> 1
B21: Sub-Total | C21: =SUM(C19:C20) -> 0 | E21: =SUM(E19:E20) -> 0 | G21: =SUM(G19:G20) -> 0 | I21: =SUM(I19:I20) -> 0
A24: D. Standard Chartered | C24: ='4th'!I24 -> 0 | D24: + | E24: =SUMIF(INDIRECT($K24&"!AC:AC"),$L24&"ACCU",INDIRECT($K24&"!AD:AD")) -> 0 | F24: - | G24: =SUMIF(INDIRECT($K24&"!AC:AC"),$L24&"DECU",INDIRECT($K24&"!AD:AD")) -> 0 | H24: = | I24: =C24+E24+G24 -> 0 | K24: SC | L24: =L$1 -> 1
A27: D. Sun Hung Kai | C27: ='4th'!I27 -> 0 | D27: + | E27: =SUMIF(INDIRECT($K27&"!AC:AC"),$L27&"ACCU",INDIRECT($K27&"!AD:AD")) -> 0 | F27: - | G27: =SUMIF(INDIRECT($K27&"!AC:AC"),$L27&"DECU",INDIRECT($K27&"!AD:AD")) -> 0 | H27: = | I27: =C27+E27+G27 -> 0 | K27: SHK | L27: =L$1 -> 1
A30: E. Morgan Stanley
A31: 1 | B31: Morgan - Titan No. 1 | C31: ='4th'!I31 -> 0 | D31: + | E31: =SUMIF(INDIRECT($K31&"!AC:AC"),$L31&"ACCU",INDIRECT($K31&"!AD:AD")) -> 0 | F31: - | G31: =SUMIF(INDIRECT($K31&"!AC:AC"),$L31&"DECU",INDIRECT($K31&"!AD:AD")) -> 0 | H31: = | I31: =C31+E31+G31 -> 0 | K31: MST1 | L31: =L$1 -> 1
A32: 2 | B32: Morgan - Titan No. 2 | C32: ='4th'!I32 -> 0 | D32: + | E32: =SUMIF(INDIRECT($K32&"!AC:AC"),$L32&"ACCU",INDIRECT($K32&"!AD:AD")) -> 0 | F32: - | G32: =SUMIF(INDIRECT($K32&"!AC:AC"),$L32&"DECU",INDIRECT($K32&"!AD:AD")) -> 0 | H32: = | I32: =C32+E32+G32 -> 0 | K32: MST2 | L32: =L$1 -> 1
A33: 3 | B33: Morgan - Perfect Legend | C33: ='4th'!I33 -> 0 | D33: + | E33: =SUMIF(INDIRECT($K33&"!AC:AC"),$L33&"ACCU",INDIRECT($K33&"!AD:AD")) -> 0 | F33: - | G33: =SUMIF(INDIRECT($K33&"!AC:AC"),$L33&"DECU",INDIRECT($K33&"!AD:AD")) -> 0 | H33: = | I33: =C33+E33+G33 -> 0 | K33: MSPL | L33: =L$1 -> 1
B34: Sub-Total | C34: =SUM(C31:C33) -> 0 | E34: =SUM(E31:E33) -> 0 | G34: =SUM(G31:G33) -> 0 | I34: =SUM(I31:I33) -> 0
B37: Grand Total | C37: =SUM(C12,C15,C21,C27,C34,C24) -> 0 | D37: + | E37: =SUM(E12,E15,E21,E27,E34,E24) -> 0 | F37: - | G37: =SUM(G12,G15,G21,G27,G34,G24) -> 0 | H37: = | I37: =SUM(I12,I15,I21,I27,I34,I24) -> 0
B39: Grand Total | C39: 1602900 | D39: + | E39: 294000 | F39: - | G39: -52500 | H39: = | I39: 1844400
E41: =E37-E39 -> -294000 | G41: =G37-G39 -> 52500

Sheet 6th
A1: ="Estimate "&stock_name&" Shares till Month of "&TEXT(I6,"mmmm yyyy")&" End" -> Estimate Great Wall Motor Shares till Month of February 2023 End | L1: =MONTH(I6) -> 2
A2: as of | B2: ='2nd'!B2:C2 -> 44805.577
A4: # | B4: Account | C4: Shares on hand | D4: + | E4: Accumulator | F4: - | G4: Decumulator | H4: = | I4: Estimate End Shares Balance
A6: A. Citibank | I6: =_6th -> 44985
A7: 1 | B7: Citibank Account No. 1 | C7: ='5th'!I7 -> 0 | D7: + | E7: =SUMIF(INDIRECT($K7&"!AC:AC"),$L7&"ACCU",INDIRECT($K7&"!AD:AD")) -> 0 | F7: - | G7: =SUMIF(INDIRECT($K7&"!AC:AC"),$L7&"DECU",INDIRECT($K7&"!AD:AD")) -> 0 | H7: = | I7: =C7+E7+G7 -> 0 | K7: CB1 | L7: =L$1 -> 2
A8: 2 | B8: Citibank Account No. 2 | C8: ='5th'!I8 -> 0 | D8: + | E8: =SUMIF(INDIRECT($K8&"!AC:AC"),$L8&"ACCU",INDIRECT($K8&"!AD:AD")) -> 0 | F8: - | G8: =SUMIF(INDIRECT($K8&"!AC:AC"),$L8&"DECU",INDIRECT($K8&"!AD:AD")) -> 0 | H8: = | I8: =C8+E8+G8 -> 0 | K8: CB2 | L8: =L$1 -> 2
A9: 3 | B9: Citibank Account No. 3 | C9: ='5th'!I9 -> 0 | D9: + | E9: =SUMIF(INDIRECT($K9&"!AC:AC"),$L9&"ACCU",INDIRECT($K9&"!AD:AD")) -> 0 | F9: - | G9: =SUMIF(INDIRECT($K9&"!AC:AC"),$L9&"DECU",INDIRECT($K9&"!AD:AD")) -> 0 | H9: = | I9: =C9+E9+G9 -> 0 | K9: CB3 | L9: =L$1 -> 2 | S9: CB3
A10: 4 | B10: Citibank Berry Hill | C10: ='5th'!I10 -> 0 | D10: + | E10: =SUMIF(INDIRECT($K10&"!AC:AC"),$L10&"ACCU",INDIRECT($K10&"!AD:AD")) -> 0 | F10: - | G10: =SUMIF(INDIRECT($K10&"!AC:AC"),$L10&"DECU",INDIRECT($K10&"!AD:AD")) -> 0 | H10: = | I10: =C10+E10+G10 -> 0 | K10: CBBH | L10: =L$1 -> 2
A11: 5 | B11: Citibank Berry Hill No. 2 | C11: ='5th'!I11 -> 0 | D11: + | E11: =SUMIF(INDIRECT($K11&"!AC:AC"),$L11&"ACCU",INDIRECT($K11&"!AD:AD")) -> 0 | F11: - | G11: =SUMIF(INDIRECT($K11&"!AC:AC"),$L11&"DECU",INDIRECT($K11&"!AD:AD")) -> 0 | H11: = | I11: =C11+E11+G11 -> 0 | K11: CBBH2 | L11: =L$1 -> 2 | S11: CBBH2
B12: Sub-Total | C12: =SUM(C7:C11) -> 0 | E12: =SUM(E7:E11) -> 0 | G12: =SUM(G7:G11) -> 0 | I12: =SUM(I7:I11) -> 0
A15: B. Bank of Singapore | C15: ='5th'!I15 -> 0 | D15: + | E15: =SUMIF(INDIRECT($K15&"!AC:AC"),$L15&"ACCU",INDIRECT($K15&"!AD:AD")) -> 0 | F15: - | G15: =SUMIF(INDIRECT($K15&"!AC:AC"),$L15&"DECU",INDIRECT($K15&"!AD:AD")) -> 0 | H15: = | I15: =C15+E15+G15 -> 0 | K15: BOS | L15: =L$1 -> 2
A18: C. Deutsche Bank
A19: 1 | B19: Deutsche - Personal | C19: ='5th'!I19 -> 0 | D19: + | E19: =SUMIF(INDIRECT($K19&"!AC:AC"),$L19&"ACCU",INDIRECT($K19&"!AD:AD")) -> 0 | F19: - | G19: =SUMIF(INDIRECT($K19&"!AC:AC"),$L19&"DECU",INDIRECT($K19&"!AD:AD")) -> 0 | H19: = | I19: =C19+E19+G19 -> 0 | K19: DBPe | L19: =L$1 -> 2
A20: 2 | B20: Deutsche - Perfect Legend | C20: ='5th'!I20 -> 0 | D20: + | E20: =SUMIF(INDIRECT($K20&"!AC:AC"),$L20&"ACCU",INDIRECT($K20&"!AD:AD")) -> 0 | F20: - | G20: =SUMIF(INDIRECT($K20&"!AC:AC"),$L20&"DECU",INDIRECT($K20&"!AD:AD")) -> 0 | H20: = | I20: =C20+E20+G20 -> 0 | K20: DBPL | L20: =L$1 -> 2
B21: Sub-Total | C21: =SUM(C19:C20) -> 0 | E21: =SUM(E19:E20) -> 0 | G21: =SUM(G19:G20) -> 0 | I21: =SUM(I19:I20) -> 0
A24: D. Standard Chartered | C24: ='5th'!I24 -> 0 | D24: + | E24: =SUMIF(INDIRECT($K24&"!AC:AC"),$L24&"ACCU",INDIRECT($K24&"!AD:AD")) -> 0 | F24: - | G24: =SUMIF(INDIRECT($K24&"!AC:AC"),$L24&"DECU",INDIRECT($K24&"!AD:AD")) -> 0 | H24: = | I24: =C24+E24+G24 -> 0 | K24: SC | L24: =L$1 -> 2
A27: D. Sun Hung Kai | C27: ='5th'!I27 -> 0 | D27: + | E27: =SUMIF(INDIRECT($K27&"!AC:AC"),$L27&"ACCU",INDIRECT($K27&"!AD:AD")) -> 0 | F27: - | G27: =SUMIF(INDIRECT($K27&"!AC:AC"),$L27&"DECU",INDIRECT($K27&"!AD:AD")) -> 0 | H27: = | I27: =C27+E27+G27 -> 0 | K27: SHK | L27: =L$1 -> 2
A30: E. Morgan Stanley
A31: 1 | B31: Morgan - Titan No. 1 | C31: ='5th'!I31 -> 0 | D31: + | E31: =SUMIF(INDIRECT($K31&"!AC:AC"),$L31&"ACCU",INDIRECT($K31&"!AD:AD")) -> 0 | F31: - | G31: =SUMIF(INDIRECT($K31&"!AC:AC"),$L31&"DECU",INDIRECT($K31&"!AD:AD")) -> 0 | H31: = | I31: =C31+E31+G31 -> 0 | K31: MST1 | L31: =L$1 -> 2
A32: 2 | B32: Morgan - Titan No. 2 | C32: ='5th'!I32 -> 0 | D32: + | E32: =SUMIF(INDIRECT($K32&"!AC:AC"),$L32&"ACCU",INDIRECT($K32&"!AD:AD")) -> 0 | F32: - | G32: =SUMIF(INDIRECT($K32&"!AC:AC"),$L32&"DECU",INDIRECT($K32&"!AD:AD")) -> 0 | H32: = | I32: =C32+E32+G32 -> 0 | K32: MST2 | L32: =L$1 -> 2
A33: 3 | B33: Morgan - Perfect Legend | C33: ='5th'!I33 -> 0 | D33: + | E33: =SUMIF(INDIRECT($K33&"!AC:AC"),$L33&"ACCU",INDIRECT($K33&"!AD:AD")) -> 0 | F33: - | G33: =SUMIF(INDIRECT($K33&"!AC:AC"),$L33&"DECU",INDIRECT($K33&"!AD:AD")) -> 0 | H33: = | I33: =C33+E33+G33 -> 0 | K33: MSPL | L33: =L$1 -> 2
B34: Sub-Total | C34: =SUM(C31:C33) -> 0 | E34: =SUM(E31:E33) -> 0 | G34: =SUM(G31:G33) -> 0 | I34: =SUM(I31:I33) -> 0
B37: Grand Total | C37: =SUM(C12,C15,C21,C27,C34,C24) -> 0 | D37: + | E37: =SUM(E12,E15,E21,E27,E34,E24) -> 0 | F37: - | G37: =SUM(G12,G15,G21,G27,G34,G24) -> 0 | H37: = | I37: =SUM(I12,I15,I21,I27,I34,I24) -> 0
B39: Grand Total | C39: 1844400 | D39: + | E39: 266000 | F39: - | G39: -61600 | H39: = | I39: 2048800
E41: =E37-E39 -> -266000 | G41: =G37-G39 -> 61600

Sheet 7th
A1: ="Estimate "&stock_name&" Shares till Month of "&TEXT(I6,"mmmm yyyy")&" End" -> Estimate Great Wall Motor Shares till Month of March 2023 End | L1: =MONTH(I6) -> 3
A2: as of | B2: ='2nd'!B2:C2 -> 44805.577
A4: # | B4: Account | C4: Shares on hand | D4: + | E4: Accumulator | F4: - | G4: Decumulator | H4: = | I4: Estimate End Shares Balance
A6: A. Citibank | I6: =_7th -> 45016
A7: 1 | B7: Citibank Account No. 1 | C7: ='6th'!I7 -> 0 | D7: + | E7: =SUMIF(INDIRECT($K7&"!AC:AC"),$L7&"ACCU",INDIRECT($K7&"!AD:AD")) -> 0 | F7: - | G7: =SUMIF(INDIRECT($K7&"!AC:AC"),$L7&"DECU",INDIRECT($K7&"!AD:AD")) -> 0 | H7: = | I7: =C7+E7+G7 -> 0 | K7: CB1 | L7: =L$1 -> 3
A8: 2 | B8: Citibank Account No. 2 | C8: ='6th'!I8 -> 0 | D8: + | E8: =SUMIF(INDIRECT($K8&"!AC:AC"),$L8&"ACCU",INDIRECT($K8&"!AD:AD")) -> 0 | F8: - | G8: =SUMIF(INDIRECT($K8&"!AC:AC"),$L8&"DECU",INDIRECT($K8&"!AD:AD")) -> 0 | H8: = | I8: =C8+E8+G8 -> 0 | K8: CB2 | L8: =L$1 -> 3
A9: 3 | B9: Citibank Account No. 3 | C9: ='6th'!I9 -> 0 | D9: + | E9: =SUMIF(INDIRECT($K9&"!AC:AC"),$L9&"ACCU",INDIRECT($K9&"!AD:AD")) -> 0 | F9: - | G9: =SUMIF(INDIRECT($K9&"!AC:AC"),$L9&"DECU",INDIRECT($K9&"!AD:AD")) -> 0 | H9: = | I9: =C9+E9+G9 -> 0 | K9: CB3 | L9: =L$1 -> 3 | S9: CB3
A10: 4 | B10: Citibank Berry Hill | C10: ='6th'!I10 -> 0 | D10: + | E10: =SUMIF(INDIRECT($K10&"!AC:AC"),$L10&"ACCU",INDIRECT($K10&"!AD:AD")) -> 0 | F10: - | G10: =SUMIF(INDIRECT($K10&"!AC:AC"),$L10&"DECU",INDIRECT($K10&"!AD:AD")) -> 0 | H10: = | I10: =C10+E10+G10 -> 0 | K10: CBBH | L10: =L$1 -> 3
A11: 5 | B11: Citibank Berry Hill No. 2 | C11: ='6th'!I11 -> 0 | D11: + | E11: =SUMIF(INDIRECT($K11&"!AC:AC"),$L11&"ACCU",INDIRECT($K11&"!AD:AD")) -> 0 | F11: - | G11: =SUMIF(INDIRECT($K11&"!AC:AC"),$L11&"DECU",INDIRECT($K11&"!AD:AD")) -> 0 | H11: = | I11: =C11+E11+G11 -> 0 | K11: CBBH2 | L11: =L$1 -> 3 | S11: CBBH2
B12: Sub-Total | C12: =SUM(C7:C11) -> 0 | E12: =SUM(E7:E11) -> 0 | G12: =SUM(G7:G11) -> 0 | I12: =SUM(I7:I11) -> 0
A15: B. Bank of Singapore | C15: ='6th'!I15 -> 0 | D15: + | E15: =SUMIF(INDIRECT($K15&"!AC:AC"),$L15&"ACCU",INDIRECT($K15&"!AD:AD")) -> 0 | F15: - | G15: =SUMIF(INDIRECT($K15&"!AC:AC"),$L15&"DECU",INDIRECT($K15&"!AD:AD")) -> 0 | H15: = | I15: =C15+E15+G15 -> 0 | K15: BOS | L15: =L$1 -> 3
A18: C. Deutsche Bank
A19: 1 | B19: Deutsche - Personal | C19: ='6th'!I19 -> 0 | D19: + | E19: =SUMIF(INDIRECT($K19&"!AC:AC"),$L19&"ACCU",INDIRECT($K19&"!AD:AD")) -> 0 | F19: - | G19: =SUMIF(INDIRECT($K19&"!AC:AC"),$L19&"DECU",INDIRECT($K19&"!AD:AD")) -> 0 | H19: = | I19: =C19+E19+G19 -> 0 | K19: DBPe | L19: =L$1 -> 3
A20: 2 | B20: Deutsche - Perfect Legend | C20: ='3rd'!I20 -> 0 | D20: + | E20: =SUMIF(INDIRECT($K20&"!AC:AC"),$L20&"ACCU",INDIRECT($K20&"!AD:AD")) -> 0 | F20: - | G20: =SUMIF(INDIRECT($K20&"!AC:AC"),$L20&"DECU",INDIRECT($K20&"!AD:AD")) -> 0 | H20: = | I20: =C20+E20+G20 -> 0 | K20: DBPL | L20: =L$1 -> 3
B21: Sub-Total | C21: =SUM(C19:C20) -> 0 | E21: =SUM(E19:E20) -> 0 | G21: =SUM(G19:G20) -> 0 | I21: =SUM(I19:I20) -> 0
A24: D. Standard Chartered | C24: ='6th'!I24 -> 0 | D24: + | E24: =SUMIF(INDIRECT($K24&"!AC:AC"),$L24&"ACCU",INDIRECT($K24&"!AD:AD")) -> 0 | F24: - | G24: =SUMIF(INDIRECT($K24&"!AC:AC"),$L24&"DECU",INDIRECT($K24&"!AD:AD")) -> 0 | H24: = | I24: =C24+E24+G24 -> 0 | K24: SC | L24: =L$1 -> 3
A27: D. Sun Hung Kai | C27: ='6th'!I27 -> 0 | D27: + | E27: =SUMIF(INDIRECT($K27&"!AC:AC"),$L27&"ACCU",INDIRECT($K27&"!AD:AD")) -> 0 | F27: - | G27: =SUMIF(INDIRECT($K27&"!AC:AC"),$L27&"DECU",INDIRECT($K27&"!AD:AD")) -> 0 | H27: = | I27: =C27+E27+G27 -> 0 | K27: SHK | L27: =L$1 -> 3
A30: E. Morgan Stanley
A31: 1 | B31: Morgan - Titan No. 1 | C31: ='6th'!I31 -> 0 | D31: + | E31: =SUMIF(INDIRECT($K31&"!AC:AC"),$L31&"ACCU",INDIRECT($K31&"!AD:AD")) -> 0 | F31: - | G31: =SUMIF(INDIRECT($K31&"!AC:AC"),$L31&"DECU",INDIRECT($K31&"!AD:AD")) -> 0 | H31: = | I31: =C31+E31+G31 -> 0 | K31: MST1 | L31: =L$1 -> 3
A32: 2 | B32: Morgan - Titan No. 2 | C32: ='6th'!I32 -> 0 | D32: + | E32: =SUMIF(INDIRECT($K32&"!AC:AC"),$L32&"ACCU",INDIRECT($K32&"!AD:AD")) -> 0 | F32: - | G32: =SUMIF(INDIRECT($K32&"!AC:AC"),$L32&"DECU",INDIRECT($K32&"!AD:AD")) -> 0 | H32: = | I32: =C32+E32+G32 -> 0 | K32: MST2 | L32: =L$1 -> 3
A33: 3 | B33: Morgan - Perfect Legend | C33: ='6th'!I33 -> 0 | D33: + | E33: =SUMIF(INDIRECT($K33&"!AC:AC"),$L33&"ACCU",INDIRECT($K33&"!AD:AD")) -> 0 | F33: - | G33: =SUMIF(INDIRECT($K33&"!AC:AC"),$L33&"DECU",INDIRECT($K33&"!AD:AD")) -> 0 | H33: = | I33: =C33+E33+G33 -> 0 | K33: MSPL | L33: =L$1 -> 3
B34: Sub-Total | C34: =SUM(C31:C33) -> 0 | E34: =SUM(E31:E33) -> 0 | G34: =SUM(G31:G33) -> 0 | I34: =SUM(I31:I33) -> 0
B37: Grand Total | C37: =SUM(C12,C15,C21,C27,C34,C24) -> 0 | D37: + | E37: =SUM(E12,E15,E21,E27,E34,E24) -> 0 | F37: - | G37: =SUM(G12,G15,G21,G27,G34,G24) -> 0 | H37: = | I37: =SUM(I12,I15,I21,I27,I34,I24) -> 0
B39: Grand Total | C39: 62550 | D39: + | E39: 0 | F39: - | G39: 0 | H39: = | I39: -647450
E41: =E37-E39 -> 0 | G41: =G37-G39 -> 0

Sheet 8th
A1: ="Estimate "&stock_name&" Shares till Month of "&TEXT(I6,"mmmm yyyy")&" End" -> Estimate Great Wall Motor Shares till Month of April 2023 End | L1: =MONTH(I6) -> 4
A2: as of | B2: ='2nd'!B2:C2 -> 44805.577
A4: # | B4: Account | C4: Shares on hand | D4: + | E4: Accumulator | F4: - | G4: Decumulator | H4: = | I4: Estimate End Shares Balance
A6: A. Citibank | I6: =_8th -> 45046
A7: 1 | B7: Citibank Account No. 1 | C7: ='7th'!I7 -> 0 | D7: + | E7: =SUMIF(INDIRECT($K7&"!AC:AC"),$L7&"ACCU",INDIRECT($K7&"!AD:AD")) -> 0 | F7: - | G7: =SUMIF(INDIRECT($K7&"!AC:AC"),$L7&"DECU",INDIRECT($K7&"!AD:AD")) -> 0 | H7: = | I7: =C7+E7+G7 -> 0 | K7: CB1 | L7: =L$1 -> 4
A8: 2 | B8: Citibank Account No. 2 | C8: ='7th'!I8 -> 0 | D8: + | E8: =SUMIF(INDIRECT($K8&"!AC:AC"),$L8&"ACCU",INDIRECT($K8&"!AD:AD")) -> 0 | F8: - | G8: =SUMIF(INDIRECT($K8&"!AC:AC"),$L8&"DECU",INDIRECT($K8&"!AD:AD")) -> 0 | H8: = | I8: =C8+E8+G8 -> 0 | K8: CB2 | L8: =L$1 -> 4
A9: 3 | B9: Citibank Account No. 3 | C9: ='7th'!I9 -> 0 | D9: + | E9: =SUMIF(INDIRECT($K9&"!AC:AC"),$L9&"ACCU",INDIRECT($K9&"!AD:AD")) -> 0 | F9: - | G9: =SUMIF(INDIRECT($K9&"!AC:AC"),$L9&"DECU",INDIRECT($K9&"!AD:AD")) -> 0 | H9: = | I9: =C9+E9+G9 -> 0 | K9: CB3 | L9: =L$1 -> 4 | S9: CB3
A10: 4 | B10: Citibank Berry Hill | C10: ='7th'!I10 -> 0 | D10: + | E10: =SUMIF(INDIRECT($K10&"!AC:AC"),$L10&"ACCU",INDIRECT($K10&"!AD:AD")) -> 0 | F10: - | G10: =SUMIF(INDIRECT($K10&"!AC:AC"),$L10&"DECU",INDIRECT($K10&"!AD:AD")) -> 0 | H10: = | I10: =C10+E10+G10 -> 0 | K10: CBBH | L10: =L$1 -> 4
A11: 5 | B11: Citibank Berry Hill No. 2 | C11: ='7th'!I11 -> 0 | D11: + | E11: =SUMIF(INDIRECT($K11&"!AC:AC"),$L11&"ACCU",INDIRECT($K11&"!AD:AD")) -> 0 | F11: - | G11: =SUMIF(INDIRECT($K11&"!AC:AC"),$L11&"DECU",INDIRECT($K11&"!AD:AD")) -> 0 | H11: = | I11: =C11+E11+G11 -> 0 | K11: CBBH2 | L11: =L$1 -> 4 | S11: CBBH2
B12: Sub-Total | C12: =SUM(C7:C11) -> 0 | E12: =SUM(E7:E11) -> 0 | G12: =SUM(G7:G11) -> 0 | I12: =SUM(I7:I11) -> 0
A15: B. Bank of Singapore | C15: ='7th'!I15 -> 0 | D15: + | E15: =SUMIF(INDIRECT($K15&"!AC:AC"),$L15&"ACCU",INDIRECT($K15&"!AD:AD")) -> 0 | F15: - | G15: =SUMIF(INDIRECT($K15&"!AC:AC"),$L15&"DECU",INDIRECT($K15&"!AD:AD")) -> 0 | H15: = | I15: =C15+E15+G15 -> 0 | K15: BOS | L15: =L$1 -> 4
A18: C. Deutsche Bank
A19: 1 | B19: Deutsche - Personal | C19: ='7th'!I19 -> 0 | D19: + | E19: =SUMIF(INDIRECT($K19&"!AC:AC"),$L19&"ACCU",INDIRECT($K19&"!AD:AD")) -> 0 | F19: - | G19: =SUMIF(INDIRECT($K19&"!AC:AC"),$L19&"DECU",INDIRECT($K19&"!AD:AD")) -> 0 | H19: = | I19: =C19+E19+G19 -> 0 | K19: DBPe | L19: =L$1 -> 4
A20: 2 | B20: Deutsche - Perfect Legend | C20: ='3rd'!I20 -> 0 | D20: + | E20: =SUMIF(INDIRECT($K20&"!AC:AC"),$L20&"ACCU",INDIRECT($K20&"!AD:AD")) -> 0 | F20: - | G20: =SUMIF(INDIRECT($K20&"!AC:AC"),$L20&"DECU",INDIRECT($K20&"!AD:AD")) -> 0 | H20: = | I20: =C20+E20+G20 -> 0 | K20: DBPL | L20: =L$1 -> 4
B21: Sub-Total | C21: =SUM(C19:C20) -> 0 | E21: =SUM(E19:E20) -> 0 | G21: =SUM(G19:G20) -> 0 | I21: =SUM(I19:I20) -> 0
A24: D. Standard Chartered | C24: ='7th'!I24 -> 0 | D24: + | E24: =SUMIF(INDIRECT($K24&"!AC:AC"),$L24&"ACCU",INDIRECT($K24&"!AD:AD")) -> 0 | F24: - | G24: =SUMIF(INDIRECT($K24&"!AC:AC"),$L24&"DECU",INDIRECT($K24&"!AD:AD")) -> 0 | H24: = | I24: =C24+E24+G24 -> 0 | K24: SC | L24: =L$1 -> 4
A27: D. Sun Hung Kai | C27: ='7th'!I27 -> 0 | D27: + | E27: =SUMIF(INDIRECT($K27&"!AC:AC"),$L27&"ACCU",INDIRECT($K27&"!AD:AD")) -> 0 | F27: - | G27: =SUMIF(INDIRECT($K27&"!AC:AC"),$L27&"DECU",INDIRECT($K27&"!AD:AD")) -> 0 | H27: = | I27: =C27+E27+G27 -> 0 | K27: SHK | L27: =L$1 -> 4
A30: E. Morgan Stanley
A31: 1 | B31: Morgan - Titan No. 1 | C31: ='7th'!I31 -> 0 | D31: + | E31: =SUMIF(INDIRECT($K31&"!AC:AC"),$L31&"ACCU",INDIRECT($K31&"!AD:AD")) -> 0 | F31: - | G31: =SUMIF(INDIRECT($K31&"!AC:AC"),$L31&"DECU",INDIRECT($K31&"!AD:AD")) -> 0 | H31: = | I31: =C31+E31+G31 -> 0 | K31: MST1 | L31: =L$1 -> 4
A32: 2 | B32: Morgan - Titan No. 2 | C32: ='7th'!I32 -> 0 | D32: + | E32: =SUMIF(INDIRECT($K32&"!AC:AC"),$L32&"ACCU",INDIRECT($K32&"!AD:AD")) -> 0 | F32: - | G32: =SUMIF(INDIRECT($K32&"!AC:AC"),$L32&"DECU",INDIRECT($K32&"!AD:AD")) -> 0 | H32: = | I32: =C32+E32+G32 -> 0 | K32: MST2 | L32: =L$1 -> 4
A33: 3 | B33: Morgan - Perfect Legend | C33: ='7th'!I33 -> 0 | D33: + | E33: =SUMIF(INDIRECT($K33&"!AC:AC"),$L33&"ACCU",INDIRECT($K33&"!AD:AD")) -> 0 | F33: - | G33: =SUMIF(INDIRECT($K33&"!AC:AC"),$L33&"DECU",INDIRECT($K33&"!AD:AD")) -> 0 | H33: = | I33: =C33+E33+G33 -> 0 | K33: MSPL | L33: =L$1 -> 4
B34: Sub-Total | C34: =SUM(C31:C33) -> 0 | E34: =SUM(E31:E33) -> 0 | G34: =SUM(G31:G33) -> 0 | I34: =SUM(I31:I33) -> 0
B37: Grand Total | C37: =SUM(C12,C15,C21,C27,C34,C24) -> 0 | D37: + | E37: =SUM(E12,E15,E21,E27,E34,E24) -> 0 | F37: - | G37: =SUM(G12,G15,G21,G27,G34,G24) -> 0 | H37: = | I37: =SUM(I12,I15,I21,I27,I34,I24) -> 0
B39: Grand Total | C39: 188550 | D39: + | E39: 0 | F39: - | G39: -710000 | H39: = | I39: -521450
E41: =E37-E39 -> 0 | G41: =G37-G39 -> 710000

Sheet 9th
A1: ="Estimate "&stock_name&" Shares till Month of "&TEXT(I6,"mmmm yyyy")&" End" -> Estimate Great Wall Motor Shares till Month of May 2023 End | L1: =MONTH(I6) -> 5
A2: as of | B2: ='2nd'!B2:C2 -> 44805.577
A4: # | B4: Account | C4: Shares on hand | D4: + | E4: Accumulator | F4: - | G4: Decumulator | H4: = | I4: Estimate End Shares Balance
A6: A. Citibank | I6: =_9th -> 45077
A7: 1 | B7: Citibank Account No. 1 | C7: ='8th'!I7 -> 0 | D7: + | E7: =SUMIF(INDIRECT($K7&"!AC:AC"),$L7&"ACCU",INDIRECT($K7&"!AD:AD")) -> 0 | F7: - | G7: =SUMIF(INDIRECT($K7&"!AC:AC"),$L7&"DECU",INDIRECT($K7&"!AD:AD")) -> 0 | H7: = | I7: =C7+E7+G7 -> 0 | K7: CB1 | L7: =L$1 -> 5
A8: 2 | B8: Citibank Account No. 2 | C8: ='8th'!I8 -> 0 | D8: + | E8: =SUMIF(INDIRECT($K8&"!AC:AC"),$L8&"ACCU",INDIRECT($K8&"!AD:AD")) -> 0 | F8: - | G8: =SUMIF(INDIRECT($K8&"!AC:AC"),$L8&"DECU",INDIRECT($K8&"!AD:AD")) -> 0 | H8: = | I8: =C8+E8+G8 -> 0 | K8: CB2 | L8: =L$1 -> 5
A9: 3 | B9: Citibank Account No. 3 | C9: ='8th'!I9 -> 0 | D9: + | E9: =SUMIF(INDIRECT($K9&"!AC:AC"),$L9&"ACCU",INDIRECT($K9&"!AD:AD")) -> 0 | F9: - | G9: =SUMIF(INDIRECT($K9&"!AC:AC"),$L9&"DECU",INDIRECT($K9&"!AD:AD")) -> 0 | H9: = | I9: =C9+E9+G9 -> 0 | K9: CB3 | L9: =L$1 -> 5 | S9: CB3
A10: 4 | B10: Citibank Berry Hill | C10: ='8th'!I10 -> 0 | D10: + | E10: =SUMIF(INDIRECT($K10&"!AC:AC"),$L10&"ACCU",INDIRECT($K10&"!AD:AD")) -> 0 | F10: - | G10: =SUMIF(INDIRECT($K10&"!AC:AC"),$L10&"DECU",INDIRECT($K10&"!AD:AD")) -> 0 | H10: = | I10: =C10+E10+G10 -> 0 | K10: CBBH | L10: =L$1 -> 5
A11: 5 | B11: Citibank Berry Hill No. 2 | C11: ='8th'!I11 -> 0 | D11: + | E11: =SUMIF(INDIRECT($K11&"!AC:AC"),$L11&"ACCU",INDIRECT($K11&"!AD:AD")) -> 0 | F11: - | G11: =SUMIF(INDIRECT($K11&"!AC:AC"),$L11&"DECU",INDIRECT($K11&"!AD:AD")) -> 0 | H11: = | I11: =C11+E11+G11 -> 0 | K11: CBBH2 | L11: =L$1 -> 5 | S11: CBBH2
B12: Sub-Total | C12: =SUM(C7:C11) -> 0 | E12: =SUM(E7:E11) -> 0 | G12: =SUM(G7:G11) -> 0 | I12: =SUM(I7:I11) -> 0
A15: B. Bank of Singapore | C15: ='8th'!I15 -> 0 | D15: + | E15: =SUMIF(INDIRECT($K15&"!AC:AC"),$L15&"ACCU",INDIRECT($K15&"!AD:AD")) -> 0 | F15: - | G15: =SUMIF(INDIRECT($K15&"!AC:AC"),$L15&"DECU",INDIRECT($K15&"!AD:AD")) -> 0 | H15: = | I15: =C15+E15+G15 -> 0 | K15: BOS | L15: =L$1 -> 5
A18: C. Deutsche Bank
A19: 1 | B19: Deutsche - Personal | C19: ='8th'!I19 -> 0 | D19: + | E19: =SUMIF(INDIRECT($K19&"!AC:AC"),$L19&"ACCU",INDIRECT($K19&"!AD:AD")) -> 0 | F19: - | G19: =SUMIF(INDIRECT($K19&"!AC:AC"),$L19&"DECU",INDIRECT($K19&"!AD:AD")) -> 0 | H19: = | I19: =C19+E19+G19 -> 0 | K19: DBPe | L19: =L$1 -> 5
A20: 2 | B20: Deutsche - Perfect Legend | C20: ='3rd'!I20 -> 0 | D20: + | E20: =SUMIF(INDIRECT($K20&"!AC:AC"),$L20&"ACCU",INDIRECT($K20&"!AD:AD")) -> 0 | F20: - | G20: =SUMIF(INDIRECT($K20&"!AC:AC"),$L20&"DECU",INDIRECT($K20&"!AD:AD")) -> 0 | H20: = | I20: =C20+E20+G20 -> 0 | K20: DBPL | L20: =L$1 -> 5
B21: Sub-Total | C21: =SUM(C19:C20) -> 0 | E21: =SUM(E19:E20) -> 0 | G21: =SUM(G19:G20) -> 0 | I21: =SUM(I19:I20) -> 0
A24: D. Standard Chartered | C24: ='8th'!I24 -> 0 | D24: + | E24: =SUMIF(INDIRECT($K24&"!AC:AC"),$L24&"ACCU",INDIRECT($K24&"!AD:AD")) -> 0 | F24: - | G24: =SUMIF(INDIRECT($K24&"!AC:AC"),$L24&"DECU",INDIRECT($K24&"!AD:AD")) -> 0 | H24: = | I24: =C24+E24+G24 -> 0 | K24: SC | L24: =L$1 -> 5
A27: D. Sun Hung Kai | C27: ='8th'!I27 -> 0 | D27: + | E27: =SUMIF(INDIRECT($K27&"!AC:AC"),$L27&"ACCU",INDIRECT($K27&"!AD:AD")) -> 0 | F27: - | G27: =SUMIF(INDIRECT($K27&"!AC:AC"),$L27&"DECU",INDIRECT($K27&"!AD:AD")) -> 0 | H27: = | I27: =C27+E27+G27 -> 0 | K27: SHK | L27: =L$1 -> 5
A30: E. Morgan Stanley
A31: 1 | B31: Morgan - Titan No. 1 | C31: ='8th'!I31 -> 0 | D31: + | E31: =SUMIF(INDIRECT($K31&"!AC:AC"),$L31&"ACCU",INDIRECT($K31&"!AD:AD")) -> 0 | F31: - | G31: =SUMIF(INDIRECT($K31&"!AC:AC"),$L31&"DECU",INDIRECT($K31&"!AD:AD")) -> 0 | H31: = | I31: =C31+E31+G31 -> 0 | K31: MST1 | L31: =L$1 -> 5
A32: 2 | B32: Morgan - Titan No. 2 | C32: ='8th'!I32 -> 0 | D32: + | E32: =SUMIF(INDIRECT($K32&"!AC:AC"),$L32&"ACCU",INDIRECT($K32&"!AD:AD")) -> 0 | F32: - | G32: =SUMIF(INDIRECT($K32&"!AC:AC"),$L32&"DECU",INDIRECT($K32&"!AD:AD")) -> 0 | H32: = | I32: =C32+E32+G32 -> 0 | K32: MST2 | L32: =L$1 -> 5
A33: 3 | B33: Morgan - Perfect Legend | C33: ='8th'!I33 -> 0 | D33: + | E33: =SUMIF(INDIRECT($K33&"!AC:AC"),$L33&"ACCU",INDIRECT($K33&"!AD:AD")) -> 0 | F33: - | G33: =SUMIF(INDIRECT($K33&"!AC:AC"),$L33&"DECU",INDIRECT($K33&"!AD:AD")) -> 0 | H33: = | I33: =C33+E33+G33 -> 0 | K33: MSPL | L33: =L$1 -> 5
B34: Sub-Total | C34: =SUM(C31:C33) -> 0 | E34: =SUM(E31:E33) -> 0 | G34: =SUM(G31:G33) -> 0 | I34: =SUM(I31:I33) -> 0
