Workbook
Name market_price: Collateral!$U$4

Sheet ALLHKD
B1: ACCUMULATORS | C1: 46234
B3: Account | C3: Estimated Amount | D3: Estimated Amount (%)
B4: Citibank - Account 1 | C4: =ACCU!R9 | D4: =C4/$C$16 | E4: =ACCU!R9-C4
B5: Citibank - Account 2 | C5: =ACCU!R18 | D5: =C5/$C$16 | E5: =ACCU!R18-C5
B6: Citibank Singapore - Account 1 | C6: =ACCU!R26 | D6: =C6/$C$16 | E6: =ACCU!R26-C6
B7: Deutsche Bank - Personal | C7: =ACCU!R54 | D7: =C7/$C$16 | E7: =ACCU!R54-C7
B8: Deutsche Bank - Perfect Legend | C8: =ACCU!R147 | D8: =C8/$C$16 | E8: =ACCU!R147-C8
B9: Sun Hung Kai Account No. 1 | C9: =ACCU!R89 | D9: =C9/$C$16 | E9: =ACCU!R89-C9
B10: Sun Hung Kai Account No. 2 | C10: =ACCU!R116 | D10: =C10/$C$16 | E10: =ACCU!R116-C10
B11: Morgan Stanley - Titan 1 | C11: =ACCU!R155 | D11: =C11/$C$16 | E11: =ACCU!R155-C11
B12: Morgan Stanley - Titan 2 | C12: =ACCU!R124 | D12: =C12/$C$16 | E12: =ACCU!R124-C12
B13: Morgan Stanley - Perfect Legend | C13: =ACCU!R164 | D13: =C13/$C$16 | E13: =ACCU!R164-C13
B14: Nomura Singapore | C14: =ACCU!R67 | D14: =C14/$C$16 | E14: =ACCU!R67-C14
B15: Bank of Singapore | C15: =ACCU!R132 | D15: =C15/$C$16 | E15: =ACCU!R132-C15 | F15: =ALLM!N13 | G15: =F15-F16
C16: =SUM(C4:C15) | D16: =C16/$C$16 | F16: =ACCU!R172 | G16: =C16-F16
B18: Decumulators | C18: =C1
B20: Account | C20: Estimated Amount | D20: Estimated Amount (%)
B21: Citibank - Account 1 | C21: =+DECU!$R$9 | D21: =C21/$C$33
B22: Citibank - Account 2 | C22: =+DECU!$R$18 | D22: =C22/$C$33
B23: Citibank Singapore - Account 1 | C23: =DECU!R28 | D23: =C23/$C$33
B24: Deutsche Bank - Personal | C24: =DECU!R53 | D24: =C24/$C$33
B25: Deutsche Bank - Perfect Legend | C25: =DECU!R136 | D25: =C25/$C$33
B26: Sun Hung Kai Account No. 1 | C26: =DECU!R86 | D26: =C26/$C$33
B27: Sun Hung Kai Account No. 2 | C27: =DECU!R108 | D27: =C27/$C$33
B28: Morgan Stanley - Titan 1 | C28: =+DECU!$R$144 | D28: =C28/$C$33
B29: Morgan Stanley - Titan 2 | C29: =+DECU!$R$116 | D29: =C29/$C$33
B30: Morgan Stanley - Perfect Legend | C30: =+DECU!$R$151 | D30: =C30/$C$33
B31: Nomura Singapore | C31: =DECU!R67 | D31: =C31/$C$33
B32: Bank of Singapore | C32: =DECU!$R$123 | D32: =C32/$C$33 | F32: =ALLM!N43 | G32: =F32-F33
C33: =SUM(C21:C32) | D33: =C33/$C$33 | F33: =+DECU!$R$158 | G33: =C33-F33
F35: =F16-F33

Sheet ALLM
B1: ACCUMULATORS | F1: =ACCU!B1
B2: HK Stock | C2: Code | D2: Total | E2: Jul 2026 | F2: Aug 2026 | G2: Sep 2026 | H2: Oct 2026 | I2: Nov 2026 | J2: Dec 2026 | K2: Jan 2027 | L2: Feb 2027 Onwards | N2: Estimated Amount | O2: %
E3: 7-2026 | F3: 8-2026 | G3: 9-2026 | H3: 10-2026 | I3: 11-2026 | J3: 12-2026 | K3: 01-2027
A4: =INDIRECT(ADDRESS(ROW()-1,COLUMN()))+1 | B4: Geely Motor | C4: 0175 | D4: =SUM(E4:L4) | E4: =IF(COUNTIF(ACCU!$AD:$AD,E$3&"-"&$C4)=0,"",COUNTIF(ACCU!$AD:$AD,E$3&"-"&$C4)) | F4: =IF(COUNTIF(ACCU!$AD:$AD,F$3&"-"&$C4)=0,"",COUNTIF(ACCU!$AD:$AD,F$3&"-"&$C4)) | G4: =IF(COUNTIF(ACCU!$AD:$AD,G$3&"-"&$C4)=0,"",COUNTIF(ACCU!$AD:$AD,G$3&"-"&$C4)) | H4: =IF(COUNTIF(ACCU!$AD:$AD,H$3&"-"&$C4)=0,"",COUNTIF(ACCU!$AD:$AD,H$3&"-"&$C4)) | I4: =IF(COUNTIF(ACCU!$AD:$AD,I$3&"-"&$C4)=0,"",COUNTIF(ACCU!$AD:$AD,I$3&"-"&$C4)) | J4: =IF(COUNTIF(ACCU!$AD:$AD,J$3&"-"&$C4)=0,"",COUNTIF(ACCU!$AD:$AD,J$3&"-"&$C4)) | K4: =IF(COUNTIF(ACCU!$AD:$AD,K$3&"-"&$C4)=0,"",COUNTIF(ACCU!$AD:$AD,K$3&"-"&$C4)) | L4: =COUNTIF(ACCU!$AE:$AE,$C4)-SUM(E4:K4) | N4: =SUMIF(ACCU!AE:AE,C4,ACCU!R:R) | O4: =N4/N$13
A5: =INDIRECT(ADDRESS(ROW()-1,COLUMN()))+1 | B5: HK Exchange | C5: 0388 | D5: =SUM(E5:L5) | E5: =IF(COUNTIF(ACCU!$AD:$AD,E$3&"-"&$C5)=0,"",COUNTIF(ACCU!$AD:$AD,E$3&"-"&$C5)) | F5: =IF(COUNTIF(ACCU!$AD:$AD,F$3&"-"&$C5)=0,"",COUNTIF(ACCU!$AD:$AD,F$3&"-"&$C5)) | G5: =IF(COUNTIF(ACCU!$AD:$AD,G$3&"-"&$C5)=0,"",COUNTIF(ACCU!$AD:$AD,G$3&"-"&$C5)) | H5: =IF(COUNTIF(ACCU!$AD:$AD,H$3&"-"&$C5)=0,"",COUNTIF(ACCU!$AD:$AD,H$3&"-"&$C5)) | I5: =IF(COUNTIF(ACCU!$AD:$AD,I$3&"-"&$C5)=0,"",COUNTIF(ACCU!$AD:$AD,I$3&"-"&$C5)) | J5: =IF(COUNTIF(ACCU!$AD:$AD,J$3&"-"&$C5)=0,"",COUNTIF(ACCU!$AD:$AD,J$3&"-"&$C5)) | K5: =IF(COUNTIF(ACCU!$AD:$AD,K$3&"-"&$C5)=0,"",COUNTIF(ACCU!$AD:$AD,K$3&"-"&$C5)) | L5: =COUNTIF(ACCU!$AE:$AE,$C5)-SUM(E5:K5) | N5: =SUMIF(ACCU!AE:AE,C5,ACCU!R:R) | O5: =N5/N$13
A6: =INDIRECT(ADDRESS(ROW()-1,COLUMN()))+1 | B6: Tencent | C6: 0700 | D6: =SUM(E6:L6) | E6: =IF(COUNTIF(ACCU!$AD:$AD,E$3&"-"&$C6)=0,"",COUNTIF(ACCU!$AD:$AD,E$3&"-"&$C6)) | F6: =IF(COUNTIF(ACCU!$AD:$AD,F$3&"-"&$C6)=0,"",COUNTIF(ACCU!$AD:$AD,F$3&"-"&$C6)) | G6: =IF(COUNTIF(ACCU!$AD:$AD,G$3&"-"&$C6)=0,"",COUNTIF(ACCU!$AD:$AD,G$3&"-"&$C6)) | H6: =IF(COUNTIF(ACCU!$AD:$AD,H$3&"-"&$C6)=0,"",COUNTIF(ACCU!$AD:$AD,H$3&"-"&$C6)) | I6: =IF(COUNTIF(ACCU!$AD:$AD,I$3&"-"&$C6)=0,"",COUNTIF(ACCU!$AD:$AD,I$3&"-"&$C6)) | J6: =IF(COUNTIF(ACCU!$AD:$AD,J$3&"-"&$C6)=0,"",COUNTIF(ACCU!$AD:$AD,J$3&"-"&$C6)) | K6: =IF(COUNTIF(ACCU!$AD:$AD,K$3&"-"&$C6)=0,"",COUNTIF(ACCU!$AD:$AD,K$3&"-"&$C6)) | L6: =COUNTIF(ACCU!$AE:$AE,$C6)-SUM(E6:K6) | N6: =SUMIF(ACCU!AE:AE,C6,ACCU!R:R) | O6: =N6/N$13
A7: =INDIRECT(ADDRESS(ROW()-1,COLUMN()))+1 | B7: Semiconductor Mfg | C7: 0981 | D7: =SUM(E7:L7) | E7: =IF(COUNTIF(ACCU!$AD:$AD,E$3&"-"&$C7)=0,"",COUNTIF(ACCU!$AD:$AD,E$3&"-"&$C7)) | F7: =IF(COUNTIF(ACCU!$AD:$AD,F$3&"-"&$C7)=0,"",COUNTIF(ACCU!$AD:$AD,F$3&"-"&$C7)) | G7: =IF(COUNTIF(ACCU!$AD:$AD,G$3&"-"&$C7)=0,"",COUNTIF(ACCU!$AD:$AD,G$3&"-"&$C7)) | H7: =IF(COUNTIF(ACCU!$AD:$AD,H$3&"-"&$C7)=0,"",COUNTIF(ACCU!$AD:$AD,H$3&"-"&$C7)) | I7: =IF(COUNTIF(ACCU!$AD:$AD,I$3&"-"&$C7)=0,"",COUNTIF(ACCU!$AD:$AD,I$3&"-"&$C7)) | J7: =IF(COUNTIF(ACCU!$AD:$AD,J$3&"-"&$C7)=0,"",COUNTIF(ACCU!$AD:$AD,J$3&"-"&$C7)) | K7: =IF(COUNTIF(ACCU!$AD:$AD,K$3&"-"&$C7)=0,"",COUNTIF(ACCU!$AD:$AD,K$3&"-"&$C7)) | L7: =COUNTIF(ACCU!$AE:$AE,$C7)-SUM(E7:K7) | N7: =SUMIF(ACCU!AE:AE,C7,ACCU!R:R) | O7: =N7/N$13
A8: =INDIRECT(ADDRESS(ROW()-1,COLUMN()))+1 | B8: Kuaishou Tech | C8: 1024 | D8: =SUM(E8:L8) | E8: =IF(COUNTIF(ACCU!$AD:$AD,E$3&"-"&$C8)=0,"",COUNTIF(ACCU!$AD:$AD,E$3&"-"&$C8)) | F8: =IF(COUNTIF(ACCU!$AD:$AD,F$3&"-"&$C8)=0,"",COUNTIF(ACCU!$AD:$AD,F$3&"-"&$C8)) | G8: =IF(COUNTIF(ACCU!$AD:$AD,G$3&"-"&$C8)=0,"",COUNTIF(ACCU!$AD:$AD,G$3&"-"&$C8)) | H8: =IF(COUNTIF(ACCU!$AD:$AD,H$3&"-"&$C8)=0,"",COUNTIF(ACCU!$AD:$AD,H$3&"-"&$C8)) | I8: =IF(COUNTIF(ACCU!$AD:$AD,I$3&"-"&$C8)=0,"",COUNTIF(ACCU!$AD:$AD,I$3&"-"&$C8)) | J8: =IF(COUNTIF(ACCU!$AD:$AD,J$3&"-"&$C8)=0,"",COUNTIF(ACCU!$AD:$AD,J$3&"-"&$C8)) | K8: =IF(COUNTIF(ACCU!$AD:$AD,K$3&"-"&$C8)=0,"",COUNTIF(ACCU!$AD:$AD,K$3&"-"&$C8)) | L8: =COUNTIF(ACCU!$AE:$AE,$C8)-SUM(E8:K8) | N8: =SUMIF(ACCU!AE:AE,C8,ACCU!R:R) | O8: =N8/N$13
A9: =INDIRECT(ADDRESS(ROW()-1,COLUMN()))+1 | B9: Shanghai Pharma | C9: 2196 | D9: =SUM(E9:L9) | E9: =IF(COUNTIF(ACCU!$AD:$AD,E$3&"-"&$C9)=0,"",COUNTIF(ACCU!$AD:$AD,E$3&"-"&$C9)) | F9: =IF(COUNTIF(ACCU!$AD:$AD,F$3&"-"&$C9)=0,"",COUNTIF(ACCU!$AD:$AD,F$3&"-"&$C9)) | G9: =IF(COUNTIF(ACCU!$AD:$AD,G$3&"-"&$C9)=0,"",COUNTIF(ACCU!$AD:$AD,G$3&"-"&$C9)) | H9: =IF(COUNTIF(ACCU!$AD:$AD,H$3&"-"&$C9)=0,"",COUNTIF(ACCU!$AD:$AD,H$3&"-"&$C9)) | I9: =IF(COUNTIF(ACCU!$AD:$AD,I$3&"-"&$C9)=0,"",COUNTIF(ACCU!$AD:$AD,I$3&"-"&$C9)) | J9: =IF(COUNTIF(ACCU!$AD:$AD,J$3&"-"&$C9)=0,"",COUNTIF(ACCU!$AD:$AD,J$3&"-"&$C9)) | K9: =IF(COUNTIF(ACCU!$AD:$AD,K$3&"-"&$C9)=0,"",COUNTIF(ACCU!$AD:$AD,K$3&"-"&$C9)) | L9: =COUNTIF(ACCU!$AE:$AE,$C9)-SUM(E9:K9) | N9: =SUMIF(ACCU!AE:AE,C9,ACCU!R:R) | O9: =N9/N$13
A10: =INDIRECT(ADDRESS(ROW()-1,COLUMN()))+1 | B10: China Molybdenum | C10: 3993 | D10: =SUM(E10:L10) | E10: =IF(COUNTIF(ACCU!$AD:$AD,E$3&"-"&$C10)=0,"",COUNTIF(ACCU!$AD:$AD,E$3&"-"&$C10)) | F10: =IF(COUNTIF(ACCU!$AD:$AD,F$3&"-"&$C10)=0,"",COUNTIF(ACCU!$AD:$AD,F$3&"-"&$C10)) | G10: =IF(COUNTIF(ACCU!$AD:$AD,G$3&"-"&$C10)=0,"",COUNTIF(ACCU!$AD:$AD,G$3&"-"&$C10)) | H10: =IF(COUNTIF(ACCU!$AD:$AD,H$3&"-"&$C10)=0,"",COUNTIF(ACCU!$AD:$AD,H$3&"-"&$C10)) | I10: =IF(COUNTIF(ACCU!$AD:$AD,I$3&"-"&$C10)=0,"",COUNTIF(ACCU!$AD:$AD,I$3&"-"&$C10)) | J10: =IF(COUNTIF(ACCU!$AD:$AD,J$3&"-"&$C10)=0,"",COUNTIF(ACCU!$AD:$AD,J$3&"-"&$C10)) | K10: =IF(COUNTIF(ACCU!$AD:$AD,K$3&"-"&$C10)=0,"",COUNTIF(ACCU!$AD:$AD,K$3&"-"&$C10)) | L10: =COUNTIF(ACCU!$AE:$AE,$C10)-SUM(E10:K10) | N10: =SUMIF(ACCU!AE:AE,C10,ACCU!R:R) | O10: =N10/N$13
A11: =INDIRECT(ADDRESS(ROW()-1,COLUMN()))+1 | B11: Baidu Inc | C11: 9888 | D11: =SUM(E11:L11) | E11: =IF(COUNTIF(ACCU!$AD:$AD,E$3&"-"&$C11)=0,"",COUNTIF(ACCU!$AD:$AD,E$3&"-"&$C11)) | F11: =IF(COUNTIF(ACCU!$AD:$AD,F$3&"-"&$C11)=0,"",COUNTIF(ACCU!$AD:$AD,F$3&"-"&$C11)) | G11: =IF(COUNTIF(ACCU!$AD:$AD,G$3&"-"&$C11)=0,"",COUNTIF(ACCU!$AD:$AD,G$3&"-"&$C11)) | H11: =IF(COUNTIF(ACCU!$AD:$AD,H$3&"-"&$C11)=0,"",COUNTIF(ACCU!$AD:$AD,H$3&"-"&$C11)) | I11: =IF(COUNTIF(ACCU!$AD:$AD,I$3&"-"&$C11)=0,"",COUNTIF(ACCU!$AD:$AD,I$3&"-"&$C11)) | J11: =IF(COUNTIF(ACCU!$AD:$AD,J$3&"-"&$C11)=0,"",COUNTIF(ACCU!$AD:$AD,J$3&"-"&$C11)) | K11: =IF(COUNTIF(ACCU!$AD:$AD,K$3&"-"&$C11)=0,"",COUNTIF(ACCU!$AD:$AD,K$3&"-"&$C11)) | L11: =COUNTIF(ACCU!$AE:$AE,$C11)-SUM(E11:K11) | N11: =SUMIF(ACCU!AE:AE,C11,ACCU!R:R) | O11: =N11/N$13
A12: =INDIRECT(ADDRESS(ROW()-1,COLUMN()))+1 | B12: Alibaba | C12: 9988 | D12: =SUM(E12:L12) | E12: =IF(COUNTIF(ACCU!$AD:$AD,E$3&"-"&$C12)=0,"",COUNTIF(ACCU!$AD:$AD,E$3&"-"&$C12)) | F12: =IF(COUNTIF(ACCU!$AD:$AD,F$3&"-"&$C12)=0,"",COUNTIF(ACCU!$AD:$AD,F$3&"-"&$C12)) | G12: =IF(COUNTIF(ACCU!$AD:$AD,G$3&"-"&$C12)=0,"",COUNTIF(ACCU!$AD:$AD,G$3&"-"&$C12)) | H12: =IF(COUNTIF(ACCU!$AD:$AD,H$3&"-"&$C12)=0,"",COUNTIF(ACCU!$AD:$AD,H$3&"-"&$C12)) | I12: =IF(COUNTIF(ACCU!$AD:$AD,I$3&"-"&$C12)=0,"",COUNTIF(ACCU!$AD:$AD,I$3&"-"&$C12)) | J12: =IF(COUNTIF(ACCU!$AD:$AD,J$3&"-"&$C12)=0,"",COUNTIF(ACCU!$AD:$AD,J$3&"-"&$C12)) | K12: =IF(COUNTIF(ACCU!$AD:$AD,K$3&"-"&$C12)=0,"",COUNTIF(ACCU!$AD:$AD,K$3&"-"&$C12)) | L12: =COUNTIF(ACCU!$AE:$AE,$C12)-SUM(E12:K12) | N12: =SUMIF(ACCU!AE:AE,C12,ACCU!R:R) | O12: =N12/N$13
C13: TOTAL: | D13: =SUM(D2:D12) | E13: =SUM(E2:E12) | F13: =SUM(F2:F12) | G13: =SUM(G2:G12) | H13: =SUM(H2:H12) | I13: =SUM(I2:I12) | J13: =SUM(J2:J12) | K13: =SUM(K4:K12) | L13: =SUM(L2:L12) | N13: =SUM(N2:INDIRECT("N"&ROW()-1)) | O13: =N13/N$13
G14: =SUM(G13:$L13)-G13 | J14: =SUM(J13:$L13)-J13
B15: JP Stock | C15: Code | D15: Total | E15: =E$2 | F15: =F$2 | G15: =G$2 | H15: =H$2 | I15: =I$2 | J15: =J$2 | K15: =K$2 | L15: =L$2 | N15: Estimated Amount | P15: Remaining | Q15: strike | R15: Single | S15: SD | T15: Adjustment
B16: Nomura | C16: 8604 | D16: =SUM(E16:L16) | L16: 0 | N16: =P16*Q16*R16*S16+T16 | P16: 19 | Q16: 457.9325 | R16: 500 | S16: 1
C17: TOTAL: | D17: =SUM(D16:D16) | E17: =SUM(E16:E16) | F17: =SUM(F16:F16) | G17: =SUM(G16:G16) | H17: =SUM(H16:H16) | I17: =SUM(I16:I16) | J17: =SUM(J16:J16) | K17: =SUM(K16:K16) | L17: =SUM(L16:L16) | N17: =SUM(N15:N16)
B19: AU Stock | C19: Code | D19: Total | E19: =E$2 | F19: =F$2 | G19: =G$2 | H19: =H$2 | I19: =I$2 | J19: =J$2 | K19: =K$2 | L19: =L$2
A20: =INDIRECT(ADDRESS(ROW()-1,COLUMN()))+1 | B20: Rio Tinto | C20: RIO | D20: =SUM(E20:L20) | L20: 0
C21: TOTAL: | D21: =SUM(D20:D20) | E21: =SUM(E20:E20) | F21: =SUM(F20:F20) | G21: =SUM(G20:G20) | H21: =SUM(H20:H20) | I21: =SUM(I20:I20) | J21: =SUM(J20:J20) | K21: =SUM(K20:K20) | L21: =SUM(L20:L20)
B23: US Stock | C23: Code | D23: Total | E23: =E$2 | F23: =F$2 | G23: =G$2 | H23: =H$2 | I23: =I$2 | J23: =J$2 | K23: =K$2 | L23: =L$2
B24: Bank of America | C24: BAC | D24: =SUM(E24:L24) | L24: 0
B25: General Electric | C25: GE | D25: =SUM(E25:L25) | E25: 0 | L25: 0
B26: Baidu | C26: BIDU | D26: =SUM(E26:L26) | L26: 0
C27: TOTAL: | D27: =SUM(D24:D26) | E27: =SUM(E24:E26) | F27: =SUM(F24:F26) | G27: =SUM(G24:G26) | H27: =SUM(H24:H26) | I27: =SUM(I24:I26) | J27: =SUM(J24:J26) | K27: =SUM(K24:K26) | L27: =SUM(L24:L26)
B29: SGD Stock | C29: Code | D29: Total | E29: =E$2 | F29: =F$2 | G29: =G$2 | H29: =H$2 | I29: =I$2 | J29: =J$2 | K29: =K$2 | L29: =L$2 | N29: Estimated Amount | P29: Remaining | Q29: strike | R29: Single | S29: SD
B30: DBS Group | C30: DBS | D30: =SUM(E30:L30) | L30: 0 | N30: =P30*Q30*R30*S30+T30 | P30: 0 | Q30: 32.0786 | R30: 100 | S30: 1
C31: TOTAL: | D31: =SUM(D30:D30) | E31: =SUM(E30:E30) | F31: =SUM(F30:F30) | G31: =SUM(G30:G30) | H31: =SUM(H30:H30) | I31: =SUM(I30:I30) | J31: =SUM(J30:J30) | K31: =SUM(K30:K30) | L31: =SUM(L30:L30) | N31: =SUM(N29:N30)
B33: DECUMULATORS | F33: =F1
B34: Stock | C34: Code | D34: Total | E34: =E$2 | F34: =F$2 | G34: =G$2 | H34: =H$2 | I34: =I$2 | J34: =J$2 | K34: =K$2 | L34: =L$2 | N34: Estimated Amount | O34: %
A35: =INDIRECT(ADDRESS(ROW()-1,COLUMN()))+1 | B35: Geely Motor | C35: 0175 | D35: =SUM(E35:L35) | E35: =IF(COUNTIF(DECU!$AD:$AD,E$3&"-"&$C35)=0,"",COUNTIF(DECU!$AD:$AD,E$3&"-"&$C35)) | F35: =IF(COUNTIF(DECU!$AD:$AD,F$3&"-"&$C35)=0,"",COUNTIF(DECU!$AD:$AD,F$3&"-"&$C35)) | G35: =IF(COUNTIF(DECU!$AD:$AD,G$3&"-"&$C35)=0,"",COUNTIF(DECU!$AD:$AD,G$3&"-"&$C35)) | H35: =IF(COUNTIF(DECU!$AD:$AD,H$3&"-"&$C35)=0,"",COUNTIF(DECU!$AD:$AD,H$3&"-"&$C35)) | I35: =IF(COUNTIF(DECU!$AD:$AD,I$3&"-"&$C35)=0,"",COUNTIF(DECU!$AD:$AD,I$3&"-"&$C35)) | J35: =IF(COUNTIF(DECU!$AD:$AD,J$3&"-"&$C35)=0,"",COUNTIF(DECU!$AD:$AD,J$3&"-"&$C35)) | K35: =IF(COUNTIF(DECU!$AD:$AD,K$3&"-"&$C35)=0,"",COUNTIF(DECU!$AD:$AD,K$3&"-"&$C35)) | L35: =COUNTIF(DECU!$AE:$AE,$C35)-SUM(E35:K35) | N35: =SUMIF(DECU!AE:AE,C35,DECU!R:R) | O35: =N35/$N$43
A36: =INDIRECT(ADDRESS(ROW()-1,COLUMN()))+1 | B36: HK Exchange | C36: 0388 | D36: =SUM(E36:L36) | E36: =IF(COUNTIF(DECU!$AD:$AD,E$3&"-"&$C36)=0,"",COUNTIF(DECU!$AD:$AD,E$3&"-"&$C36)) | F36: =IF(COUNTIF(DECU!$AD:$AD,F$3&"-"&$C36)=0,"",COUNTIF(DECU!$AD:$AD,F$3&"-"&$C36)) | G36: =IF(COUNTIF(DECU!$AD:$AD,G$3&"-"&$C36)=0,"",COUNTIF(DECU!$AD:$AD,G$3&"-"&$C36)) | H36: =IF(COUNTIF(DECU!$AD:$AD,H$3&"-"&$C36)=0,"",COUNTIF(DECU!$AD:$AD,H$3&"-"&$C36)) | I36: =IF(COUNTIF(DECU!$AD:$AD,I$3&"-"&$C36)=0,"",COUNTIF(DECU!$AD:$AD,I$3&"-"&$C36)) | J36: =IF(COUNTIF(DECU!$AD:$AD,J$3&"-"&$C36)=0,"",COUNTIF(DECU!$AD:$AD,J$3&"-"&$C36)) | K36: =IF(COUNTIF(DECU!$AD:$AD,K$3&"-"&$C36)=0,"",COUNTIF(DECU!$AD:$AD,K$3&"-"&$C36)) | L36: =COUNTIF(DECU!$AE:$AE,$C36)-SUM(E36:K36) | N36: =SUMIF(DECU!AE:AE,C36,DECU!R:R) | O36: =N36/$N$43
A37: =INDIRECT(ADDRESS(ROW()-1,COLUMN()))+1 | B37: Tencent | C37: 0700 | D37: =SUM(E37:L37) | E37: =IF(COUNTIF(DECU!$AD:$AD,E$3&"-"&$C37)=0,"",COUNTIF(DECU!$AD:$AD,E$3&"-"&$C37)) | F37: =IF(COUNTIF(DECU!$AD:$AD,F$3&"-"&$C37)=0,"",COUNTIF(DECU!$AD:$AD,F$3&"-"&$C37)) | G37: =IF(COUNTIF(DECU!$AD:$AD,G$3&"-"&$C37)=0,"",COUNTIF(DECU!$AD:$AD,G$3&"-"&$C37)) | H37: =IF(COUNTIF(DECU!$AD:$AD,H$3&"-"&$C37)=0,"",COUNTIF(DECU!$AD:$AD,H$3&"-"&$C37)) | I37: =IF(COUNTIF(DECU!$AD:$AD,I$3&"-"&$C37)=0,"",COUNTIF(DECU!$AD:$AD,I$3&"-"&$C37)) | J37: =IF(COUNTIF(DECU!$AD:$AD,J$3&"-"&$C37)=0,"",COUNTIF(DECU!$AD:$AD,J$3&"-"&$C37)) | K37: =IF(COUNTIF(DECU!$AD:$AD,K$3&"-"&$C37)=0,"",COUNTIF(DECU!$AD:$AD,K$3&"-"&$C37)) | L37: =COUNTIF(DECU!$AE:$AE,$C37)-SUM(E37:K37) | N37: =SUMIF(DECU!AE:AE,C37,DECU!R:R) | O37: =N37/$N$43
A38: =INDIRECT(ADDRESS(ROW()-1,COLUMN()))+1 | B38: Semiconductor Mfg Intl Corp | C38: 0981 | D38: =SUM(E38:L38) | E38: =IF(COUNTIF(DECU!$AD:$AD,E$3&"-"&$C38)=0,"",COUNTIF(DECU!$AD:$AD,E$3&"-"&$C38)) | F38: =IF(COUNTIF(DECU!$AD:$AD,F$3&"-"&$C38)=0,"",COUNTIF(DECU!$AD:$AD,F$3&"-"&$C38)) | G38: =IF(COUNTIF(DECU!$AD:$AD,G$3&"-"&$C38)=0,"",COUNTIF(DECU!$AD:$AD,G$3&"-"&$C38)) | H38: =IF(COUNTIF(DECU!$AD:$AD,H$3&"-"&$C38)=0,"",COUNTIF(DECU!$AD:$AD,H$3&"-"&$C38)) | I38: =IF(COUNTIF(DECU!$AD:$AD,I$3&"-"&$C38)=0,"",COUNTIF(DECU!$AD:$AD,I$3&"-"&$C38)) | J38: =IF(COUNTIF(DECU!$AD:$AD,J$3&"-"&$C38)=0,"",COUNTIF(DECU!$AD:$AD,J$3&"-"&$C38)) | K38: =IF(COUNTIF(DECU!$AD:$AD,K$3&"-"&$C38)=0,"",COUNTIF(DECU!$AD:$AD,K$3&"-"&$C38)) | L38: =COUNTIF(DECU!$AE:$AE,$C38)-SUM(E38:K38) | N38: =SUMIF(DECU!AE:AE,C38,DECU!R:R) | O38: =N38/$N$43
A39: =INDIRECT(ADDRESS(ROW()-1,COLUMN()))+1 | B39: Kuaishou Tech | C39: 1024 | D39: =SUM(E39:L39) | E39: =IF(COUNTIF(DECU!$AD:$AD,E$3&"-"&$C39)=0,"",COUNTIF(DECU!$AD:$AD,E$3&"-"&$C39)) | F39: =IF(COUNTIF(DECU!$AD:$AD,F$3&"-"&$C39)=0,"",COUNTIF(DECU!$AD:$AD,F$3&"-"&$C39)) | G39: =IF(COUNTIF(DECU!$AD:$AD,G$3&"-"&$C39)=0,"",COUNTIF(DECU!$AD:$AD,G$3&"-"&$C39)) | H39: =IF(COUNTIF(DECU!$AD:$AD,H$3&"-"&$C39)=0,"",COUNTIF(DECU!$AD:$AD,H$3&"-"&$C39)) | I39: =IF(COUNTIF(DECU!$AD:$AD,I$3&"-"&$C39)=0,"",COUNTIF(DECU!$AD:$AD,I$3&"-"&$C39)) | J39: =IF(COUNTIF(DECU!$AD:$AD,J$3&"-"&$C39)=0,"",COUNTIF(DECU!$AD:$AD,J$3&"-"&$C39)) | K39: =IF(COUNTIF(DECU!$AD:$AD,K$3&"-"&$C39)=0,"",COUNTIF(DECU!$AD:$AD,K$3&"-"&$C39)) | L39: =COUNTIF(DECU!$AE:$AE,$C39)-SUM(E39:K39) | N39: =SUMIF(DECU!AE:AE,C39,DECU!R:R) | O39: =N39/$N$43
A40: =INDIRECT(ADDRESS(ROW()-1,COLUMN()))+1 | B40: Shanghai Fosun | C40: 2196 | D40: =SUM(E40:L40) | E40: =IF(COUNTIF(DECU!$AD:$AD,E$3&"-"&$C40)=0,"",COUNTIF(DECU!$AD:$AD,E$3&"-"&$C40)) | F40: =IF(COUNTIF(DECU!$AD:$AD,F$3&"-"&$C40)=0,"",COUNTIF(DECU!$AD:$AD,F$3&"-"&$C40)) | G40: =IF(COUNTIF(DECU!$AD:$AD,G$3&"-"&$C40)=0,"",COUNTIF(DECU!$AD:$AD,G$3&"-"&$C40)) | H40: =IF(COUNTIF(DECU!$AD:$AD,H$3&"-"&$C40)=0,"",COUNTIF(DECU!$AD:$AD,H$3&"-"&$C40)) | I40: =IF(COUNTIF(DECU!$AD:$AD,I$3&"-"&$C40)=0,"",COUNTIF(DECU!$AD:$AD,I$3&"-"&$C40)) | J40: =IF(COUNTIF(DECU!$AD:$AD,J$3&"-"&$C40)=0,"",COUNTIF(DECU!$AD:$AD,J$3&"-"&$C40)) | K40: =IF(COUNTIF(DECU!$AD:$AD,K$3&"-"&$C40)=0,"",COUNTIF(DECU!$AD:$AD,K$3&"-"&$C40)) | L40: =COUNTIF(DECU!$AE:$AE,$C40)-SUM(E40:K40) | N40: =SUMIF(DECU!AE:AE,C40,DECU!R:R) | O40: =N40/$N$43
A41: =INDIRECT(ADDRESS(ROW()-1,COLUMN()))+1 | B41: China Molybdenum | C41: 3993 | D41: =SUM(E41:L41) | E41: =IF(COUNTIF(DECU!$AD:$AD,E$3&"-"&$C41)=0,"",COUNTIF(DECU!$AD:$AD,E$3&"-"&$C41)) | F41: =IF(COUNTIF(DECU!$AD:$AD,F$3&"-"&$C41)=0,"",COUNTIF(DECU!$AD:$AD,F$3&"-"&$C41)) | G41: =IF(COUNTIF(DECU!$AD:$AD,G$3&"-"&$C41)=0,"",COUNTIF(DECU!$AD:$AD,G$3&"-"&$C41)) | H41: =IF(COUNTIF(DECU!$AD:$AD,H$3&"-"&$C41)=0,"",COUNTIF(DECU!$AD:$AD,H$3&"-"&$C41)) | I41: =IF(COUNTIF(DECU!$AD:$AD,I$3&"-"&$C41)=0,"",COUNTIF(DECU!$AD:$AD,I$3&"-"&$C41)) | J41: =IF(COUNTIF(DECU!$AD:$AD,J$3&"-"&$C41)=0,"",COUNTIF(DECU!$AD:$AD,J$3&"-"&$C41)) | K41: =IF(COUNTIF(DECU!$AD:$AD,K$3&"-"&$C41)=0,"",COUNTIF(DECU!$AD:$AD,K$3&"-"&$C41)) | L41: =COUNTIF(DECU!$AE:$AE,$C41)-SUM(E41:K41) | N41: =SUMIF(DECU!AE:AE,C41,DECU!R:R) | O41: =N41/$N$43
A42: =INDIRECT(ADDRESS(ROW()-1,COLUMN()))+1 | B42: Alibaba | C42: 9988 | D42: =SUM(E42:L42) | E42: =IF(COUNTIF(DECU!$AD:$AD,E$3&"-"&$C42)=0,"",COUNTIF(DECU!$AD:$AD,E$3&"-"&$C42)) | F42: =IF(COUNTIF(DECU!$AD:$AD,F$3&"-"&$C42)=0,"",COUNTIF(DECU!$AD:$AD,F$3&"-"&$C42)) | G42: =IF(COUNTIF(DECU!$AD:$AD,G$3&"-"&$C42)=0,"",COUNTIF(DECU!$AD:$AD,G$3&"-"&$C42)) | H42: =IF(COUNTIF(DECU!$AD:$AD,H$3&"-"&$C42)=0,"",COUNTIF(DECU!$AD:$AD,H$3&"-"&$C42)) | I42: =IF(COUNTIF(DECU!$AD:$AD,I$3&"-"&$C42)=0,"",COUNTIF(DECU!$AD:$AD,I$3&"-"&$C42)) | J42: =IF(COUNTIF(DECU!$AD:$AD,J$3&"-"&$C42)=0,"",COUNTIF(DECU!$AD:$AD,J$3&"-"&$C42)) | K42: =IF(COUNTIF(DECU!$AD:$AD,K$3&"-"&$C42)=0,"",COUNTIF(DECU!$AD:$AD,K$3&"-"&$C42)) | L42: =COUNTIF(DECU!$AE:$AE,$C42)-SUM(E42:K42) | N42: =SUMIF(DECU!AE:AE,C42,DECU!R:R) | O42: =N42/$N$43
C43: TOTAL: | D43: =SUM(D34:D42) | E43: =SUM(E34:E42) | F43: =SUM(F34:F42) | G43: =SUM(G34:G42) | H43: =SUM(H34:H42) | I43: =SUM(I34:I42) | J43: =SUM(J34:J42) | K43: =SUM(K34:K42) | L43: =SUM(L34:L42) | N43: =SUM(N34:N42) | O43: =N43/N$43
G44: =SUM(G43:$L43)-G43 | J44: =SUM(J43:$L43)-J43
...

Sheet ACCU
A1: =SUM(A7,A16,A34,A52,A122,A130,A145,A153,A162,A114,A65,A24,A87) | B1: =ALLHKD!C1 | H1: ACCUMULATORS | N1: For the Whole Structure
A3: CITIBANK Account No. 1 | K3: 1 month = 20 days
B5: ACCUMULATOR | C5: CODE | E5: SHARES / DAY | H5: SPOT PRICE | I5: STRIKE PRICE | J5: K/O PRICE | K5: LIFE TERM OF CONTRACT | N5: START DATE | O5: END DATE | Q5: Estimated Total Shares Remaining | R5: Estimated Amount | T5: Estimated Amount per month | Y5: Month 1 | Z5: Month 2
D6: CB1 | K6: RCVD mos. | L6: REM mos. | M6: Total mos. | U6: Price | V6: NOW | W6: NEXT | X6: sd | Y6: hkd | Z6: hkd
A7: =IF(B7<>"",INDIRECT(ADDRESS(ROW()-1,COLUMN()))+1,0) | Q7: =E7*L7*20*X7 | R7: =E7*I7*L7*20*X7 | T7: =E7*I7*20*X7 | U7: 12.18 | V7: 21 | W7: 21 | X7: 2 | Y7: =X7*V7*E7*I7 | Z7: =X7*W7*E7*I7 | AB7: =MONTH(O7) | AC7: =YEAR(O7) | AD7: =AB7&"-"&AC7&"-"&C7 | AE7: =C7 | AF7: =MATCH(AE7,ALLM!C$2:C$13,)
O9: Total | Q9: =SUM(Q6:Q8) | R9: =SUM(R6:R8) | T9: =SUM(T6:T8)
R10: HKD | T10: HKD
A12: CITIBANK ACCOUNT # 2 | K12: 1 month = 20 days
B14: ACCUMULATOR | C14: CODE | E14: SHARES / DAY | H14: SPOT PRICE | I14: STRIKE PRICE | J14: K/O PRICE | K14: LIFE TERM OF CONTRACT | N14: START DATE | O14: END DATE | Q14: Estimated Total Shares Remaining | R14: Estimated Amount | T14: Estimated Amount per month
D15: CB2 | K15: RCVD mos. | L15: REM mos. | M15: Total mos.
A16: =IF(B16<>"",INDIRECT(ADDRESS(ROW()-1,COLUMN()))+1,0) | Q16: =E16*L16*20*X16 | R16: =E16*I16*L16*20*X16 | T16: =E16*I16*20*X16 | V16: 21 | W16: 41 | X16: 2 | Y16: =X16*V16*E16*I16 | Z16: =X16*W16*E16*I16 | AB16: =MONTH(O16) | AC16: =YEAR(O16) | AD16: =AB16&"-"&AC16&"-"&C16 | AE16: =C16 | AF16: =MATCH(AE16,ALLM!C$2:C$13,)
O18: Total | Q18: =SUM(Q15:Q17) | R18: =SUM(R15:R17) | T18: =SUM(T15:T17)
R19: HKD | T19: HKD
A20: CITIBANK SINGAPORE - ACCOUNT # 1
B22: ACCUMULATOR | C22: CODE | E22: SHARES / DAY | H22: SPOT PRICE | I22: STRIKE PRICE | J22: K/O PRICE | K22: LIFE TERM OF CONTRACT | N22: START DATE | O22: END DATE | Q22: Estimated Total Shares Remaining | R22: Estimated Amount | T22: Estimated Amount per month
D23: CBSG | K23: RCVD mos. | L23: REM mos. | M23: Total mos.
A24: =IF(B24<>"",INDIRECT(ADDRESS(ROW()-1,COLUMN()))+1,0) | Q24: =E24*L24*X24 | R24: =E24*I24*L24*X24 | T24: =E24*I24*20*X24 | V24: 19 | W24: 19 | X24: 1 | Y24: =X24*V24*E24*I24 | Z24: =X24*W24*E24*I24 | AB24: =MONTH(O24) | AC24: =YEAR(O24) | AD24: =AB24&"-"&AC24&"-"&C24 | AE24: =C24 | AF24: =MATCH(AE24,ALLM!C$2:C$13,)
O26: Total | Q26: =SUM(Q23:Q25) | R26: =SUM(R23:R25) | T26: =SUM(T23:T25)
R27: HKD | T27: HKD
A29: CITIBANK BERRY HILL | K29: 1 month = 20 days
B31: ACCUMULATOR | C31: CODE | E31: SHARES / DAY | H31: SPOT PRICE | I31: STRIKE PRICE | J31: K/O PRICE | K31: LIFE TERM OF CONTRACT | N31: START DATE | O31: END DATE | Q31: Estimated Total Shares Remaining | R31: Estimated Amount | T31: Estimated Amount per month
D32: CBBH | K32: RCVD mos. | L32: REM mos. | M32: Total mos.
A33: =IF(B33<>"",INDIRECT(ADDRESS(ROW()-1,COLUMN()))+1,0) | Q33: =E33*L33*20*X33 | R33: =E33*I33*L33*20*X33 | T33: =E33*I33*20*X33 | V33: 20 | W33: 40 | X33: 2 | Y33: =X33*V33*E33*I33 | Z33: =X33*W33*E33*I33 | AB33: =MONTH(O33) | AC33: =YEAR(O33) | AD33: =AB33&"-"&AC33&"-"&C33 | AE33: =C33 | AF33: =MATCH(AE33,ALLM!C$2:C$13,)
A34: =IF(B34<>"",INDIRECT(ADDRESS(ROW()-1,COLUMN()))+1,0) | Q34: =E34*L34*20*X34 | R34: =E34*I34*L34*20*X34 | T34: =E34*I34*20*X34 | V34: 0 | W34: 19 | X34: 2 | Y34: =X34*V34*E34*I34 | Z34: =X34*W34*E34*I34 | AB34: =MONTH(O34) | AC34: =YEAR(O34) | AD34: =AB34&"-"&AC34&"-"&C34 | AE34: =C34 | AF34: =MATCH(AE34,ALLM!C$2:C$13,)
O36: Total | Q36: =SUM(Q32:Q35) | R36: =SUM(R32:R35) | T36: =SUM(T32:T35)
R37: HKD | T37: HKD
O39: TOTAL CITIBANK | Q39: =SUM(Q9,Q36,Q18,Q26) | R39: =SUM(R9,R36,R18,R26) | T39: =SUM(T9,T36,T18,T26)
R40: HKD | T40: HKD
A42: DEUTSCHE BANK (Personal)
B44: ACCUMULATOR | C44: CODE | E44: SHARES / DAY | H44: SPOT PRICE | I44: STRIKE PRICE | J44: K/O PRICE | K44: LIFE TERM OF CONTRACT | N44: START DATE | O44: END DATE | Q44: Estimated Total Shares Remaining | R44: Estimated Amount | T44: Estimated Amount per month
D45: DBPe | K45: RCVD DAYS | L45: REM DAYS | M45: Total DAYS
A46: =IF(B46<>"",INDIRECT(ADDRESS(ROW()-1,COLUMN()))+1,0) | B46: Alibaba | C46: 9988 | D46: Alibaba - 6 | E46: 200 | F46: / | G46: 400 | H46: 168.4000 | I46: 133.8612 | J46: 185.2400 | K46: 194 | L46: =M46-K46 | M46: 244 | N46: 29-Sep-2025 | O46: 25-Sep-2026 | Q46: =E46*L46*X46 | R46: =E46*I46*L46*X46 | T46: =E46*I46*20*X46 | U46: 413 | V46: 0 | W46: 30 | X46: 2 | Y46: =X46*V46*E46*I46 | Z46: =X46*W46*E46*I46 | AB46: =MONTH(O46) | AC46: =YEAR(O46) | AD46: =AB46&"-"&AC46&"-"&C46 | AE46: =C46 | AF46: =MATCH(AE46,ALLM!C$2:C$13,)
A47: =IF(B47<>"",INDIRECT(ADDRESS(ROW()-1,COLUMN()))+1,0) | B47: Tencent | C47: 0700 | D47: Tencent - 8 | E47: 130 | F47: / | G47: 260 | H47: 636.0000 | I47: 565.4040 | J47: 699.6000 | K47: 176 | L47: =M47-K47 | M47: 244 | N47: 27-Oct-2025 | O47: 23-Oct-2026 | Q47: =E47*L47*X47 | R47: =E47*I47*L47*X47 | T47: =E47*I47*20*X47 | U47: 413 | V47: 0 | W47: 30 | X47: 2 | Y47: =X47*V47*E47*I47 | Z47: =X47*W47*E47*I47 | AB47: =MONTH(O47) | AC47: =YEAR(O47) | AD47: =AB47&"-"&AC47&"-"&C47 | AE47: =C47 | AF47: =MATCH(AE47,ALLM!C$2:C$13,)
A48: =IF(B48<>"",INDIRECT(ADDRESS(ROW()-1,COLUMN()))+1,0) | B48: Alibaba | C48: 9988 | D48: Alibaba - 7 | E48: 300 | F48: / | G48: 600 | H48: 172.8593 | I48: 145.7204 | J48: 181.5023 | K48: 177 | L48: =M48-K48 | M48: 245 | N48: 31-Oct-2025 | O48: 29-Oct-2026 | Q48: =E48*L48*X48 | R48: =E48*I48*L48*X48 | T48: =E48*I48*20*X48 | U48: 413 | V48: 0 | W48: 20 | X48: 2 | Y48: =X48*V48*E48*I48 | Z48: =X48*W48*E48*I48 | AB48: =MONTH(O48) | AC48: =YEAR(O48) | AD48: =AB48&"-"&AC48&"-"&C48 | AE48: =C48 | AF48: =MATCH(AE48,ALLM!C$2:C$13,)
A49: =IF(B49<>"",INDIRECT(ADDRESS(ROW()-1,COLUMN()))+1,0) | B49: Tencent | C49: 0700 | D49: Tencent - 10 | E49: 100 | F49: / | G49: 200 | H49: 619.5000 | I49: 557.7978 | J49: 650.4750 | K49: 130 | L49: =M49-K49 | M49: 311 | N49: 13-Jan-2026 | O49: 19-Apr-2027 | Q49: =E49*L49*X49 | R49: =E49*I49*L49*X49 | T49: =E49*I49*20*X49 | U49: 413 | V49: 0 | W49: 20 | X49: 2 | Y49: =X49*V49*E49*I49 | Z49: =X49*W49*E49*I49 | AB49: =MONTH(O49) | AC49: =YEAR(O49) | AD49: =AB49&"-"&AC49&"-"&C49 | AE49: =C49 | AF49: =MATCH(AE49,ALLM!C$2:C$13,)
A50: =IF(B50<>"",INDIRECT(ADDRESS(ROW()-1,COLUMN()))+1,0) | B50: Geely Motor | C50: 0175 | D50: Geely Motor - 14 | E50: 1200 | F50: / | G50: 2400 | H50: 25.0542 | I50: 20.5044 | J50: 26.3069 | K50: 66 | L50: =M50-K50 | M50: 247 | N50: 14-Apr-2026 | O50: 14-Apr-2027 | Q50: =E50*L50*X50 | R50: =E50*I50*L50*X50 | T50: =E50*I50*20*X50 | U50: 413 | V50: 0 | W50: 20 | X50: 2 | Y50: =X50*V50*E50*I50 | Z50: =X50*W50*E50*I50 | AB50: =MONTH(O50) | AC50: =YEAR(O50) | AD50: =AB50&"-"&AC50&"-"&C50 | AE50: =C50 | AF50: =MATCH(AE50,ALLM!C$2:C$13,)
A51: =IF(B51<>"",INDIRECT(ADDRESS(ROW()-1,COLUMN()))+1,0) | B51: China Molybdenum | C51: 3993 | D51: China Molybdenum - 19 | E51: 3000 | F51: / | G51: 6000 | H51: 20.0200 | I51: 15.4454 | J51: 23.0230 | K51: 47 | L51: =M51-K51 | M51: 248 | N51: 12-May-2026 | O51: 10-May-2027 | Q51: =E51*L51*X51 | R51: =E51*I51*L51*X51 | T51: =E51*I51*20*X51 | U51: 413 | V51: 0 | W51: 20 | X51: 1 | Y51: =X51*V51*E51*I51 | Z51: =X51*W51*E51*I51 | AB51: =MONTH(O51) | AC51: =YEAR(O51) | AD51: =AB51&"-"&AC51&"-"&C51 | AE51: =C51 | AF51: =MATCH(AE51,ALLM!C$2:C$13,)
A52: =IF(B52<>"",INDIRECT(ADDRESS(ROW()-1,COLUMN()))+1,0) | B52: HK Exchange | C52: 0388 | D52: HK EXCHANGE - 18 | E52: 200 | F52: / | G52: 400 | H52: 409.6000 | I52: 370.6061 | J52: 450.5600 | K52: 47 | L52: =M52-K52 | M52: 247 | N52: 20-May-2026 | O52: 18-May-2027 | Q52: =E52*L52*X52 | R52: =E52*I52*L52*X52 | T52: =E52*I52*20*X52 | U52: 413 | V52: 0 | W52: 20 | X52: 1 | Y52: =X52*V52*E52*I52 | Z52: =X52*W52*E52*I52 | AB52: =MONTH(O52) | AC52: =YEAR(O52) | AD52: =AB52&"-"&AC52&"-"&C52 | AE52: =C52 | AF52: =MATCH(AE52,ALLM!C$2:C$13,)
O54: Deutsche Bank (Personal) Total | Q54: =SUM(Q45:Q53) | R54: =SUM(R45:R53) | T54: =SUM(T45:T53)
R55: HKD | T55: HKD
...

Sheet DECU
A1: =SUM(,A16,A114,A149,A35,A121,A7,A134,A51,A84,A142,A26,A106,A65) | B1: =ACCU!B1 | I1: DECUMULATOR | N1: For the Whole Structure
A3: CITIBANK Account No. 1 | K3: 1 month = 20 days
I4: `
B5: DECUMULATOR | C5: CODE | E5: SHARES / DAY | H5: SPOT PRICE | I5: STRIKE PRICE | J5: K/O PRICE | K5: LIFE TERM OF CONTRACT | N5: START DATE | O5: END DATE | Q5: Estimated Shares to sell | R5: Estimated Amount | T5: Estimated Amount per month | Y5: july | Z5: aug | AH5: =SUM(AH8:AH1048576) | AI5: =SUM(AI8:AI1048576)
D6: CB1 | K6: RCVD mos. | L6: REM mos. | M6: Total mos. | U6: Closing | V6: Current | W6: Next | X6: sd | Y6: hkd | Z6: hkd | AH6: Double | AI6: Single
A7: =IF(B7<>"",INDIRECT(ADDRESS(ROW()-1,COLUMN()))+1,0) | Q7: =E7*L7*20*X7 | R7: =E7*I7*L7*20*X7 | T7: =E7*I7*20*X7 | V7: 0 | W7: 42 | X7: 1 | AB7: =MONTH(O7) | AC7: =YEAR(O7) | AD7: =AB7&"-"&AC7&"-"&C7 | AE7: =C7 | AF7: =MATCH(AE7,ALLM!$C$34:$C$43,) | AH7: =IF(C7="2333",IF(X7=2,1,0),0) | AI7: =IF(C7="2333",IF(X7=1,1,0),0)
O9: Total | Q9: =SUM(Q6:Q8) | R9: =SUM(R6:R8) | T9: =SUM(T6:T8)
Q10: Shares | R10: HKD | T10: HKD
A12: CITIBANK Account No. 2 | K12: 1 month = 20 days
B14: DECUMULATOR | C14: CODE | E14: SHARES / DAY | H14: SPOT PRICE | I14: STRIKE PRICE | J14: K/O PRICE | K14: LIFE TERM OF CONTRACT | N14: START DATE | O14: END DATE | Q14: Estimated Shares to sell | R14: Estimated Amount | T14: Estimated Amount per month | Y14: july | Z14: aug
D15: CB2 | K15: RCVD mos. | L15: REM mos. | M15: Total mos. | Y15: hkd | Z15: hkd
A16: =IF(B16<>"",INDIRECT(ADDRESS(ROW()-1,COLUMN()))+1,0) | Q16: =E16*L16*20*X16 | R16: =E16*I16*L16*20*X16 | T16: =E16*I16*20*X16 | U16: 12.18 | V16: 0 | W16: 42 | X16: 1 | Y16: =X16*V16*E16*I16 | Z16: =X16*W16*E16*I16 | AB16: =MONTH(O16) | AC16: =YEAR(O16) | AD16: =AB16&"-"&AC16&"-"&C16 | AE16: =C16 | AF16: =MATCH(AE16,ALLM!$C$34:$C$43,) | AH16: =IF(C16="2333",IF(X16=2,1,0),0) | AI16: =IF(C16="2333",IF(X16=1,1,0),0)
O18: Total | Q18: =SUM(Q15:Q17) | R18: =SUM(R15:R17) | T18: =SUM(T15:T17)
Q19: Shares | R19: HKD | T19: HKD
A22: CITIBANK Singapore - Account No. 1
B24: DECUMULATOR | C24: CODE | E24: SHARES / DAY | H24: SPOT PRICE | I24: STRIKE PRICE | J24: K/O PRICE | K24: LIFE TERM OF CONTRACT | N24: START DATE | O24: END DATE | Q24: Estimated Shares to sell | R24: Estimated Amount | T24: Estimated Amount per month | Y24: july | Z24: aug
D25: CBSG | K25: RCVD mos. | L25: REM mos. | M25: Total mos. | Y25: hkd | Z25: hkd
A26: =IF(B26<>"",INDIRECT(ADDRESS(ROW()-1,COLUMN()))+1,0) | Q26: =E26*L26*20*X26 | R26: =E26*I26*L26*20*X26 | T26: =E26*I26*20*X26 | U26: 12.18 | V26: 0 | W26: 42 | X26: 1 | Y26: =X26*V26*E26*I26 | Z26: =X26*W26*E26*I26 | AB26: =MONTH(O26) | AC26: =YEAR(O26) | AD26: =AB26&"-"&AC26&"-"&C26 | AE26: =C26 | AF26: =MATCH(AE26,ALLM!$C$34:$C$43,) | AH26: =IF(C26="2333",IF(X26=2,1,0),0) | AI26: =IF(C26="2333",IF(X26=1,1,0),0)
O28: Total | Q28: =SUM(Q25:Q27) | R28: =SUM(R25:R27) | T28: =SUM(T25:T27)
Q29: Shares | R29: HKD | T29: HKD
A31: CITIBANK Berry Hill | K31: 1 month = 20 days
B33: DECUMULATOR | C33: CODE | E33: SHARES / DAY | H33: SPOT PRICE | I33: STRIKE PRICE | J33: K/O PRICE | K33: LIFE TERM OF CONTRACT | N33: START DATE | O33: END DATE | Q33: Estimated Shares to sell | R33: Estimated Amount | T33: Estimated Amount per month | Y33: july | Z33: aug
D34: CBBH | K34: RCVD mos. | L34: REM mos. | M34: Total mos. | Y34: hkd | Z34: hkd
A35: =IF(B35<>"",INDIRECT(ADDRESS(ROW()-1,COLUMN()))+1,0) | H35: 5.0200 | I35: 6.2710 | J35: 4.7690 | K35: 12 | L35: =M35-K35 | M35: 12 | N35: 15-Apr-2020 | O35: 14-Apr-2021 | Q35: =E35*L35*X35 | R35: =E35*I35*L35*X35 | T35: =E35*I35*20*X35 | U35: 25.7 | V35: 0 | W35: 0 | X35: 2 | Y35: =X35*V35*E35*I35 | Z35: =X35*W35*E35*I35 | AB35: =MONTH(O35) | AC35: =YEAR(O35) | AD35: =AB35&"-"&AC35&"-"&C35 | AE35: =C35 | AF35: =MATCH(AE35,ALLM!$C$34:$C$43,) | AH35: =IF(C35="2333",IF(X35=2,1,0),0) | AI35: =IF(C35="2333",IF(X35=1,1,0),0)
O37: Total | Q37: =SUM(Q34:Q36) | R37: =SUM(R34:R36) | T37: =SUM(T34:T36)
Q38: Shares | R38: HKD | T38: HKD
O42: TOTAL CITIBANK | R42: =SUM(R18,R37,R9,R28) | T42: =SUM(T9,T37,T18,T28)
R43: HKD | T43: HKD
A45: DEUTSCHE BANK (Personal)
B47: DECUMULATOR | C47: CODE | E47: SHARES / DAY | H47: SPOT PRICE | I47: STRIKE PRICE | J47: K/O PRICE | K47: LIFE TERM OF CONTRACT | N47: START DATE | O47: END DATE | Q47: Estimated Shares to sell | R47: Estimated Amount | T47: Estimated Amount per month | Y47: july | Z47: aug
D48: DBPe | K48: RCVD DAYS | L48: REM DAYS | M48: Total DAYS | Y48: hkd | Z48: hkd
A49: =IF(B49<>"",INDIRECT(ADDRESS(ROW()-1,COLUMN()))+1,0) | B49: HK Exchange | C49: 0388 | D49: HK Exchange - 11 | E49: 53 | F49: / | G49: 106 | H49: 377.0000 | I49: 428.4605 | J49: 358.1500 | K49: 10 | L49: =M49-K49 | M49: 248 | N49: 7-Jul-2026 | O49: 5-Jul-2027 | Q49: =E49*L49*X49 | R49: =E49*I49*L49*X49 | T49: =E49*I49*20*X49 | U49: 3.08 | V49: 0 | W49: 20 | X49: 1 | Y49: =X49*V49*E49*I49 | Z49: =X49*W49*E49*I49 | AB49: =MONTH(O49) | AC49: =YEAR(O49) | AD49: =AB49&"-"&AC49&"-"&C49 | AE49: =C49 | AF49: =MATCH(AE49,ALLM!$C$34:$C$43,) | AH49: =IF(C49="2333",IF(X49=2,1,0),0) | AI49: =IF(C49="2333",IF(X49=1,1,0),0)
A50: =IF(B50<>"",INDIRECT(ADDRESS(ROW()-1,COLUMN()))+1,0) | B50: Kuaishou Tech | C50: 1024 | D50: Kuaishou Tech - 12 | E50: 140 | F50: / | G50: 280 | H50: 41.8200 | I50: 61.0321 | J50: 39.7290 | K50: 10 | L50: =M50-K50 | M50: 248 | N50: 9-Jul-2026 | O50: 7-Jul-2027 | Q50: =E50*L50*X50 | R50: =E50*I50*L50*X50 | T50: =E50*I50*20*X50 | U50: 3.08 | V50: 0 | W50: 20 | X50: 1 | Y50: =X50*V50*E50*I50 | Z50: =X50*W50*E50*I50 | AB50: =MONTH(O50) | AC50: =YEAR(O50) | AD50: =AB50&"-"&AC50&"-"&C50 | AE50: =C50 | AF50: =MATCH(AE50,ALLM!$C$34:$C$43,) | AH50: =IF(C50="2333",IF(X50=2,1,0),0) | AI50: =IF(C50="2333",IF(X50=1,1,0),0)
A51: =IF(B51<>"",INDIRECT(ADDRESS(ROW()-1,COLUMN()))+1,0) | B51: Alibaba | C51: 9988 | D51: Alibaba - 13 | E51: 150 | F51: / | G51: 300 | H51: 111.2000 | I51: 150.9540 | J51: 105.6400 | K51: 10 | L51: =M51-K51 | M51: 248 | N51: 14-Jul-2026 | O51: 12-Jul-2027 | Q51: =E51*L51*X51 | R51: =E51*I51*L51*X51 | T51: =E51*I51*20*X51 | U51: 3.08 | V51: 0 | W51: 20 | X51: 1 | Y51: =X51*V51*E51*I51 | Z51: =X51*W51*E51*I51 | AB51: =MONTH(O51) | AC51: =YEAR(O51) | AD51: =AB51&"-"&AC51&"-"&C51 | AE51: =C51 | AF51: =MATCH(AE51,ALLM!$C$34:$C$43,) | AH51: =IF(C51="2333",IF(X51=2,1,0),0) | AI51: =IF(C51="2333",IF(X51=1,1,0),0)
O53: Total | Q53: =SUM(Q48:Q52) | R53: =SUM(R48:R52) | T53: =SUM(T48:T52)
Q54: Shares | R54: HKD | T54: HKD
A57: NOMURA SINGAPORE
B59: DECUMULATOR | C59: CODE | E59: SHARES / DAY | H59: SPOT PRICE | I59: STRIKE PRICE | J59: K/O PRICE | K59: LIFE TERM OF CONTRACT | N59: START DATE | O59: END DATE | Q59: Estimated Shares to sell | R59: Estimated Amount | T59: Estimated Amount per month | Y59: july | Z59: aug
D60: NSG | K60: RCVD DAYS | L60: REM DAYS | M60: Total DAYS | Y60: hkd | Z60: hkd
A61: =IF(B61<>"",INDIRECT(ADDRESS(ROW()-1,COLUMN()))+1,0) | B61: China Molybdenum | C61: 3993 | D61: China Molybdenum - 4 | E61: 799 | F61: / | G61: 1598 | H61: 15.3388 | I61: 21.2764 | J61: 14.5719 | K61: 20 | L61: =M61-K61 | M61: 249 | N61: 29-Jun-2026 | O61: 28-Jun-2027 | Q61: =E61*L61*X61 | R61: =E61*I61*L61*X61 | T61: =E61*I61*20*X61 | U61: 25.7 | V61: 0 | W61: 22 | X61: 1 | Y61: =X61*V61*E61*I61 | Z61: =X61*W61*E61*I61 | AB61: =MONTH(O61) | AC61: =YEAR(O61) | AD61: =AB61&"-"&AC61&"-"&C61 | AE61: =C61 | AF61: =MATCH(AE61,ALLM!$C$34:$C$43,) | AH61: =IF(C61="2333",IF(X61=2,1,0),0) | AI61: =IF(C61="2333",IF(X61=1,1,0),0)
...

Sheet Collateral
A1: Collateral Needed
A2: Great Wall Motor (2333)
A3: ="As of "&TEXT(ALLHKD!C1,"mmmm d, yyyy") | U3: market price
U4: 9.2
A5: CITIBANK Account No. 1
E6: ` | I6: `
B7: ACCUMULATOR | C7: CODE | E7: SHARES / DAY | H7: SPOT PRICE | I7: STRIKE PRICE | J7: K/O PRICE | K7: LIFE TERM OF CONTRACT | N7: START DATE | O7: END DATE | Q7: Estimated Total Shares Remaining | R7: Estimated Amount | T7: Estimated Amount per month | Y7: Month 1 | Z7: Month 2
D8: CB1 | K8: RCVD mos. | L8: REM mos. | M8: Total mos. | U8: Price | V8: NOW | W8: NEXT | X8: sd | Y8: hkd | Z8: hkd
A9: =INDIRECT(ADDRESS(ROW()-1,COLUMN()))+1 | B9: Great Wall Motor | C9: 2333 | D9: GREATWALL - 41 | E9: 5000 | F9: / | G9: 10000 | H9: 9.1347 | I9: 7.675 | J9: 10.0482 | K9: 0 | L9: =M9-K9 | M9: 9 | N9: 44076 | O9: 44348 | Q9: =E9*L9*20*X9 | R9: =E9*I9*L9*20*X9 | T9: =E9*I9*20*X9 | U9: 9.12 | V9: 0 | W9: 1 | X9: 1 | Y9: =X9*V9*E9*I9*20 | Z9: =X9*W9*E9*I9*20 | AB9: =MONTH(O9) | AC9: =YEAR(O9) | AD9: =AB9&"-"&AC9&"-"&C9 | AE9: =C9 | AF9: =MATCH(AE9,ALLM!C$2:C$13,)
O11: Total | Q11: =SUM(Q8:Q10) | R11: =SUM(R8:R10) | T11: =SUM(T8:T10)
R12: HKD | T12: HKD
R14: Estimated Amount | S14: 0.3 | T14: Margin requirement
H15: Collateral 1: 30% x Estimated Amount Total | R15: =R11 | T15: =-R15*S14
B17: DECUMULATOR | C17: CODE | E17: SHARES / DAY | H17: SPOT PRICE | I17: STRIKE PRICE | J17: K/O PRICE | K17: LIFE TERM OF CONTRACT | N17: START DATE | O17: END DATE | Q17: Estimated Shares to sell | R17: Estimated Amount | T17: Estimated Amount per month | Y17: july | Z17: aug | AH17: =SUM(AH24:AH1048576) | AI17: =SUM(AI24:AI1048576)
D18: CB1 | K18: RCVD mos. | L18: REM mos. | M18: Total mos. | U18: Closing | V18: Current | W18: Next | X18: sd | Y18: hkd | Z18: hkd | AH18: Double | AI18: Single
A19: =INDIRECT(ADDRESS(ROW()-1,COLUMN()))+1 | B19: Great Wall Motor | C19: 2333 | D19: GREATWALL - 57 | E19: 5000 | F19: / | G19: 10000 | H19: 4.09 | I19: 5.6017 | J19: 3.8855 | K19: 5 | L19: =M19-K19 | M19: 12 | N19: 43915 | O19: 44279 | Q19: =E19*L19*20*X19 | R19: =E19*I19*L19*20*X19 | T19: =E19*I19*20*X19 | U19: 9.12 | V19: 1 | W19: 2 | X19: 2 | Y19: =X19*V19*E19*I19*20 | Z19: =X19*W19*E19*I19*20 | AB19: =MONTH(O19) | AC19: =YEAR(O19) | AD19: =AB19&"-"&AC19&"-"&C19 | AE19: =C19 | AF19: =MATCH(AE19,ALLM!$C$34:$C$43,) | AH19: =IF(C19="2333",IF(X19=2,1,0),0) | AI19: =IF(C19="2333",IF(X19=1,1,0),0)
A20: =INDIRECT(ADDRESS(ROW()-1,COLUMN()))+1 | B20: Great Wall Motor | C20: 2333 | D20: GREATWALL - 58 | E20: 3000 | F20: / | G20: 6000 | H20: 4.6771 | I20: 6.3599 | J20: 4.4432 | K20: 5 | L20: =M20-K20 | M20: 12 | N20: 43916 | O20: 44280 | Q20: =E20*L20*20*X20 | R20: =E20*I20*L20*20*X20 | T20: =E20*I20*20*X20 | U20: 9.12 | V20: 1 | W20: 2 | X20: 2 | Y20: =X20*V20*E20*I20*20 | Z20: =X20*W20*E20*I20*20 | AB20: =MONTH(O20) | AC20: =YEAR(O20) | AD20: =AB20&"-"&AC20&"-"&C20 | AE20: =C20 | AF20: =MATCH(AE20,ALLM!$C$34:$C$43,) | AH20: =IF(C20="2333",IF(X20=2,1,0),0) | AI20: =IF(C20="2333",IF(X20=1,1,0),0)
A21: =INDIRECT(ADDRESS(ROW()-1,COLUMN()))+1 | B21: Great Wall Motor | C21: 2333 | D21: GREATWALL - 59 | E21: 5000 | F21: / | G21: 10000 | H21: 4.936 | I21: 6.2796 | J21: 4.6892 | K21: 5 | L21: =M21-K21 | M21: 9 | N21: 43922 | O21: 44196 | Q21: =E21*L21*20*X21 | R21: =E21*I21*L21*20*X21 | T21: =E21*I21*20*X21 | U21: 9.12 | V21: 1 | W21: 0 | X21: 2 | Y21: =X21*V21*E21*I21*20 | Z21: =X21*W21*E21*I21*20 | AB21: =MONTH(O21) | AC21: =YEAR(O21) | AD21: =AB21&"-"&AC21&"-"&C21 | AE21: =C21 | AF21: =MATCH(AE21,ALLM!$C$34:$C$43,) | AH21: =IF(C21="2333",IF(X21=2,1,0),0) | AI21: =IF(C21="2333",IF(X21=1,1,0),0)
A22: =INDIRECT(ADDRESS(ROW()-1,COLUMN()))+1 | B22: Great Wall Motor | C22: 2333 | D22: GREATWALL - 60 | E22: 2100 | F22: / | G22: 4200 | H22: 5.02 | I22: 6.271 | J22: 4.769 | K22: 4 | L22: =M22-K22 | M22: 12 | N22: 43936 | O22: 44300 | Q22: =E22*L22*20*X22 | R22: =E22*I22*L22*20*X22 | T22: =E22*I22*20*X22 | U22: 9.12 | V22: 1 | W22: 2 | X22: 2 | Y22: =X22*V22*E22*I22*20 | Z22: =X22*W22*E22*I22*20 | AB22: =MONTH(O22) | AC22: =YEAR(O22) | AD22: =AB22&"-"&AC22&"-"&C22 | AE22: =C22 | AF22: =MATCH(AE22,ALLM!$C$34:$C$43,) | AH22: =IF(C22="2333",IF(X22=2,1,0),0) | AI22: =IF(C22="2333",IF(X22=1,1,0),0)
A23: =INDIRECT(ADDRESS(ROW()-1,COLUMN()))+1 | B23: Great Wall Motor | C23: 2333 | D23: GREATWALL - 62 | E23: 5000 | F23: / | G23: 10000 | H23: 5.19 | I23: 6.1771 | J23: 4.9305 | K23: 2 | L23: =M23-K23 | M23: 12 | N23: 44018 | O23: 44382 | Q23: =E23*L23*20*X23 | R23: =E23*I23*L23*20*X23 | T23: =E23*I23*20*X23 | U23: 9.12 | V23: 0 | W23: 1 | X23: 2 | Y23: =X23*V23*E23*I23*20 | Z23: =X23*W23*E23*I23*20 | AB23: =MONTH(O23) | AC23: =YEAR(O23) | AD23: =AB23&"-"&AC23&"-"&C23 | AE23: =C23 | AF23: =MATCH(AE23,ALLM!$C$34:$C$43,) | AH23: =IF(C23="2333",IF(X23=2,1,0),0) | AI23: =IF(C23="2333",IF(X23=1,1,0),0)
O25: Total | Q25: =SUM(Q18:Q24) | R25: =SUM(R18:R24) | T25: =SUM(T18:T24)
Q26: Shares | R26: HKD | T26: HKD
J28: Total Shares to sell | Q28: =Q25
J29: On hand | Q29: 1187350
J30: Balance shares for decu | Q30: =Q28-Q29
R32: Estimated Amount | S32: 0.3 | T32: Margin requirement
H33: Collateral 2: 30% x Estimated Amount Total | R33: =R25 | T33: =-R33*S32
Q35: Market Price | R35: =market_price
L36: Estimated Shares | N36: On Hand | Q36: Balance shares for decu | R36: Strike Price minus Market Price | T36: Collateral needed
H37: Collateral 3: | J37: Strike 1 | L37: =I19 | N37: =Q29 | Q37: =Q19-N37 | R37: =L37-market_price | T37: =Q37*R37
J38: Strike 2 | L38: =I20 | N38: 0 | Q38: =Q20 | R38: =L38-market_price | T38: =Q38*R38
J39: Strike 3 | L39: =I21 | N39: 0 | Q39: =Q21 | R39: =L39-market_price | T39: =Q39*R39
J40: Strike 4 | L40: =I22 | N40: 0 | Q40: =Q22 | R40: =L40-market_price | T40: =Q40*R40
J41: Strike 5 | L41: =I23 | N41: 0 | Q41: =Q23 | R41: =L41-market_price | T41: =Q41*R41
I42: Sub Total | N42: =SUM(N37:O41) | Q42: =SUM(Q37:Q41) | T42: =SUM(T37:T41)
H44: Total collateral needed | T44: =T33+T42+T15
R45: USD Rate 7.75 | T45: =T44/7.75
A48: CITIBANK Account No. 2
E49: ` | I49: `
B50: ACCUMULATOR | C50: CODE | E50: SHARES / DAY | H50: SPOT PRICE | I50: STRIKE PRICE | J50: K/O PRICE | K50: LIFE TERM OF CONTRACT | N50: START DATE | O50: END DATE | Q50: Estimated Total Shares Remaining | R50: Estimated Amount | T50: Estimated Amount per month | Y50: Month 1 | Z50: Month 2
...

Sheet ALLAUD
B1: ACCUMULATORS | C1: =ALLHKD!C1
B3: Account | C3: Estimated Amount | D3: Estimated Amount (%)
B4: Citibank - Account 1 | D4: =C4/$C$15
B5: Citibank - Account 2 | D5: =C5/$C$15
B6: Citibank - Berry Hill | D6: =C6/$C$15
B7: Deutsche Bank - Personal | D7: =C7/$C$15
B8: Deutsche Bank - Perfect Legend | D8: =C8/$C$15
B9: Standard Chartered | D9: =C9/$C$15
B10: Sun Hung Kai | D10: =C10/$C$15
B11: Morgan Stanley - Titan 1 | D11: =C11/$C$15
B12: Morgan Stanley - Titan 2 | D12: =C12/$C$15
B13: Morgan Stanley - Perfect Legend | C13: ='ACCU AUD'!R12 | D13: =C13/$C$15
B14: Bank of Singapore | D14: =C14/$C$15
C15: =SUM(C4:C14) | D15: =C15/$C$15 | F15: ='ACCU AUD'!R12 | G15: =C15-F15
B17: Decumulators | C17: =C1
B19: Account | C19: Estimated Amount | D19: Estimated Amount (%)
B20: Citibank - Account 1 | D20: =C20/$C$31
B21: Citibank - Account 2 | D21: =C21/$C$31
B22: Citibank - Berry Hill | D22: =C22/$C$31
B23: Deutsche Bank - Personal | D23: =C23/$C$31
B24: Deutsche Bank - Perfect Legend | D24: =C24/$C$31
B25: Standard Chartered | D25: =C25/$C$31
B26: Sun Hung Kai | D26: =C26/$C$31
B27: Morgan Stanley - Titan 1 | D27: =C27/$C$31
B28: Morgan Stanley - Titan 2 | D28: =C28/$C$31
B29: Morgan Stanley - Perfect Legend | C29: ='DECU AUD'!R11 | D29: =C29/$C$31
B30: Bank of Singapore | D30: =C30/$C$31
C31: =SUM(C20:C30) | D31: =C31/$C$31 | F31: ='DECU AUD'!R11 | G31: =C31-F31
F33: =F15-F31

Sheet ALLM AUD
B1: ACCUMULATORS | F1: =ACCU!B1
B2: AU Stock | C2: Code | D2: Total | E2: =ALLM!E2 | F2: =ALLM!F2 | G2: =ALLM!G2 | H2: =ALLM!H2 | I2: =ALLM!I2 | J2: =ALLM!J2 | K2: =ALLM!K2 | L2: =ALLM!L2 | N2: Estimated Amount | O2: %
E3: =ALLM!E3 | F3: =ALLM!F3 | G3: =ALLM!G3 | H3: =ALLM!H3 | I3: =ALLM!I3 | J3: =ALLM!J3 | K3: =ALLM!K3
B4: Rio Tinto | C4: RIO | D4: =SUM(E4:L4) | E4: =IF(COUNTIF('ACCU AUD'!$AD:$AD,E$3&"-"&$C4)=0,"",COUNTIF('ACCU AUD'!$AD:$AD,E$3&"-"&$C4)) | F4: =IF(COUNTIF('ACCU AUD'!$AD:$AD,F$3&"-"&$C4)=0,"",COUNTIF('ACCU AUD'!$AD:$AD,F$3&"-"&$C4)) | G4: =IF(COUNTIF('ACCU AUD'!$AD:$AD,G$3&"-"&$C4)=0,"",COUNTIF('ACCU AUD'!$AD:$AD,G$3&"-"&$C4)) | H4: =IF(COUNTIF('ACCU AUD'!$AD:$AD,H$3&"-"&$C4)=0,"",COUNTIF('ACCU AUD'!$AD:$AD,H$3&"-"&$C4)) | I4: =IF(COUNTIF('ACCU AUD'!$AD:$AD,I$3&"-"&$C4)=0,"",COUNTIF('ACCU AUD'!$AD:$AD,I$3&"-"&$C4)) | J4: =IF(COUNTIF('ACCU AUD'!$AD:$AD,J$3&"-"&$C4)=0,"",COUNTIF('ACCU AUD'!$AD:$AD,J$3&"-"&$C4)) | K4: =IF(COUNTIF('ACCU AUD'!$AD:$AD,K$3&"-"&$C4)=0,"",COUNTIF('ACCU AUD'!$AD:$AD,K$3&"-"&$C4)) | L4: =COUNTIF('ACCU AUD'!$AE:$AE,$C4)-SUM(E4:K4) | N4: =SUMIF('ACCU AUD'!AE:AE,C4,'ACCU AUD'!R:R) | O4: =N4/N$17
B5: Geely Motor | C5: 0175 | D5: =SUM(E5:L5) | E5: =IF(COUNTIF('ACCU AUD'!$AD:$AD,E$3&"-"&$C5)=0,"",COUNTIF('ACCU AUD'!$AD:$AD,E$3&"-"&$C5)) | F5: =IF(COUNTIF('ACCU AUD'!$AD:$AD,F$3&"-"&$C5)=0,"",COUNTIF('ACCU AUD'!$AD:$AD,F$3&"-"&$C5)) | G5: =IF(COUNTIF('ACCU AUD'!$AD:$AD,G$3&"-"&$C5)=0,"",COUNTIF('ACCU AUD'!$AD:$AD,G$3&"-"&$C5)) | H5: =IF(COUNTIF('ACCU AUD'!$AD:$AD,H$3&"-"&$C5)=0,"",COUNTIF('ACCU AUD'!$AD:$AD,H$3&"-"&$C5)) | I5: =IF(COUNTIF('ACCU AUD'!$AD:$AD,I$3&"-"&$C5)=0,"",COUNTIF('ACCU AUD'!$AD:$AD,I$3&"-"&$C5)) | J5: =IF(COUNTIF('ACCU AUD'!$AD:$AD,J$3&"-"&$C5)=0,"",COUNTIF('ACCU AUD'!$AD:$AD,J$3&"-"&$C5)) | K5: =IF(COUNTIF('ACCU AUD'!$AD:$AD,K$3&"-"&$C5)=0,"",COUNTIF('ACCU AUD'!$AD:$AD,K$3&"-"&$C5)) | L5: =COUNTIF('ACCU AUD'!$AE:$AE,$C5)-SUM(E5:K5) | N5: =SUMIF('ACCU AUD'!AE:AE,C5,'ACCU AUD'!R:R) | O5: =N5/N$17
B6: Cathay Pacific Airways LTD | C6: 0293 | D6: =SUM(E6:L6) | E6: =IF(COUNTIF('ACCU AUD'!$AD:$AD,E$3&"-"&$C6)=0,"",COUNTIF('ACCU AUD'!$AD:$AD,E$3&"-"&$C6)) | F6: =IF(COUNTIF('ACCU AUD'!$AD:$AD,F$3&"-"&$C6)=0,"",COUNTIF('ACCU AUD'!$AD:$AD,F$3&"-"&$C6)) | G6: =IF(COUNTIF('ACCU AUD'!$AD:$AD,G$3&"-"&$C6)=0,"",COUNTIF('ACCU AUD'!$AD:$AD,G$3&"-"&$C6)) | H6: =IF(COUNTIF('ACCU AUD'!$AD:$AD,H$3&"-"&$C6)=0,"",COUNTIF('ACCU AUD'!$AD:$AD,H$3&"-"&$C6)) | I6: =IF(COUNTIF('ACCU AUD'!$AD:$AD,I$3&"-"&$C6)=0,"",COUNTIF('ACCU AUD'!$AD:$AD,I$3&"-"&$C6)) | J6: =IF(COUNTIF('ACCU AUD'!$AD:$AD,J$3&"-"&$C6)=0,"",COUNTIF('ACCU AUD'!$AD:$AD,J$3&"-"&$C6)) | K6: =IF(COUNTIF('ACCU AUD'!$AD:$AD,K$3&"-"&$C6)=0,"",COUNTIF('ACCU AUD'!$AD:$AD,K$3&"-"&$C6)) | L6: =COUNTIF('ACCU AUD'!$AE:$AE,$C6)-SUM(E6:K6) | N6: =SUMIF('ACCU AUD'!AE:AE,C6,'ACCU AUD'!R:R) | O6: =N6/N$17
B7: Jiangxi Copper | C7: 0358 | D7: =SUM(E7:L7) | E7: =IF(COUNTIF('ACCU AUD'!$AD:$AD,E$3&"-"&$C7)=0,"",COUNTIF('ACCU AUD'!$AD:$AD,E$3&"-"&$C7)) | F7: =IF(COUNTIF('ACCU AUD'!$AD:$AD,F$3&"-"&$C7)=0,"",COUNTIF('ACCU AUD'!$AD:$AD,F$3&"-"&$C7)) | G7: =IF(COUNTIF('ACCU AUD'!$AD:$AD,G$3&"-"&$C7)=0,"",COUNTIF('ACCU AUD'!$AD:$AD,G$3&"-"&$C7)) | H7: =IF(COUNTIF('ACCU AUD'!$AD:$AD,H$3&"-"&$C7)=0,"",COUNTIF('ACCU AUD'!$AD:$AD,H$3&"-"&$C7)) | I7: =IF(COUNTIF('ACCU AUD'!$AD:$AD,I$3&"-"&$C7)=0,"",COUNTIF('ACCU AUD'!$AD:$AD,I$3&"-"&$C7)) | J7: =IF(COUNTIF('ACCU AUD'!$AD:$AD,J$3&"-"&$C7)=0,"",COUNTIF('ACCU AUD'!$AD:$AD,J$3&"-"&$C7)) | K7: =IF(COUNTIF('ACCU AUD'!$AD:$AD,K$3&"-"&$C7)=0,"",COUNTIF('ACCU AUD'!$AD:$AD,K$3&"-"&$C7)) | L7: =COUNTIF('ACCU AUD'!$AE:$AE,$C7)-SUM(E7:K7) | N7: =SUMIF('ACCU AUD'!AE:AE,C7,'ACCU AUD'!R:R) | O7: =N7/N$17
B8: Tencent | C8: 0700 | D8: =SUM(E8:L8) | E8: =IF(COUNTIF('ACCU AUD'!$AD:$AD,E$3&"-"&$C8)=0,"",COUNTIF('ACCU AUD'!$AD:$AD,E$3&"-"&$C8)) | F8: =IF(COUNTIF('ACCU AUD'!$AD:$AD,F$3&"-"&$C8)=0,"",COUNTIF('ACCU AUD'!$AD:$AD,F$3&"-"&$C8)) | G8: =IF(COUNTIF('ACCU AUD'!$AD:$AD,G$3&"-"&$C8)=0,"",COUNTIF('ACCU AUD'!$AD:$AD,G$3&"-"&$C8)) | H8: =IF(COUNTIF('ACCU AUD'!$AD:$AD,H$3&"-"&$C8)=0,"",COUNTIF('ACCU AUD'!$AD:$AD,H$3&"-"&$C8)) | I8: =IF(COUNTIF('ACCU AUD'!$AD:$AD,I$3&"-"&$C8)=0,"",COUNTIF('ACCU AUD'!$AD:$AD,I$3&"-"&$C8)) | J8: =IF(COUNTIF('ACCU AUD'!$AD:$AD,J$3&"-"&$C8)=0,"",COUNTIF('ACCU AUD'!$AD:$AD,J$3&"-"&$C8)) | K8: =IF(COUNTIF('ACCU AUD'!$AD:$AD,K$3&"-"&$C8)=0,"",COUNTIF('ACCU AUD'!$AD:$AD,K$3&"-"&$C8)) | L8: =COUNTIF('ACCU AUD'!$AE:$AE,$C8)-SUM(E8:K8) | N8: =SUMIF('ACCU AUD'!AE:AE,C8,'ACCU AUD'!R:R) | O8: =N8/N$17
B9: China Construction | C9: 0939 | D9: =SUM(E9:L9) | E9: =IF(COUNTIF('ACCU AUD'!$AD:$AD,E$3&"-"&$C9)=0,"",COUNTIF('ACCU AUD'!$AD:$AD,E$3&"-"&$C9)) | F9: =IF(COUNTIF('ACCU AUD'!$AD:$AD,F$3&"-"&$C9)=0,"",COUNTIF('ACCU AUD'!$AD:$AD,F$3&"-"&$C9)) | G9: =IF(COUNTIF('ACCU AUD'!$AD:$AD,G$3&"-"&$C9)=0,"",COUNTIF('ACCU AUD'!$AD:$AD,G$3&"-"&$C9)) | H9: =IF(COUNTIF('ACCU AUD'!$AD:$AD,H$3&"-"&$C9)=0,"",COUNTIF('ACCU AUD'!$AD:$AD,H$3&"-"&$C9)) | I9: =IF(COUNTIF('ACCU AUD'!$AD:$AD,I$3&"-"&$C9)=0,"",COUNTIF('ACCU AUD'!$AD:$AD,I$3&"-"&$C9)) | J9: =IF(COUNTIF('ACCU AUD'!$AD:$AD,J$3&"-"&$C9)=0,"",COUNTIF('ACCU AUD'!$AD:$AD,J$3&"-"&$C9)) | K9: =IF(COUNTIF('ACCU AUD'!$AD:$AD,K$3&"-"&$C9)=0,"",COUNTIF('ACCU AUD'!$AD:$AD,K$3&"-"&$C9)) | L9: =COUNTIF('ACCU AUD'!$AE:$AE,$C9)-SUM(E9:K9) | N9: =SUMIF('ACCU AUD'!AE:AE,C9,'ACCU AUD'!R:R) | O9: =N9/N$17
B10: BYD Company Limited | C10: 1211 | D10: =SUM(E10:L10) | E10: =IF(COUNTIF('ACCU AUD'!$AD:$AD,E$3&"-"&$C10)=0,"",COUNTIF('ACCU AUD'!$AD:$AD,E$3&"-"&$C10)) | F10: =IF(COUNTIF('ACCU AUD'!$AD:$AD,F$3&"-"&$C10)=0,"",COUNTIF('ACCU AUD'!$AD:$AD,F$3&"-"&$C10)) | G10: =IF(COUNTIF('ACCU AUD'!$AD:$AD,G$3&"-"&$C10)=0,"",COUNTIF('ACCU AUD'!$AD:$AD,G$3&"-"&$C10)) | H10: =IF(COUNTIF('ACCU AUD'!$AD:$AD,H$3&"-"&$C10)=0,"",COUNTIF('ACCU AUD'!$AD:$AD,H$3&"-"&$C10)) | I10: =IF(COUNTIF('ACCU AUD'!$AD:$AD,I$3&"-"&$C10)=0,"",COUNTIF('ACCU AUD'!$AD:$AD,I$3&"-"&$C10)) | J10: =IF(COUNTIF('ACCU AUD'!$AD:$AD,J$3&"-"&$C10)=0,"",COUNTIF('ACCU AUD'!$AD:$AD,J$3&"-"&$C10)) | K10: =IF(COUNTIF('ACCU AUD'!$AD:$AD,K$3&"-"&$C10)=0,"",COUNTIF('ACCU AUD'!$AD:$AD,K$3&"-"&$C10)) | L10: =COUNTIF('ACCU AUD'!$AE:$AE,$C10)-SUM(E10:K10) | N10: =SUMIF('ACCU AUD'!AE:AE,C10,'ACCU AUD'!R:R) | O10: =N10/N$17
B11: Agricultural Bank of China | C11: 1288 | D11: =SUM(E11:L11) | E11: =IF(COUNTIF('ACCU AUD'!$AD:$AD,E$3&"-"&$C11)=0,"",COUNTIF('ACCU AUD'!$AD:$AD,E$3&"-"&$C11)) | F11: =IF(COUNTIF('ACCU AUD'!$AD:$AD,F$3&"-"&$C11)=0,"",COUNTIF('ACCU AUD'!$AD:$AD,F$3&"-"&$C11)) | G11: =IF(COUNTIF('ACCU AUD'!$AD:$AD,G$3&"-"&$C11)=0,"",COUNTIF('ACCU AUD'!$AD:$AD,G$3&"-"&$C11)) | H11: =IF(COUNTIF('ACCU AUD'!$AD:$AD,H$3&"-"&$C11)=0,"",COUNTIF('ACCU AUD'!$AD:$AD,H$3&"-"&$C11)) | I11: =IF(COUNTIF('ACCU AUD'!$AD:$AD,I$3&"-"&$C11)=0,"",COUNTIF('ACCU AUD'!$AD:$AD,I$3&"-"&$C11)) | J11: =IF(COUNTIF('ACCU AUD'!$AD:$AD,J$3&"-"&$C11)=0,"",COUNTIF('ACCU AUD'!$AD:$AD,J$3&"-"&$C11)) | K11: =IF(COUNTIF('ACCU AUD'!$AD:$AD,K$3&"-"&$C11)=0,"",COUNTIF('ACCU AUD'!$AD:$AD,K$3&"-"&$C11)) | L11: =COUNTIF('ACCU AUD'!$AE:$AE,$C11)-SUM(E11:K11) | N11: =SUMIF('ACCU AUD'!AE:AE,C11,'ACCU AUD'!R:R) | O11: =N11/N$17
B12: Great Wall Motor | C12: 2333 | D12: =SUM(E12:L12) | E12: =IF(COUNTIF('ACCU AUD'!$AD:$AD,E$3&"-"&$C12)=0,"",COUNTIF('ACCU AUD'!$AD:$AD,E$3&"-"&$C12)) | F12: =IF(COUNTIF('ACCU AUD'!$AD:$AD,F$3&"-"&$C12)=0,"",COUNTIF('ACCU AUD'!$AD:$AD,F$3&"-"&$C12)) | G12: =IF(COUNTIF('ACCU AUD'!$AD:$AD,G$3&"-"&$C12)=0,"",COUNTIF('ACCU AUD'!$AD:$AD,G$3&"-"&$C12)) | H12: =IF(COUNTIF('ACCU AUD'!$AD:$AD,H$3&"-"&$C12)=0,"",COUNTIF('ACCU AUD'!$AD:$AD,H$3&"-"&$C12)) | I12: =IF(COUNTIF('ACCU AUD'!$AD:$AD,I$3&"-"&$C12)=0,"",COUNTIF('ACCU AUD'!$AD:$AD,I$3&"-"&$C12)) | J12: =IF(COUNTIF('ACCU AUD'!$AD:$AD,J$3&"-"&$C12)=0,"",COUNTIF('ACCU AUD'!$AD:$AD,J$3&"-"&$C12)) | K12: =IF(COUNTIF('ACCU AUD'!$AD:$AD,K$3&"-"&$C12)=0,"",COUNTIF('ACCU AUD'!$AD:$AD,K$3&"-"&$C12)) | L12: =COUNTIF('ACCU AUD'!$AE:$AE,$C12)-SUM(E12:K12) | N12: =SUMIF('ACCU AUD'!AE:AE,C12,'ACCU AUD'!R:R) | O12: =N12/N$17
B13: Zijin Mining | C13: 2899 | D13: =SUM(E13:L13) | E13: =IF(COUNTIF('ACCU AUD'!$AD:$AD,E$3&"-"&$C13)=0,"",COUNTIF('ACCU AUD'!$AD:$AD,E$3&"-"&$C13)) | F13: =IF(COUNTIF('ACCU AUD'!$AD:$AD,F$3&"-"&$C13)=0,"",COUNTIF('ACCU AUD'!$AD:$AD,F$3&"-"&$C13)) | G13: =IF(COUNTIF('ACCU AUD'!$AD:$AD,G$3&"-"&$C13)=0,"",COUNTIF('ACCU AUD'!$AD:$AD,G$3&"-"&$C13)) | H13: =IF(COUNTIF('ACCU AUD'!$AD:$AD,H$3&"-"&$C13)=0,"",COUNTIF('ACCU AUD'!$AD:$AD,H$3&"-"&$C13)) | I13: =IF(COUNTIF('ACCU AUD'!$AD:$AD,I$3&"-"&$C13)=0,"",COUNTIF('ACCU AUD'!$AD:$AD,I$3&"-"&$C13)) | J13: =IF(COUNTIF('ACCU AUD'!$AD:$AD,J$3&"-"&$C13)=0,"",COUNTIF('ACCU AUD'!$AD:$AD,J$3&"-"&$C13)) | K13: =IF(COUNTIF('ACCU AUD'!$AD:$AD,K$3&"-"&$C13)=0,"",COUNTIF('ACCU AUD'!$AD:$AD,K$3&"-"&$C13)) | L13: =COUNTIF('ACCU AUD'!$AE:$AE,$C13)-SUM(E13:K13) | N13: =SUMIF('ACCU AUD'!AE:AE,C13,'ACCU AUD'!R:R) | O13: =N13/N$17
B14: Bank of China | C14: 3988 | D14: =SUM(E14:L14) | E14: =IF(COUNTIF('ACCU AUD'!$AD:$AD,E$3&"-"&$C14)=0,"",COUNTIF('ACCU AUD'!$AD:$AD,E$3&"-"&$C14)) | F14: =IF(COUNTIF('ACCU AUD'!$AD:$AD,F$3&"-"&$C14)=0,"",COUNTIF('ACCU AUD'!$AD:$AD,F$3&"-"&$C14)) | G14: =IF(COUNTIF('ACCU AUD'!$AD:$AD,G$3&"-"&$C14)=0,"",COUNTIF('ACCU AUD'!$AD:$AD,G$3&"-"&$C14)) | H14: =IF(COUNTIF('ACCU AUD'!$AD:$AD,H$3&"-"&$C14)=0,"",COUNTIF('ACCU AUD'!$AD:$AD,H$3&"-"&$C14)) | I14: =IF(COUNTIF('ACCU AUD'!$AD:$AD,I$3&"-"&$C14)=0,"",COUNTIF('ACCU AUD'!$AD:$AD,I$3&"-"&$C14)) | J14: =IF(COUNTIF('ACCU AUD'!$AD:$AD,J$3&"-"&$C14)=0,"",COUNTIF('ACCU AUD'!$AD:$AD,J$3&"-"&$C14)) | K14: =IF(COUNTIF('ACCU AUD'!$AD:$AD,K$3&"-"&$C14)=0,"",COUNTIF('ACCU AUD'!$AD:$AD,K$3&"-"&$C14)) | L14: =COUNTIF('ACCU AUD'!$AE:$AE,$C14)-SUM(E14:K14) | N14: =SUMIF('ACCU AUD'!AE:AE,C14,'ACCU AUD'!R:R) | O14: =N14/N$17
B15: China Molybdenum | C15: 3993 | D15: =SUM(E15:L15) | E15: =IF(COUNTIF('ACCU AUD'!$AD:$AD,E$3&"-"&$C15)=0,"",COUNTIF('ACCU AUD'!$AD:$AD,E$3&"-"&$C15)) | F15: =IF(COUNTIF('ACCU AUD'!$AD:$AD,F$3&"-"&$C15)=0,"",COUNTIF('ACCU AUD'!$AD:$AD,F$3&"-"&$C15)) | G15: =IF(COUNTIF('ACCU AUD'!$AD:$AD,G$3&"-"&$C15)=0,"",COUNTIF('ACCU AUD'!$AD:$AD,G$3&"-"&$C15)) | H15: =IF(COUNTIF('ACCU AUD'!$AD:$AD,H$3&"-"&$C15)=0,"",COUNTIF('ACCU AUD'!$AD:$AD,H$3&"-"&$C15)) | I15: =IF(COUNTIF('ACCU AUD'!$AD:$AD,I$3&"-"&$C15)=0,"",COUNTIF('ACCU AUD'!$AD:$AD,I$3&"-"&$C15)) | J15: =IF(COUNTIF('ACCU AUD'!$AD:$AD,J$3&"-"&$C15)=0,"",COUNTIF('ACCU AUD'!$AD:$AD,J$3&"-"&$C15)) | K15: =IF(COUNTIF('ACCU AUD'!$AD:$AD,K$3&"-"&$C15)=0,"",COUNTIF('ACCU AUD'!$AD:$AD,K$3&"-"&$C15)) | L15: =COUNTIF('ACCU AUD'!$AE:$AE,$C15)-SUM(E15:K15) | N15: =SUMIF('ACCU AUD'!AE:AE,C15,'ACCU AUD'!R:R) | O15: =N15/N$17
B16: Citic Securities | C16: 6030 | D16: =SUM(E16:L16) | E16: =IF(COUNTIF('ACCU AUD'!$AD:$AD,E$3&"-"&$C16)=0,"",COUNTIF('ACCU AUD'!$AD:$AD,E$3&"-"&$C16)) | F16: =IF(COUNTIF('ACCU AUD'!$AD:$AD,F$3&"-"&$C16)=0,"",COUNTIF('ACCU AUD'!$AD:$AD,F$3&"-"&$C16)) | G16: =IF(COUNTIF('ACCU AUD'!$AD:$AD,G$3&"-"&$C16)=0,"",COUNTIF('ACCU AUD'!$AD:$AD,G$3&"-"&$C16)) | H16: =IF(COUNTIF('ACCU AUD'!$AD:$AD,H$3&"-"&$C16)=0,"",COUNTIF('ACCU AUD'!$AD:$AD,H$3&"-"&$C16)) | I16: =IF(COUNTIF('ACCU AUD'!$AD:$AD,I$3&"-"&$C16)=0,"",COUNTIF('ACCU AUD'!$AD:$AD,I$3&"-"&$C16)) | J16: =IF(COUNTIF('ACCU AUD'!$AD:$AD,J$3&"-"&$C16)=0,"",COUNTIF('ACCU AUD'!$AD:$AD,J$3&"-"&$C16)) | K16: =IF(COUNTIF('ACCU AUD'!$AD:$AD,K$3&"-"&$C16)=0,"",COUNTIF('ACCU AUD'!$AD:$AD,K$3&"-"&$C16)) | L16: =COUNTIF('ACCU AUD'!$AE:$AE,$C16)-SUM(E16:K16) | N16: =SUMIF('ACCU AUD'!AE:AE,C16,'ACCU AUD'!R:R) | O16: =N16/N$17
C17: TOTAL: | D17: =SUM(D4:D16) | E17: =SUM(E4:E16) | F17: =SUM(F4:F16) | G17: =SUM(G4:G16) | H17: =SUM(H4:H16) | I17: =SUM(I4:I16) | J17: =SUM(J4:J16) | K17: =SUM(K4:K16) | L17: =SUM(L4:L16) | N17: =SUM(N4:N16) | O17: =N17/N$17
B19: DECUMULATORS | F19: =F1
B20: AU Stock | C20: Code | D20: Total | E20: =E$2 | F20: =F$2 | G20: =G$2 | H20: =H$2 | I20: =I$2 | J20: =J$2 | K20: =K$2 | L20: =L$2 | N20: Estimated Amount | O20: %
B21: Rio Tinto | C21: RIO | D21: =SUM(E21:L21) | E21: =IF(COUNTIF('DECU AUD'!$AD:$AD,E$3&"-"&$C21)=0,"",COUNTIF('DECU AUD'!$AD:$AD,E$3&"-"&$C21)) | F21: =IF(COUNTIF('DECU AUD'!$AD:$AD,F$3&"-"&$C21)=0,"",COUNTIF('DECU AUD'!$AD:$AD,F$3&"-"&$C21)) | G21: =IF(COUNTIF('DECU AUD'!$AD:$AD,G$3&"-"&$C21)=0,"",COUNTIF('DECU AUD'!$AD:$AD,G$3&"-"&$C21)) | H21: =IF(COUNTIF('DECU AUD'!$AD:$AD,H$3&"-"&$C21)=0,"",COUNTIF('DECU AUD'!$AD:$AD,H$3&"-"&$C21)) | I21: =IF(COUNTIF('DECU AUD'!$AD:$AD,I$3&"-"&$C21)=0,"",COUNTIF('DECU AUD'!$AD:$AD,I$3&"-"&$C21)) | J21: =IF(COUNTIF('DECU AUD'!$AD:$AD,J$3&"-"&$C21)=0,"",COUNTIF('DECU AUD'!$AD:$AD,J$3&"-"&$C21)) | K21: =IF(COUNTIF('DECU AUD'!$AD:$AD,K$3&"-"&$C21)=0,"",COUNTIF('DECU AUD'!$AD:$AD,K$3&"-"&$C21)) | L21: =COUNTIF('DECU AUD'!$AE:$AE,$C21)-SUM(E21:K21) | N21: =SUMIF('DECU AUD'!AE:AE,C21,'DECU AUD'!R:R) | O21: =N21/$N$22
C22: TOTAL: | D22: =SUM(D21:D21) | E22: =SUM(E21:E21) | F22: =SUM(F21:F21) | G22: =SUM(G21:G21) | H22: =SUM(H21:H21) | I22: =SUM(I21:I21) | J22: =SUM(J21:J21) | K22: =SUM(K21:K21) | L22: =SUM(L21:L21) | N22: =SUM(N21:N21) | O22: =N22/N$22
B24: JP Stock | C24: Code | D24: Total | E24: =E$2 | F24: =F$2 | G24: =G$2 | H24: =H$2 | I24: =I$2 | J24: =J$2 | K24: =K$2 | L24: =L$2
B25: Nomura | C25: 8604 | D25: =SUM(E25:L25) | L25: 0
C26: TOTAL: | D26: =SUM(D25:D25) | E26: =SUM(E25:E25) | F26: =SUM(F25:F25) | G26: =SUM(G25:G25) | H26: =SUM(H25:H25) | I26: =SUM(I25:I25) | J26: =SUM(J25:J25) | K26: =SUM(K25:K25) | L26: =SUM(L25:L25)
B29: US Stock | C29: Code | D29: Total | E29: =E$2 | F29: =F$2 | G29: =G$2 | H29: =H$2 | I29: =I$2 | J29: =J$2 | K29: =K$2 | L29: =L$2
B30: General Electric | C30: GE | D30: =SUM(E30:L30) | L30: 0
C31: TOTAL: | D31: =SUM(D30:D30) | E31: =SUM(E30:E30) | F31: =SUM(F30:F30) | G31: =SUM(G30:G30) | H31: =SUM(H30:H30) | I31: =SUM(I30:I30) | J31: =SUM(J30:J30) | K31: =SUM(K30:K30) | L31: =SUM(L30:L30)

Sheet ACCU AUD
A1: =SUM(A10) | B1: =ALLHKD!C1 | H1: ACCUMULATORS | N1: For the Whole Structure
A3: MORGAN STANLEY (Perfect Legend w/ Lucio)
B5: ACCUMULATOR | C5: CODE | E5: SHARES / DAY | H5: SPOT PRICE | I5: STRIKE PRICE | J5: K/O PRICE | K5: LIFE TERM OF CONTRACT | N5: START DATE | O5: END DATE | Q5: Estimated Total Shares Remaining | R5: Estimated Amount | T5: Estimated Amount per month | Y5: Month 1 | Z5: Month 2
D6: CB1 | K6: RCVD DAYS | L6: REM DAYS | M6: Total DAYS | V6: NOW | W6: NEXT | X6: sd | Y6: hkd | Z6: hkd
A7: =INDIRECT(ADDRESS(ROW()-1,COLUMN()))+1 | B7: Rio Tinto | C7: RIO | D7: GREATWALL - 26 | E7: 81 | F7: / | G7: =E7*2 | H7: 103.7708 | I7: 89.8967 | J7: 108.9594 | K7: 108 | L7: =M7-K7 | M7: 255 | N7: 43615 | O7: 43980 | Q7: =E7*L7*X7 | R7: =E7*I7*L7*X7 | T7: =E7*I7*20*X7 | V7: 23 | W7: 42 | X7: 1 | Y7: =X7*V7*E7*I7 | Z7: =X7*W7*E7*I7 | AB7: =MONTH(O7) | AC7: =YEAR(O7) | AD7: =AB7&"-"&AC7&"-"&C7 | AE7: =C7 | AF7: =MATCH(AE7,#REF!,)
A8: =INDIRECT(ADDRESS(ROW()-1,COLUMN()))+1 | B8: Rio Tinto | C8: RIO | D8: JIANGXI - 40 | E8: 61 | F8: / | G8: =E8*2 | H8: 101.6371 | I8: 87.5502 | J8: 106.7189 | K8: 88 | L8: =M8-K8 | M8: 255 | N8: 43629 | O8: 43994 | Q8: =E8*L8*X8 | R8: =E8*I8*L8*X8 | T8: =E8*I8*20*X8 | V8: 21 | W8: 43 | X8: 1 | Y8: =X8*V8*E8*I8 | Z8: =X8*W8*E8*I8 | AB8: =MONTH(O8) | AC8: =YEAR(O8) | AD8: =AB8&"-"&AC8&"-"&C8 | AE8: =C8 | AF8: =MATCH(AE8,#REF!,)
A9: =INDIRECT(ADDRESS(ROW()-1,COLUMN()))+1 | B9: Rio Tinto | C9: RIO | D9: JIANGXI - 40 | E9: 101 | F9: / | G9: =E9*2 | H9: 103.5853 | I9: 88.7623 | J9: 108.7646 | K9: 66 | L9: =M9-K9 | M9: 254 | N9: 43654 | O9: 44018 | Q9: =E9*L9*X9 | R9: =E9*I9*L9*X9 | T9: =E9*I9*20*X9 | V9: 21 | W9: 43 | X9: 1 | Y9: =X9*V9*E9*I9 | Z9: =X9*W9*E9*I9 | AB9: =MONTH(O9) | AC9: =YEAR(O9) | AD9: =AB9&"-"&AC9&"-"&C9 | AE9: =C9 | AF9: =MATCH(AE9,#REF!,)
A10: =INDIRECT(ADDRESS(ROW()-1,COLUMN()))+1 | B10: Rio Tinto | C10: RIO | D10: JIANGXI - 40 | E10: 121 | F10: / | G10: =E10*2 | H10: 103.3905 | I10: 87.7475 | J10: 108.5601 | K10: 66 | L10: =M10-K10 | M10: 255 | N10: 43656 | O10: 44021 | Q10: =E10*L10*X10 | R10: =E10*I10*L10*X10 | T10: =E10*I10*20*X10 | V10: 23 | W10: 43 | X10: 1 | Y10: =X10*V10*E10*I10 | Z10: =X10*W10*E10*I10 | AB10: =MONTH(O10) | AC10: =YEAR(O10) | AD10: =AB10&"-"&AC10&"-"&C10 | AE10: =C10 | AF10: =MATCH(AE10,#REF!,)
O12: Total | Q12: =SUM(Q6:Q11) | R12: =SUM(R6:R11) | T12: =SUM(T6:T11)
R13: AUD | T13: AUD
N15: RATE | O15: 1.44
R16: AUD | T16: USD
N17: =ACCU!N178 | R17: =R12-Y17 | T17: =R17/O15 | Y17: =SUM(Y6:Y16) | Z17: =SUM(Z6:Z16)
N18: =ACCU!N179 | R18: =R12-Z17 | T18: =R18/O15
N19: Remaining End of August 2019 | R19: =R18-T12 | T19: =R19/O15

Sheet DECU AUD
A1: =SUM(A9) | B1: =ALLHKD!C1 | H1: DECUMULATORS | N1: For the Whole Structure
A3: MORGAN STANLEY (Perfect Legend w/ Lucio)
B5: DECUMULATOR | C5: CODE | E5: SHARES / DAY | H5: SPOT PRICE | I5: STRIKE PRICE | J5: K/O PRICE | K5: LIFE TERM OF CONTRACT | N5: START DATE | O5: END DATE | Q5: Estimated Total Shares Remaining | R5: Estimated Amount | T5: Estimated Amount per month | Y5: Month 1 | Z5: Month 2
D6: CB1 | K6: RCVD DAYS | L6: REM DAYS | M6: Total DAYS | V6: NOW | W6: NEXT | X6: sd | Y6: hkd | Z6: hkd
A7: =INDIRECT(ADDRESS(ROW()-1,COLUMN()))+1 | B7: Rio Tinto | C7: RIO | D7: GREATWALL - 26 | E7: 150 | F7: / | G7: =E7*2 | H7: 85.2381 | I7: 95.0661 | J7: 80.9762 | K7: 45 | L7: =M7-K7 | M7: 190 | N7: 43690 | O7: 43963 | Q7: =E7*L7*X7 | R7: =E7*I7*L7*X7 | T7: =E7*I7*20*X7 | V7: 21 | W7: 43 | X7: 1 | Y7: =X7*V7*E7*I7 | Z7: =X7*W7*E7*I7 | AB7: =MONTH(O7) | AC7: =YEAR(O7) | AD7: =AB7&"-"&AC7&"-"&C7 | AE7: =C7 | AF7: =MATCH(AE7,#REF!,)
