Workbook
Name Average: [1]Equities!$D:$D
Name BLOCKED: [1]Equities!$I:$I
Name UNBLOCKED: [1]Equities!$H:$H

Sheet 1
A1: Short Stock Summary
A2: =ALL!A1 -> As of September 20, 2022
L3: Ex-Date | M3: 44749
L4: Dividends | M4: RMB 0.2068
A5: 1 | B5: =INDEX(Stocks!A:B,MATCH(P6,Stocks!A:A,),2)&" ("&P6&")" -> Agricultural Bank of China (1288:HK) | G5: Market Price | L5: Pay-out Date | M5: 44778
C6: Account | D6: Shares | E6: Ave. Cost | F6: Amount | H6: Sell Qty | I6: Amount HKD | J6: =IF(COUNTIF(J7:J18,">0")<>0,IF(COUNTIF(J7:J18,"<0")<>0,"Gain / Loss", "Gain"),"Loss") -> Loss | K6: ="% "&IF(COUNTIF(K7:K18,">=0")<>0,IF(COUNTIF(K7:K18,"<0")<>0,"Gain / Loss", "Gain"),"Loss") -> % Loss | P6: 1288:HK
C7: Citibank Singapore A/C No. 1 | D7: =SUMIF(Download!B:B,Q7,Download!G:G) -> 0 | E7: =SUMIF(Download!B:B,Q7,Download!H:H) -> 0 | F7: =D7*E7 -> 0 | H7: 100000 | I7: =H7*H5 -> 0 | J7: =(H5-E7)*H7 -> 0 | K7: =(H5/E7)-1 -> #DIV/0! | O7: CBSG | P7: =P6 -> 1288:HK | Q7: =O7&P7 -> CBSG1288:HK
C8: Citibank Account No. 2 | D8: =SUMIF(Download!B:B,Q8,Download!G:G) -> 0 | E8: =SUMIF(Download!B:B,Q8,Download!H:H) -> 0 | F8: =D8*E8 -> 0 | H8: =H7 -> 100000 | I8: =H8*H5 -> 0 | J8: =(H5-E8)*H8 -> 0 | K8: =(H5/E8)-1 -> #DIV/0! | O8: CB2 | P8: =P7 -> 1288:HK | Q8: =O8&P8 -> CB21288:HK
C9: Citibank Account No. 3 | D9: =SUMIF(Download!B:B,Q9,Download!G:G) -> 0 | E9: =SUMIF(Download!B:B,Q9,Download!H:H) -> 0 | F9: =D9*E9 -> 0 | H9: =H8 -> 100000 | I9: =H9*H5 -> 0 | J9: =(H5-E9)*H9 -> 0 | K9: =(H5/E9)-1 -> #DIV/0! | O9: CB3 | P9: =P7 -> 1288:HK | Q9: =O9&P9 -> CB31288:HK
C10: Citibank Berry Hill | D10: =SUMIF(Download!B:B,Q10,Download!G:G) -> 0 | E10: =SUMIF(Download!B:B,Q10,Download!H:H) -> 0 | F10: =D10*E10 -> 0 | H10: =H9 -> 100000 | I10: =H10*H5 -> 0 | J10: =(H5-E10)*H10 -> 0 | K10: =(H5/E10)-1 -> #DIV/0! | O10: CBBH | P10: =P8 -> 1288:HK | Q10: =O10&P10 -> CBBH1288:HK
C11: Bank of Singapore | D11: =SUMIF(Download!B:B,Q11,Download!G:G) -> 0 | E11: =SUMIF(Download!B:B,Q11,Download!H:H) -> 0 | F11: =D11*E11 -> 0 | H11: =H10 -> 100000 | I11: =H11*H5 -> 0 | J11: =(H5-E11)*H11 -> 0 | K11: =(H5/E11)-1 -> #DIV/0! | O11: BOS | P11: =P10 -> 1288:HK | Q11: =O11&P11 -> BOS1288:HK
C12: Deutsche Bank Personal | D12: =SUMIF(Download!B:B,Q12,Download!G:G) -> 0 | E12: =SUMIF(Download!B:B,Q12,Download!H:H) -> 0 | F12: =D12*E12 -> 0 | H12: =H11 -> 100000 | I12: =H12*H5 -> 0 | J12: =(H5-E12)*H12 -> 0 | K12: =(H5/E12)-1 -> #DIV/0! | O12: DBPe | P12: =P11 -> 1288:HK | Q12: =O12&P12 -> DBPe1288:HK
C13: Deutsche Bank Perfect Legend | D13: =SUMIF(Download!B:B,Q13,Download!G:G) -> 0 | E13: =SUMIF(Download!B:B,Q13,Download!H:H) -> 0 | F13: =D13*E13 -> 0 | H13: =H12 -> 100000 | I13: =H13*H5 -> 0 | J13: =(H5-E13)*H13 -> 0 | K13: =(H5/E13)-1 -> #DIV/0! | O13: DBPL | P13: =P12 -> 1288:HK | Q13: =O13&P13 -> DBPL1288:HK
C14: Standard Chartered Bank | D14: =SUMIF(Download!B:B,Q14,Download!G:G) -> 0 | E14: =SUMIF(Download!B:B,Q14,Download!H:H) -> 0 | F14: =D14*E14 -> 0 | H14: =H13 -> 100000 | I14: =H14*H5 -> 0 | J14: =(H5-E14)*H14 -> 0 | K14: =(H5/E14)-1 -> #DIV/0! | O14: SC | P14: =P13 -> 1288:HK | Q14: =O14&P14 -> SC1288:HK
C15: Sun Hung Kai | D15: =SUMIF(Download!B:B,Q15,Download!G:G) -> 0 | E15: =SUMIF(Download!B:B,Q15,Download!H:H) -> 0 | F15: =D15*E15 -> 0 | H15: =H14 -> 100000 | I15: =H15*H5 -> 0 | J15: =(H5-E15)*H15 -> 0 | K15: =(H5/E15)-1 -> #DIV/0! | O15: SHK | P15: =P14 -> 1288:HK | Q15: =O15&P15 -> SHK1288:HK
C16: Morgan Stanley Titan No. 1 | D16: =SUMIF(Download!B:B,Q16,Download!G:G) -> 0 | E16: =SUMIF(Download!B:B,Q16,Download!H:H) -> 0 | F16: =D16*E16 -> 0 | H16: =H15 -> 100000 | I16: =H16*H5 -> 0 | J16: =(H5-E16)*H16 -> 0 | K16: =(H5/E16)-1 -> #DIV/0! | O16: MST1 | P16: =P15 -> 1288:HK | Q16: =O16&P16 -> MST11288:HK
C17: Morgan Stanley Titan No. 2 | D17: =SUMIF(Download!B:B,Q17,Download!G:G) -> 0 | E17: =SUMIF(Download!B:B,Q17,Download!H:H) -> 0 | F17: =D17*E17 -> 0 | H17: =H16 -> 100000 | I17: =H17*H5 -> 0 | J17: =(H5-E17)*H17 -> 0 | K17: =(H5/E17)-1 -> #DIV/0! | L17: with Decu Strike 2.6905 | O17: MST2 | P17: =P16 -> 1288:HK | Q17: =O17&P17 -> MST21288:HK
C18: Morgan Stanley Perfect Legend | D18: =SUMIF(Download!B:B,Q18,Download!G:G) -> 0 | E18: =SUMIF(Download!B:B,Q18,Download!H:H) -> 0 | F18: =D18*E18 -> 0 | H18: =H17 -> 100000 | I18: =H18*H5 -> 0 | J18: =(H5-E18)*H18 -> 0 | K18: =(H5/E18)-1 -> #DIV/0! | O18: MSPL | P18: =P17 -> 1288:HK | Q18: =O18&P18 -> MSPL1288:HK
C20: Total | D20: =SUM(D6:D19) -> 0 | E20: =F20/D20 -> #DIV/0! | F20: =SUM(F6:F19) -> 0
L21: Ex-Date | M21: 44749
L22: Dividends | M22: RMB 0.2210
A23: 2 | B23: =INDEX(Stocks!A:B,MATCH(P24,Stocks!A:A,),2)&" ("&P24&")" -> Bank of China (3988:HK) | G23: Market Price | L23: Pay-out Date | M23: 44783
C24: Account | D24: Shares | E24: Ave. Cost | F24: Amount | H24: Sell Qty | I24: Amount HKD | J24: =IF(COUNTIF(J25:J36,">0")<>0,IF(COUNTIF(J25:J36,"<0")<>0,"Gain / Loss", "Gain"),"Loss") -> Loss | K24: ="% "&IF(COUNTIF(K25:K36,">=0")<>0,IF(COUNTIF(K25:K36,"<0")<>0,"Gain / Loss", "Gain"),"Loss") -> % Loss | P24: 3988:HK
C25: Citibank Singapore A/C No. 1 | D25: =SUMIF(Download!B:B,Q25,Download!G:G) -> 0 | E25: =SUMIF(Download!B:B,Q25,Download!H:H) -> 0 | F25: =D25*E25 -> 0 | H25: 100000 | I25: =H25*H23 -> 0 | J25: =(H23-E25)*H25 -> 0 | K25: =(H23/E25)-1 -> #DIV/0! | O25: CBSG | P25: =P24 -> 3988:HK | Q25: =O25&P25 -> CBSG3988:HK
C26: Citibank Account No. 2 | D26: =SUMIF(Download!B:B,Q26,Download!G:G) -> 0 | E26: =SUMIF(Download!B:B,Q26,Download!H:H) -> 0 | F26: =D26*E26 -> 0 | H26: =H25 -> 100000 | I26: =H26*H23 -> 0 | J26: =(H23-E26)*H26 -> 0 | K26: =(H23/E26)-1 -> #DIV/0! | O26: CB2 | P26: =P25 -> 3988:HK | Q26: =O26&P26 -> CB23988:HK
C27: Citibank Account No. 3 | D27: =SUMIF(Download!B:B,Q27,Download!G:G) -> 0 | E27: =SUMIF(Download!B:B,Q27,Download!H:H) -> 0 | F27: =D27*E27 -> 0 | H27: =H26 -> 100000 | I27: =H27*H23 -> 0 | J27: =(H23-E27)*H27 -> 0 | K27: =(H23/E27)-1 -> #DIV/0! | O27: CB3 | P27: =P26 -> 3988:HK | Q27: =O27&P27 -> CB33988:HK
C28: Citibank Berry Hill | D28: =SUMIF(Download!B:B,Q28,Download!G:G) -> 0 | E28: =SUMIF(Download!B:B,Q28,Download!H:H) -> 0 | F28: =D28*E28 -> 0 | H28: =H27 -> 100000 | I28: =H28*H23 -> 0 | J28: =(H23-E28)*H28 -> 0 | K28: =(H23/E28)-1 -> #DIV/0! | O28: CBBH | P28: =P26 -> 3988:HK | Q28: =O28&P28 -> CBBH3988:HK
C29: Bank of Singapore | D29: =SUMIF(Download!B:B,Q29,Download!G:G) -> 0 | E29: =SUMIF(Download!B:B,Q29,Download!H:H) -> 0 | F29: =D29*E29 -> 0 | H29: =H28 -> 100000 | I29: =H29*H23 -> 0 | J29: =(H23-E29)*H29 -> 0 | K29: =(H23/E29)-1 -> #DIV/0! | L29: with Decu Strike 2.9932 | O29: BOS | P29: =P28 -> 3988:HK | Q29: =O29&P29 -> BOS3988:HK
C30: Deutsche Bank Personal | D30: =SUMIF(Download!B:B,Q30,Download!G:G) -> 0 | E30: =SUMIF(Download!B:B,Q30,Download!H:H) -> 0 | F30: =D30*E30 -> 0 | H30: =H29 -> 100000 | I30: =H30*H23 -> 0 | J30: =(H23-E30)*H30 -> 0 | K30: =(H23/E30)-1 -> #DIV/0! | L30: with Decu Strike 2.9154 | O30: DBPe | P30: =P29 -> 3988:HK | Q30: =O30&P30 -> DBPe3988:HK
C31: Deutsche Bank Perfect Legend | D31: =SUMIF(Download!B:B,Q31,Download!G:G) -> 0 | E31: =SUMIF(Download!B:B,Q31,Download!H:H) -> 0 | F31: =D31*E31 -> 0 | H31: =H30 -> 100000 | I31: =H31*H23 -> 0 | J31: =(H23-E31)*H31 -> 0 | K31: =(H23/E31)-1 -> #DIV/0! | O31: DBPL | P31: =P30 -> 3988:HK | Q31: =O31&P31 -> DBPL3988:HK
C32: Standard Chartered Bank | D32: =SUMIF(Download!B:B,Q32,Download!G:G) -> 0 | E32: =SUMIF(Download!B:B,Q32,Download!H:H) -> 0 | F32: =D32*E32 -> 0 | H32: =H31 -> 100000 | I32: =H32*H23 -> 0 | J32: =(H23-E32)*H32 -> 0 | K32: =(H23/E32)-1 -> #DIV/0! | O32: SC | P32: =P31 -> 3988:HK | Q32: =O32&P32 -> SC3988:HK
C33: Sun Hung Kai | D33: =SUMIF(Download!B:B,Q33,Download!G:G) -> 0 | E33: =SUMIF(Download!B:B,Q33,Download!H:H) -> 0 | F33: =D33*E33 -> 0 | H33: =H32 -> 100000 | I33: =H33*H23 -> 0 | J33: =(H23-E33)*H33 -> 0 | K33: =(H23/E33)-1 -> #DIV/0! | O33: SHK | P33: =P32 -> 3988:HK | Q33: =O33&P33 -> SHK3988:HK
C34: Morgan Stanley Titan No. 1 | D34: =SUMIF(Download!B:B,Q34,Download!G:G) -> 0 | E34: =SUMIF(Download!B:B,Q34,Download!H:H) -> 0 | F34: =D34*E34 -> 0 | H34: =H33 -> 100000 | I34: =H34*H23 -> 0 | J34: =(H23-E34)*H34 -> 0 | K34: =(H23/E34)-1 -> #DIV/0! | L34: with Decu Strike 2.9066 | O34: MST1 | P34: =P33 -> 3988:HK | Q34: =O34&P34 -> MST13988:HK
C35: Morgan Stanley Titan No. 2 | D35: =SUMIF(Download!B:B,Q35,Download!G:G) -> 0 | E35: =SUMIF(Download!B:B,Q35,Download!H:H) -> 0 | F35: =D35*E35 -> 0 | H35: =H34 -> 100000 | I35: =H35*H23 -> 0 | J35: =(H23-E35)*H35 -> 0 | K35: =(H23/E35)-1 -> #DIV/0! | O35: MST2 | P35: =P34 -> 3988:HK | Q35: =O35&P35 -> MST23988:HK
C36: Morgan Stanley Perfect Legend | D36: =SUMIF(Download!B:B,Q36,Download!G:G) -> 0 | E36: =SUMIF(Download!B:B,Q36,Download!H:H) -> 0 | F36: =D36*E36 -> 0 | H36: =H35 -> 100000 | I36: =H36*H23 -> 0 | J36: =(H23-E36)*H36 -> 0 | K36: =(H23/E36)-1 -> #DIV/0! | L36: with Decu Strike 2.9681 | O36: MSPL | P36: =P35 -> 3988:HK | Q36: =O36&P36 -> MSPL3988:HK
C38: Total | D38: =SUM(D23:D37) -> 0 | E38: =F38/D38 -> #DIV/0! | F38: =SUM(F23:F37) -> 0
K41: 1 | L41: Ex-Date | M41: 44630
L42: Dividends | M42: USD 0.18
L43: Pay-out Date | M43: 44679
K44: 2 | L44: Ex-Date | M44: 44791
...

Sheet 2
A1: Short Stock Summary
A2: =ALL!A1 -> As of September 20, 2022
K4: 1 | L4: Ex-Date | M4: 44931
L5: Dividends | M5: 1 share of Meituan - W for every 10 Shares
A6: 1 | B6: =INDEX(Stocks!A:B,MATCH(P7,Stocks!A:A,),2)&" ("&P7&")" -> Tencent (700:HK) | G6: Market Price | L6: Pay-out Date | M6: 45009
C7: Account | D7: Shares | E7: Ave. Cost | F7: Amount | H7: Sell Qty | I7: Amount HKD | J7: =IF(COUNTIF(J8:J19,">0")<>0,IF(COUNTIF(J8:J19,"<0")<>0,"Gain / Loss", "Gain"),"Loss") -> Loss | K7: ="% "&IF(COUNTIF(K8:K19,">=0")<>0,IF(COUNTIF(K8:K19,"<0")<>0,"Gain / Loss", "Gain"),"Loss") -> % Loss | P7: 700:HK
C8: Citibank Singapore A/C No. 1 | D8: =SUMIF(Download!B:B,Q8,Download!G:G) -> 0 | E8: =SUMIF(Download!B:B,Q8,Download!H:H) -> 0 | F8: =D8*E8 -> 0 | H8: 500 | I8: =H8*H6 -> 0 | J8: =(H6-E8)*H8 -> 0 | K8: =(H6/E8)-1 -> #DIV/0! | O8: CBSG | P8: =P7 -> 700:HK | Q8: =O8&P8 -> CBSG700:HK
C9: Citibank Account No. 2 | D9: =SUMIF(Download!B:B,Q9,Download!G:G) -> 0 | E9: =SUMIF(Download!B:B,Q9,Download!H:H) -> 0 | F9: =D9*E9 -> 0 | H9: =H8 -> 500 | I9: =H9*H6 -> 0 | J9: =(H6-E9)*H9 -> 0 | K9: =(H6/E9)-1 -> #DIV/0! | O9: CB2 | P9: =P7 -> 700:HK | Q9: =O9&P9 -> CB2700:HK
C10: Citibank Account No. 3 | D10: =SUMIF(Download!B:B,Q10,Download!G:G) -> 0 | E10: =SUMIF(Download!B:B,Q10,Download!H:H) -> 0 | F10: =D10*E10 -> 0 | H10: =H9 -> 500 | I10: =H10*H6 -> 0 | J10: =(H6-E10)*H10 -> 0 | K10: =(H6/E10)-1 -> #DIV/0! | O10: CB3 | P10: =P8 -> 700:HK | Q10: =O10&P10 -> CB3700:HK
C11: Citibank Berry Hill | D11: =SUMIF(Download!B:B,Q11,Download!G:G) -> 0 | E11: =SUMIF(Download!B:B,Q11,Download!H:H) -> 0 | F11: =D11*E11 -> 0 | H11: =H10 -> 500 | I11: =H11*H6 -> 0 | J11: =(H6-E11)*H11 -> 0 | K11: =(H6/E11)-1 -> #DIV/0! | O11: CBBH | P11: =P10 -> 700:HK | Q11: =O11&P11 -> CBBH700:HK
C12: Bank of Singapore | D12: =SUMIF(Download!B:B,Q12,Download!G:G) -> 0 | E12: =SUMIF(Download!B:B,Q12,Download!H:H) -> 0 | F12: =D12*E12 -> 0 | H12: =H11 -> 500 | I12: =H12*H6 -> 0 | J12: =(H6-E12)*H12 -> 0 | K12: =(H6/E12)-1 -> #DIV/0! | O12: BOS | P12: =P11 -> 700:HK | Q12: =O12&P12 -> BOS700:HK
C13: Deutsche Bank Personal | D13: =SUMIF(Download!B:B,Q13,Download!G:G) -> 0 | E13: =SUMIF(Download!B:B,Q13,Download!H:H) -> 0 | F13: =D13*E13 -> 0 | H13: =H12 -> 500 | I13: =H13*H6 -> 0 | J13: =(H6-E13)*H13 -> 0 | K13: =(H6/E13)-1 -> #DIV/0! | O13: DBPe | P13: =P12 -> 700:HK | Q13: =O13&P13 -> DBPe700:HK
C14: Deutsche Bank Perfect Legend | D14: =SUMIF(Download!B:B,Q14,Download!G:G) -> 0 | E14: =SUMIF(Download!B:B,Q14,Download!H:H) -> 0 | F14: =D14*E14 -> 0 | H14: =H13 -> 500 | I14: =H14*H6 -> 0 | J14: =(H6-E14)*H14 -> 0 | K14: =(H6/E14)-1 -> #DIV/0! | O14: DBPL | P14: =P13 -> 700:HK | Q14: =O14&P14 -> DBPL700:HK
C15: Standard Chartered Bank | D15: =SUMIF(Download!B:B,Q15,Download!G:G) -> 0 | E15: =SUMIF(Download!B:B,Q15,Download!H:H) -> 0 | F15: =D15*E15 -> 0 | H15: =H14 -> 500 | I15: =H15*H6 -> 0 | J15: =(H6-E15)*H15 -> 0 | K15: =(H6/E15)-1 -> #DIV/0! | O15: SC | P15: =P14 -> 700:HK | Q15: =O15&P15 -> SC700:HK
C16: Sun Hung Kai | D16: =SUMIF(Download!B:B,Q16,Download!G:G) -> 0 | E16: =SUMIF(Download!B:B,Q16,Download!H:H) -> 0 | F16: =D16*E16 -> 0 | H16: =H15 -> 500 | I16: =H16*H6 -> 0 | J16: =(H6-E16)*H16 -> 0 | K16: =(H6/E16)-1 -> #DIV/0! | O16: SHK | P16: =P15 -> 700:HK | Q16: =O16&P16 -> SHK700:HK
C17: Morgan Stanley Titan No. 1 | D17: =SUMIF(Download!B:B,Q17,Download!G:G) -> 0 | E17: =SUMIF(Download!B:B,Q17,Download!H:H) -> 0 | F17: =D17*E17 -> 0 | H17: =H16 -> 500 | I17: =H17*H6 -> 0 | J17: =(H6-E17)*H17 -> 0 | K17: =(H6/E17)-1 -> #DIV/0! | O17: MST1 | P17: =P16 -> 700:HK | Q17: =O17&P17 -> MST1700:HK
C18: Morgan Stanley Titan No. 2 | D18: =SUMIF(Download!B:B,Q18,Download!G:G) -> 0 | E18: =SUMIF(Download!B:B,Q18,Download!H:H) -> 0 | F18: =D18*E18 -> 0 | H18: =H17 -> 500 | I18: =H18*H6 -> 0 | J18: =(H6-E18)*H18 -> 0 | K18: =(H6/E18)-1 -> #DIV/0! | O18: MST2 | P18: =P17 -> 700:HK | Q18: =O18&P18 -> MST2700:HK
C19: Morgan Stanley Perfect Legend | D19: =SUMIF(Download!B:B,Q19,Download!G:G) -> 0 | E19: =SUMIF(Download!B:B,Q19,Download!H:H) -> 0 | F19: =D19*E19 -> 0 | H19: =H18 -> 500 | I19: =H19*H6 -> 0 | J19: =(H6-E19)*H19 -> 0 | K19: =(H6/E19)-1 -> #DIV/0! | O19: MSPL | P19: =P18 -> 700:HK | Q19: =O19&P19 -> MSPL700:HK
C21: Total | D21: =SUM(D7:D20) -> 0 | E21: =F21/D21 -> #DIV/0! | F21: =SUM(F7:F20) -> 0
A25: 2 | B25: =INDEX(Stocks!A:B,MATCH(P26,Stocks!A:A,),2)&" ("&P26&")" -> Kuaishou Tech (1024:HK) | G25: Market Price
C26: Account | D26: Shares | E26: Ave. Cost | F26: Amount | H26: Sell Qty | I26: Amount HKD | J26: =IF(COUNTIF(J27:J38,">0")<>0,IF(COUNTIF(J27:J38,"<0")<>0,"Gain / Loss", "Gain"),"Loss") -> Loss | K26: ="% "&IF(COUNTIF(K27:K38,">=0")<>0,IF(COUNTIF(K27:K38,"<0")<>0,"Gain / Loss", "Gain"),"Loss") -> % Loss | P26: 1024:HK
C27: Citibank Singapore A/C No. 1 | D27: =SUMIF(Download!B:B,Q27,Download!G:G) -> 0 | E27: =SUMIF(Download!B:B,Q27,Download!H:H) -> 0 | F27: =D27*E27 -> 0 | H27: 3000 | I27: =H27*H25 -> 0 | J27: =(H25-E27)*H27 -> 0 | K27: =(H25/E27)-1 -> #DIV/0! | O27: CBSG | P27: =P26 -> 1024:HK | Q27: =O27&P27 -> CBSG1024:HK
C28: Citibank Account No. 2 | D28: =SUMIF(Download!B:B,Q28,Download!G:G) -> 0 | E28: =SUMIF(Download!B:B,Q28,Download!H:H) -> 0 | F28: =D28*E28 -> 0 | H28: =H27 -> 3000 | I28: =H28*H25 -> 0 | J28: =(H25-E28)*H28 -> 0 | K28: =(H25/E28)-1 -> #DIV/0! | O28: CB2 | P28: =P26 -> 1024:HK | Q28: =O28&P28 -> CB21024:HK
C29: Citibank Account No. 3 | D29: =SUMIF(Download!B:B,Q29,Download!G:G) -> 0 | E29: =SUMIF(Download!B:B,Q29,Download!H:H) -> 0 | F29: =D29*E29 -> 0 | H29: =H28 -> 3000 | I29: =H29*H25 -> 0 | J29: =(H25-E29)*H29 -> 0 | K29: =(H25/E29)-1 -> #DIV/0! | O29: CB3 | P29: =P27 -> 1024:HK | Q29: =O29&P29 -> CB31024:HK
C30: Citibank Berry Hill | D30: =SUMIF(Download!B:B,Q30,Download!G:G) -> 0 | E30: =SUMIF(Download!B:B,Q30,Download!H:H) -> 0 | F30: =D30*E30 -> 0 | H30: =H29 -> 3000 | I30: =H30*H25 -> 0 | J30: =(H25-E30)*H30 -> 0 | K30: =(H25/E30)-1 -> #DIV/0! | O30: CBBH | P30: =P29 -> 1024:HK | Q30: =O30&P30 -> CBBH1024:HK
C31: Bank of Singapore | D31: =SUMIF(Download!B:B,Q31,Download!G:G) -> 0 | E31: =SUMIF(Download!B:B,Q31,Download!H:H) -> 0 | F31: =D31*E31 -> 0 | H31: =H30 -> 3000 | I31: =H31*H25 -> 0 | J31: =(H25-E31)*H31 -> 0 | K31: =(H25/E31)-1 -> #DIV/0! | O31: BOS | P31: =P30 -> 1024:HK | Q31: =O31&P31 -> BOS1024:HK
C32: Deutsche Bank Personal | D32: =SUMIF(Download!B:B,Q32,Download!G:G) -> 0 | E32: =SUMIF(Download!B:B,Q32,Download!H:H) -> 0 | F32: =D32*E32 -> 0 | H32: =H31 -> 3000 | I32: =H32*H25 -> 0 | J32: =(H25-E32)*H32 -> 0 | K32: =(H25/E32)-1 -> #DIV/0! | O32: DBPe | P32: =P31 -> 1024:HK | Q32: =O32&P32 -> DBPe1024:HK
C33: Deutsche Bank Perfect Legend | D33: =SUMIF(Download!B:B,Q33,Download!G:G) -> 0 | E33: =SUMIF(Download!B:B,Q33,Download!H:H) -> 0 | F33: =D33*E33 -> 0 | H33: =H32 -> 3000 | I33: =H33*H25 -> 0 | J33: =(H25-E33)*H33 -> 0 | K33: =(H25/E33)-1 -> #DIV/0! | O33: DBPL | P33: =P32 -> 1024:HK | Q33: =O33&P33 -> DBPL1024:HK
C34: Standard Chartered Bank | D34: =SUMIF(Download!B:B,Q34,Download!G:G) -> 0 | E34: =SUMIF(Download!B:B,Q34,Download!H:H) -> 0 | F34: =D34*E34 -> 0 | H34: =H33 -> 3000 | I34: =H34*H25 -> 0 | J34: =(H25-E34)*H34 -> 0 | K34: =(H25/E34)-1 -> #DIV/0! | O34: SC | P34: =P33 -> 1024:HK | Q34: =O34&P34 -> SC1024:HK
C35: Sun Hung Kai | D35: =SUMIF(Download!B:B,Q35,Download!G:G) -> 0 | E35: =SUMIF(Download!B:B,Q35,Download!H:H) -> 0 | F35: =D35*E35 -> 0 | H35: =H34 -> 3000 | I35: =H35*H25 -> 0 | J35: =(H25-E35)*H35 -> 0 | K35: =(H25/E35)-1 -> #DIV/0! | L35: with Decu Strike 84.3945 | O35: SHK | P35: =P34 -> 1024:HK | Q35: =O35&P35 -> SHK1024:HK
C36: Morgan Stanley Titan No. 1 | D36: =SUMIF(Download!B:B,Q36,Download!G:G) -> 0 | E36: =SUMIF(Download!B:B,Q36,Download!H:H) -> 0 | F36: =D36*E36 -> 0 | H36: =H35 -> 3000 | I36: =H36*H25 -> 0 | J36: =(H25-E36)*H36 -> 0 | K36: =(H25/E36)-1 -> #DIV/0! | O36: MST1 | P36: =P35 -> 1024:HK | Q36: =O36&P36 -> MST11024:HK
C37: Morgan Stanley Titan No. 2 | D37: =SUMIF(Download!B:B,Q37,Download!G:G) -> 0 | E37: =SUMIF(Download!B:B,Q37,Download!H:H) -> 0 | F37: =D37*E37 -> 0 | H37: =H36 -> 3000 | I37: =H37*H25 -> 0 | J37: =(H25-E37)*H37 -> 0 | K37: =(H25/E37)-1 -> #DIV/0! | O37: MST2 | P37: =P36 -> 1024:HK | Q37: =O37&P37 -> MST21024:HK
C38: Morgan Stanley Perfect Legend | D38: =SUMIF(Download!B:B,Q38,Download!G:G) -> 0 | E38: =SUMIF(Download!B:B,Q38,Download!H:H) -> 0 | F38: =D38*E38 -> 0 | H38: =H37 -> 3000 | I38: =H38*H25 -> 0 | J38: =(H25-E38)*H38 -> 0 | K38: =(H25/E38)-1 -> #DIV/0! | O38: MSPL | P38: =P37 -> 1024:HK | Q38: =O38&P38 -> MSPL1024:HK
C40: Total | D40: =SUM(D26:D39) -> 0 | E40: =F40/D40 -> #DIV/0! | F40: =SUM(F26:F39) -> 0
A44: 3 | B44: =INDEX(Stocks!A:B,MATCH(P45,Stocks!A:A,),2)&" ("&P45&")" -> Xiaomi Corp (1810:HK) | G44: Market Price
C45: Account | D45: Shares | E45: Ave. Cost | F45: Amount | H45: Sell Qty | I45: Amount HKD | J45: =IF(COUNTIF(J46:J57,">0")<>0,IF(COUNTIF(J46:J57,"<0")<>0,"Gain / Loss", "Gain"),"Loss") -> Loss | K45: ="% "&IF(COUNTIF(K46:K57,">=0")<>0,IF(COUNTIF(K46:K57,"<0")<>0,"Gain / Loss", "Gain"),"Loss") -> % Loss | P45: 1810:HK
C46: Citibank Singapore A/C No. 1 | D46: =SUMIF(Download!B:B,Q46,Download!G:G) -> 0 | E46: =SUMIF(Download!B:B,Q46,Download!H:H) -> 0 | F46: =D46*E46 -> 0 | H46: 15000 | I46: =H46*H44 -> 0 | J46: =(H44-E46)*H46 -> 0 | K46: =(H44/E46)-1 -> #DIV/0! | O46: CBSG | P46: =P45 -> 1810:HK | Q46: =O46&P46 -> CBSG1810:HK
C47: Citibank Account No. 2 | D47: =SUMIF(Download!B:B,Q47,Download!G:G) -> 0 | E47: =SUMIF(Download!B:B,Q47,Download!H:H) -> 0 | F47: =D47*E47 -> 0 | H47: =H46 -> 15000 | I47: =H47*H44 -> 0 | J47: =(H44-E47)*H47 -> 0 | K47: =(H44/E47)-1 -> #DIV/0! | O47: CB2 | P47: =P45 -> 1810:HK | Q47: =O47&P47 -> CB21810:HK
C48: Citibank Account No. 3 | D48: =SUMIF(Download!B:B,Q48,Download!G:G) -> 0 | E48: =SUMIF(Download!B:B,Q48,Download!H:H) -> 0 | F48: =D48*E48 -> 0 | H48: =H47 -> 15000 | I48: =H48*H44 -> 0 | J48: =(H44-E48)*H48 -> 0 | K48: =(H44/E48)-1 -> #DIV/0! | O48: CB3 | P48: =P46 -> 1810:HK | Q48: =O48&P48 -> CB31810:HK
C49: Citibank Berry Hill | D49: =SUMIF(Download!B:B,Q49,Download!G:G) -> 0 | E49: =SUMIF(Download!B:B,Q49,Download!H:H) -> 0 | F49: =D49*E49 -> 0 | H49: =H48 -> 15000 | I49: =H49*H44 -> 0 | J49: =(H44-E49)*H49 -> 0 | K49: =(H44/E49)-1 -> #DIV/0! | O49: CBBH | P49: =P48 -> 1810:HK | Q49: =O49&P49 -> CBBH1810:HK
...

Sheet 3
A1: Short Stock Summary
A2: =ALL!A1 -> As of September 20, 2022
L3: Ex-Date | M3: 44714
L4: Dividends | M4: HKD 0.21000
A5: 1 | B5: =INDEX(Stocks!A:B,MATCH(P6,Stocks!A:A,),2)&" ("&P6&")" -> Geely Motor (175:HK) | G5: Market Price | L5: Pay-out Date | M5: 44768
C6: Account | D6: Shares | E6: Ave. Cost | F6: Amount | H6: Sell Qty | I6: Amount HKD | J6: =IF(COUNTIF(J7:J18,">0")<>0,IF(COUNTIF(J7:J18,"<0")<>0,"Gain / Loss", "Gain"),"Loss") -> Loss | K6: ="% "&IF(COUNTIF(K7:K18,">=0")<>0,IF(COUNTIF(K7:K18,"<0")<>0,"Gain / Loss", "Gain"),"Loss") -> % Loss | P6: 175:HK
C7: Citibank Singapore A/C No. 1 | D7: =SUMIF(Download!B:B,Q7,Download!G:G) -> 0 | E7: =SUMIF(Download!B:B,Q7,Download!H:H) -> 0 | F7: =D7*E7 -> 0 | H7: 40000 | I7: =H7*H5 -> 0 | J7: =(H5-E7)*H7 -> 0 | K7: =(H5/E7)-1 -> #DIV/0! | O7: CBSG | P7: =P6 -> 175:HK | Q7: =O7&P7 -> CBSG175:HK
C8: Citibank Account No. 2 | D8: =SUMIF(Download!B:B,Q8,Download!G:G) -> 0 | E8: =SUMIF(Download!B:B,Q8,Download!H:H) -> 0 | F8: =D8*E8 -> 0 | H8: =H7 -> 40000 | I8: =H8*H5 -> 0 | J8: =(H5-E8)*H8 -> 0 | K8: =(H5/E8)-1 -> #DIV/0! | O8: CB2 | P8: =P6 -> 175:HK | Q8: =O8&P8 -> CB2175:HK
C9: Citibank Account No. 3 | D9: =SUMIF(Download!B:B,Q9,Download!G:G) -> 0 | E9: =SUMIF(Download!B:B,Q9,Download!H:H) -> 0 | F9: =D9*E9 -> 0 | H9: =H8 -> 40000 | I9: =H9*H5 -> 0 | J9: =(H5-E9)*H9 -> 0 | K9: =(H5/E9)-1 -> #DIV/0! | L9: with Decu Strike 18.2650; 16.8226 | O9: CB3 | P9: =P7 -> 175:HK | Q9: =O9&P9 -> CB3175:HK
C10: Citibank Berry Hill | D10: =SUMIF(Download!B:B,Q10,Download!G:G) -> 0 | E10: =SUMIF(Download!B:B,Q10,Download!H:H) -> 0 | F10: =D10*E10 -> 0 | H10: =H9 -> 40000 | I10: =H10*H5 -> 0 | J10: =(H5-E10)*H10 -> 0 | K10: =(H5/E10)-1 -> #DIV/0! | O10: CBBH | P10: =P9 -> 175:HK | Q10: =O10&P10 -> CBBH175:HK
C11: Bank of Singapore | D11: =SUMIF(Download!B:B,Q11,Download!G:G) -> 0 | E11: =SUMIF(Download!B:B,Q11,Download!H:H) -> 0 | F11: =D11*E11 -> 0 | H11: =H10 -> 40000 | I11: =H11*H5 -> 0 | J11: =(H5-E11)*H11 -> 0 | K11: =(H5/E11)-1 -> #DIV/0! | L11: with Decu Strike 18.5495; 16.0786 | O11: BOS | P11: =P10 -> 175:HK | Q11: =O11&P11 -> BOS175:HK
C12: Deutsche Bank Personal | D12: =SUMIF(Download!B:B,Q12,Download!G:G) -> 0 | E12: =SUMIF(Download!B:B,Q12,Download!H:H) -> 0 | F12: =D12*E12 -> 0 | H12: =H11 -> 40000 | I12: =H12*H5 -> 0 | J12: =(H5-E12)*H12 -> 0 | K12: =(H5/E12)-1 -> #DIV/0! | L12: with Decu Strike 18.3121 | O12: DBPe | P12: =P11 -> 175:HK | Q12: =O12&P12 -> DBPe175:HK
C13: Deutsche Bank Perfect Legend | D13: =SUMIF(Download!B:B,Q13,Download!G:G) -> 0 | E13: =SUMIF(Download!B:B,Q13,Download!H:H) -> 0 | F13: =D13*E13 -> 0 | H13: =H12 -> 40000 | I13: =H13*H5 -> 0 | J13: =(H5-E13)*H13 -> 0 | K13: =(H5/E13)-1 -> #DIV/0! | O13: DBPL | P13: =P12 -> 175:HK | Q13: =O13&P13 -> DBPL175:HK
C14: Standard Chartered Bank | D14: =SUMIF(Download!B:B,Q14,Download!G:G) -> 0 | E14: =SUMIF(Download!B:B,Q14,Download!H:H) -> 0 | F14: =D14*E14 -> 0 | H14: =H13 -> 40000 | I14: =H14*H5 -> 0 | J14: =(H5-E14)*H14 -> 0 | K14: =(H5/E14)-1 -> #DIV/0! | O14: SC | P14: =P13 -> 175:HK | Q14: =O14&P14 -> SC175:HK
C15: Sun Hung Kai | D15: =SUMIF(Download!B:B,Q15,Download!G:G) -> 0 | E15: =SUMIF(Download!B:B,Q15,Download!H:H) -> 0 | F15: =D15*E15 -> 0 | H15: =H14 -> 40000 | I15: =H15*H5 -> 0 | J15: =(H5-E15)*H15 -> 0 | K15: =(H5/E15)-1 -> #DIV/0! | O15: SHK | P15: =P14 -> 175:HK | Q15: =O15&P15 -> SHK175:HK
C16: Morgan Stanley Titan No. 1 | D16: =SUMIF(Download!B:B,Q16,Download!G:G) -> 0 | E16: =SUMIF(Download!B:B,Q16,Download!H:H) -> 0 | F16: =D16*E16 -> 0 | H16: =H15 -> 40000 | I16: =H16*H5 -> 0 | J16: =(H5-E16)*H16 -> 0 | K16: =(H5/E16)-1 -> #DIV/0! | O16: MST1 | P16: =P15 -> 175:HK | Q16: =O16&P16 -> MST1175:HK
C17: Morgan Stanley Titan No. 2 | D17: =SUMIF(Download!B:B,Q17,Download!G:G) -> 0 | E17: =SUMIF(Download!B:B,Q17,Download!H:H) -> 0 | F17: =D17*E17 -> 0 | H17: =H16 -> 40000 | I17: =H17*H5 -> 0 | J17: =(H5-E17)*H17 -> 0 | K17: =(H5/E17)-1 -> #DIV/0! | L17: with Decu Strike 17.6825; 18.4524; 15.6995 | O17: MST2 | P17: =P16 -> 175:HK | Q17: =O17&P17 -> MST2175:HK
C18: Morgan Stanley Perfect Legend | D18: =SUMIF(Download!B:B,Q18,Download!G:G) -> 0 | E18: =SUMIF(Download!B:B,Q18,Download!H:H) -> 0 | F18: =D18*E18 -> 0 | H18: =H17 -> 40000 | I18: =H18*H5 -> 0 | J18: =(H5-E18)*H18 -> 0 | K18: =(H5/E18)-1 -> #DIV/0! | O18: MSPL | P18: =P17 -> 175:HK | Q18: =O18&P18 -> MSPL175:HK
C20: Total | D20: =SUM(D6:D19) -> 0 | E20: =F20/D20 -> #DIV/0! | F20: =SUM(F6:F19) -> 0
L21: Ex-Date | M21: 44691
L22: Dividends | M22: RMB 0.0700
A23: 2 | B23: =INDEX(Stocks!A:B,MATCH(P24,Stocks!A:A,),2)&" ("&P24&")" -> Great Wall Motor (2333:HK) | G23: Market Price | L23: Pay-out Date | M23: 44733
C24: Account | D24: Shares | E24: Ave. Cost | F24: Amount | H24: Sell Qty | I24: Amount HKD | J24: =IF(COUNTIF(J25:J36,">0")<>0,IF(COUNTIF(J25:J36,"<0")<>0,"Gain / Loss", "Gain"),"Loss") -> Loss | K24: ="% "&IF(COUNTIF(K25:K36,">=0")<>0,IF(COUNTIF(K25:K36,"<0")<>0,"Gain / Loss", "Gain"),"Loss") -> % Loss | P24: 2333:HK
C25: Citibank Singapore A/C No. 1 | D25: =SUMIF(Download!B:B,Q25,Download!G:G) -> 0 | E25: =SUMIF(Download!B:B,Q25,Download!H:H) -> 0 | F25: =D25*E25 -> 0 | H25: 20000 | I25: =H25*H23 -> 0 | J25: =(H23-E25)*H25 -> 0 | K25: =(H23/E25)-1 -> #DIV/0! | O25: CBSG | P25: =P24 -> 2333:HK | Q25: =O25&P25 -> CBSG2333:HK
C26: Citibank Account No. 2 | D26: =SUMIF(Download!B:B,Q26,Download!G:G) -> 0 | E26: =SUMIF(Download!B:B,Q26,Download!H:H) -> 0 | F26: =D26*E26 -> 0 | H26: =H25 -> 20000 | I26: =H26*H23 -> 0 | J26: =(H23-E26)*H26 -> 0 | K26: =(H23/E26)-1 -> #DIV/0! | O26: CB2 | P26: =P24 -> 2333:HK | Q26: =O26&P26 -> CB22333:HK
C27: Citibank Account No. 3 | D27: =SUMIF(Download!B:B,Q27,Download!G:G) -> 0 | E27: =SUMIF(Download!B:B,Q27,Download!H:H) -> 0 | F27: =D27*E27 -> 0 | H27: =H26 -> 20000 | I27: =H27*H23 -> 0 | J27: =(H23-E27)*H27 -> 0 | K27: =(H23/E27)-1 -> #DIV/0! | O27: CB3 | P27: =P25 -> 2333:HK | Q27: =O27&P27 -> CB32333:HK
C28: Citibank Berry Hill | D28: =SUMIF(Download!B:B,Q28,Download!G:G) -> 0 | E28: =SUMIF(Download!B:B,Q28,Download!H:H) -> 0 | F28: =D28*E28 -> 0 | H28: =H27 -> 20000 | I28: =H28*H23 -> 0 | J28: =(H23-E28)*H28 -> 0 | K28: =(H23/E28)-1 -> #DIV/0! | O28: CBBH | P28: =P27 -> 2333:HK | Q28: =O28&P28 -> CBBH2333:HK
C29: Bank of Singapore | D29: =SUMIF(Download!B:B,Q29,Download!G:G) -> 0 | E29: =SUMIF(Download!B:B,Q29,Download!H:H) -> 0 | F29: =D29*E29 -> 0 | H29: =H28 -> 20000 | I29: =H29*H23 -> 0 | J29: =(H23-E29)*H29 -> 0 | K29: =(H23/E29)-1 -> #DIV/0! | O29: BOS | P29: =P28 -> 2333:HK | Q29: =O29&P29 -> BOS2333:HK
C30: Deutsche Bank Personal | D30: =SUMIF(Download!B:B,Q30,Download!G:G) -> 0 | E30: =SUMIF(Download!B:B,Q30,Download!H:H) -> 0 | F30: =D30*E30 -> 0 | H30: =H29 -> 20000 | I30: =H30*H23 -> 0 | J30: =(H23-E30)*H30 -> 0 | K30: =(H23/E30)-1 -> #DIV/0! | O30: DBPe | P30: =P29 -> 2333:HK | Q30: =O30&P30 -> DBPe2333:HK
C31: Deutsche Bank Perfect Legend | D31: =SUMIF(Download!B:B,Q31,Download!G:G) -> 0 | E31: =SUMIF(Download!B:B,Q31,Download!H:H) -> 0 | F31: =D31*E31 -> 0 | H31: =H30 -> 20000 | I31: =H31*H23 -> 0 | J31: =(H23-E31)*H31 -> 0 | K31: =(H23/E31)-1 -> #DIV/0! | O31: DBPL | P31: =P30 -> 2333:HK | Q31: =O31&P31 -> DBPL2333:HK
C32: Standard Chartered Bank | D32: =SUMIF(Download!B:B,Q32,Download!G:G) -> 0 | E32: =SUMIF(Download!B:B,Q32,Download!H:H) -> 0 | F32: =D32*E32 -> 0 | H32: =H31 -> 20000 | I32: =H32*H23 -> 0 | J32: =(H23-E32)*H32 -> 0 | K32: =(H23/E32)-1 -> #DIV/0! | O32: SC | P32: =P31 -> 2333:HK | Q32: =O32&P32 -> SC2333:HK
C33: Sun Hung Kai | D33: =SUMIF(Download!B:B,Q33,Download!G:G) -> 0 | E33: =SUMIF(Download!B:B,Q33,Download!H:H) -> 0 | F33: =D33*E33 -> 0 | H33: =H32 -> 20000 | I33: =H33*H23 -> 0 | J33: =(H23-E33)*H33 -> 0 | K33: =(H23/E33)-1 -> #DIV/0! | L33: with Decu Strike 12.1255; 10.8958; 14.4087; 14.4659; 14.6152; 13.5447 | O33: SHK | P33: =P32 -> 2333:HK | Q33: =O33&P33 -> SHK2333:HK
C34: Morgan Stanley Titan No. 1 | D34: =SUMIF(Download!B:B,Q34,Download!G:G) -> 0 | E34: =SUMIF(Download!B:B,Q34,Download!H:H) -> 0 | F34: =D34*E34 -> 0 | H34: =H33 -> 20000 | I34: =H34*H23 -> 0 | J34: =(H23-E34)*H34 -> 0 | K34: =(H23/E34)-1 -> #DIV/0! | L34: with Decu Strike 12.0965; 14.3173; 14.0640; 13.6959 | O34: MST1 | P34: =P33 -> 2333:HK | Q34: =O34&P34 -> MST12333:HK
C35: Morgan Stanley Titan No. 2 | D35: =SUMIF(Download!B:B,Q35,Download!G:G) -> 0 | E35: =SUMIF(Download!B:B,Q35,Download!H:H) -> 0 | F35: =D35*E35 -> 0 | H35: =H34 -> 20000 | I35: =H35*H23 -> 0 | J35: =(H23-E35)*H35 -> 0 | K35: =(H23/E35)-1 -> #DIV/0! | O35: MST2 | P35: =P34 -> 2333:HK | Q35: =O35&P35 -> MST22333:HK
C36: Morgan Stanley Perfect Legend | D36: =SUMIF(Download!B:B,Q36,Download!G:G) -> 0 | E36: =SUMIF(Download!B:B,Q36,Download!H:H) -> 0 | F36: =D36*E36 -> 0 | H36: =H35 -> 20000 | I36: =H36*H23 -> 0 | J36: =(H23-E36)*H36 -> 0 | K36: =(H23/E36)-1 -> #DIV/0! | L36: with Decu Strike 14.2469; 14.4763; 13.6245 | O36: MSPL | P36: =P35 -> 2333:HK | Q36: =O36&P36 -> MSPL2333:HK
C38: Total | D38: =SUM(D24:D37) -> 0 | E38: =F38/D38 -> #DIV/0! | F38: =SUM(F24:F37) -> 0
L39: Ex-Date | M39: 44741
L40: Dividends | M40: RMB 0.07125
A41: 3 | B41: =INDEX(Stocks!A:B,MATCH(P42,Stocks!A:A,),2)&" ("&P42&")" -> China Molybdenum (3993:HK) | G41: Market Price | L41: Pay-out Date | M41: 44769
C42: Account | D42: Shares | E42: Ave. Cost | F42: Amount | H42: Sell Qty | I42: Amount HKD | J42: =IF(COUNTIF(J43:J54,">0")<>0,IF(COUNTIF(J43:J54,"<0")<>0,"Gain / Loss", "Gain"),"Loss") -> Loss | K42: ="% "&IF(COUNTIF(K43:K54,">=0")<>0,IF(COUNTIF(K43:K54,"<0")<>0,"Gain / Loss", "Gain"),"Loss") -> % Loss | P42: 3993:HK
...

Sheet 4
A1: Short Stock Summary | L1: Out
A2: =ALL!A1 -> As of September 20, 2022
K3: 1 | L3: Ex-Date | M3: 44725
L4: Dividends | M4: HKD 0.0670
L5: Pay-out Date | M5: 44742
K6: 2 | L6: Ex-Date | M6: 44832
L7: Dividends | M7: HKD 0.07
A8: 1 | B8: =INDEX(Stocks!A:B,MATCH(P9,Stocks!A:A,),2)&" ("&P9&")" -> Beijing Water (371:HK) | G8: Market Price | L8: Pay-out Date | M8: 44854
C9: Account | D9: Shares | E9: Ave. Cost | F9: Amount | H9: Sell Qty | I9: Amount HKD | J9: =IF(COUNTIF(J10:J21,">0")<>0,IF(COUNTIF(J10:J21,"<0")<>0,"Gain / Loss", "Gain"),"Loss") -> Loss | K9: ="% "&IF(COUNTIF(K10:K21,">=0")<>0,IF(COUNTIF(K10:K21,"<0")<>0,"Gain / Loss", "Gain"),"Loss") -> % Loss | P9: 371:HK
C10: Citibank Singapore A/C No. 1 | D10: =SUMIF(Download!B:B,Q10,Download!G:G) -> 0 | E10: =SUMIF(Download!B:B,Q10,Download!H:H) -> 0 | F10: =D10*E10 -> 0 | H10: 200000 | I10: =H10*H8 -> 0 | J10: =(H8-E10)*H10 -> 0 | K10: =(H8/E10)-1 -> #DIV/0! | O10: CBSG | P10: =P9 -> 371:HK | Q10: =O10&P10 -> CBSG371:HK
C11: Citibank Account No. 2 | D11: =SUMIF(Download!B:B,Q11,Download!G:G) -> 0 | E11: =SUMIF(Download!B:B,Q11,Download!H:H) -> 0 | F11: =D11*E11 -> 0 | H11: =H10 -> 200000 | I11: =H11*H8 -> 0 | J11: =(H8-E11)*H11 -> 0 | K11: =(H8/E11)-1 -> #DIV/0! | O11: CB2 | P11: =P9 -> 371:HK | Q11: =O11&P11 -> CB2371:HK
C12: Citibank Account No. 3 | D12: =SUMIF(Download!B:B,Q12,Download!G:G) -> 0 | E12: =SUMIF(Download!B:B,Q12,Download!H:H) -> 0 | F12: =D12*E12 -> 0 | H12: =H11 -> 200000 | I12: =H12*H8 -> 0 | J12: =(H8-E12)*H12 -> 0 | K12: =(H8/E12)-1 -> #DIV/0! | O12: CB3 | P12: =P10 -> 371:HK | Q12: =O12&P12 -> CB3371:HK
C13: Citibank Berry Hill | D13: =SUMIF(Download!B:B,Q13,Download!G:G) -> 0 | E13: =SUMIF(Download!B:B,Q13,Download!H:H) -> 0 | F13: =D13*E13 -> 0 | H13: =H12 -> 200000 | I13: =H13*H8 -> 0 | J13: =(H8-E13)*H13 -> 0 | K13: =(H8/E13)-1 -> #DIV/0! | O13: CBBH | P13: =P12 -> 371:HK | Q13: =O13&P13 -> CBBH371:HK
C14: Bank of Singapore | D14: =SUMIF(Download!B:B,Q14,Download!G:G) -> 0 | E14: =SUMIF(Download!B:B,Q14,Download!H:H) -> 0 | F14: =D14*E14 -> 0 | H14: =H13 -> 200000 | I14: =H14*H8 -> 0 | J14: =(H8-E14)*H14 -> 0 | K14: =(H8/E14)-1 -> #DIV/0! | O14: BOS | P14: =P13 -> 371:HK | Q14: =O14&P14 -> BOS371:HK
C15: Deutsche Bank Personal | D15: =SUMIF(Download!B:B,Q15,Download!G:G) -> 0 | E15: =SUMIF(Download!B:B,Q15,Download!H:H) -> 0 | F15: =D15*E15 -> 0 | H15: =H14 -> 200000 | I15: =H15*H8 -> 0 | J15: =(H8-E15)*H15 -> 0 | K15: =(H8/E15)-1 -> #DIV/0! | O15: DBPe | P15: =P14 -> 371:HK | Q15: =O15&P15 -> DBPe371:HK
C16: Deutsche Bank Perfect Legend | D16: =SUMIF(Download!B:B,Q16,Download!G:G) -> 0 | E16: =SUMIF(Download!B:B,Q16,Download!H:H) -> 0 | F16: =D16*E16 -> 0 | H16: =H15 -> 200000 | I16: =H16*H8 -> 0 | J16: =(H8-E16)*H16 -> 0 | K16: =(H8/E16)-1 -> #DIV/0! | O16: DBPL | P16: =P15 -> 371:HK | Q16: =O16&P16 -> DBPL371:HK
C17: Standard Chartered Bank | D17: =SUMIF(Download!B:B,Q17,Download!G:G) -> 0 | E17: =SUMIF(Download!B:B,Q17,Download!H:H) -> 0 | F17: =D17*E17 -> 0 | H17: =H16 -> 200000 | I17: =H17*H8 -> 0 | J17: =(H8-E17)*H17 -> 0 | K17: =(H8/E17)-1 -> #DIV/0! | O17: SC | P17: =P16 -> 371:HK | Q17: =O17&P17 -> SC371:HK
C18: Sun Hung Kai | D18: =SUMIF(Download!B:B,Q18,Download!G:G) -> 0 | E18: =SUMIF(Download!B:B,Q18,Download!H:H) -> 0 | F18: =D18*E18 -> 0 | H18: =H17 -> 200000 | I18: =H18*H8 -> 0 | J18: =(H8-E18)*H18 -> 0 | K18: =(H8/E18)-1 -> #DIV/0! | O18: SHK | P18: =P17 -> 371:HK | Q18: =O18&P18 -> SHK371:HK
C19: Morgan Stanley Titan No. 1 | D19: =SUMIF(Download!B:B,Q19,Download!G:G) -> 0 | E19: =SUMIF(Download!B:B,Q19,Download!H:H) -> 0 | F19: =D19*E19 -> 0 | H19: =H18 -> 200000 | I19: =H19*H8 -> 0 | J19: =(H8-E19)*H19 -> 0 | K19: =(H8/E19)-1 -> #DIV/0! | O19: MST1 | P19: =P18 -> 371:HK | Q19: =O19&P19 -> MST1371:HK
C20: Morgan Stanley Titan No. 2 | D20: =SUMIF(Download!B:B,Q20,Download!G:G) -> 0 | E20: =SUMIF(Download!B:B,Q20,Download!H:H) -> 0 | F20: =D20*E20 -> 0 | H20: =H19 -> 200000 | I20: =H20*H8 -> 0 | J20: =(H8-E20)*H20 -> 0 | K20: =(H8/E20)-1 -> #DIV/0! | O20: MST2 | P20: =P19 -> 371:HK | Q20: =O20&P20 -> MST2371:HK
C21: Morgan Stanley Perfect Legend | D21: =SUMIF(Download!B:B,Q21,Download!G:G) -> 0 | E21: =SUMIF(Download!B:B,Q21,Download!H:H) -> 0 | F21: =D21*E21 -> 0 | H21: =H20 -> 200000 | I21: =H21*H8 -> 0 | J21: =(H8-E21)*H21 -> 0 | K21: =(H8/E21)-1 -> #DIV/0! | O21: MSPL | P21: =P20 -> 371:HK | Q21: =O21&P21 -> MSPL371:HK
C23: Total | D23: =SUM(D9:D22) -> 0 | E23: =F23/D23 -> #DIV/0! | F23: =SUM(F9:F22) -> 0
L24: Ex-Date | M24: 44027
L25: Dividends | M25: HKD4.6800
A26: 2 | B26: =INDEX(Stocks!A:B,MATCH(P27,Stocks!A:A,),2)&" ("&P27&")" -> Cathay Pacific (293:HK) | G26: Market Price | L26: Pay-out Date | M26: 44048
C27: Account | D27: Shares | E27: Ave. Cost | F27: Amount | H27: Sell Qty | I27: Amount HKD | J27: =IF(COUNTIF(J28:J39,">0")<>0,IF(COUNTIF(J28:J39,"<0")<>0,"Gain / Loss", "Gain"),"Loss") -> Loss | K27: ="% "&IF(COUNTIF(K28:K39,">=0")<>0,IF(COUNTIF(K28:K39,"<0")<>0,"Gain / Loss", "Gain"),"Loss") -> % Loss | P27: 293:HK
C28: Citibank Singapore A/C No. 1 | D28: =SUMIF(Download!B:B,Q28,Download!G:G) -> 0 | E28: =SUMIF(Download!B:B,Q28,Download!H:H) -> 0 | F28: =D28*E28 -> 0 | I28: =H28*H26 -> 0 | J28: =(H26-E28)*H28 -> 0 | K28: =(H26/E28)-1 -> #DIV/0! | O28: CBSG | P28: =P27 -> 293:HK | Q28: =O28&P28 -> CBSG293:HK
C29: Citibank Account No. 2 | D29: =SUMIF(Download!B:B,Q29,Download!G:G) -> 0 | E29: =SUMIF(Download!B:B,Q29,Download!H:H) -> 0 | F29: =D29*E29 -> 0 | I29: =H29*H26 -> 0 | J29: =(H26-E29)*H29 -> 0 | K29: =(H26/E29)-1 -> #DIV/0! | O29: CB2 | P29: =P27 -> 293:HK | Q29: =O29&P29 -> CB2293:HK
C30: Citibank Account No. 3 | D30: =SUMIF(Download!B:B,Q30,Download!G:G) -> 0 | E30: =SUMIF(Download!B:B,Q30,Download!H:H) -> 0 | F30: =D30*E30 -> 0 | I30: =H30*H26 -> 0 | J30: =(H26-E30)*H30 -> 0 | K30: =(H26/E30)-1 -> #DIV/0! | O30: CB3 | P30: =P28 -> 293:HK | Q30: =O30&P30 -> CB3293:HK
C31: Citibank Berry Hill | D31: =SUMIF(Download!B:B,Q31,Download!G:G) -> 0 | E31: =SUMIF(Download!B:B,Q31,Download!H:H) -> 0 | F31: =D31*E31 -> 0 | I31: =H31*H26 -> 0 | J31: =(H26-E31)*H31 -> 0 | K31: =(H26/E31)-1 -> #DIV/0! | O31: CBBH | P31: =P30 -> 293:HK | Q31: =O31&P31 -> CBBH293:HK
C32: Bank of Singapore | D32: =SUMIF(Download!B:B,Q32,Download!G:G) -> 0 | E32: =SUMIF(Download!B:B,Q32,Download!H:H) -> 0 | F32: =D32*E32 -> 0 | I32: =H32*H26 -> 0 | J32: =(H26-E32)*H32 -> 0 | K32: =(H26/E32)-1 -> #DIV/0! | O32: BOS | P32: =P31 -> 293:HK | Q32: =O32&P32 -> BOS293:HK
C33: Deutsche Bank Personal | D33: =SUMIF(Download!B:B,Q33,Download!G:G) -> 0 | E33: =SUMIF(Download!B:B,Q33,Download!H:H) -> 0 | F33: =D33*E33 -> 0 | I33: =H33*H26 -> 0 | J33: =(H26-E33)*H33 -> 0 | K33: =(H26/E33)-1 -> #DIV/0! | O33: DBPe | P33: =P32 -> 293:HK | Q33: =O33&P33 -> DBPe293:HK
C34: Deutsche Bank Perfect Legend | D34: =SUMIF(Download!B:B,Q34,Download!G:G) -> 0 | E34: =SUMIF(Download!B:B,Q34,Download!H:H) -> 0 | F34: =D34*E34 -> 0 | I34: =H34*H26 -> 0 | J34: =(H26-E34)*H34 -> 0 | K34: =(H26/E34)-1 -> #DIV/0! | O34: DBPL | P34: =P33 -> 293:HK | Q34: =O34&P34 -> DBPL293:HK
C35: Standard Chartered Bank | D35: =SUMIF(Download!B:B,Q35,Download!G:G) -> 0 | E35: =SUMIF(Download!B:B,Q35,Download!H:H) -> 0 | F35: =D35*E35 -> 0 | I35: =H35*H26 -> 0 | J35: =(H26-E35)*H35 -> 0 | K35: =(H26/E35)-1 -> #DIV/0! | O35: SC | P35: =P34 -> 293:HK | Q35: =O35&P35 -> SC293:HK
C36: Sun Hung Kai | D36: =SUMIF(Download!B:B,Q36,Download!G:G) -> 0 | E36: =SUMIF(Download!B:B,Q36,Download!H:H) -> 0 | F36: =D36*E36 -> 0 | I36: =H36*H26 -> 0 | J36: =(H26-E36)*H36 -> 0 | K36: =(H26/E36)-1 -> #DIV/0! | O36: SHK | P36: =P35 -> 293:HK | Q36: =O36&P36 -> SHK293:HK
C37: Morgan Stanley Titan No. 1 | D37: =SUMIF(Download!B:B,Q37,Download!G:G) -> 0 | E37: =SUMIF(Download!B:B,Q37,Download!H:H) -> 0 | F37: =D37*E37 -> 0 | I37: =H37*H26 -> 0 | J37: =(H26-E37)*H37 -> 0 | K37: =(H26/E37)-1 -> #DIV/0! | O37: MST1 | P37: =P36 -> 293:HK | Q37: =O37&P37 -> MST1293:HK
C38: Morgan Stanley Titan No. 2 | D38: =SUMIF(Download!B:B,Q38,Download!G:G) -> 0 | E38: =SUMIF(Download!B:B,Q38,Download!H:H) -> 0 | F38: =D38*E38 -> 0 | I38: =H38*H26 -> 0 | J38: =(H26-E38)*H38 -> 0 | K38: =(H26/E38)-1 -> #DIV/0! | O38: MST2 | P38: =P37 -> 293:HK | Q38: =O38&P38 -> MST2293:HK
C39: Morgan Stanley Perfect Legend | D39: =SUMIF(Download!B:B,Q39,Download!G:G) -> 0 | E39: =SUMIF(Download!B:B,Q39,Download!H:H) -> 0 | F39: =D39*E39 -> 0 | I39: =H39*H26 -> 0 | J39: =(H26-E39)*H39 -> 0 | K39: =(H26/E39)-1 -> #DIV/0! | O39: MSPL | P39: =P38 -> 293:HK | Q39: =O39&P39 -> MSPL293:HK
C41: Total | D41: =SUM(D27:D40) -> 0 | E41: =F41/D41 -> #DIV/0! | F41: =SUM(F27:F40) -> 0
L43: Ex-Date | M43: 44739
...

Sheet DQ Monitoring
A1: Decumulator Pricing Check
A2: =ALL!A1 -> As of September 20, 2022
A4: 1 | B4: =INDEX(Stocks!A:B,MATCH(K5,Stocks!A:A,),2)&" ("&K5&")" -> Cathay Pacific (293:HK) | H4: 6 months DQ only
C5: Account | D5: Shares | E5: Ave. Cost | F5: Amount | H5: Target DQ Strike | K5: 293:HK
C6: Citibank Account No. 1 | D6: =SUMIF(Download!B:B,L6,Download!G:G) -> 0 | E6: =SUMIF(Download!B:B,L6,Download!H:H) -> 0 | F6: =D6*E6 -> 0 | H6: =E6-1 -> -1 | J6: CB1 | K6: =K5 -> 293:HK | L6: =J6&K6 -> CB1293:HK
C7: Citibank Account No. 2 | D7: =SUMIF(Download!B:B,L7,Download!G:G) -> 0 | E7: =SUMIF(Download!B:B,L7,Download!H:H) -> 0 | F7: =D7*E7 -> 0 | H7: =E7-1 -> -1 | J7: CB2 | K7: =K6 -> 293:HK | L7: =J7&K7 -> CB2293:HK
C8: Citibank Account No. 3 | D8: =SUMIF(Download!B:B,L8,Download!G:G) -> 0 | E8: =SUMIF(Download!B:B,L8,Download!H:H) -> 0 | F8: =D8*E8 -> 0 | H8: =E8-1 -> -1 | J8: CB3 | K8: =K6 -> 293:HK | L8: =J8&K8 -> CB3293:HK
C9: Citibank Berry Hill | D9: =SUMIF(Download!B:B,L9,Download!G:G) -> 0 | E9: =SUMIF(Download!B:B,L9,Download!H:H) -> 0 | F9: =D9*E9 -> 0 | H9: =E9-1 -> -1 | J9: CBBH | K9: =K7 -> 293:HK | L9: =J9&K9 -> CBBH293:HK
C10: Bank of Singapore | D10: =SUMIF(Download!B:B,L10,Download!G:G) -> 0 | E10: =SUMIF(Download!B:B,L10,Download!H:H) -> 0 | F10: =D10*E10 -> 0 | H10: =E10-1 -> -1 | J10: BOS | K10: =K9 -> 293:HK | L10: =J10&K10 -> BOS293:HK
C11: Deutsche Bank Personal | D11: =SUMIF(Download!B:B,L11,Download!G:G) -> 0 | E11: =SUMIF(Download!B:B,L11,Download!H:H) -> 0 | F11: =D11*E11 -> 0 | H11: =E11-1 -> -1 | J11: DBPe | K11: =K10 -> 293:HK | L11: =J11&K11 -> DBPe293:HK
C12: Deutsche Bank Perfect Legend | D12: =SUMIF(Download!B:B,L12,Download!G:G) -> 0 | E12: =SUMIF(Download!B:B,L12,Download!H:H) -> 0 | F12: =D12*E12 -> 0 | H12: =E12-1 -> -1 | J12: DBPL | K12: =K11 -> 293:HK | L12: =J12&K12 -> DBPL293:HK
C13: Standard Chartered Bank | D13: =SUMIF(Download!B:B,L13,Download!G:G) -> 0 | E13: =SUMIF(Download!B:B,L13,Download!H:H) -> 0 | F13: =D13*E13 -> 0 | H13: =E13-1 -> -1 | J13: SC | K13: =K12 -> 293:HK | L13: =J13&K13 -> SC293:HK
C14: Sun Hung Kai | D14: =SUMIF(Download!B:B,L14,Download!G:G) -> 0 | E14: =SUMIF(Download!B:B,L14,Download!H:H) -> 0 | F14: =D14*E14 -> 0 | H14: =E14-1 -> -1 | J14: SHK | K14: =K13 -> 293:HK | L14: =J14&K14 -> SHK293:HK
C15: Morgan Stanley Titan No. 1 | D15: =SUMIF(Download!B:B,L15,Download!G:G) -> 0 | E15: =SUMIF(Download!B:B,L15,Download!H:H) -> 0 | F15: =D15*E15 -> 0 | H15: =E15-1 -> -1 | J15: MST1 | K15: =K14 -> 293:HK | L15: =J15&K15 -> MST1293:HK
C16: Morgan Stanley Titan No. 2 | D16: =SUMIF(Download!B:B,L16,Download!G:G) -> 0 | E16: =SUMIF(Download!B:B,L16,Download!H:H) -> 0 | F16: =D16*E16 -> 0 | H16: =E16-1 -> -1 | J16: MST2 | K16: =K15 -> 293:HK | L16: =J16&K16 -> MST2293:HK
C17: Morgan Stanley Perfect Legend | D17: =SUMIF(Download!B:B,L17,Download!G:G) -> 0 | E17: =SUMIF(Download!B:B,L17,Download!H:H) -> 0 | F17: =D17*E17 -> 0 | H17: =E17-1 -> -1 | J17: MSPL | K17: =K16 -> 293:HK | L17: =J17&K17 -> MSPL293:HK
C19: Total | D19: =SUM(D5:D18) -> 0 | E19: =F19/D19 -> #DIV/0! | F19: =SUM(F5:F18) -> 0
A22: =INDIRECT("A"&ROW()-18)+1 -> 2 | B22: =INDEX(Stocks!A:B,MATCH(K23,Stocks!A:A,),2)&" ("&K23&")" -> Beijing Water (371:HK) | H22: 6 months DQ only
C23: Account | D23: Shares | E23: Ave. Cost | F23: Amount | H23: Target DQ Strike | K23: 371:HK
C24: Citibank Account No. 1 | D24: =SUMIF(Download!B:B,L24,Download!G:G) -> 0 | E24: =SUMIF(Download!B:B,L24,Download!H:H) -> 0 | F24: =D24*E24 -> 0 | H24: =E24-1 -> -1 | J24: CB1 | K24: =K23 -> 371:HK | L24: =J24&K24 -> CB1371:HK
C25: Citibank Account No. 2 | D25: =SUMIF(Download!B:B,L25,Download!G:G) -> 0 | E25: =SUMIF(Download!B:B,L25,Download!H:H) -> 0 | F25: =D25*E25 -> 0 | H25: =E25-1 -> -1 | J25: CB2 | K25: =K24 -> 371:HK | L25: =J25&K25 -> CB2371:HK
C26: Citibank Account No. 3 | D26: =SUMIF(Download!B:B,L26,Download!G:G) -> 0 | E26: =SUMIF(Download!B:B,L26,Download!H:H) -> 0 | F26: =D26*E26 -> 0 | H26: =E26-1 -> -1 | J26: CB3 | K26: =K24 -> 371:HK | L26: =J26&K26 -> CB3371:HK
C27: Citibank Berry Hill | D27: =SUMIF(Download!B:B,L27,Download!G:G) -> 0 | E27: =SUMIF(Download!B:B,L27,Download!H:H) -> 0 | F27: =D27*E27 -> 0 | H27: =E27-1 -> -1 | J27: CBBH | K27: =K25 -> 371:HK | L27: =J27&K27 -> CBBH371:HK
C28: Bank of Singapore | D28: =SUMIF(Download!B:B,L28,Download!G:G) -> 0 | E28: =SUMIF(Download!B:B,L28,Download!H:H) -> 0 | F28: =D28*E28 -> 0 | H28: =E28-1 -> -1 | J28: BOS | K28: =K27 -> 371:HK | L28: =J28&K28 -> BOS371:HK
C29: Deutsche Bank Personal | D29: =SUMIF(Download!B:B,L29,Download!G:G) -> 0 | E29: =SUMIF(Download!B:B,L29,Download!H:H) -> 0 | F29: =D29*E29 -> 0 | H29: =E29-1 -> -1 | J29: DBPe | K29: =K28 -> 371:HK | L29: =J29&K29 -> DBPe371:HK
C30: Deutsche Bank Perfect Legend | D30: =SUMIF(Download!B:B,L30,Download!G:G) -> 0 | E30: =SUMIF(Download!B:B,L30,Download!H:H) -> 0 | F30: =D30*E30 -> 0 | H30: =E30-1 -> -1 | J30: DBPL | K30: =K29 -> 371:HK | L30: =J30&K30 -> DBPL371:HK
C31: Standard Chartered Bank | D31: =SUMIF(Download!B:B,L31,Download!G:G) -> 0 | E31: =SUMIF(Download!B:B,L31,Download!H:H) -> 0 | F31: =D31*E31 -> 0 | H31: =E31-1 -> -1 | J31: SC | K31: =K30 -> 371:HK | L31: =J31&K31 -> SC371:HK
C32: Sun Hung Kai | D32: =SUMIF(Download!B:B,L32,Download!G:G) -> 0 | E32: =SUMIF(Download!B:B,L32,Download!H:H) -> 0 | F32: =D32*E32 -> 0 | H32: =E32-1 -> -1 | J32: SHK | K32: =K31 -> 371:HK | L32: =J32&K32 -> SHK371:HK
C33: Morgan Stanley Titan No. 1 | D33: =SUMIF(Download!B:B,L33,Download!G:G) -> 0 | E33: =SUMIF(Download!B:B,L33,Download!H:H) -> 0 | F33: =D33*E33 -> 0 | H33: =E33-1 -> -1 | J33: MST1 | K33: =K32 -> 371:HK | L33: =J33&K33 -> MST1371:HK
C34: Morgan Stanley Titan No. 2 | D34: =SUMIF(Download!B:B,L34,Download!G:G) -> 0 | E34: =SUMIF(Download!B:B,L34,Download!H:H) -> 0 | F34: =D34*E34 -> 0 | H34: =E34-1 -> -1 | J34: MST2 | K34: =K33 -> 371:HK | L34: =J34&K34 -> MST2371:HK
C35: Morgan Stanley Perfect Legend | D35: =SUMIF(Download!B:B,L35,Download!G:G) -> 0 | E35: =SUMIF(Download!B:B,L35,Download!H:H) -> 0 | F35: =D35*E35 -> 0 | H35: =E35-1 -> -1 | J35: MSPL | K35: =K34 -> 371:HK | L35: =J35&K35 -> MSPL371:HK
C37: Total | D37: =SUM(D23:D36) -> 0 | E37: =F37/D37 -> #DIV/0! | F37: =SUM(F23:F36) -> 0
A40: =INDIRECT("A"&ROW()-18)+1 -> 3 | B40: =INDEX(Stocks!A:B,MATCH(K41,Stocks!A:A,),2)&" ("&K41&")" -> China Construction Bank (939:HK) | H40: 6 months DQ only
C41: Account | D41: Shares | E41: Ave. Cost | F41: Amount | H41: Target DQ Strike | K41: 939:HK
C42: Citibank Account No. 1 | D42: =SUMIF(Download!B:B,L42,Download!G:G) -> 0 | E42: =SUMIF(Download!B:B,L42,Download!H:H) -> 0 | F42: =D42*E42 -> 0 | H42: =E42-1 -> -1 | J42: CB1 | K42: =K41 -> 939:HK | L42: =J42&K42 -> CB1939:HK
C43: Citibank Account No. 2 | D43: =SUMIF(Download!B:B,L43,Download!G:G) -> 0 | E43: =SUMIF(Download!B:B,L43,Download!H:H) -> 0 | F43: =D43*E43 -> 0 | H43: =E43-1 -> -1 | J43: CB2 | K43: =K42 -> 939:HK | L43: =J43&K43 -> CB2939:HK
C44: Citibank Account No. 3 | D44: =SUMIF(Download!B:B,L44,Download!G:G) -> 0 | E44: =SUMIF(Download!B:B,L44,Download!H:H) -> 0 | F44: =D44*E44 -> 0 | H44: =E44-1 -> -1 | J44: CB3 | K44: =K43 -> 939:HK | L44: =J44&K44 -> CB3939:HK
C45: Citibank Berry Hill | D45: =SUMIF(Download!B:B,L45,Download!G:G) -> 0 | E45: =SUMIF(Download!B:B,L45,Download!H:H) -> 0 | F45: =D45*E45 -> 0 | H45: =E45-1 -> -1 | J45: CBBH | K45: =K43 -> 939:HK | L45: =J45&K45 -> CBBH939:HK
C46: Bank of Singapore | D46: =SUMIF(Download!B:B,L46,Download!G:G) -> 0 | E46: =SUMIF(Download!B:B,L46,Download!H:H) -> 0 | F46: =D46*E46 -> 0 | H46: =E46-1 -> -1 | J46: BOS | K46: =K45 -> 939:HK | L46: =J46&K46 -> BOS939:HK
C47: Deutsche Bank Personal | D47: =SUMIF(Download!B:B,L47,Download!G:G) -> 0 | E47: =SUMIF(Download!B:B,L47,Download!H:H) -> 0 | F47: =D47*E47 -> 0 | H47: =E47-1 -> -1 | J47: DBPe | K47: =K46 -> 939:HK | L47: =J47&K47 -> DBPe939:HK
...

Sheet ALL
A1: As of September 20, 2022
A4: Citibank Singapore Account No. 1
B5: Account | C5: Code | D5: Shares | E5: Ave. Cost | F5: Amount
B6: =INDEX(Stocks!A:B,MATCH(I6,Stocks!A:A,),2) -> HSBC | C6: 5:HK | D6: =SUMIF(Download!B:B,J6,Download!G:G) -> 0 | E6: =SUMIF(Download!B:B,J6,Download!H:H) -> 0 | F6: =IF(RIGHT(I6,2)="JP","JPY",RIGHT(I6,2)&"D") -> HKD | G6: =D6*E6 -> 0 | H6: CBSG | I6: =C6 -> 5:HK | J6: =H6&I6 -> CBSG5:HK
B7: =INDEX(Stocks!A:B,MATCH(I7,Stocks!A:A,),2) -> Geely Motor | C7: 175:HK | D7: =SUMIF(Download!B:B,J7,Download!G:G) -> 0 | E7: =SUMIF(Download!B:B,J7,Download!H:H) -> 0 | F7: =IF(RIGHT(I7,2)="JP","JPY",RIGHT(I7,2)&"D") -> HKD | G7: =D7*E7 -> 0 | H7: CBSG | I7: =C7 -> 175:HK | J7: =H7&I7 -> CBSG175:HK
B8: =INDEX(Stocks!A:B,MATCH(I8,Stocks!A:A,),2) -> Cathay Pacific | C8: 293:HK | D8: =SUMIF(Download!B:B,J8,Download!G:G) -> 0 | E8: =SUMIF(Download!B:B,J8,Download!H:H) -> 0 | F8: =IF(RIGHT(I8,2)="JP","JPY",RIGHT(I8,2)&"D") -> HKD | G8: =D8*E8 -> 0 | H8: CBSG | I8: =C8 -> 293:HK | J8: =H8&I8 -> CBSG293:HK
B9: =INDEX(Stocks!A:B,MATCH(I9,Stocks!A:A,),2) -> Jiangxi Copper | C9: 358:HK | D9: =SUMIF(Download!B:B,J9,Download!G:G) -> 0 | E9: =SUMIF(Download!B:B,J9,Download!H:H) -> 0 | F9: =IF(RIGHT(I9,2)="JP","JPY",RIGHT(I9,2)&"D") -> HKD | G9: =D9*E9 -> 0 | H9: CBSG | I9: =C9 -> 358:HK | J9: =H9&I9 -> CBSG358:HK
B10: =INDEX(Stocks!A:B,MATCH(I10,Stocks!A:A,),2) -> HK Exchange | C10: 388:HK | D10: =SUMIF(Download!B:B,J10,Download!G:G) -> 0 | E10: =SUMIF(Download!B:B,J10,Download!H:H) -> 0 | F10: =IF(RIGHT(I10,2)="JP","JPY",RIGHT(I10,2)&"D") -> HKD | G10: =D10*E10 -> 0 | H10: CBSG | I10: =C10 -> 388:HK | J10: =H10&I10 -> CBSG388:HK
B11: =INDEX(Stocks!A:B,MATCH(I11,Stocks!A:A,),2) -> Tencent | C11: 700:HK | D11: =SUMIF(Download!B:B,J11,Download!G:G) -> 0 | E11: =SUMIF(Download!B:B,J11,Download!H:H) -> 0 | F11: =IF(RIGHT(I11,2)="JP","JPY",RIGHT(I11,2)&"D") -> HKD | G11: =D11*E11 -> 0 | H11: CBSG | I11: =C11 -> 700:HK | J11: =H11&I11 -> CBSG700:HK
B12: =INDEX(Stocks!A:B,MATCH(I12,Stocks!A:A,),2) -> Semiconductor Mfg | C12: 981:HK | D12: =SUMIF(Download!B:B,J12,Download!G:G) -> 0 | E12: =SUMIF(Download!B:B,J12,Download!H:H) -> 0 | F12: =IF(RIGHT(I12,2)="JP","JPY",RIGHT(I12,2)&"D") -> HKD | G12: =D12*E12 -> 0 | H12: CBSG | I12: =C12 -> 981:HK | J12: =H12&I12 -> CBSG981:HK
B13: =INDEX(Stocks!A:B,MATCH(I13,Stocks!A:A,),2) -> Kuaishou Tech | C13: 1024:HK | D13: =SUMIF(Download!B:B,J13,Download!G:G) -> 0 | E13: =SUMIF(Download!B:B,J13,Download!H:H) -> 0 | F13: =IF(RIGHT(I13,2)="JP","JPY",RIGHT(I13,2)&"D") -> HKD | G13: =D13*E13 -> 0 | H13: CBSG | I13: =C13 -> 1024:HK | J13: =H13&I13 -> CBSG1024:HK
B14: =INDEX(Stocks!A:B,MATCH(I14,Stocks!A:A,),2) -> Xiaomi Corp | C14: 1810:HK | D14: =SUMIF(Download!B:B,J14,Download!G:G) -> 0 | E14: =SUMIF(Download!B:B,J14,Download!H:H) -> 0 | F14: =IF(RIGHT(I14,2)="JP","JPY",RIGHT(I14,2)&"D") -> HKD | G14: =D14*E14 -> 0 | H14: CBSG | I14: =C14 -> 1810:HK | J14: =H14&I14 -> CBSG1810:HK
B15: =INDEX(Stocks!A:B,MATCH(I15,Stocks!A:A,),2) -> Shanghai Fosun | C15: 2196:HK | D15: =SUMIF(Download!B:B,J15,Download!G:G) -> 0 | E15: =SUMIF(Download!B:B,J15,Download!H:H) -> 0 | F15: =IF(RIGHT(I15,2)="JP","JPY",RIGHT(I15,2)&"D") -> HKD | G15: =D15*E15 -> 0 | H15: CBSG | I15: =C15 -> 2196:HK | J15: =H15&I15 -> CBSG2196:HK
B16: =INDEX(Stocks!A:B,MATCH(I16,Stocks!A:A,),2) -> Great Wall Motor | C16: 2333:HK | D16: =SUMIF(Download!B:B,J16,Download!G:G) -> 0 | E16: =SUMIF(Download!B:B,J16,Download!H:H) -> 0 | F16: =IF(RIGHT(I16,2)="JP","JPY",RIGHT(I16,2)&"D") -> HKD | G16: =D16*E16 -> 0 | H16: CBSG | I16: =C16 -> 2333:HK | J16: =H16&I16 -> CBSG2333:HK
B17: =INDEX(Stocks!A:B,MATCH(I17,Stocks!A:A,),2) -> Bank of China | C17: 3988:HK | D17: =SUMIF(Download!B:B,J17,Download!G:G) -> 0 | E17: =SUMIF(Download!B:B,J17,Download!H:H) -> 0 | F17: =IF(RIGHT(I17,2)="JP","JPY",RIGHT(I17,2)&"D") -> HKD | G17: =D17*E17 -> 0 | H17: CBSG | I17: =C17 -> 3988:HK | J17: =H17&I17 -> CBSG3988:HK
... B23: =INDEX(Stocks!A:B,MATCH(I23,Stocks!A:A,),2) -> Coinbase | C23: COIN:US | D23: =SUMIF(Download!B:B,J23,Download!G:G) -> 0 | E23: =SUMIF(Download!B:B,J23,Download!H:H) -> 0 | F23: =IF(RIGHT(I23,2)="JP","JPY",RIGHT(I23,2)&"D") -> USD | G23: =D23*E23 -> 0 | H23: CBSG | I23: =C23 -> COIN:US | J23: =H23&I23 -> CBSGCOIN:US
D24: =SUBTOTAL(9,D5:D23) -> 0
A26: Citibank Account No. 2
B27: Account | C27: Code | D27: Shares | E27: Ave. Cost | F27: Amount
B28: =INDEX(Stocks!A:B,MATCH(I28,Stocks!A:A,),2) -> Geely Motor | C28: 175:HK | D28: =SUMIF(Download!B:B,J28,Download!G:G) -> 0 | E28: =SUMIF(Download!B:B,J28,Download!H:H) -> 0 | F28: =IF(RIGHT(I28,2)="JP","JPY",RIGHT(I28,2)&"D") -> HKD | G28: =D28*E28 -> 0 | H28: CB2 | I28: =C28 -> 175:HK | J28: =H28&I28 -> CB2175:HK
B29: =INDEX(Stocks!A:B,MATCH(I29,Stocks!A:A,),2) -> Jiangxi Copper | C29: 358:HK | D29: =SUMIF(Download!B:B,J29,Download!G:G) -> 0 | E29: =SUMIF(Download!B:B,J29,Download!H:H) -> 0 | F29: =IF(RIGHT(I29,2)="JP","JPY",RIGHT(I29,2)&"D") -> HKD | G29: =D29*E29 -> 0 | H29: CB2 | I29: =C29 -> 358:HK | J29: =H29&I29 -> CB2358:HK
B30: =INDEX(Stocks!A:B,MATCH(I30,Stocks!A:A,),2) -> HK Exchange | C30: 388:HK | D30: =SUMIF(Download!B:B,J30,Download!G:G) -> 0 | E30: =SUMIF(Download!B:B,J30,Download!H:H) -> 0 | F30: =IF(RIGHT(I30,2)="JP","JPY",RIGHT(I30,2)&"D") -> HKD | G30: =D30*E30 -> 0 | H30: CB2 | I30: =C30 -> 388:HK | J30: =H30&I30 -> CB2388:HK
B31: =INDEX(Stocks!A:B,MATCH(I31,Stocks!A:A,),2) -> Tencent | C31: 700:HK | D31: =SUMIF(Download!B:B,J31,Download!G:G) -> 0 | E31: =SUMIF(Download!B:B,J31,Download!H:H) -> 0 | F31: =IF(RIGHT(I31,2)="JP","JPY",RIGHT(I31,2)&"D") -> HKD | G31: =D31*E31 -> 0 | H31: CB2 | I31: =C31 -> 700:HK | J31: =H31&I31 -> CB2700:HK
B32: =INDEX(Stocks!A:B,MATCH(I32,Stocks!A:A,),2) -> Kuaishou Tech | C32: 1024:HK | D32: =SUMIF(Download!B:B,J32,Download!G:G) -> 0 | E32: =SUMIF(Download!B:B,J32,Download!H:H) -> 0 | F32: =IF(RIGHT(I32,2)="JP","JPY",RIGHT(I32,2)&"D") -> HKD | G32: =D32*E32 -> 0 | H32: CB2 | I32: =C32 -> 1024:HK | J32: =H32&I32 -> CB21024:HK
B33: =INDEX(Stocks!A:B,MATCH(I33,Stocks!A:A,),2) -> Agricultural Bank of China | C33: 1288:HK | D33: =SUMIF(Download!B:B,J33,Download!G:G) -> 0 | E33: =SUMIF(Download!B:B,J33,Download!H:H) -> 0 | F33: =IF(RIGHT(I33,2)="JP","JPY",RIGHT(I33,2)&"D") -> HKD | G33: =D33*E33 -> 0 | H33: CB2 | I33: =C33 -> 1288:HK | J33: =H33&I33 -> CB21288:HK
B34: =INDEX(Stocks!A:B,MATCH(I34,Stocks!A:A,),2) -> AIA Group | C34: 1299:HK | D34: =SUMIF(Download!B:B,J34,Download!G:G) -> 0 | E34: =SUMIF(Download!B:B,J34,Download!H:H) -> 0 | F34: =IF(RIGHT(I34,2)="JP","JPY",RIGHT(I34,2)&"D") -> HKD | G34: =D34*E34 -> 0 | H34: CB2 | I34: =C34 -> 1299:HK | J34: =H34&I34 -> CB21299:HK
B35: =INDEX(Stocks!A:B,MATCH(I35,Stocks!A:A,),2) -> Postal Savings Bank of China | C35: 1658:HK | D35: =SUMIF(Download!B:B,J35,Download!G:G) -> 0 | E35: =SUMIF(Download!B:B,J35,Download!H:H) -> 0 | F35: =IF(RIGHT(I35,2)="JP","JPY",RIGHT(I35,2)&"D") -> HKD | G35: =D35*E35 -> 0 | H35: CB2 | I35: =C35 -> 1658:HK | J35: =H35&I35 -> CB21658:HK
B36: =INDEX(Stocks!A:B,MATCH(I36,Stocks!A:A,),2) -> Shanghai Fosun | C36: 2196:HK | D36: =SUMIF(Download!B:B,J36,Download!G:G) -> 0 | E36: =SUMIF(Download!B:B,J36,Download!H:H) -> 0 | F36: =IF(RIGHT(I36,2)="JP","JPY",RIGHT(I36,2)&"D") -> HKD | G36: =D36*E36 -> 0 | H36: CB2 | I36: =C36 -> 2196:HK | J36: =H36&I36 -> CB22196:HK
B37: =INDEX(Stocks!A:B,MATCH(I37,Stocks!A:A,),2) -> Great Wall Motor | C37: 2333:HK | D37: =SUMIF(Download!B:B,J37,Download!G:G) -> 0 | E37: =SUMIF(Download!B:B,J37,Download!H:H) -> 0 | F37: =IF(RIGHT(I37,2)="JP","JPY",RIGHT(I37,2)&"D") -> HKD | G37: =D37*E37 -> 0 | H37: CB2 | I37: =C37 -> 2333:HK | J37: =H37&I37 -> CB22333:HK
B38: =INDEX(Stocks!A:B,MATCH(I38,Stocks!A:A,),2) -> Zijin Mining | C38: 2899:HK | D38: =SUMIF(Download!B:B,J38,Download!G:G) -> 0 | E38: =SUMIF(Download!B:B,J38,Download!H:H) -> 0 | F38: =IF(RIGHT(I38,2)="JP","JPY",RIGHT(I38,2)&"D") -> HKD | G38: =D38*E38 -> 0 | H38: CB2 | I38: =C38 -> 2899:HK | J38: =H38&I38 -> CB22899:HK
B39: =INDEX(Stocks!A:B,MATCH(I39,Stocks!A:A,),2) -> Bank of China | C39: 3988:HK | D39: =SUMIF(Download!B:B,J39,Download!G:G) -> 0 | E39: =SUMIF(Download!B:B,J39,Download!H:H) -> 0 | F39: =IF(RIGHT(I39,2)="JP","JPY",RIGHT(I39,2)&"D") -> HKD | G39: =D39*E39 -> 0 | H39: CB2 | I39: =C39 -> 3988:HK | J39: =H39&I39 -> CB23988:HK
... B44: =INDEX(Stocks!A:B,MATCH(I44,Stocks!A:A,),2) -> Alibaba | C44: 9988:HK | D44: =SUMIF(Download!B:B,J44,Download!G:G) -> 0 | E44: =SUMIF(Download!B:B,J44,Download!H:H) -> 0 | F44: =IF(RIGHT(I44,2)="JP","JPY",RIGHT(I44,2)&"D") -> HKD | G44: =D44*E44 -> 0 | H44: CB2 | I44: =C44 -> 9988:HK | J44: =H44&I44 -> CB29988:HK
D45: =SUBTOTAL(9,D27:D44) -> 0
A47: Citibank Account No. 3
B48: Account | C48: Code | D48: Shares | E48: Ave. Cost | F48: Amount
B49: =INDEX(Stocks!A:B,MATCH(I49,Stocks!A:A,),2) -> HSBC | C49: 5:HK | D49: =SUMIF(Download!B:B,J49,Download!G:G) -> 0 | E49: =SUMIF(Download!B:B,J49,Download!H:H) -> 0 | F49: =IF(RIGHT(I49,2)="JP","JPY",RIGHT(I49,2)&"D") -> HKD | G49: =D49*E49 -> 0 | H49: CB3 | I49: =C49 -> 5:HK | J49: =H49&I49 -> CB35:HK
B50: =INDEX(Stocks!A:B,MATCH(I50,Stocks!A:A,),2) -> Geely Motor | C50: 175:HK | D50: =SUMIF(Download!B:B,J50,Download!G:G) -> 0 | E50: =SUMIF(Download!B:B,J50,Download!H:H) -> 0 | F50: =IF(RIGHT(I50,2)="JP","JPY",RIGHT(I50,2)&"D") -> HKD | G50: =D50*E50 -> 0 | H50: CB3 | I50: =C50 -> 175:HK | J50: =H50&I50 -> CB3175:HK
B51: =INDEX(Stocks!A:B,MATCH(I51,Stocks!A:A,),2) -> Cathay Pacific | C51: 293:HK | D51: =SUMIF(Download!B:B,J51,Download!G:G) -> 0 | E51: =SUMIF(Download!B:B,J51,Download!H:H) -> 0 | F51: =IF(RIGHT(I51,2)="JP","JPY",RIGHT(I51,2)&"D") -> HKD | G51: =D51*E51 -> 0 | H51: CB3 | I51: =C51 -> 293:HK | J51: =H51&I51 -> CB3293:HK
B52: =INDEX(Stocks!A:B,MATCH(I52,Stocks!A:A,),2) -> Jiangxi Copper | C52: 358:HK | D52: =SUMIF(Download!B:B,J52,Download!G:G) -> 0 | E52: =SUMIF(Download!B:B,J52,Download!H:H) -> 0 | F52: =IF(RIGHT(I52,2)="JP","JPY",RIGHT(I52,2)&"D") -> HKD | G52: =D52*E52 -> 0 | H52: CB3 | I52: =C52 -> 358:HK | J52: =H52&I52 -> CB3358:HK
B53: =INDEX(Stocks!A:B,MATCH(I53,Stocks!A:A,),2) -> Beijing Water | C53: 371:HK | D53: =SUMIF(Download!B:B,J53,Download!G:G) -> 0 | E53: =SUMIF(Download!B:B,J53,Download!H:H) -> 0 | F53: =IF(RIGHT(I53,2)="JP","JPY",RIGHT(I53,2)&"D") -> HKD | G53: =D53*E53 -> 0 | H53: CB3 | I53: =C53 -> 371:HK | J53: =H53&I53 -> CB3371:HK
...

Sheet Download
G1: =IFERROR(VALUE(LEFT(D1,LEN(D1)-7)),"") | J1: =SUM(J2:J1048576) -> 0
G2: =IFERROR(VALUE(LEFT(D2,LEN(D2)-7)),"") | H2: =IFERROR(ROUND(VALUE(RIGHT(E2,LEN(E2)-4)),4),"") | J2: =IF(B2="","",MATCH(B2,ALL!J:J,))
G3: =IFERROR(VALUE(LEFT(D3,LEN(D3)-7)),"") | H3: =IFERROR(ROUND(VALUE(RIGHT(E3,LEN(E3)-4)),4),"") | J3: =IF(B3="","",MATCH(B3,ALL!J:J,))
G4: =IFERROR(VALUE(LEFT(D4,LEN(D4)-7)),"") | H4: =IFERROR(ROUND(VALUE(RIGHT(E4,LEN(E4)-4)),4),"") | J4: =IF(B4="","",MATCH(B4,ALL!J:J,))
G5: =IFERROR(VALUE(LEFT(D5,LEN(D5)-7)),"") | H5: =IFERROR(ROUND(VALUE(RIGHT(E5,LEN(E5)-4)),4),"") | J5: =IF(B5="","",MATCH(B5,ALL!J:J,))
G6: =IFERROR(VALUE(LEFT(D6,LEN(D6)-7)),"") | H6: =IFERROR(ROUND(VALUE(RIGHT(E6,LEN(E6)-4)),4),"") | J6: =IF(B6="","",MATCH(B6,ALL!J:J,))
G7: =IFERROR(VALUE(LEFT(D7,LEN(D7)-7)),"") | H7: =IFERROR(ROUND(VALUE(RIGHT(E7,LEN(E7)-4)),4),"") | J7: =IF(B7="","",MATCH(B7,ALL!J:J,))
G8: =IFERROR(VALUE(LEFT(D8,LEN(D8)-7)),"") | H8: =IFERROR(ROUND(VALUE(RIGHT(E8,LEN(E8)-4)),4),"") | J8: =IF(B8="","",MATCH(B8,ALL!J:J,))
G9: =IFERROR(VALUE(LEFT(D9,LEN(D9)-7)),"") | H9: =IFERROR(ROUND(VALUE(RIGHT(E9,LEN(E9)-4)),4),"") | J9: =IF(B9="","",MATCH(B9,ALL!J:J,))
G10: =IFERROR(VALUE(LEFT(D10,LEN(D10)-7)),"") | H10: =IFERROR(ROUND(VALUE(RIGHT(E10,LEN(E10)-4)),4),"") | J10: =IF(B10="","",MATCH(B10,ALL!J:J,))
G11: =IFERROR(VALUE(LEFT(D11,LEN(D11)-7)),"") | H11: =IFERROR(ROUND(VALUE(RIGHT(E11,LEN(E11)-4)),4),"") | J11: =IF(B11="","",MATCH(B11,ALL!J:J,))
G12: =IFERROR(VALUE(LEFT(D12,LEN(D12)-7)),"") | H12: =IFERROR(ROUND(VALUE(RIGHT(E12,LEN(E12)-4)),4),"") | J12: =IF(B12="","",MATCH(B12,ALL!J:J,))
G13: =IFERROR(VALUE(LEFT(D13,LEN(D13)-7)),"") | H13: =IFERROR(ROUND(VALUE(RIGHT(E13,LEN(E13)-4)),4),"") | J13: =IF(B13="","",MATCH(B13,ALL!J:J,))
... G299: =IFERROR(VALUE(LEFT(D299,LEN(D299)-7)),"") | H299: =IFERROR(ROUND(VALUE(RIGHT(E299,LEN(E299)-4)),4),"") | J299: =IF(B299="","",MATCH(B299,ALL!J:J,))

Sheet Heroku
G1: Heroku | J1: Big Boss | M1: Difference | O1: =SUM(M2:M272) -> 0
A2: CB1 | B2: =IF(C2="","",A2&C2) | G2: =IFERROR(VALUE(LEFT(D2,LEN(D2)-7)),"") | H2: =IFERROR(VALUE(RIGHT(E2,LEN(E2)-4)),"") | J2: =IF(B2="","",SUMIF(Download!B:B,B2,Download!G:G)) | K2: =IF(B2="","",SUMIF(Download!B:B,B2,Download!H:H)) | M2: =IF(B2="","",G2-J2) | N2: =IF(B2="","",H2-K2)
A3: CB1 | B3: =IF(C3="","",A3&C3) | G3: =IFERROR(VALUE(LEFT(D3,LEN(D3)-7)),"") | H3: =IFERROR(VALUE(RIGHT(E3,LEN(E3)-4)),"") | J3: =IF(B3="","",SUMIF(Download!B:B,B3,Download!G:G)) | K3: =IF(B3="","",SUMIF(Download!B:B,B3,Download!H:H)) | M3: =IF(B3="","",G3-J3) | N3: =IF(B3="","",H3-K3)
A4: CB1 | B4: =IF(C4="","",A4&C4) | G4: =IFERROR(VALUE(LEFT(D4,LEN(D4)-7)),"") | H4: =IFERROR(VALUE(RIGHT(E4,LEN(E4)-4)),"") | J4: =IF(B4="","",SUMIF(Download!B:B,B4,Download!G:G)) | K4: =IF(B4="","",SUMIF(Download!B:B,B4,Download!H:H)) | M4: =IF(B4="","",G4-J4) | N4: =IF(B4="","",H4-K4)
A5: CB1 | B5: =IF(C5="","",A5&C5) | G5: =IFERROR(VALUE(LEFT(D5,LEN(D5)-7)),"") | H5: =IFERROR(VALUE(RIGHT(E5,LEN(E5)-4)),"") | J5: =IF(B5="","",SUMIF(Download!B:B,B5,Download!G:G)) | K5: =IF(B5="","",SUMIF(Download!B:B,B5,Download!H:H)) | M5: =IF(B5="","",G5-J5) | N5: =IF(B5="","",H5-K5)
A6: CB1 | B6: =IF(C6="","",A6&C6) | G6: =IFERROR(VALUE(LEFT(D6,LEN(D6)-7)),"") | H6: =IFERROR(VALUE(RIGHT(E6,LEN(E6)-4)),"") | J6: =IF(B6="","",SUMIF(Download!B:B,B6,Download!G:G)) | K6: =IF(B6="","",SUMIF(Download!B:B,B6,Download!H:H)) | M6: =IF(B6="","",G6-J6) | N6: =IF(B6="","",H6-K6)
A7: CB1 | B7: =IF(C7="","",A7&C7) | G7: =IFERROR(VALUE(LEFT(D7,LEN(D7)-7)),"") | H7: =IFERROR(VALUE(RIGHT(E7,LEN(E7)-4)),"") | J7: =IF(B7="","",SUMIF(Download!B:B,B7,Download!G:G)) | K7: =IF(B7="","",SUMIF(Download!B:B,B7,Download!H:H)) | M7: =IF(B7="","",G7-J7) | N7: =IF(B7="","",H7-K7)
